Workbook

Sheet P&G-SL
D1: 202601 | E1: 202602 | F1: 202603 | G1: 202604 | H1: 202605 | I1: 202606 | J1: 202607 | K1: 202608 | L1: 202609 | M1: 202610 | N1: 202611 | O1: 202612 | P1: TOTAL
A2: P&G SL 2026 | D2: Enero | E2: Febrero | F2: Marzo | G2: Abril | H2: Mayo | I2: Junio | J2: Julio | K2: Agosto | L2: Septiembre | M2: Octubre | N2: Noviembre | O2: Diciembre | P2: Total
A3: Shopify daily average | Actualizado: 31/07/2026 12:25 h | D3: =IFERROR(IF(DATE(VALUE(LEFT(D$1,4)),VALUE(RIGHT(D$1,2)),1)>TODAY(),"",IF(EOMONTH(DATE(VALUE(LEFT(D$1,4)),VALUE(RIGHT(D$1,2)),1),0)<TODAY(),D6/DAY(EOMONTH(DATE(VALUE(LEFT(D$1,4)),VALUE(RIGHT(D$1,2)),1),0)),D6/MAX(NOW()-DATE(VALUE(LEFT(D$1,4)),VALUE(RIGHT(D$1,2)),1),1/24))),"") | E3: =IFERROR(IF(DATE(VALUE(LEFT(E$1,4)),VALUE(RIGHT(E$1,2)),1)>TODAY(),"",IF(EOMONTH(DATE(VALUE(LEFT(E$1,4)),VALUE(RIGHT(E$1,2)),1),0)<TODAY(),E6/DAY(EOMONTH(DATE(VALUE(LEFT(E$1,4)),VALUE(RIGHT(E$1,2)),1),0)),E6/MAX(NOW()-DATE(VALUE(LEFT(E$1,4)),VALUE(RIGHT(E$1,2)),1),1/24))),"") | F3: =IFERROR(IF(DATE(VALUE(LEFT(F$1,4)),VALUE(RIGHT(F$1,2)),1)>TODAY(),"",IF(EOMONTH(DATE(VALUE(LEFT(F$1,4)),VALUE(RIGHT(F$1,2)),1),0)<TODAY(),F6/DAY(EOMONTH(DATE(VALUE(LEFT(F$1,4)),VALUE(RIGHT(F$1,2)),1),0)),F6/MAX(NOW()-DATE(VALUE(LEFT(F$1,4)),VALUE(RIGHT(F$1,2)),1),1/24))),"") | G3: =IFERROR(IF(DATE(VALUE(LEFT(G$1,4)),VALUE(RIGHT(G$1,2)),1)>TODAY(),"",IF(EOMONTH(DATE(VALUE(LEFT(G$1,4)),VALUE(RIGHT(G$1,2)),1),0)<TODAY(),G6/DAY(EOMONTH(DATE(VALUE(LEFT(G$1,4)),VALUE(RIGHT(G$1,2)),1),0)),G6/MAX(NOW()-DATE(VALUE(LEFT(G$1,4)),VALUE(RIGHT(G$1,2)),1),1/24))),"") | H3: =IFERROR(IF(DATE(VALUE(LEFT(H$1,4)),VALUE(RIGHT(H$1,2)),1)>TODAY(),"",IF(EOMONTH(DATE(VALUE(LEFT(H$1,4)),VALUE(RIGHT(H$1,2)),1),0)<TODAY(),H6/DAY(EOMONTH(DATE(VALUE(LEFT(H$1,4)),VALUE(RIGHT(H$1,2)),1),0)),H6/MAX(NOW()-DATE(VALUE(LEFT(H$1,4)),VALUE(RIGHT(H$1,2)),1),1/24))),"") | I3: =IFERROR(IF(DATE(VALUE(LEFT(I$1,4)),VALUE(RIGHT(I$1,2)),1)>TODAY(),"",IF(EOMONTH(DATE(VALUE(LEFT(I$1,4)),VALUE(RIGHT(I$1,2)),1),0)<TODAY(),I6/DAY(EOMONTH(DATE(VALUE(LEFT(I$1,4)),VALUE(RIGHT(I$1,2)),1),0)),I6/MAX(NOW()-DATE(VALUE(LEFT(I$1,4)),VALUE(RIGHT(I$1,2)),1),1/24))),"") | J3: =IFERROR(IF(DATE(VALUE(LEFT(J$1,4)),VALUE(RIGHT(J$1,2)),1)>TODAY(),"",IF(EOMONTH(DATE(VALUE(LEFT(J$1,4)),VALUE(RIGHT(J$1,2)),1),0)<TODAY(),J6/DAY(EOMONTH(DATE(VALUE(LEFT(J$1,4)),VALUE(RIGHT(J$1,2)),1),0)),J6/MAX(NOW()-DATE(VALUE(LEFT(J$1,4)),VALUE(RIGHT(J$1,2)),1),1/24))),"") | K3: =IFERROR(IF(DATE(VALUE(LEFT(K$1,4)),VALUE(RIGHT(K$1,2)),1)>TODAY(),"",IF(EOMONTH(DATE(VALUE(LEFT(K$1,4)),VALUE(RIGHT(K$1,2)),1),0)<TODAY(),K6/DAY(EOMONTH(DATE(VALUE(LEFT(K$1,4)),VALUE(RIGHT(K$1,2)),1),0)),K6/MAX(NOW()-DATE(VALUE(LEFT(K$1,4)),VALUE(RIGHT(K$1,2)),1),1/24))),"") | ... O3: =IFERROR(IF(DATE(VALUE(LEFT(O$1,4)),VALUE(RIGHT(O$1,2)),1)>TODAY(),"",IF(EOMONTH(DATE(VALUE(LEFT(O$1,4)),VALUE(RIGHT(O$1,2)),1),0)<TODAY(),O6/DAY(EOMONTH(DATE(VALUE(LEFT(O$1,4)),VALUE(RIGHT(O$1,2)),1),0)),O6/MAX(NOW()-DATE(VALUE(LEFT(O$1,4)),VALUE(RIGHT(O$1,2)),1),1/24))),"")
A4: Turnover | D4: =D5+D45+D50 | E4: =E5+E45+E50 | F4: =F5+F45+F50 | G4: =G5+G45+G50 | H4: =H5+H45+H50 | I4: =I5+I45+I50 | J4: =J5+J45+J50 | K4: =K5+K45+K50 | ... O4: =O5+O45+O50 | P4: =SUM(D4:O4)
A5: Product sales | B5: Product sales | D5: =D6+D35+D40+D42 | E5: =E6+E35+E40+E42 | F5: =F6+F35+F40+F42 | G5: =G6+G35+G40+G42 | H5: =H6+H35+H40+H42 | I5: =I6+I35+I40+I42 | J5: =J6+J35+J40+J42 | K5: =K6+K35+K40+K42 | ... O5: =O6+O35+O40+O42 | P5: =SUM(D5:O5)
A6: Shopify | C6: Shopify | D6: =D7+D9+D11+D13+D15+D17+D19+D21+D23+D25+D27+D29+D31+D33 | E6: =E7+E9+E11+E13+E15+E17+E19+E21+E23+E25+E27+E29+E31+E33 | F6: =F7+F9+F11+F13+F15+F17+F19+F21+F23+F25+F27+F29+F31+F33 | G6: =G7+G9+G11+G13+G15+G17+G19+G21+G23+G25+G27+G29+G31+G33 | H6: =H7+H9+H11+H13+H15+H17+H19+H21+H23+H25+H27+H29+H31+H33 | I6: =I7+I9+I11+I13+I15+I17+I19+I21+I23+I25+I27+I29+I31+I33 | J6: =J7+J9+J11+J13+J15+J17+J19+J21+J23+J25+J27+J29+J31+J33 | K6: =K7+K9+K11+K13+K15+K17+K19+K21+K23+K25+K27+K29+K31+K33 | ... O6: =O7+O9+O11+O13+O15+O17+O19+O21+O23+O25+O27+O29+O31+O33 | P6: =SUM(D6:O6) | Q6: ->
A7: ES | C7: ES | D7: =SUMIFS('i-shopify-sl'!$I:$I,'i-shopify-sl'!$A:$A,D$1,'i-shopify-sl'!$C:$C,$C7) | E7: =SUMIFS('i-shopify-sl'!$I:$I,'i-shopify-sl'!$A:$A,E$1,'i-shopify-sl'!$C:$C,$C7) | F7: =SUMIFS('i-shopify-sl'!$I:$I,'i-shopify-sl'!$A:$A,F$1,'i-shopify-sl'!$C:$C,$C7) | G7: =SUMIFS('i-shopify-sl'!$I:$I,'i-shopify-sl'!$A:$A,G$1,'i-shopify-sl'!$C:$C,$C7) | H7: =SUMIFS('i-shopify-sl'!$I:$I,'i-shopify-sl'!$A:$A,H$1,'i-shopify-sl'!$C:$C,$C7) | I7: =SUMIFS('i-shopify-sl'!$I:$I,'i-shopify-sl'!$A:$A,I$1,'i-shopify-sl'!$C:$C,$C7) | J7: =SUMIFS('i-shopify-sl'!$I:$I,'i-shopify-sl'!$A:$A,J$1,'i-shopify-sl'!$C:$C,$C7) | K7: =SUMIFS('i-shopify-sl'!$I:$I,'i-shopify-sl'!$A:$A,K$1,'i-shopify-sl'!$C:$C,$C7) | ... O7: =SUMIFS('i-shopify-sl'!$I:$I,'i-shopify-sl'!$A:$A,O$1,'i-shopify-sl'!$C:$C,$C7) | P7: =SUM(D7:O7) | Q7: ->
A8: avg/day | C8: avg/day | D8: =IFERROR(IF(DATE(VALUE(LEFT(D$1,4)),VALUE(RIGHT(D$1,2)),1)>TODAY(),"",IF(EOMONTH(DATE(VALUE(LEFT(D$1,4)),VALUE(RIGHT(D$1,2)),1),0)<TODAY(),D7/DAY(EOMONTH(DATE(VALUE(LEFT(D$1,4)),VALUE(RIGHT(D$1,2)),1),0)),D7/MAX(NOW()-DATE(VALUE(LEFT(D$1,4)),VALUE(RIGHT(D$1,2)),1),1/24))),"") | E8: =IFERROR(IF(DATE(VALUE(LEFT(E$1,4)),VALUE(RIGHT(E$1,2)),1)>TODAY(),"",IF(EOMONTH(DATE(VALUE(LEFT(E$1,4)),VALUE(RIGHT(E$1,2)),1),0)<TODAY(),E7/DAY(EOMONTH(DATE(VALUE(LEFT(E$1,4)),VALUE(RIGHT(E$1,2)),1),0)),E7/MAX(NOW()-DATE(VALUE(LEFT(E$1,4)),VALUE(RIGHT(E$1,2)),1),1/24))),"") | F8: =IFERROR(IF(DATE(VALUE(LEFT(F$1,4)),VALUE(RIGHT(F$1,2)),1)>TODAY(),"",IF(EOMONTH(DATE(VALUE(LEFT(F$1,4)),VALUE(RIGHT(F$1,2)),1),0)<TODAY(),F7/DAY(EOMONTH(DATE(VALUE(LEFT(F$1,4)),VALUE(RIGHT(F$1,2)),1),0)),F7/MAX(NOW()-DATE(VALUE(LEFT(F$1,4)),VALUE(RIGHT(F$1,2)),1),1/24))),"") | G8: =IFERROR(IF(DATE(VALUE(LEFT(G$1,4)),VALUE(RIGHT(G$1,2)),1)>TODAY(),"",IF(EOMONTH(DATE(VALUE(LEFT(G$1,4)),VALUE(RIGHT(G$1,2)),1),0)<TODAY(),G7/DAY(EOMONTH(DATE(VALUE(LEFT(G$1,4)),VALUE(RIGHT(G$1,2)),1),0)),G7/MAX(NOW()-DATE(VALUE(LEFT(G$1,4)),VALUE(RIGHT(G$1,2)),1),1/24))),"") | H8: =IFERROR(IF(DATE(VALUE(LEFT(H$1,4)),VALUE(RIGHT(H$1,2)),1)>TODAY(),"",IF(EOMONTH(DATE(VALUE(LEFT(H$1,4)),VALUE(RIGHT(H$1,2)),1),0)<TODAY(),H7/DAY(EOMONTH(DATE(VALUE(LEFT(H$1,4)),VALUE(RIGHT(H$1,2)),1),0)),H7/MAX(NOW()-DATE(VALUE(LEFT(H$1,4)),VALUE(RIGHT(H$1,2)),1),1/24))),"") | I8: =IFERROR(IF(DATE(VALUE(LEFT(I$1,4)),VALUE(RIGHT(I$1,2)),1)>TODAY(),"",IF(EOMONTH(DATE(VALUE(LEFT(I$1,4)),VALUE(RIGHT(I$1,2)),1),0)<TODAY(),I7/DAY(EOMONTH(DATE(VALUE(LEFT(I$1,4)),VALUE(RIGHT(I$1,2)),1),0)),I7/MAX(NOW()-DATE(VALUE(LEFT(I$1,4)),VALUE(RIGHT(I$1,2)),1),1/24))),"") | J8: =IFERROR(IF(DATE(VALUE(LEFT(J$1,4)),VALUE(RIGHT(J$1,2)),1)>TODAY(),"",IF(EOMONTH(DATE(VALUE(LEFT(J$1,4)),VALUE(RIGHT(J$1,2)),1),0)<TODAY(),J7/DAY(EOMONTH(DATE(VALUE(LEFT(J$1,4)),VALUE(RIGHT(J$1,2)),1),0)),J7/MAX(NOW()-DATE(VALUE(LEFT(J$1,4)),VALUE(RIGHT(J$1,2)),1),1/24))),"") | K8: =IFERROR(IF(DATE(VALUE(LEFT(K$1,4)),VALUE(RIGHT(K$1,2)),1)>TODAY(),"",IF(EOMONTH(DATE(VALUE(LEFT(K$1,4)),VALUE(RIGHT(K$1,2)),1),0)<TODAY(),K7/DAY(EOMONTH(DATE(VALUE(LEFT(K$1,4)),VALUE(RIGHT(K$1,2)),1),0)),K7/MAX(NOW()-DATE(VALUE(LEFT(K$1,4)),VALUE(RIGHT(K$1,2)),1),1/24))),"") | ... O8: =IFERROR(IF(DATE(VALUE(LEFT(O$1,4)),VALUE(RIGHT(O$1,2)),1)>TODAY(),"",IF(EOMONTH(DATE(VALUE(LEFT(O$1,4)),VALUE(RIGHT(O$1,2)),1),0)<TODAY(),O7/DAY(EOMONTH(DATE(VALUE(LEFT(O$1,4)),VALUE(RIGHT(O$1,2)),1),0)),O7/MAX(NOW()-DATE(VALUE(LEFT(O$1,4)),VALUE(RIGHT(O$1,2)),1),1/24))),"") | P8: =SUM(D8:O8)
A9: FR | C9: FR | D9: =SUMIFS('i-shopify-sl'!$I:$I,'i-shopify-sl'!$A:$A,D$1,'i-shopify-sl'!$C:$C,$C9) | E9: =SUMIFS('i-shopify-sl'!$I:$I,'i-shopify-sl'!$A:$A,E$1,'i-shopify-sl'!$C:$C,$C9) | F9: =SUMIFS('i-shopify-sl'!$I:$I,'i-shopify-sl'!$A:$A,F$1,'i-shopify-sl'!$C:$C,$C9) | G9: =SUMIFS('i-shopify-sl'!$I:$I,'i-shopify-sl'!$A:$A,G$1,'i-shopify-sl'!$C:$C,$C9) | H9: =SUMIFS('i-shopify-sl'!$I:$I,'i-shopify-sl'!$A:$A,H$1,'i-shopify-sl'!$C:$C,$C9) | I9: =SUMIFS('i-shopify-sl'!$I:$I,'i-shopify-sl'!$A:$A,I$1,'i-shopify-sl'!$C:$C,$C9) | J9: =SUMIFS('i-shopify-sl'!$I:$I,'i-shopify-sl'!$A:$A,J$1,'i-shopify-sl'!$C:$C,$C9) | K9: =SUMIFS('i-shopify-sl'!$I:$I,'i-shopify-sl'!$A:$A,K$1,'i-shopify-sl'!$C:$C,$C9) | ... O9: =SUMIFS('i-shopify-sl'!$I:$I,'i-shopify-sl'!$A:$A,O$1,'i-shopify-sl'!$C:$C,$C9) | P9: =SUM(D9:O9) | Q9: ->
A10: avg/day | C10: avg/day | D10: =IFERROR(IF(DATE(VALUE(LEFT(D$1,4)),VALUE(RIGHT(D$1,2)),1)>TODAY(),"",IF(EOMONTH(DATE(VALUE(LEFT(D$1,4)),VALUE(RIGHT(D$1,2)),1),0)<TODAY(),D9/DAY(EOMONTH(DATE(VALUE(LEFT(D$1,4)),VALUE(RIGHT(D$1,2)),1),0)),D9/MAX(NOW()-DATE(VALUE(LEFT(D$1,4)),VALUE(RIGHT(D$1,2)),1),1/24))),"") | E10: =IFERROR(IF(DATE(VALUE(LEFT(E$1,4)),VALUE(RIGHT(E$1,2)),1)>TODAY(),"",IF(EOMONTH(DATE(VALUE(LEFT(E$1,4)),VALUE(RIGHT(E$1,2)),1),0)<TODAY(),E9/DAY(EOMONTH(DATE(VALUE(LEFT(E$1,4)),VALUE(RIGHT(E$1,2)),1),0)),E9/MAX(NOW()-DATE(VALUE(LEFT(E$1,4)),VALUE(RIGHT(E$1,2)),1),1/24))),"") | F10: =IFERROR(IF(DATE(VALUE(LEFT(F$1,4)),VALUE(RIGHT(F$1,2)),1)>TODAY(),"",IF(EOMONTH(DATE(VALUE(LEFT(F$1,4)),VALUE(RIGHT(F$1,2)),1),0)<TODAY(),F9/DAY(EOMONTH(DATE(VALUE(LEFT(F$1,4)),VALUE(RIGHT(F$1,2)),1),0)),F9/MAX(NOW()-DATE(VALUE(LEFT(F$1,4)),VALUE(RIGHT(F$1,2)),1),1/24))),"") | G10: =IFERROR(IF(DATE(VALUE(LEFT(G$1,4)),VALUE(RIGHT(G$1,2)),1)>TODAY(),"",IF(EOMONTH(DATE(VALUE(LEFT(G$1,4)),VALUE(RIGHT(G$1,2)),1),0)<TODAY(),G9/DAY(EOMONTH(DATE(VALUE(LEFT(G$1,4)),VALUE(RIGHT(G$1,2)),1),0)),G9/MAX(NOW()-DATE(VALUE(LEFT(G$1,4)),VALUE(RIGHT(G$1,2)),1),1/24))),"") | H10: =IFERROR(IF(DATE(VALUE(LEFT(H$1,4)),VALUE(RIGHT(H$1,2)),1)>TODAY(),"",IF(EOMONTH(DATE(VALUE(LEFT(H$1,4)),VALUE(RIGHT(H$1,2)),1),0)<TODAY(),H9/DAY(EOMONTH(DATE(VALUE(LEFT(H$1,4)),VALUE(RIGHT(H$1,2)),1),0)),H9/MAX(NOW()-DATE(VALUE(LEFT(H$1,4)),VALUE(RIGHT(H$1,2)),1),1/24))),"") | I10: =IFERROR(IF(DATE(VALUE(LEFT(I$1,4)),VALUE(RIGHT(I$1,2)),1)>TODAY(),"",IF(EOMONTH(DATE(VALUE(LEFT(I$1,4)),VALUE(RIGHT(I$1,2)),1),0)<TODAY(),I9/DAY(EOMONTH(DATE(VALUE(LEFT(I$1,4)),VALUE(RIGHT(I$1,2)),1),0)),I9/MAX(NOW()-DATE(VALUE(LEFT(I$1,4)),VALUE(RIGHT(I$1,2)),1),1/24))),"") | J10: =IFERROR(IF(DATE(VALUE(LEFT(J$1,4)),VALUE(RIGHT(J$1,2)),1)>TODAY(),"",IF(EOMONTH(DATE(VALUE(LEFT(J$1,4)),VALUE(RIGHT(J$1,2)),1),0)<TODAY(),J9/DAY(EOMONTH(DATE(VALUE(LEFT(J$1,4)),VALUE(RIGHT(J$1,2)),1),0)),J9/MAX(NOW()-DATE(VALUE(LEFT(J$1,4)),VALUE(RIGHT(J$1,2)),1),1/24))),"") | K10: =IFERROR(IF(DATE(VALUE(LEFT(K$1,4)),VALUE(RIGHT(K$1,2)),1)>TODAY(),"",IF(EOMONTH(DATE(VALUE(LEFT(K$1,4)),VALUE(RIGHT(K$1,2)),1),0)<TODAY(),K9/DAY(EOMONTH(DATE(VALUE(LEFT(K$1,4)),VALUE(RIGHT(K$1,2)),1),0)),K9/MAX(NOW()-DATE(VALUE(LEFT(K$1,4)),VALUE(RIGHT(K$1,2)),1),1/24))),"") | ... O10: =IFERROR(IF(DATE(VALUE(LEFT(O$1,4)),VALUE(RIGHT(O$1,2)),1)>TODAY(),"",IF(EOMONTH(DATE(VALUE(LEFT(O$1,4)),VALUE(RIGHT(O$1,2)),1),0)<TODAY(),O9/DAY(EOMONTH(DATE(VALUE(LEFT(O$1,4)),VALUE(RIGHT(O$1,2)),1),0)),O9/MAX(NOW()-DATE(VALUE(LEFT(O$1,4)),VALUE(RIGHT(O$1,2)),1),1/24))),"") | P10: =SUM(D10:O10)
A11: DE | C11: DE | D11: =SUMIFS('i-shopify-sl'!$I:$I,'i-shopify-sl'!$A:$A,D$1,'i-shopify-sl'!$C:$C,$C11) | E11: =SUMIFS('i-shopify-sl'!$I:$I,'i-shopify-sl'!$A:$A,E$1,'i-shopify-sl'!$C:$C,$C11) | F11: =SUMIFS('i-shopify-sl'!$I:$I,'i-shopify-sl'!$A:$A,F$1,'i-shopify-sl'!$C:$C,$C11) | G11: =SUMIFS('i-shopify-sl'!$I:$I,'i-shopify-sl'!$A:$A,G$1,'i-shopify-sl'!$C:$C,$C11) | H11: =SUMIFS('i-shopify-sl'!$I:$I,'i-shopify-sl'!$A:$A,H$1,'i-shopify-sl'!$C:$C,$C11) | I11: =SUMIFS('i-shopify-sl'!$I:$I,'i-shopify-sl'!$A:$A,I$1,'i-shopify-sl'!$C:$C,$C11) | J11: =SUMIFS('i-shopify-sl'!$I:$I,'i-shopify-sl'!$A:$A,J$1,'i-shopify-sl'!$C:$C,$C11) | K11: =SUMIFS('i-shopify-sl'!$I:$I,'i-shopify-sl'!$A:$A,K$1,'i-shopify-sl'!$C:$C,$C11) | ... O11: =SUMIFS('i-shopify-sl'!$I:$I,'i-shopify-sl'!$A:$A,O$1,'i-shopify-sl'!$C:$C,$C11) | P11: =SUM(D11:O11) | Q11: ->
A12: avg/day | C12: avg/day | D12: =IFERROR(IF(DATE(VALUE(LEFT(D$1,4)),VALUE(RIGHT(D$1,2)),1)>TODAY(),"",IF(EOMONTH(DATE(VALUE(LEFT(D$1,4)),VALUE(RIGHT(D$1,2)),1),0)<TODAY(),D11/DAY(EOMONTH(DATE(VALUE(LEFT(D$1,4)),VALUE(RIGHT(D$1,2)),1),0)),D11/MAX(NOW()-DATE(VALUE(LEFT(D$1,4)),VALUE(RIGHT(D$1,2)),1),1/24))),"") | E12: =IFERROR(IF(DATE(VALUE(LEFT(E$1,4)),VALUE(RIGHT(E$1,2)),1)>TODAY(),"",IF(EOMONTH(DATE(VALUE(LEFT(E$1,4)),VALUE(RIGHT(E$1,2)),1),0)<TODAY(),E11/DAY(EOMONTH(DATE(VALUE(LEFT(E$1,4)),VALUE(RIGHT(E$1,2)),1),0)),E11/MAX(NOW()-DATE(VALUE(LEFT(E$1,4)),VALUE(RIGHT(E$1,2)),1),1/24))),"") | F12: =IFERROR(IF(DATE(VALUE(LEFT(F$1,4)),VALUE(RIGHT(F$1,2)),1)>TODAY(),"",IF(EOMONTH(DATE(VALUE(LEFT(F$1,4)),VALUE(RIGHT(F$1,2)),1),0)<TODAY(),F11/DAY(EOMONTH(DATE(VALUE(LEFT(F$1,4)),VALUE(RIGHT(F$1,2)),1),0)),F11/MAX(NOW()-DATE(VALUE(LEFT(F$1,4)),VALUE(RIGHT(F$1,2)),1),1/24))),"") | G12: =IFERROR(IF(DATE(VALUE(LEFT(G$1,4)),VALUE(RIGHT(G$1,2)),1)>TODAY(),"",IF(EOMONTH(DATE(VALUE(LEFT(G$1,4)),VALUE(RIGHT(G$1,2)),1),0)<TODAY(),G11/DAY(EOMONTH(DATE(VALUE(LEFT(G$1,4)),VALUE(RIGHT(G$1,2)),1),0)),G11/MAX(NOW()-DATE(VALUE(LEFT(G$1,4)),VALUE(RIGHT(G$1,2)),1),1/24))),"") | H12: =IFERROR(IF(DATE(VALUE(LEFT(H$1,4)),VALUE(RIGHT(H$1,2)),1)>TODAY(),"",IF(EOMONTH(DATE(VALUE(LEFT(H$1,4)),VALUE(RIGHT(H$1,2)),1),0)<TODAY(),H11/DAY(EOMONTH(DATE(VALUE(LEFT(H$1,4)),VALUE(RIGHT(H$1,2)),1),0)),H11/MAX(NOW()-DATE(VALUE(LEFT(H$1,4)),VALUE(RIGHT(H$1,2)),1),1/24))),"") | I12: =IFERROR(IF(DATE(VALUE(LEFT(I$1,4)),VALUE(RIGHT(I$1,2)),1)>TODAY(),"",IF(EOMONTH(DATE(VALUE(LEFT(I$1,4)),VALUE(RIGHT(I$1,2)),1),0)<TODAY(),I11/DAY(EOMONTH(DATE(VALUE(LEFT(I$1,4)),VALUE(RIGHT(I$1,2)),1),0)),I11/MAX(NOW()-DATE(VALUE(LEFT(I$1,4)),VALUE(RIGHT(I$1,2)),1),1/24))),"") | J12: =IFERROR(IF(DATE(VALUE(LEFT(J$1,4)),VALUE(RIGHT(J$1,2)),1)>TODAY(),"",IF(EOMONTH(DATE(VALUE(LEFT(J$1,4)),VALUE(RIGHT(J$1,2)),1),0)<TODAY(),J11/DAY(EOMONTH(DATE(VALUE(LEFT(J$1,4)),VALUE(RIGHT(J$1,2)),1),0)),J11/MAX(NOW()-DATE(VALUE(LEFT(J$1,4)),VALUE(RIGHT(J$1,2)),1),1/24))),"") | K12: =IFERROR(IF(DATE(VALUE(LEFT(K$1,4)),VALUE(RIGHT(K$1,2)),1)>TODAY(),"",IF(EOMONTH(DATE(VALUE(LEFT(K$1,4)),VALUE(RIGHT(K$1,2)),1),0)<TODAY(),K11/DAY(EOMONTH(DATE(VALUE(LEFT(K$1,4)),VALUE(RIGHT(K$1,2)),1),0)),K11/MAX(NOW()-DATE(VALUE(LEFT(K$1,4)),VALUE(RIGHT(K$1,2)),1),1/24))),"") | ... O12: =IFERROR(IF(DATE(VALUE(LEFT(O$1,4)),VALUE(RIGHT(O$1,2)),1)>TODAY(),"",IF(EOMONTH(DATE(VALUE(LEFT(O$1,4)),VALUE(RIGHT(O$1,2)),1),0)<TODAY(),O11/DAY(EOMONTH(DATE(VALUE(LEFT(O$1,4)),VALUE(RIGHT(O$1,2)),1),0)),O11/MAX(NOW()-DATE(VALUE(LEFT(O$1,4)),VALUE(RIGHT(O$1,2)),1),1/24))),"") | P12: =SUM(D12:O12)
A13: IT | C13: IT | D13: =SUMIFS('i-shopify-sl'!$I:$I,'i-shopify-sl'!$A:$A,D$1,'i-shopify-sl'!$C:$C,$C13) | E13: =SUMIFS('i-shopify-sl'!$I:$I,'i-shopify-sl'!$A:$A,E$1,'i-shopify-sl'!$C:$C,$C13) | F13: =SUMIFS('i-shopify-sl'!$I:$I,'i-shopify-sl'!$A:$A,F$1,'i-shopify-sl'!$C:$C,$C13) | G13: =SUMIFS('i-shopify-sl'!$I:$I,'i-shopify-sl'!$A:$A,G$1,'i-shopify-sl'!$C:$C,$C13) | H13: =SUMIFS('i-shopify-sl'!$I:$I,'i-shopify-sl'!$A:$A,H$1,'i-shopify-sl'!$C:$C,$C13) | I13: =SUMIFS('i-shopify-sl'!$I:$I,'i-shopify-sl'!$A:$A,I$1,'i-shopify-sl'!$C:$C,$C13) | J13: =SUMIFS('i-shopify-sl'!$I:$I,'i-shopify-sl'!$A:$A,J$1,'i-shopify-sl'!$C:$C,$C13) | K13: =SUMIFS('i-shopify-sl'!$I:$I,'i-shopify-sl'!$A:$A,K$1,'i-shopify-sl'!$C:$C,$C13) | ... O13: =SUMIFS('i-shopify-sl'!$I:$I,'i-shopify-sl'!$A:$A,O$1,'i-shopify-sl'!$C:$C,$C13) | P13: =SUM(D13:O13) | Q13: ->
A14: avg/day | C14: avg/day | D14: =IFERROR(IF(DATE(VALUE(LEFT(D$1,4)),VALUE(RIGHT(D$1,2)),1)>TODAY(),"",IF(EOMONTH(DATE(VALUE(LEFT(D$1,4)),VALUE(RIGHT(D$1,2)),1),0)<TODAY(),D13/DAY(EOMONTH(DATE(VALUE(LEFT(D$1,4)),VALUE(RIGHT(D$1,2)),1),0)),D13/MAX(NOW()-DATE(VALUE(LEFT(D$1,4)),VALUE(RIGHT(D$1,2)),1),1/24))),"") | E14: =IFERROR(IF(DATE(VALUE(LEFT(E$1,4)),VALUE(RIGHT(E$1,2)),1)>TODAY(),"",IF(EOMONTH(DATE(VALUE(LEFT(E$1,4)),VALUE(RIGHT(E$1,2)),1),0)<TODAY(),E13/DAY(EOMONTH(DATE(VALUE(LEFT(E$1,4)),VALUE(RIGHT(E$1,2)),1),0)),E13/MAX(NOW()-DATE(VALUE(LEFT(E$1,4)),VALUE(RIGHT(E$1,2)),1),1/24))),"") | F14: =IFERROR(IF(DATE(VALUE(LEFT(F$1,4)),VALUE(RIGHT(F$1,2)),1)>TODAY(),"",IF(EOMONTH(DATE(VALUE(LEFT(F$1,4)),VALUE(RIGHT(F$1,2)),1),0)<TODAY(),F13/DAY(EOMONTH(DATE(VALUE(LEFT(F$1,4)),VALUE(RIGHT(F$1,2)),1),0)),F13/MAX(NOW()-DATE(VALUE(LEFT(F$1,4)),VALUE(RIGHT(F$1,2)),1),1/24))),"") | G14: =IFERROR(IF(DATE(VALUE(LEFT(G$1,4)),VALUE(RIGHT(G$1,2)),1)>TODAY(),"",IF(EOMONTH(DATE(VALUE(LEFT(G$1,4)),VALUE(RIGHT(G$1,2)),1),0)<TODAY(),G13/DAY(EOMONTH(DATE(VALUE(LEFT(G$1,4)),VALUE(RIGHT(G$1,2)),1),0)),G13/MAX(NOW()-DATE(VALUE(LEFT(G$1,4)),VALUE(RIGHT(G$1,2)),1),1/24))),"") | H14: =IFERROR(IF(DATE(VALUE(LEFT(H$1,4)),VALUE(RIGHT(H$1,2)),1)>TODAY(),"",IF(EOMONTH(DATE(VALUE(LEFT(H$1,4)),VALUE(RIGHT(H$1,2)),1),0)<TODAY(),H13/DAY(EOMONTH(DATE(VALUE(LEFT(H$1,4)),VALUE(RIGHT(H$1,2)),1),0)),H13/MAX(NOW()-DATE(VALUE(LEFT(H$1,4)),VALUE(RIGHT(H$1,2)),1),1/24))),"") | I14: =IFERROR(IF(DATE(VALUE(LEFT(I$1,4)),VALUE(RIGHT(I$1,2)),1)>TODAY(),"",IF(EOMONTH(DATE(VALUE(LEFT(I$1,4)),VALUE(RIGHT(I$1,2)),1),0)<TODAY(),I13/DAY(EOMONTH(DATE(VALUE(LEFT(I$1,4)),VALUE(RIGHT(I$1,2)),1),0)),I13/MAX(NOW()-DATE(VALUE(LEFT(I$1,4)),VALUE(RIGHT(I$1,2)),1),1/24))),"") | J14: =IFERROR(IF(DATE(VALUE(LEFT(J$1,4)),VALUE(RIGHT(J$1,2)),1)>TODAY(),"",IF(EOMONTH(DATE(VALUE(LEFT(J$1,4)),VALUE(RIGHT(J$1,2)),1),0)<TODAY(),J13/DAY(EOMONTH(DATE(VALUE(LEFT(J$1,4)),VALUE(RIGHT(J$1,2)),1),0)),J13/MAX(NOW()-DATE(VALUE(LEFT(J$1,4)),VALUE(RIGHT(J$1,2)),1),1/24))),"") | K14: =IFERROR(IF(DATE(VALUE(LEFT(K$1,4)),VALUE(RIGHT(K$1,2)),1)>TODAY(),"",IF(EOMONTH(DATE(VALUE(LEFT(K$1,4)),VALUE(RIGHT(K$1,2)),1),0)<TODAY(),K13/DAY(EOMONTH(DATE(VALUE(LEFT(K$1,4)),VALUE(RIGHT(K$1,2)),1),0)),K13/MAX(NOW()-DATE(VALUE(LEFT(K$1,4)),VALUE(RIGHT(K$1,2)),1),1/24))),"") | ... O14: =IFERROR(IF(DATE(VALUE(LEFT(O$1,4)),VALUE(RIGHT(O$1,2)),1)>TODAY(),"",IF(EOMONTH(DATE(VALUE(LEFT(O$1,4)),VALUE(RIGHT(O$1,2)),1),0)<TODAY(),O13/DAY(EOMONTH(DATE(VALUE(LEFT(O$1,4)),VALUE(RIGHT(O$1,2)),1),0)),O13/MAX(NOW()-DATE(VALUE(LEFT(O$1,4)),VALUE(RIGHT(O$1,2)),1),1/24))),"") | P14: =SUM(D14:O14)
A15: AT | C15: AT | D15: =SUMIFS('i-shopify-sl'!$I:$I,'i-shopify-sl'!$A:$A,D$1,'i-shopify-sl'!$C:$C,$C15) | E15: =SUMIFS('i-shopify-sl'!$I:$I,'i-shopify-sl'!$A:$A,E$1,'i-shopify-sl'!$C:$C,$C15) | F15: =SUMIFS('i-shopify-sl'!$I:$I,'i-shopify-sl'!$A:$A,F$1,'i-shopify-sl'!$C:$C,$C15) | G15: =SUMIFS('i-shopify-sl'!$I:$I,'i-shopify-sl'!$A:$A,G$1,'i-shopify-sl'!$C:$C,$C15) | H15: =SUMIFS('i-shopify-sl'!$I:$I,'i-shopify-sl'!$A:$A,H$1,'i-shopify-sl'!$C:$C,$C15) | I15: =SUMIFS('i-shopify-sl'!$I:$I,'i-shopify-sl'!$A:$A,I$1,'i-shopify-sl'!$C:$C,$C15) | J15: =SUMIFS('i-shopify-sl'!$I:$I,'i-shopify-sl'!$A:$A,J$1,'i-shopify-sl'!$C:$C,$C15) | K15: =SUMIFS('i-shopify-sl'!$I:$I,'i-shopify-sl'!$A:$A,K$1,'i-shopify-sl'!$C:$C,$C15) | ... O15: =SUMIFS('i-shopify-sl'!$I:$I,'i-shopify-sl'!$A:$A,O$1,'i-shopify-sl'!$C:$C,$C15) | P15: =SUM(D15:O15) | Q15: ->
A16: avg/day | C16: avg/day | D16: =IFERROR(IF(DATE(VALUE(LEFT(D$1,4)),VALUE(RIGHT(D$1,2)),1)>TODAY(),"",IF(EOMONTH(DATE(VALUE(LEFT(D$1,4)),VALUE(RIGHT(D$1,2)),1),0)<TODAY(),D15/DAY(EOMONTH(DATE(VALUE(LEFT(D$1,4)),VALUE(RIGHT(D$1,2)),1),0)),D15/MAX(NOW()-DATE(VALUE(LEFT(D$1,4)),VALUE(RIGHT(D$1,2)),1),1/24))),"") | E16: =IFERROR(IF(DATE(VALUE(LEFT(E$1,4)),VALUE(RIGHT(E$1,2)),1)>TODAY(),"",IF(EOMONTH(DATE(VALUE(LEFT(E$1,4)),VALUE(RIGHT(E$1,2)),1),0)<TODAY(),E15/DAY(EOMONTH(DATE(VALUE(LEFT(E$1,4)),VALUE(RIGHT(E$1,2)),1),0)),E15/MAX(NOW()-DATE(VALUE(LEFT(E$1,4)),VALUE(RIGHT(E$1,2)),1),1/24))),"") | F16: =IFERROR(IF(DATE(VALUE(LEFT(F$1,4)),VALUE(RIGHT(F$1,2)),1)>TODAY(),"",IF(EOMONTH(DATE(VALUE(LEFT(F$1,4)),VALUE(RIGHT(F$1,2)),1),0)<TODAY(),F15/DAY(EOMONTH(DATE(VALUE(LEFT(F$1,4)),VALUE(RIGHT(F$1,2)),1),0)),F15/MAX(NOW()-DATE(VALUE(LEFT(F$1,4)),VALUE(RIGHT(F$1,2)),1),1/24))),"") | G16: =IFERROR(IF(DATE(VALUE(LEFT(G$1,4)),VALUE(RIGHT(G$1,2)),1)>TODAY(),"",IF(EOMONTH(DATE(VALUE(LEFT(G$1,4)),VALUE(RIGHT(G$1,2)),1),0)<TODAY(),G15/DAY(EOMONTH(DATE(VALUE(LEFT(G$1,4)),VALUE(RIGHT(G$1,2)),1),0)),G15/MAX(NOW()-DATE(VALUE(LEFT(G$1,4)),VALUE(RIGHT(G$1,2)),1),1/24))),"") | H16: =IFERROR(IF(DATE(VALUE(LEFT(H$1,4)),VALUE(RIGHT(H$1,2)),1)>TODAY(),"",IF(EOMONTH(DATE(VALUE(LEFT(H$1,4)),VALUE(RIGHT(H$1,2)),1),0)<TODAY(),H15/DAY(EOMONTH(DATE(VALUE(LEFT(H$1,4)),VALUE(RIGHT(H$1,2)),1),0)),H15/MAX(NOW()-DATE(VALUE(LEFT(H$1,4)),VALUE(RIGHT(H$1,2)),1),1/24))),"") | I16: =IFERROR(IF(DATE(VALUE(LEFT(I$1,4)),VALUE(RIGHT(I$1,2)),1)>TODAY(),"",IF(EOMONTH(DATE(VALUE(LEFT(I$1,4)),VALUE(RIGHT(I$1,2)),1),0)<TODAY(),I15/DAY(EOMONTH(DATE(VALUE(LEFT(I$1,4)),VALUE(RIGHT(I$1,2)),1),0)),I15/MAX(NOW()-DATE(VALUE(LEFT(I$1,4)),VALUE(RIGHT(I$1,2)),1),1/24))),"") | J16: =IFERROR(IF(DATE(VALUE(LEFT(J$1,4)),VALUE(RIGHT(J$1,2)),1)>TODAY(),"",IF(EOMONTH(DATE(VALUE(LEFT(J$1,4)),VALUE(RIGHT(J$1,2)),1),0)<TODAY(),J15/DAY(EOMONTH(DATE(VALUE(LEFT(J$1,4)),VALUE(RIGHT(J$1,2)),1),0)),J15/MAX(NOW()-DATE(VALUE(LEFT(J$1,4)),VALUE(RIGHT(J$1,2)),1),1/24))),"") | K16: =IFERROR(IF(DATE(VALUE(LEFT(K$1,4)),VALUE(RIGHT(K$1,2)),1)>TODAY(),"",IF(EOMONTH(DATE(VALUE(LEFT(K$1,4)),VALUE(RIGHT(K$1,2)),1),0)<TODAY(),K15/DAY(EOMONTH(DATE(VALUE(LEFT(K$1,4)),VALUE(RIGHT(K$1,2)),1),0)),K15/MAX(NOW()-DATE(VALUE(LEFT(K$1,4)),VALUE(RIGHT(K$1,2)),1),1/24))),"") | ... O16: =IFERROR(IF(DATE(VALUE(LEFT(O$1,4)),VALUE(RIGHT(O$1,2)),1)>TODAY(),"",IF(EOMONTH(DATE(VALUE(LEFT(O$1,4)),VALUE(RIGHT(O$1,2)),1),0)<TODAY(),O15/DAY(EOMONTH(DATE(VALUE(LEFT(O$1,4)),VALUE(RIGHT(O$1,2)),1),0)),O15/MAX(NOW()-DATE(VALUE(LEFT(O$1,4)),VALUE(RIGHT(O$1,2)),1),1/24))),"") | P16: =SUM(D16:O16)
A17: BE | C17: BE | D17: =SUMIFS('i-shopify-sl'!$I:$I,'i-shopify-sl'!$A:$A,D$1,'i-shopify-sl'!$C:$C,$C17) | E17: =SUMIFS('i-shopify-sl'!$I:$I,'i-shopify-sl'!$A:$A,E$1,'i-shopify-sl'!$C:$C,$C17) | F17: =SUMIFS('i-shopify-sl'!$I:$I,'i-shopify-sl'!$A:$A,F$1,'i-shopify-sl'!$C:$C,$C17) | G17: =SUMIFS('i-shopify-sl'!$I:$I,'i-shopify-sl'!$A:$A,G$1,'i-shopify-sl'!$C:$C,$C17) | H17: =SUMIFS('i-shopify-sl'!$I:$I,'i-shopify-sl'!$A:$A,H$1,'i-shopify-sl'!$C:$C,$C17) | I17: =SUMIFS('i-shopify-sl'!$I:$I,'i-shopify-sl'!$A:$A,I$1,'i-shopify-sl'!$C:$C,$C17) | J17: =SUMIFS('i-shopify-sl'!$I:$I,'i-shopify-sl'!$A:$A,J$1,'i-shopify-sl'!$C:$C,$C17) | K17: =SUMIFS('i-shopify-sl'!$I:$I,'i-shopify-sl'!$A:$A,K$1,'i-shopify-sl'!$C:$C,$C17) | ... O17: =SUMIFS('i-shopify-sl'!$I:$I,'i-shopify-sl'!$A:$A,O$1,'i-shopify-sl'!$C:$C,$C17) | P17: =SUM(D17:O17) | Q17: ->
A18: avg/day | C18: avg/day | D18: =IFERROR(IF(DATE(VALUE(LEFT(D$1,4)),VALUE(RIGHT(D$1,2)),1)>TODAY(),"",IF(EOMONTH(DATE(VALUE(LEFT(D$1,4)),VALUE(RIGHT(D$1,2)),1),0)<TODAY(),D17/DAY(EOMONTH(DATE(VALUE(LEFT(D$1,4)),VALUE(RIGHT(D$1,2)),1),0)),D17/MAX(NOW()-DATE(VALUE(LEFT(D$1,4)),VALUE(RIGHT(D$1,2)),1),1/24))),"") | E18: =IFERROR(IF(DATE(VALUE(LEFT(E$1,4)),VALUE(RIGHT(E$1,2)),1)>TODAY(),"",IF(EOMONTH(DATE(VALUE(LEFT(E$1,4)),VALUE(RIGHT(E$1,2)),1),0)<TODAY(),E17/DAY(EOMONTH(DATE(VALUE(LEFT(E$1,4)),VALUE(RIGHT(E$1,2)),1),0)),E17/MAX(NOW()-DATE(VALUE(LEFT(E$1,4)),VALUE(RIGHT(E$1,2)),1),1/24))),"") | F18: =IFERROR(IF(DATE(VALUE(LEFT(F$1,4)),VALUE(RIGHT(F$1,2)),1)>TODAY(),"",IF(EOMONTH(DATE(VALUE(LEFT(F$1,4)),VALUE(RIGHT(F$1,2)),1),0)<TODAY(),F17/DAY(EOMONTH(DATE(VALUE(LEFT(F$1,4)),VALUE(RIGHT(F$1,2)),1),0)),F17/MAX(NOW()-DATE(VALUE(LEFT(F$1,4)),VALUE(RIGHT(F$1,2)),1),1/24))),"") | G18: =IFERROR(IF(DATE(VALUE(LEFT(G$1,4)),VALUE(RIGHT(G$1,2)),1)>TODAY(),"",IF(EOMONTH(DATE(VALUE(LEFT(G$1,4)),VALUE(RIGHT(G$1,2)),1),0)<TODAY(),G17/DAY(EOMONTH(DATE(VALUE(LEFT(G$1,4)),VALUE(RIGHT(G$1,2)),1),0)),G17/MAX(NOW()-DATE(VALUE(LEFT(G$1,4)),VALUE(RIGHT(G$1,2)),1),1/24))),"") | H18: =IFERROR(IF(DATE(VALUE(LEFT(H$1,4)),VALUE(RIGHT(H$1,2)),1)>TODAY(),"",IF(EOMONTH(DATE(VALUE(LEFT(H$1,4)),VALUE(RIGHT(H$1,2)),1),0)<TODAY(),H17/DAY(EOMONTH(DATE(VALUE(LEFT(H$1,4)),VALUE(RIGHT(H$1,2)),1),0)),H17/MAX(NOW()-DATE(VALUE(LEFT(H$1,4)),VALUE(RIGHT(H$1,2)),1),1/24))),"") | I18: =IFERROR(IF(DATE(VALUE(LEFT(I$1,4)),VALUE(RIGHT(I$1,2)),1)>TODAY(),"",IF(EOMONTH(DATE(VALUE(LEFT(I$1,4)),VALUE(RIGHT(I$1,2)),1),0)<TODAY(),I17/DAY(EOMONTH(DATE(VALUE(LEFT(I$1,4)),VALUE(RIGHT(I$1,2)),1),0)),I17/MAX(NOW()-DATE(VALUE(LEFT(I$1,4)),VALUE(RIGHT(I$1,2)),1),1/24))),"") | J18: =IFERROR(IF(DATE(VALUE(LEFT(J$1,4)),VALUE(RIGHT(J$1,2)),1)>TODAY(),"",IF(EOMONTH(DATE(VALUE(LEFT(J$1,4)),VALUE(RIGHT(J$1,2)),1),0)<TODAY(),J17/DAY(EOMONTH(DATE(VALUE(LEFT(J$1,4)),VALUE(RIGHT(J$1,2)),1),0)),J17/MAX(NOW()-DATE(VALUE(LEFT(J$1,4)),VALUE(RIGHT(J$1,2)),1),1/24))),"") | K18: =IFERROR(IF(DATE(VALUE(LEFT(K$1,4)),VALUE(RIGHT(K$1,2)),1)>TODAY(),"",IF(EOMONTH(DATE(VALUE(LEFT(K$1,4)),VALUE(RIGHT(K$1,2)),1),0)<TODAY(),K17/DAY(EOMONTH(DATE(VALUE(LEFT(K$1,4)),VALUE(RIGHT(K$1,2)),1),0)),K17/MAX(NOW()-DATE(VALUE(LEFT(K$1,4)),VALUE(RIGHT(K$1,2)),1),1/24))),"") | ... O18: =IFERROR(IF(DATE(VALUE(LEFT(O$1,4)),VALUE(RIGHT(O$1,2)),1)>TODAY(),"",IF(EOMONTH(DATE(VALUE(LEFT(O$1,4)),VALUE(RIGHT(O$1,2)),1),0)<TODAY(),O17/DAY(EOMONTH(DATE(VALUE(LEFT(O$1,4)),VALUE(RIGHT(O$1,2)),1),0)),O17/MAX(NOW()-DATE(VALUE(LEFT(O$1,4)),VALUE(RIGHT(O$1,2)),1),1/24))),"") | P18: =SUM(D18:O18)
A19: NL | C19: NL | D19: =SUMIFS('i-shopify-sl'!$I:$I,'i-shopify-sl'!$A:$A,D$1,'i-shopify-sl'!$C:$C,$C19) | E19: =SUMIFS('i-shopify-sl'!$I:$I,'i-shopify-sl'!$A:$A,E$1,'i-shopify-sl'!$C:$C,$C19) | F19: =SUMIFS('i-shopify-sl'!$I:$I,'i-shopify-sl'!$A:$A,F$1,'i-shopify-sl'!$C:$C,$C19) | G19: =SUMIFS('i-shopify-sl'!$I:$I,'i-shopify-sl'!$A:$A,G$1,'i-shopify-sl'!$C:$C,$C19) | H19: =SUMIFS('i-shopify-sl'!$I:$I,'i-shopify-sl'!$A:$A,H$1,'i-shopify-sl'!$C:$C,$C19) | I19: =SUMIFS('i-shopify-sl'!$I:$I,'i-shopify-sl'!$A:$A,I$1,'i-shopify-sl'!$C:$C,$C19) | J19: =SUMIFS('i-shopify-sl'!$I:$I,'i-shopify-sl'!$A:$A,J$1,'i-shopify-sl'!$C:$C,$C19) | K19: =SUMIFS('i-shopify-sl'!$I:$I,'i-shopify-sl'!$A:$A,K$1,'i-shopify-sl'!$C:$C,$C19) | ... O19: =SUMIFS('i-shopify-sl'!$I:$I,'i-shopify-sl'!$A:$A,O$1,'i-shopify-sl'!$C:$C,$C19) | P19: =SUM(D19:O19) | Q19: ->
A20: avg/day | C20: avg/day | D20: =IFERROR(IF(DATE(VALUE(LEFT(D$1,4)),VALUE(RIGHT(D$1,2)),1)>TODAY(),"",IF(EOMONTH(DATE(VALUE(LEFT(D$1,4)),VALUE(RIGHT(D$1,2)),1),0)<TODAY(),D19/DAY(EOMONTH(DATE(VALUE(LEFT(D$1,4)),VALUE(RIGHT(D$1,2)),1),0)),D19/MAX(NOW()-DATE(VALUE(LEFT(D$1,4)),VALUE(RIGHT(D$1,2)),1),1/24))),"") | E20: =IFERROR(IF(DATE(VALUE(LEFT(E$1,4)),VALUE(RIGHT(E$1,2)),1)>TODAY(),"",IF(EOMONTH(DATE(VALUE(LEFT(E$1,4)),VALUE(RIGHT(E$1,2)),1),0)<TODAY(),E19/DAY(EOMONTH(DATE(VALUE(LEFT(E$1,4)),VALUE(RIGHT(E$1,2)),1),0)),E19/MAX(NOW()-DATE(VALUE(LEFT(E$1,4)),VALUE(RIGHT(E$1,2)),1),1/24))),"") | F20: =IFERROR(IF(DATE(VALUE(LEFT(F$1,4)),VALUE(RIGHT(F$1,2)),1)>TODAY(),"",IF(EOMONTH(DATE(VALUE(LEFT(F$1,4)),VALUE(RIGHT(F$1,2)),1),0)<TODAY(),F19/DAY(EOMONTH(DATE(VALUE(LEFT(F$1,4)),VALUE(RIGHT(F$1,2)),1),0)),F19/MAX(NOW()-DATE(VALUE(LEFT(F$1,4)),VALUE(RIGHT(F$1,2)),1),1/24))),"") | G20: =IFERROR(IF(DATE(VALUE(LEFT(G$1,4)),VALUE(RIGHT(G$1,2)),1)>TODAY(),"",IF(EOMONTH(DATE(VALUE(LEFT(G$1,4)),VALUE(RIGHT(G$1,2)),1),0)<TODAY(),G19/DAY(EOMONTH(DATE(VALUE(LEFT(G$1,4)),VALUE(RIGHT(G$1,2)),1),0)),G19/MAX(NOW()-DATE(VALUE(LEFT(G$1,4)),VALUE(RIGHT(G$1,2)),1),1/24))),"") | H20: =IFERROR(IF(DATE(VALUE(LEFT(H$1,4)),VALUE(RIGHT(H$1,2)),1)>TODAY(),"",IF(EOMONTH(DATE(VALUE(LEFT(H$1,4)),VALUE(RIGHT(H$1,2)),1),0)<TODAY(),H19/DAY(EOMONTH(DATE(VALUE(LEFT(H$1,4)),VALUE(RIGHT(H$1,2)),1),0)),H19/MAX(NOW()-DATE(VALUE(LEFT(H$1,4)),VALUE(RIGHT(H$1,2)),1),1/24))),"") | I20: =IFERROR(IF(DATE(VALUE(LEFT(I$1,4)),VALUE(RIGHT(I$1,2)),1)>TODAY(),"",IF(EOMONTH(DATE(VALUE(LEFT(I$1,4)),VALUE(RIGHT(I$1,2)),1),0)<TODAY(),I19/DAY(EOMONTH(DATE(VALUE(LEFT(I$1,4)),VALUE(RIGHT(I$1,2)),1),0)),I19/MAX(NOW()-DATE(VALUE(LEFT(I$1,4)),VALUE(RIGHT(I$1,2)),1),1/24))),"") | J20: =IFERROR(IF(DATE(VALUE(LEFT(J$1,4)),VALUE(RIGHT(J$1,2)),1)>TODAY(),"",IF(EOMONTH(DATE(VALUE(LEFT(J$1,4)),VALUE(RIGHT(J$1,2)),1),0)<TODAY(),J19/DAY(EOMONTH(DATE(VALUE(LEFT(J$1,4)),VALUE(RIGHT(J$1,2)),1),0)),J19/MAX(NOW()-DATE(VALUE(LEFT(J$1,4)),VALUE(RIGHT(J$1,2)),1),1/24))),"") | K20: =IFERROR(IF(DATE(VALUE(LEFT(K$1,4)),VALUE(RIGHT(K$1,2)),1)>TODAY(),"",IF(EOMONTH(DATE(VALUE(LEFT(K$1,4)),VALUE(RIGHT(K$1,2)),1),0)<TODAY(),K19/DAY(EOMONTH(DATE(VALUE(LEFT(K$1,4)),VALUE(RIGHT(K$1,2)),1),0)),K19/MAX(NOW()-DATE(VALUE(LEFT(K$1,4)),VALUE(RIGHT(K$1,2)),1),1/24))),"") | ... O20: =IFERROR(IF(DATE(VALUE(LEFT(O$1,4)),VALUE(RIGHT(O$1,2)),1)>TODAY(),"",IF(EOMONTH(DATE(VALUE(LEFT(O$1,4)),VALUE(RIGHT(O$1,2)),1),0)<TODAY(),O19/DAY(EOMONTH(DATE(VALUE(LEFT(O$1,4)),VALUE(RIGHT(O$1,2)),1),0)),O19/MAX(NOW()-DATE(VALUE(LEFT(O$1,4)),VALUE(RIGHT(O$1,2)),1),1/24))),"") | P20: =SUM(D20:O20)
A21: PT | C21: PT | D21: =SUMIFS('i-shopify-sl'!$I:$I,'i-shopify-sl'!$A:$A,D$1,'i-shopify-sl'!$C:$C,$C21) | E21: =SUMIFS('i-shopify-sl'!$I:$I,'i-shopify-sl'!$A:$A,E$1,'i-shopify-sl'!$C:$C,$C21) | F21: =SUMIFS('i-shopify-sl'!$I:$I,'i-shopify-sl'!$A:$A,F$1,'i-shopify-sl'!$C:$C,$C21) | G21: =SUMIFS('i-shopify-sl'!$I:$I,'i-shopify-sl'!$A:$A,G$1,'i-shopify-sl'!$C:$C,$C21) | H21: =SUMIFS('i-shopify-sl'!$I:$I,'i-shopify-sl'!$A:$A,H$1,'i-shopify-sl'!$C:$C,$C21) | I21: =SUMIFS('i-shopify-sl'!$I:$I,'i-shopify-sl'!$A:$A,I$1,'i-shopify-sl'!$C:$C,$C21) | J21: =SUMIFS('i-shopify-sl'!$I:$I,'i-shopify-sl'!$A:$A,J$1,'i-shopify-sl'!$C:$C,$C21) | K21: =SUMIFS('i-shopify-sl'!$I:$I,'i-shopify-sl'!$A:$A,K$1,'i-shopify-sl'!$C:$C,$C21) | ... O21: =SUMIFS('i-shopify-sl'!$I:$I,'i-shopify-sl'!$A:$A,O$1,'i-shopify-sl'!$C:$C,$C21) | P21: =SUM(D21:O21) | Q21: ->
A22: avg/day | C22: avg/day | D22: =IFERROR(IF(DATE(VALUE(LEFT(D$1,4)),VALUE(RIGHT(D$1,2)),1)>TODAY(),"",IF(EOMONTH(DATE(VALUE(LEFT(D$1,4)),VALUE(RIGHT(D$1,2)),1),0)<TODAY(),D21/DAY(EOMONTH(DATE(VALUE(LEFT(D$1,4)),VALUE(RIGHT(D$1,2)),1),0)),D21/MAX(NOW()-DATE(VALUE(LEFT(D$1,4)),VALUE(RIGHT(D$1,2)),1),1/24))),"") | E22: =IFERROR(IF(DATE(VALUE(LEFT(E$1,4)),VALUE(RIGHT(E$1,2)),1)>TODAY(),"",IF(EOMONTH(DATE(VALUE(LEFT(E$1,4)),VALUE(RIGHT(E$1,2)),1),0)<TODAY(),E21/DAY(EOMONTH(DATE(VALUE(LEFT(E$1,4)),VALUE(RIGHT(E$1,2)),1),0)),E21/MAX(NOW()-DATE(VALUE(LEFT(E$1,4)),VALUE(RIGHT(E$1,2)),1),1/24))),"") | F22: =IFERROR(IF(DATE(VALUE(LEFT(F$1,4)),VALUE(RIGHT(F$1,2)),1)>TODAY(),"",IF(EOMONTH(DATE(VALUE(LEFT(F$1,4)),VALUE(RIGHT(F$1,2)),1),0)<TODAY(),F21/DAY(EOMONTH(DATE(VALUE(LEFT(F$1,4)),VALUE(RIGHT(F$1,2)),1),0)),F21/MAX(NOW()-DATE(VALUE(LEFT(F$1,4)),VALUE(RIGHT(F$1,2)),1),1/24))),"") | G22: =IFERROR(IF(DATE(VALUE(LEFT(G$1,4)),VALUE(RIGHT(G$1,2)),1)>TODAY(),"",IF(EOMONTH(DATE(VALUE(LEFT(G$1,4)),VALUE(RIGHT(G$1,2)),1),0)<TODAY(),G21/DAY(EOMONTH(DATE(VALUE(LEFT(G$1,4)),VALUE(RIGHT(G$1,2)),1),0)),G21/MAX(NOW()-DATE(VALUE(LEFT(G$1,4)),VALUE(RIGHT(G$1,2)),1),1/24))),"") | H22: =IFERROR(IF(DATE(VALUE(LEFT(H$1,4)),VALUE(RIGHT(H$1,2)),1)>TODAY(),"",IF(EOMONTH(DATE(VALUE(LEFT(H$1,4)),VALUE(RIGHT(H$1,2)),1),0)<TODAY(),H21/DAY(EOMONTH(DATE(VALUE(LEFT(H$1,4)),VALUE(RIGHT(H$1,2)),1),0)),H21/MAX(NOW()-DATE(VALUE(LEFT(H$1,4)),VALUE(RIGHT(H$1,2)),1),1/24))),"") | I22: =IFERROR(IF(DATE(VALUE(LEFT(I$1,4)),VALUE(RIGHT(I$1,2)),1)>TODAY(),"",IF(EOMONTH(DATE(VALUE(LEFT(I$1,4)),VALUE(RIGHT(I$1,2)),1),0)<TODAY(),I21/DAY(EOMONTH(DATE(VALUE(LEFT(I$1,4)),VALUE(RIGHT(I$1,2)),1),0)),I21/MAX(NOW()-DATE(VALUE(LEFT(I$1,4)),VALUE(RIGHT(I$1,2)),1),1/24))),"") | J22: =IFERROR(IF(DATE(VALUE(LEFT(J$1,4)),VALUE(RIGHT(J$1,2)),1)>TODAY(),"",IF(EOMONTH(DATE(VALUE(LEFT(J$1,4)),VALUE(RIGHT(J$1,2)),1),0)<TODAY(),J21/DAY(EOMONTH(DATE(VALUE(LEFT(J$1,4)),VALUE(RIGHT(J$1,2)),1),0)),J21/MAX(NOW()-DATE(VALUE(LEFT(J$1,4)),VALUE(RIGHT(J$1,2)),1),1/24))),"") | K22: =IFERROR(IF(DATE(VALUE(LEFT(K$1,4)),VALUE(RIGHT(K$1,2)),1)>TODAY(),"",IF(EOMONTH(DATE(VALUE(LEFT(K$1,4)),VALUE(RIGHT(K$1,2)),1),0)<TODAY(),K21/DAY(EOMONTH(DATE(VALUE(LEFT(K$1,4)),VALUE(RIGHT(K$1,2)),1),0)),K21/MAX(NOW()-DATE(VALUE(LEFT(K$1,4)),VALUE(RIGHT(K$1,2)),1),1/24))),"") | ... O22: =IFERROR(IF(DATE(VALUE(LEFT(O$1,4)),VALUE(RIGHT(O$1,2)),1)>TODAY(),"",IF(EOMONTH(DATE(VALUE(LEFT(O$1,4)),VALUE(RIGHT(O$1,2)),1),0)<TODAY(),O21/DAY(EOMONTH(DATE(VALUE(LEFT(O$1,4)),VALUE(RIGHT(O$1,2)),1),0)),O21/MAX(NOW()-DATE(VALUE(LEFT(O$1,4)),VALUE(RIGHT(O$1,2)),1),1/24))),"") | P22: =SUM(D22:O22)
A23: CZ | C23: CZ | D23: =SUMIFS('i-shopify-sl'!$I:$I,'i-shopify-sl'!$A:$A,D$1,'i-shopify-sl'!$C:$C,$C23) | E23: =SUMIFS('i-shopify-sl'!$I:$I,'i-shopify-sl'!$A:$A,E$1,'i-shopify-sl'!$C:$C,$C23) | F23: =SUMIFS('i-shopify-sl'!$I:$I,'i-shopify-sl'!$A:$A,F$1,'i-shopify-sl'!$C:$C,$C23) | G23: =SUMIFS('i-shopify-sl'!$I:$I,'i-shopify-sl'!$A:$A,G$1,'i-shopify-sl'!$C:$C,$C23) | H23: =SUMIFS('i-shopify-sl'!$I:$I,'i-shopify-sl'!$A:$A,H$1,'i-shopify-sl'!$C:$C,$C23) | I23: =SUMIFS('i-shopify-sl'!$I:$I,'i-shopify-sl'!$A:$A,I$1,'i-shopify-sl'!$C:$C,$C23) | J23: =SUMIFS('i-shopify-sl'!$I:$I,'i-shopify-sl'!$A:$A,J$1,'i-shopify-sl'!$C:$C,$C23) | K23: =SUMIFS('i-shopify-sl'!$I:$I,'i-shopify-sl'!$A:$A,K$1,'i-shopify-sl'!$C:$C,$C23) | ... O23: =SUMIFS('i-shopify-sl'!$I:$I,'i-shopify-sl'!$A:$A,O$1,'i-shopify-sl'!$C:$C,$C23) | P23: =SUM(D23:O23) | Q23: ->
A24: avg/day | C24: avg/day | D24: =IFERROR(IF(DATE(VALUE(LEFT(D$1,4)),VALUE(RIGHT(D$1,2)),1)>TODAY(),"",IF(EOMONTH(DATE(VALUE(LEFT(D$1,4)),VALUE(RIGHT(D$1,2)),1),0)<TODAY(),D23/DAY(EOMONTH(DATE(VALUE(LEFT(D$1,4)),VALUE(RIGHT(D$1,2)),1),0)),D23/MAX(NOW()-DATE(VALUE(LEFT(D$1,4)),VALUE(RIGHT(D$1,2)),1),1/24))),"") | E24: =IFERROR(IF(DATE(VALUE(LEFT(E$1,4)),VALUE(RIGHT(E$1,2)),1)>TODAY(),"",IF(EOMONTH(DATE(VALUE(LEFT(E$1,4)),VALUE(RIGHT(E$1,2)),1),0)<TODAY(),E23/DAY(EOMONTH(DATE(VALUE(LEFT(E$1,4)),VALUE(RIGHT(E$1,2)),1),0)),E23/MAX(NOW()-DATE(VALUE(LEFT(E$1,4)),VALUE(RIGHT(E$1,2)),1),1/24))),"") | F24: =IFERROR(IF(DATE(VALUE(LEFT(F$1,4)),VALUE(RIGHT(F$1,2)),1)>TODAY(),"",IF(EOMONTH(DATE(VALUE(LEFT(F$1,4)),VALUE(RIGHT(F$1,2)),1),0)<TODAY(),F23/DAY(EOMONTH(DATE(VALUE(LEFT(F$1,4)),VALUE(RIGHT(F$1,2)),1),0)),F23/MAX(NOW()-DATE(VALUE(LEFT(F$1,4)),VALUE(RIGHT(F$1,2)),1),1/24))),"") | G24: =IFERROR(IF(DATE(VALUE(LEFT(G$1,4)),VALUE(RIGHT(G$1,2)),1)>TODAY(),"",IF(EOMONTH(DATE(VALUE(LEFT(G$1,4)),VALUE(RIGHT(G$1,2)),1),0)<TODAY(),G23/DAY(EOMONTH(DATE(VALUE(LEFT(G$1,4)),VALUE(RIGHT(G$1,2)),1),0)),G23/MAX(NOW()-DATE(VALUE(LEFT(G$1,4)),VALUE(RIGHT(G$1,2)),1),1/24))),"") | H24: =IFERROR(IF(DATE(VALUE(LEFT(H$1,4)),VALUE(RIGHT(H$1,2)),1)>TODAY(),"",IF(EOMONTH(DATE(VALUE(LEFT(H$1,4)),VALUE(RIGHT(H$1,2)),1),0)<TODAY(),H23/DAY(EOMONTH(DATE(VALUE(LEFT(H$1,4)),VALUE(RIGHT(H$1,2)),1),0)),H23/MAX(NOW()-DATE(VALUE(LEFT(H$1,4)),VALUE(RIGHT(H$1,2)),1),1/24))),"") | I24: =IFERROR(IF(DATE(VALUE(LEFT(I$1,4)),VALUE(RIGHT(I$1,2)),1)>TODAY(),"",IF(EOMONTH(DATE(VALUE(LEFT(I$1,4)),VALUE(RIGHT(I$1,2)),1),0)<TODAY(),I23/DAY(EOMONTH(DATE(VALUE(LEFT(I$1,4)),VALUE(RIGHT(I$1,2)),1),0)),I23/MAX(NOW()-DATE(VALUE(LEFT(I$1,4)),VALUE(RIGHT(I$1,2)),1),1/24))),"") | J24: =IFERROR(IF(DATE(VALUE(LEFT(J$1,4)),VALUE(RIGHT(J$1,2)),1)>TODAY(),"",IF(EOMONTH(DATE(VALUE(LEFT(J$1,4)),VALUE(RIGHT(J$1,2)),1),0)<TODAY(),J23/DAY(EOMONTH(DATE(VALUE(LEFT(J$1,4)),VALUE(RIGHT(J$1,2)),1),0)),J23/MAX(NOW()-DATE(VALUE(LEFT(J$1,4)),VALUE(RIGHT(J$1,2)),1),1/24))),"") | K24: =IFERROR(IF(DATE(VALUE(LEFT(K$1,4)),VALUE(RIGHT(K$1,2)),1)>TODAY(),"",IF(EOMONTH(DATE(VALUE(LEFT(K$1,4)),VALUE(RIGHT(K$1,2)),1),0)<TODAY(),K23/DAY(EOMONTH(DATE(VALUE(LEFT(K$1,4)),VALUE(RIGHT(K$1,2)),1),0)),K23/MAX(NOW()-DATE(VALUE(LEFT(K$1,4)),VALUE(RIGHT(K$1,2)),1),1/24))),"") | ... O24: =IFERROR(IF(DATE(VALUE(LEFT(O$1,4)),VALUE(RIGHT(O$1,2)),1)>TODAY(),"",IF(EOMONTH(DATE(VALUE(LEFT(O$1,4)),VALUE(RIGHT(O$1,2)),1),0)<TODAY(),O23/DAY(EOMONTH(DATE(VALUE(LEFT(O$1,4)),VALUE(RIGHT(O$1,2)),1),0)),O23/MAX(NOW()-DATE(VALUE(LEFT(O$1,4)),VALUE(RIGHT(O$1,2)),1),1/24))),"") | P24: =SUM(D24:O24)
A25: DK | C25: DK | D25: =SUMIFS('i-shopify-sl'!$I:$I,'i-shopify-sl'!$A:$A,D$1,'i-shopify-sl'!$C:$C,$C25) | E25: =SUMIFS('i-shopify-sl'!$I:$I,'i-shopify-sl'!$A:$A,E$1,'i-shopify-sl'!$C:$C,$C25) | F25: =SUMIFS('i-shopify-sl'!$I:$I,'i-shopify-sl'!$A:$A,F$1,'i-shopify-sl'!$C:$C,$C25) | G25: =SUMIFS('i-shopify-sl'!$I:$I,'i-shopify-sl'!$A:$A,G$1,'i-shopify-sl'!$C:$C,$C25) | H25: =SUMIFS('i-shopify-sl'!$I:$I,'i-shopify-sl'!$A:$A,H$1,'i-shopify-sl'!$C:$C,$C25) | I25: =SUMIFS('i-shopify-sl'!$I:$I,'i-shopify-sl'!$A:$A,I$1,'i-shopify-sl'!$C:$C,$C25) | J25: =SUMIFS('i-shopify-sl'!$I:$I,'i-shopify-sl'!$A:$A,J$1,'i-shopify-sl'!$C:$C,$C25) | K25: =SUMIFS('i-shopify-sl'!$I:$I,'i-shopify-sl'!$A:$A,K$1,'i-shopify-sl'!$C:$C,$C25) | ... O25: =SUMIFS('i-shopify-sl'!$I:$I,'i-shopify-sl'!$A:$A,O$1,'i-shopify-sl'!$C:$C,$C25) | P25: =SUM(D25:O25) | Q25: ->
A26: avg/day | C26: avg/day | D26: =IFERROR(IF(DATE(VALUE(LEFT(D$1,4)),VALUE(RIGHT(D$1,2)),1)>TODAY(),"",IF(EOMONTH(DATE(VALUE(LEFT(D$1,4)),VALUE(RIGHT(D$1,2)),1),0)<TODAY(),D25/DAY(EOMONTH(DATE(VALUE(LEFT(D$1,4)),VALUE(RIGHT(D$1,2)),1),0)),D25/MAX(NOW()-DATE(VALUE(LEFT(D$1,4)),VALUE(RIGHT(D$1,2)),1),1/24))),"") | E26: =IFERROR(IF(DATE(VALUE(LEFT(E$1,4)),VALUE(RIGHT(E$1,2)),1)>TODAY(),"",IF(EOMONTH(DATE(VALUE(LEFT(E$1,4)),VALUE(RIGHT(E$1,2)),1),0)<TODAY(),E25/DAY(EOMONTH(DATE(VALUE(LEFT(E$1,4)),VALUE(RIGHT(E$1,2)),1),0)),E25/MAX(NOW()-DATE(VALUE(LEFT(E$1,4)),VALUE(RIGHT(E$1,2)),1),1/24))),"") | F26: =IFERROR(IF(DATE(VALUE(LEFT(F$1,4)),VALUE(RIGHT(F$1,2)),1)>TODAY(),"",IF(EOMONTH(DATE(VALUE(LEFT(F$1,4)),VALUE(RIGHT(F$1,2)),1),0)<TODAY(),F25/DAY(EOMONTH(DATE(VALUE(LEFT(F$1,4)),VALUE(RIGHT(F$1,2)),1),0)),F25/MAX(NOW()-DATE(VALUE(LEFT(F$1,4)),VALUE(RIGHT(F$1,2)),1),1/24))),"") | G26: =IFERROR(IF(DATE(VALUE(LEFT(G$1,4)),VALUE(RIGHT(G$1,2)),1)>TODAY(),"",IF(EOMONTH(DATE(VALUE(LEFT(G$1,4)),VALUE(RIGHT(G$1,2)),1),0)<TODAY(),G25/DAY(EOMONTH(DATE(VALUE(LEFT(G$1,4)),VALUE(RIGHT(G$1,2)),1),0)),G25/MAX(NOW()-DATE(VALUE(LEFT(G$1,4)),VALUE(RIGHT(G$1,2)),1),1/24))),"") | H26: =IFERROR(IF(DATE(VALUE(LEFT(H$1,4)),VALUE(RIGHT(H$1,2)),1)>TODAY(),"",IF(EOMONTH(DATE(VALUE(LEFT(H$1,4)),VALUE(RIGHT(H$1,2)),1),0)<TODAY(),H25/DAY(EOMONTH(DATE(VALUE(LEFT(H$1,4)),VALUE(RIGHT(H$1,2)),1),0)),H25/MAX(NOW()-DATE(VALUE(LEFT(H$1,4)),VALUE(RIGHT(H$1,2)),1),1/24))),"") | I26: =IFERROR(IF(DATE(VALUE(LEFT(I$1,4)),VALUE(RIGHT(I$1,2)),1)>TODAY(),"",IF(EOMONTH(DATE(VALUE(LEFT(I$1,4)),VALUE(RIGHT(I$1,2)),1),0)<TODAY(),I25/DAY(EOMONTH(DATE(VALUE(LEFT(I$1,4)),VALUE(RIGHT(I$1,2)),1),0)),I25/MAX(NOW()-DATE(VALUE(LEFT(I$1,4)),VALUE(RIGHT(I$1,2)),1),1/24))),"") | J26: =IFERROR(IF(DATE(VALUE(LEFT(J$1,4)),VALUE(RIGHT(J$1,2)),1)>TODAY(),"",IF(EOMONTH(DATE(VALUE(LEFT(J$1,4)),VALUE(RIGHT(J$1,2)),1),0)<TODAY(),J25/DAY(EOMONTH(DATE(VALUE(LEFT(J$1,4)),VALUE(RIGHT(J$1,2)),1),0)),J25/MAX(NOW()-DATE(VALUE(LEFT(J$1,4)),VALUE(RIGHT(J$1,2)),1),1/24))),"") | K26: =IFERROR(IF(DATE(VALUE(LEFT(K$1,4)),VALUE(RIGHT(K$1,2)),1)>TODAY(),"",IF(EOMONTH(DATE(VALUE(LEFT(K$1,4)),VALUE(RIGHT(K$1,2)),1),0)<TODAY(),K25/DAY(EOMONTH(DATE(VALUE(LEFT(K$1,4)),VALUE(RIGHT(K$1,2)),1),0)),K25/MAX(NOW()-DATE(VALUE(LEFT(K$1,4)),VALUE(RIGHT(K$1,2)),1),1/24))),"") | ... O26: =IFERROR(IF(DATE(VALUE(LEFT(O$1,4)),VALUE(RIGHT(O$1,2)),1)>TODAY(),"",IF(EOMONTH(DATE(VALUE(LEFT(O$1,4)),VALUE(RIGHT(O$1,2)),1),0)<TODAY(),O25/DAY(EOMONTH(DATE(VALUE(LEFT(O$1,4)),VALUE(RIGHT(O$1,2)),1),0)),O25/MAX(NOW()-DATE(VALUE(LEFT(O$1,4)),VALUE(RIGHT(O$1,2)),1),1/24))),"") | P26: =SUM(D26:O26)
A27: IE | C27: IE | D27: =SUMIFS('i-shopify-sl'!$I:$I,'i-shopify-sl'!$A:$A,D$1,'i-shopify-sl'!$C:$C,$C27) | E27: =SUMIFS('i-shopify-sl'!$I:$I,'i-shopify-sl'!$A:$A,E$1,'i-shopify-sl'!$C:$C,$C27) | F27: =SUMIFS('i-shopify-sl'!$I:$I,'i-shopify-sl'!$A:$A,F$1,'i-shopify-sl'!$C:$C,$C27) | G27: =SUMIFS('i-shopify-sl'!$I:$I,'i-shopify-sl'!$A:$A,G$1,'i-shopify-sl'!$C:$C,$C27) | H27: =SUMIFS('i-shopify-sl'!$I:$I,'i-shopify-sl'!$A:$A,H$1,'i-shopify-sl'!$C:$C,$C27) | I27: =SUMIFS('i-shopify-sl'!$I:$I,'i-shopify-sl'!$A:$A,I$1,'i-shopify-sl'!$C:$C,$C27) | J27: =SUMIFS('i-shopify-sl'!$I:$I,'i-shopify-sl'!$A:$A,J$1,'i-shopify-sl'!$C:$C,$C27) | K27: =SUMIFS('i-shopify-sl'!$I:$I,'i-shopify-sl'!$A:$A,K$1,'i-shopify-sl'!$C:$C,$C27) | ... O27: =SUMIFS('i-shopify-sl'!$I:$I,'i-shopify-sl'!$A:$A,O$1,'i-shopify-sl'!$C:$C,$C27) | P27: =SUM(D27:O27) | Q27: ->
A28: avg/day | C28: avg/day | D28: =IFERROR(IF(DATE(VALUE(LEFT(D$1,4)),VALUE(RIGHT(D$1,2)),1)>TODAY(),"",IF(EOMONTH(DATE(VALUE(LEFT(D$1,4)),VALUE(RIGHT(D$1,2)),1),0)<TODAY(),D27/DAY(EOMONTH(DATE(VALUE(LEFT(D$1,4)),VALUE(RIGHT(D$1,2)),1),0)),D27/MAX(NOW()-DATE(VALUE(LEFT(D$1,4)),VALUE(RIGHT(D$1,2)),1),1/24))),"") | E28: =IFERROR(IF(DATE(VALUE(LEFT(E$1,4)),VALUE(RIGHT(E$1,2)),1)>TODAY(),"",IF(EOMONTH(DATE(VALUE(LEFT(E$1,4)),VALUE(RIGHT(E$1,2)),1),0)<TODAY(),E27/DAY(EOMONTH(DATE(VALUE(LEFT(E$1,4)),VALUE(RIGHT(E$1,2)),1),0)),E27/MAX(NOW()-DATE(VALUE(LEFT(E$1,4)),VALUE(RIGHT(E$1,2)),1),1/24))),"") | F28: =IFERROR(IF(DATE(VALUE(LEFT(F$1,4)),VALUE(RIGHT(F$1,2)),1)>TODAY(),"",IF(EOMONTH(DATE(VALUE(LEFT(F$1,4)),VALUE(RIGHT(F$1,2)),1),0)<TODAY(),F27/DAY(EOMONTH(DATE(VALUE(LEFT(F$1,4)),VALUE(RIGHT(F$1,2)),1),0)),F27/MAX(NOW()-DATE(VALUE(LEFT(F$1,4)),VALUE(RIGHT(F$1,2)),1),1/24))),"") | G28: =IFERROR(IF(DATE(VALUE(LEFT(G$1,4)),VALUE(RIGHT(G$1,2)),1)>TODAY(),"",IF(EOMONTH(DATE(VALUE(LEFT(G$1,4)),VALUE(RIGHT(G$1,2)),1),0)<TODAY(),G27/DAY(EOMONTH(DATE(VALUE(LEFT(G$1,4)),VALUE(RIGHT(G$1,2)),1),0)),G27/MAX(NOW()-DATE(VALUE(LEFT(G$1,4)),VALUE(RIGHT(G$1,2)),1),1/24))),"") | H28: =IFERROR(IF(DATE(VALUE(LEFT(H$1,4)),VALUE(RIGHT(H$1,2)),1)>TODAY(),"",IF(EOMONTH(DATE(VALUE(LEFT(H$1,4)),VALUE(RIGHT(H$1,2)),1),0)<TODAY(),H27/DAY(EOMONTH(DATE(VALUE(LEFT(H$1,4)),VALUE(RIGHT(H$1,2)),1),0)),H27/MAX(NOW()-DATE(VALUE(LEFT(H$1,4)),VALUE(RIGHT(H$1,2)),1),1/24))),"") | I28: =IFERROR(IF(DATE(VALUE(LEFT(I$1,4)),VALUE(RIGHT(I$1,2)),1)>TODAY(),"",IF(EOMONTH(DATE(VALUE(LEFT(I$1,4)),VALUE(RIGHT(I$1,2)),1),0)<TODAY(),I27/DAY(EOMONTH(DATE(VALUE(LEFT(I$1,4)),VALUE(RIGHT(I$1,2)),1),0)),I27/MAX(NOW()-DATE(VALUE(LEFT(I$1,4)),VALUE(RIGHT(I$1,2)),1),1/24))),"") | J28: =IFERROR(IF(DATE(VALUE(LEFT(J$1,4)),VALUE(RIGHT(J$1,2)),1)>TODAY(),"",IF(EOMONTH(DATE(VALUE(LEFT(J$1,4)),VALUE(RIGHT(J$1,2)),1),0)<TODAY(),J27/DAY(EOMONTH(DATE(VALUE(LEFT(J$1,4)),VALUE(RIGHT(J$1,2)),1),0)),J27/MAX(NOW()-DATE(VALUE(LEFT(J$1,4)),VALUE(RIGHT(J$1,2)),1),1/24))),"") | K28: =IFERROR(IF(DATE(VALUE(LEFT(K$1,4)),VALUE(RIGHT(K$1,2)),1)>TODAY(),"",IF(EOMONTH(DATE(VALUE(LEFT(K$1,4)),VALUE(RIGHT(K$1,2)),1),0)<TODAY(),K27/DAY(EOMONTH(DATE(VALUE(LEFT(K$1,4)),VALUE(RIGHT(K$1,2)),1),0)),K27/MAX(NOW()-DATE(VALUE(LEFT(K$1,4)),VALUE(RIGHT(K$1,2)),1),1/24))),"") | ... O28: =IFERROR(IF(DATE(VALUE(LEFT(O$1,4)),VALUE(RIGHT(O$1,2)),1)>TODAY(),"",IF(EOMONTH(DATE(VALUE(LEFT(O$1,4)),VALUE(RIGHT(O$1,2)),1),0)<TODAY(),O27/DAY(EOMONTH(DATE(VALUE(LEFT(O$1,4)),VALUE(RIGHT(O$1,2)),1),0)),O27/MAX(NOW()-DATE(VALUE(LEFT(O$1,4)),VALUE(RIGHT(O$1,2)),1),1/24))),"") | P28: =SUM(D28:O28)
A29: LU | C29: LU | D29: =SUMIFS('i-shopify-sl'!$I:$I,'i-shopify-sl'!$A:$A,D$1,'i-shopify-sl'!$C:$C,$C29) | E29: =SUMIFS('i-shopify-sl'!$I:$I,'i-shopify-sl'!$A:$A,E$1,'i-shopify-sl'!$C:$C,$C29) | F29: =SUMIFS('i-shopify-sl'!$I:$I,'i-shopify-sl'!$A:$A,F$1,'i-shopify-sl'!$C:$C,$C29) | G29: =SUMIFS('i-shopify-sl'!$I:$I,'i-shopify-sl'!$A:$A,G$1,'i-shopify-sl'!$C:$C,$C29) | H29: =SUMIFS('i-shopify-sl'!$I:$I,'i-shopify-sl'!$A:$A,H$1,'i-shopify-sl'!$C:$C,$C29) | I29: =SUMIFS('i-shopify-sl'!$I:$I,'i-shopify-sl'!$A:$A,I$1,'i-shopify-sl'!$C:$C,$C29) | J29: =SUMIFS('i-shopify-sl'!$I:$I,'i-shopify-sl'!$A:$A,J$1,'i-shopify-sl'!$C:$C,$C29) | K29: =SUMIFS('i-shopify-sl'!$I:$I,'i-shopify-sl'!$A:$A,K$1,'i-shopify-sl'!$C:$C,$C29) | ... O29: =SUMIFS('i-shopify-sl'!$I:$I,'i-shopify-sl'!$A:$A,O$1,'i-shopify-sl'!$C:$C,$C29) | P29: =SUM(D29:O29) | Q29: ->
A30: avg/day | C30: avg/day | D30: =IFERROR(IF(DATE(VALUE(LEFT(D$1,4)),VALUE(RIGHT(D$1,2)),1)>TODAY(),"",IF(EOMONTH(DATE(VALUE(LEFT(D$1,4)),VALUE(RIGHT(D$1,2)),1),0)<TODAY(),D29/DAY(EOMONTH(DATE(VALUE(LEFT(D$1,4)),VALUE(RIGHT(D$1,2)),1),0)),D29/MAX(NOW()-DATE(VALUE(LEFT(D$1,4)),VALUE(RIGHT(D$1,2)),1),1/24))),"") | E30: =IFERROR(IF(DATE(VALUE(LEFT(E$1,4)),VALUE(RIGHT(E$1,2)),1)>TODAY(),"",IF(EOMONTH(DATE(VALUE(LEFT(E$1,4)),VALUE(RIGHT(E$1,2)),1),0)<TODAY(),E29/DAY(EOMONTH(DATE(VALUE(LEFT(E$1,4)),VALUE(RIGHT(E$1,2)),1),0)),E29/MAX(NOW()-DATE(VALUE(LEFT(E$1,4)),VALUE(RIGHT(E$1,2)),1),1/24))),"") | F30: =IFERROR(IF(DATE(VALUE(LEFT(F$1,4)),VALUE(RIGHT(F$1,2)),1)>TODAY(),"",IF(EOMONTH(DATE(VALUE(LEFT(F$1,4)),VALUE(RIGHT(F$1,2)),1),0)<TODAY(),F29/DAY(EOMONTH(DATE(VALUE(LEFT(F$1,4)),VALUE(RIGHT(F$1,2)),1),0)),F29/MAX(NOW()-DATE(VALUE(LEFT(F$1,4)),VALUE(RIGHT(F$1,2)),1),1/24))),"") | G30: =IFERROR(IF(DATE(VALUE(LEFT(G$1,4)),VALUE(RIGHT(G$1,2)),1)>TODAY(),"",IF(EOMONTH(DATE(VALUE(LEFT(G$1,4)),VALUE(RIGHT(G$1,2)),1),0)<TODAY(),G29/DAY(EOMONTH(DATE(VALUE(LEFT(G$1,4)),VALUE(RIGHT(G$1,2)),1),0)),G29/MAX(NOW()-DATE(VALUE(LEFT(G$1,4)),VALUE(RIGHT(G$1,2)),1),1/24))),"") | H30: =IFERROR(IF(DATE(VALUE(LEFT(H$1,4)),VALUE(RIGHT(H$1,2)),1)>TODAY(),"",IF(EOMONTH(DATE(VALUE(LEFT(H$1,4)),VALUE(RIGHT(H$1,2)),1),0)<TODAY(),H29/DAY(EOMONTH(DATE(VALUE(LEFT(H$1,4)),VALUE(RIGHT(H$1,2)),1),0)),H29/MAX(NOW()-DATE(VALUE(LEFT(H$1,4)),VALUE(RIGHT(H$1,2)),1),1/24))),"") | I30: =IFERROR(IF(DATE(VALUE(LEFT(I$1,4)),VALUE(RIGHT(I$1,2)),1)>TODAY(),"",IF(EOMONTH(DATE(VALUE(LEFT(I$1,4)),VALUE(RIGHT(I$1,2)),1),0)<TODAY(),I29/DAY(EOMONTH(DATE(VALUE(LEFT(I$1,4)),VALUE(RIGHT(I$1,2)),1),0)),I29/MAX(NOW()-DATE(VALUE(LEFT(I$1,4)),VALUE(RIGHT(I$1,2)),1),1/24))),"") | J30: =IFERROR(IF(DATE(VALUE(LEFT(J$1,4)),VALUE(RIGHT(J$1,2)),1)>TODAY(),"",IF(EOMONTH(DATE(VALUE(LEFT(J$1,4)),VALUE(RIGHT(J$1,2)),1),0)<TODAY(),J29/DAY(EOMONTH(DATE(VALUE(LEFT(J$1,4)),VALUE(RIGHT(J$1,2)),1),0)),J29/MAX(NOW()-DATE(VALUE(LEFT(J$1,4)),VALUE(RIGHT(J$1,2)),1),1/24))),"") | K30: =IFERROR(IF(DATE(VALUE(LEFT(K$1,4)),VALUE(RIGHT(K$1,2)),1)>TODAY(),"",IF(EOMONTH(DATE(VALUE(LEFT(K$1,4)),VALUE(RIGHT(K$1,2)),1),0)<TODAY(),K29/DAY(EOMONTH(DATE(VALUE(LEFT(K$1,4)),VALUE(RIGHT(K$1,2)),1),0)),K29/MAX(NOW()-DATE(VALUE(LEFT(K$1,4)),VALUE(RIGHT(K$1,2)),1),1/24))),"") | ... O30: =IFERROR(IF(DATE(VALUE(LEFT(O$1,4)),VALUE(RIGHT(O$1,2)),1)>TODAY(),"",IF(EOMONTH(DATE(VALUE(LEFT(O$1,4)),VALUE(RIGHT(O$1,2)),1),0)<TODAY(),O29/DAY(EOMONTH(DATE(VALUE(LEFT(O$1,4)),VALUE(RIGHT(O$1,2)),1),0)),O29/MAX(NOW()-DATE(VALUE(LEFT(O$1,4)),VALUE(RIGHT(O$1,2)),1),1/24))),"") | P30: =SUM(D30:O30)
A31: PL | C31: PL | D31: =SUMIFS('i-shopify-sl'!$I:$I,'i-shopify-sl'!$A:$A,D$1,'i-shopify-sl'!$C:$C,$C31) | E31: =SUMIFS('i-shopify-sl'!$I:$I,'i-shopify-sl'!$A:$A,E$1,'i-shopify-sl'!$C:$C,$C31) | F31: =SUMIFS('i-shopify-sl'!$I:$I,'i-shopify-sl'!$A:$A,F$1,'i-shopify-sl'!$C:$C,$C31) | G31: =SUMIFS('i-shopify-sl'!$I:$I,'i-shopify-sl'!$A:$A,G$1,'i-shopify-sl'!$C:$C,$C31) | H31: =SUMIFS('i-shopify-sl'!$I:$I,'i-shopify-sl'!$A:$A,H$1,'i-shopify-sl'!$C:$C,$C31) | I31: =SUMIFS('i-shopify-sl'!$I:$I,'i-shopify-sl'!$A:$A,I$1,'i-shopify-sl'!$C:$C,$C31) | J31: =SUMIFS('i-shopify-sl'!$I:$I,'i-shopify-sl'!$A:$A,J$1,'i-shopify-sl'!$C:$C,$C31) | K31: =SUMIFS('i-shopify-sl'!$I:$I,'i-shopify-sl'!$A:$A,K$1,'i-shopify-sl'!$C:$C,$C31) | ... O31: =SUMIFS('i-shopify-sl'!$I:$I,'i-shopify-sl'!$A:$A,O$1,'i-shopify-sl'!$C:$C,$C31) | P31: =SUM(D31:O31) | Q31: ->
A32: avg/day | C32: avg/day | D32: =IFERROR(IF(DATE(VALUE(LEFT(D$1,4)),VALUE(RIGHT(D$1,2)),1)>TODAY(),"",IF(EOMONTH(DATE(VALUE(LEFT(D$1,4)),VALUE(RIGHT(D$1,2)),1),0)<TODAY(),D31/DAY(EOMONTH(DATE(VALUE(LEFT(D$1,4)),VALUE(RIGHT(D$1,2)),1),0)),D31/MAX(NOW()-DATE(VALUE(LEFT(D$1,4)),VALUE(RIGHT(D$1,2)),1),1/24))),"") | E32: =IFERROR(IF(DATE(VALUE(LEFT(E$1,4)),VALUE(RIGHT(E$1,2)),1)>TODAY(),"",IF(EOMONTH(DATE(VALUE(LEFT(E$1,4)),VALUE(RIGHT(E$1,2)),1),0)<TODAY(),E31/DAY(EOMONTH(DATE(VALUE(LEFT(E$1,4)),VALUE(RIGHT(E$1,2)),1),0)),E31/MAX(NOW()-DATE(VALUE(LEFT(E$1,4)),VALUE(RIGHT(E$1,2)),1),1/24))),"") | F32: =IFERROR(IF(DATE(VALUE(LEFT(F$1,4)),VALUE(RIGHT(F$1,2)),1)>TODAY(),"",IF(EOMONTH(DATE(VALUE(LEFT(F$1,4)),VALUE(RIGHT(F$1,2)),1),0)<TODAY(),F31/DAY(EOMONTH(DATE(VALUE(LEFT(F$1,4)),VALUE(RIGHT(F$1,2)),1),0)),F31/MAX(NOW()-DATE(VALUE(LEFT(F$1,4)),VALUE(RIGHT(F$1,2)),1),1/24))),"") | G32: =IFERROR(IF(DATE(VALUE(LEFT(G$1,4)),VALUE(RIGHT(G$1,2)),1)>TODAY(),"",IF(EOMONTH(DATE(VALUE(LEFT(G$1,4)),VALUE(RIGHT(G$1,2)),1),0)<TODAY(),G31/DAY(EOMONTH(DATE(VALUE(LEFT(G$1,4)),VALUE(RIGHT(G$1,2)),1),0)),G31/MAX(NOW()-DATE(VALUE(LEFT(G$1,4)),VALUE(RIGHT(G$1,2)),1),1/24))),"") | H32: =IFERROR(IF(DATE(VALUE(LEFT(H$1,4)),VALUE(RIGHT(H$1,2)),1)>TODAY(),"",IF(EOMONTH(DATE(VALUE(LEFT(H$1,4)),VALUE(RIGHT(H$1,2)),1),0)<TODAY(),H31/DAY(EOMONTH(DATE(VALUE(LEFT(H$1,4)),VALUE(RIGHT(H$1,2)),1),0)),H31/MAX(NOW()-DATE(VALUE(LEFT(H$1,4)),VALUE(RIGHT(H$1,2)),1),1/24))),"") | I32: =IFERROR(IF(DATE(VALUE(LEFT(I$1,4)),VALUE(RIGHT(I$1,2)),1)>TODAY(),"",IF(EOMONTH(DATE(VALUE(LEFT(I$1,4)),VALUE(RIGHT(I$1,2)),1),0)<TODAY(),I31/DAY(EOMONTH(DATE(VALUE(LEFT(I$1,4)),VALUE(RIGHT(I$1,2)),1),0)),I31/MAX(NOW()-DATE(VALUE(LEFT(I$1,4)),VALUE(RIGHT(I$1,2)),1),1/24))),"") | J32: =IFERROR(IF(DATE(VALUE(LEFT(J$1,4)),VALUE(RIGHT(J$1,2)),1)>TODAY(),"",IF(EOMONTH(DATE(VALUE(LEFT(J$1,4)),VALUE(RIGHT(J$1,2)),1),0)<TODAY(),J31/DAY(EOMONTH(DATE(VALUE(LEFT(J$1,4)),VALUE(RIGHT(J$1,2)),1),0)),J31/MAX(NOW()-DATE(VALUE(LEFT(J$1,4)),VALUE(RIGHT(J$1,2)),1),1/24))),"") | K32: =IFERROR(IF(DATE(VALUE(LEFT(K$1,4)),VALUE(RIGHT(K$1,2)),1)>TODAY(),"",IF(EOMONTH(DATE(VALUE(LEFT(K$1,4)),VALUE(RIGHT(K$1,2)),1),0)<TODAY(),K31/DAY(EOMONTH(DATE(VALUE(LEFT(K$1,4)),VALUE(RIGHT(K$1,2)),1),0)),K31/MAX(NOW()-DATE(VALUE(LEFT(K$1,4)),VALUE(RIGHT(K$1,2)),1),1/24))),"") | ... O32: =IFERROR(IF(DATE(VALUE(LEFT(O$1,4)),VALUE(RIGHT(O$1,2)),1)>TODAY(),"",IF(EOMONTH(DATE(VALUE(LEFT(O$1,4)),VALUE(RIGHT(O$1,2)),1),0)<TODAY(),O31/DAY(EOMONTH(DATE(VALUE(LEFT(O$1,4)),VALUE(RIGHT(O$1,2)),1),0)),O31/MAX(NOW()-DATE(VALUE(LEFT(O$1,4)),VALUE(RIGHT(O$1,2)),1),1/24))),"") | P32: =SUM(D32:O32)
A33: SE | C33: SE | D33: =SUMIFS('i-shopify-sl'!$I:$I,'i-shopify-sl'!$A:$A,D$1,'i-shopify-sl'!$C:$C,$C33) | E33: =SUMIFS('i-shopify-sl'!$I:$I,'i-shopify-sl'!$A:$A,E$1,'i-shopify-sl'!$C:$C,$C33) | F33: =SUMIFS('i-shopify-sl'!$I:$I,'i-shopify-sl'!$A:$A,F$1,'i-shopify-sl'!$C:$C,$C33) | G33: =SUMIFS('i-shopify-sl'!$I:$I,'i-shopify-sl'!$A:$A,G$1,'i-shopify-sl'!$C:$C,$C33) | H33: =SUMIFS('i-shopify-sl'!$I:$I,'i-shopify-sl'!$A:$A,H$1,'i-shopify-sl'!$C:$C,$C33) | I33: =SUMIFS('i-shopify-sl'!$I:$I,'i-shopify-sl'!$A:$A,I$1,'i-shopify-sl'!$C:$C,$C33) | J33: =SUMIFS('i-shopify-sl'!$I:$I,'i-shopify-sl'!$A:$A,J$1,'i-shopify-sl'!$C:$C,$C33) | K33: =SUMIFS('i-shopify-sl'!$I:$I,'i-shopify-sl'!$A:$A,K$1,'i-shopify-sl'!$C:$C,$C33) | ... O33: =SUMIFS('i-shopify-sl'!$I:$I,'i-shopify-sl'!$A:$A,O$1,'i-shopify-sl'!$C:$C,$C33) | P33: =SUM(D33:O33) | Q33: ->
A34: avg/day | C34: avg/day | D34: =IFERROR(IF(DATE(VALUE(LEFT(D$1,4)),VALUE(RIGHT(D$1,2)),1)>TODAY(),"",IF(EOMONTH(DATE(VALUE(LEFT(D$1,4)),VALUE(RIGHT(D$1,2)),1),0)<TODAY(),D33/DAY(EOMONTH(DATE(VALUE(LEFT(D$1,4)),VALUE(RIGHT(D$1,2)),1),0)),D33/MAX(NOW()-DATE(VALUE(LEFT(D$1,4)),VALUE(RIGHT(D$1,2)),1),1/24))),"") | E34: =IFERROR(IF(DATE(VALUE(LEFT(E$1,4)),VALUE(RIGHT(E$1,2)),1)>TODAY(),"",IF(EOMONTH(DATE(VALUE(LEFT(E$1,4)),VALUE(RIGHT(E$1,2)),1),0)<TODAY(),E33/DAY(EOMONTH(DATE(VALUE(LEFT(E$1,4)),VALUE(RIGHT(E$1,2)),1),0)),E33/MAX(NOW()-DATE(VALUE(LEFT(E$1,4)),VALUE(RIGHT(E$1,2)),1),1/24))),"") | F34: =IFERROR(IF(DATE(VALUE(LEFT(F$1,4)),VALUE(RIGHT(F$1,2)),1)>TODAY(),"",IF(EOMONTH(DATE(VALUE(LEFT(F$1,4)),VALUE(RIGHT(F$1,2)),1),0)<TODAY(),F33/DAY(EOMONTH(DATE(VALUE(LEFT(F$1,4)),VALUE(RIGHT(F$1,2)),1),0)),F33/MAX(NOW()-DATE(VALUE(LEFT(F$1,4)),VALUE(RIGHT(F$1,2)),1),1/24))),"") | G34: =IFERROR(IF(DATE(VALUE(LEFT(G$1,4)),VALUE(RIGHT(G$1,2)),1)>TODAY(),"",IF(EOMONTH(DATE(VALUE(LEFT(G$1,4)),VALUE(RIGHT(G$1,2)),1),0)<TODAY(),G33/DAY(EOMONTH(DATE(VALUE(LEFT(G$1,4)),VALUE(RIGHT(G$1,2)),1),0)),G33/MAX(NOW()-DATE(VALUE(LEFT(G$1,4)),VALUE(RIGHT(G$1,2)),1),1/24))),"") | H34: =IFERROR(IF(DATE(VALUE(LEFT(H$1,4)),VALUE(RIGHT(H$1,2)),1)>TODAY(),"",IF(EOMONTH(DATE(VALUE(LEFT(H$1,4)),VALUE(RIGHT(H$1,2)),1),0)<TODAY(),H33/DAY(EOMONTH(DATE(VALUE(LEFT(H$1,4)),VALUE(RIGHT(H$1,2)),1),0)),H33/MAX(NOW()-DATE(VALUE(LEFT(H$1,4)),VALUE(RIGHT(H$1,2)),1),1/24))),"") | I34: =IFERROR(IF(DATE(VALUE(LEFT(I$1,4)),VALUE(RIGHT(I$1,2)),1)>TODAY(),"",IF(EOMONTH(DATE(VALUE(LEFT(I$1,4)),VALUE(RIGHT(I$1,2)),1),0)<TODAY(),I33/DAY(EOMONTH(DATE(VALUE(LEFT(I$1,4)),VALUE(RIGHT(I$1,2)),1),0)),I33/MAX(NOW()-DATE(VALUE(LEFT(I$1,4)),VALUE(RIGHT(I$1,2)),1),1/24))),"") | J34: =IFERROR(IF(DATE(VALUE(LEFT(J$1,4)),VALUE(RIGHT(J$1,2)),1)>TODAY(),"",IF(EOMONTH(DATE(VALUE(LEFT(J$1,4)),VALUE(RIGHT(J$1,2)),1),0)<TODAY(),J33/DAY(EOMONTH(DATE(VALUE(LEFT(J$1,4)),VALUE(RIGHT(J$1,2)),1),0)),J33/MAX(NOW()-DATE(VALUE(LEFT(J$1,4)),VALUE(RIGHT(J$1,2)),1),1/24))),"") | K34: =IFERROR(IF(DATE(VALUE(LEFT(K$1,4)),VALUE(RIGHT(K$1,2)),1)>TODAY(),"",IF(EOMONTH(DATE(VALUE(LEFT(K$1,4)),VALUE(RIGHT(K$1,2)),1),0)<TODAY(),K33/DAY(EOMONTH(DATE(VALUE(LEFT(K$1,4)),VALUE(RIGHT(K$1,2)),1),0)),K33/MAX(NOW()-DATE(VALUE(LEFT(K$1,4)),VALUE(RIGHT(K$1,2)),1),1/24))),"") | ... O34: =IFERROR(IF(DATE(VALUE(LEFT(O$1,4)),VALUE(RIGHT(O$1,2)),1)>TODAY(),"",IF(EOMONTH(DATE(VALUE(LEFT(O$1,4)),VALUE(RIGHT(O$1,2)),1),0)<TODAY(),O33/DAY(EOMONTH(DATE(VALUE(LEFT(O$1,4)),VALUE(RIGHT(O$1,2)),1),0)),O33/MAX(NOW()-DATE(VALUE(LEFT(O$1,4)),VALUE(RIGHT(O$1,2)),1),1/24))),"") | P34: =SUM(D34:O34)
A35: Marketplaces | C35: Marketplaces | D35: =SUM(D36:D39) | E35: =SUM(E36:E39) | F35: =SUM(F36:F39) | G35: =SUM(G36:G39) | H35: =SUM(H36:H39) | I35: =SUM(I36:I39) | J35: =SUM(J36:J39) | K35: =SUM(K36:K39) | ... O35: =SUM(O36:O39) | P35: =SUM(D35:O35) | Q35: ->
A36: HANNUN | C36: HANNUN | D36: =SUMIFS('i-marketplaces-sl'!$I:$I,'i-marketplaces-sl'!$A:$A,D$1,'i-marketplaces-sl'!$C:$C,"HANNUN") | E36: =SUMIFS('i-marketplaces-sl'!$I:$I,'i-marketplaces-sl'!$A:$A,E$1,'i-marketplaces-sl'!$C:$C,"HANNUN") | F36: =SUMIFS('i-marketplaces-sl'!$I:$I,'i-marketplaces-sl'!$A:$A,F$1,'i-marketplaces-sl'!$C:$C,"HANNUN") | G36: =SUMIFS('i-marketplaces-sl'!$I:$I,'i-marketplaces-sl'!$A:$A,G$1,'i-marketplaces-sl'!$C:$C,"HANNUN") | H36: =SUMIFS('i-marketplaces-sl'!$I:$I,'i-marketplaces-sl'!$A:$A,H$1,'i-marketplaces-sl'!$C:$C,"HANNUN") | I36: =SUMIFS('i-marketplaces-sl'!$I:$I,'i-marketplaces-sl'!$A:$A,I$1,'i-marketplaces-sl'!$C:$C,"HANNUN") | J36: =SUMIFS('i-marketplaces-sl'!$I:$I,'i-marketplaces-sl'!$A:$A,J$1,'i-marketplaces-sl'!$C:$C,"HANNUN") | K36: =SUMIFS('i-marketplaces-sl'!$I:$I,'i-marketplaces-sl'!$A:$A,K$1,'i-marketplaces-sl'!$C:$C,"HANNUN") | ... O36: =SUMIFS('i-marketplaces-sl'!$I:$I,'i-marketplaces-sl'!$A:$A,O$1,'i-marketplaces-sl'!$C:$C,"HANNUN") | P36: =SUM(D36:O36) | Q36: ->
A37: TOASTY | C37: TOASTY | D37: =SUMIFS('i-marketplaces-sl'!$I:$I,'i-marketplaces-sl'!$A:$A,D$1,'i-marketplaces-sl'!$C:$C,"TOASTY") | E37: =SUMIFS('i-marketplaces-sl'!$I:$I,'i-marketplaces-sl'!$A:$A,E$1,'i-marketplaces-sl'!$C:$C,"TOASTY") | F37: =SUMIFS('i-marketplaces-sl'!$I:$I,'i-marketplaces-sl'!$A:$A,F$1,'i-marketplaces-sl'!$C:$C,"TOASTY") | G37: =SUMIFS('i-marketplaces-sl'!$I:$I,'i-marketplaces-sl'!$A:$A,G$1,'i-marketplaces-sl'!$C:$C,"TOASTY") | H37: =SUMIFS('i-marketplaces-sl'!$I:$I,'i-marketplaces-sl'!$A:$A,H$1,'i-marketplaces-sl'!$C:$C,"TOASTY") | I37: =SUMIFS('i-marketplaces-sl'!$I:$I,'i-marketplaces-sl'!$A:$A,I$1,'i-marketplaces-sl'!$C:$C,"TOASTY") | J37: =SUMIFS('i-marketplaces-sl'!$I:$I,'i-marketplaces-sl'!$A:$A,J$1,'i-marketplaces-sl'!$C:$C,"TOASTY") | K37: =SUMIFS('i-marketplaces-sl'!$I:$I,'i-marketplaces-sl'!$A:$A,K$1,'i-marketplaces-sl'!$C:$C,"TOASTY") | ... O37: =SUMIFS('i-marketplaces-sl'!$I:$I,'i-marketplaces-sl'!$A:$A,O$1,'i-marketplaces-sl'!$C:$C,"TOASTY") | P37: =SUM(D37:O37) | Q37: ->
A38: CHOOSE | C38: CHOOSE | D38: =SUMIFS('i-marketplaces-sl'!$I:$I,'i-marketplaces-sl'!$A:$A,D$1,'i-marketplaces-sl'!$C:$C,"CHOOSE") | E38: =SUMIFS('i-marketplaces-sl'!$I:$I,'i-marketplaces-sl'!$A:$A,E$1,'i-marketplaces-sl'!$C:$C,"CHOOSE") | F38: =SUMIFS('i-marketplaces-sl'!$I:$I,'i-marketplaces-sl'!$A:$A,F$1,'i-marketplaces-sl'!$C:$C,"CHOOSE") | G38: =SUMIFS('i-marketplaces-sl'!$I:$I,'i-marketplaces-sl'!$A:$A,G$1,'i-marketplaces-sl'!$C:$C,"CHOOSE") | H38: =SUMIFS('i-marketplaces-sl'!$I:$I,'i-marketplaces-sl'!$A:$A,H$1,'i-marketplaces-sl'!$C:$C,"CHOOSE") | I38: =SUMIFS('i-marketplaces-sl'!$I:$I,'i-marketplaces-sl'!$A:$A,I$1,'i-marketplaces-sl'!$C:$C,"CHOOSE") | J38: =SUMIFS('i-marketplaces-sl'!$I:$I,'i-marketplaces-sl'!$A:$A,J$1,'i-marketplaces-sl'!$C:$C,"CHOOSE") | K38: =SUMIFS('i-marketplaces-sl'!$I:$I,'i-marketplaces-sl'!$A:$A,K$1,'i-marketplaces-sl'!$C:$C,"CHOOSE") | ... O38: =SUMIFS('i-marketplaces-sl'!$I:$I,'i-marketplaces-sl'!$A:$A,O$1,'i-marketplaces-sl'!$C:$C,"CHOOSE") | P38: =SUM(D38:O38) | Q38: ->
A39: MAISONSDUMONDE | C39: MAISONSDUMONDE | D39: =SUMIFS('i-marketplaces-sl'!$I:$I,'i-marketplaces-sl'!$A:$A,D$1,'i-marketplaces-sl'!$C:$C,"MAISONS") | E39: =SUMIFS('i-marketplaces-sl'!$I:$I,'i-marketplaces-sl'!$A:$A,E$1,'i-marketplaces-sl'!$C:$C,"MAISONS") | F39: =SUMIFS('i-marketplaces-sl'!$I:$I,'i-marketplaces-sl'!$A:$A,F$1,'i-marketplaces-sl'!$C:$C,"MAISONS") | G39: =SUMIFS('i-marketplaces-sl'!$I:$I,'i-marketplaces-sl'!$A:$A,G$1,'i-marketplaces-sl'!$C:$C,"MAISONS") | H39: =SUMIFS('i-marketplaces-sl'!$I:$I,'i-marketplaces-sl'!$A:$A,H$1,'i-marketplaces-sl'!$C:$C,"MAISONS") | I39: =SUMIFS('i-marketplaces-sl'!$I:$I,'i-marketplaces-sl'!$A:$A,I$1,'i-marketplaces-sl'!$C:$C,"MAISONS") | J39: =SUMIFS('i-marketplaces-sl'!$I:$I,'i-marketplaces-sl'!$A:$A,J$1,'i-marketplaces-sl'!$C:$C,"MAISONS") | K39: =SUMIFS('i-marketplaces-sl'!$I:$I,'i-marketplaces-sl'!$A:$A,K$1,'i-marketplaces-sl'!$C:$C,"MAISONS") | ... O39: =SUMIFS('i-marketplaces-sl'!$I:$I,'i-marketplaces-sl'!$A:$A,O$1,'i-marketplaces-sl'!$C:$C,"MAISONS") | P39: =SUM(D39:O39) | Q39: ->
A40: Rappels | C40: Rappels | D40: =D41 | E40: =E41 | F40: =F41 | G40: =G41 | H40: =H41 | I40: =I41 | J40: =J41 | K40: =K41 | ... O40: =O41 | P40: =SUM(D40:O40) | Q40: ->
...

Sheet params
A1: <- Volver a P&G-SL
A2: key | B2: value
A3: entity | B3: SL
A4: year | B4: 2026
A5: generated_at_utc | B5: 2026-07-31T10:25:14Z
A6: pct_staff_uk | B6: 0.15
A7: pct_staff_us | B7: 0.1
A8: pct_admin_uk | B8: 0.15
A9: pct_admin_us | B9: 0.1

Sheet i-shopify-sl
A1: <- Volver a P&G-SL
A2: yyyymm | B2: entity | C2: line_item | D2: detail | E2: amount_original | F2: currency_original | G2: reporting_currency | H2: fx_rate | I2: amount_reporting | J2: source | K2: invoice_number | L2: drive_url
A3: 202601 | B3: SL | C3: AT | D3: AT | E3: 5472.24 | F3: EUR | G3: EUR | H3: 1 | I3: 5472.24 | J3: finance.informe_vat_gestorias_detalle
A4: 202601 | B4: SL | C4: BE | D4: BE | E4: 422.71 | F4: EUR | G4: EUR | H4: 1 | I4: 422.71 | J4: finance.informe_vat_gestorias_detalle
A5: 202601 | B5: SL | C5: CZ | D5: CZ | E5: 66.82 | F5: EUR | G5: EUR | H5: 1 | I5: 66.82 | J5: finance.informe_vat_gestorias_detalle
A6: 202601 | B6: SL | C6: DE | D6: DE | E6: 20230.26 | F6: EUR | G6: EUR | H6: 1 | I6: 20230.26 | J6: finance.informe_vat_gestorias_detalle
A7: 202601 | B7: SL | C7: ES | D7: ES | E7: 61194.44 | F7: EUR | G7: EUR | H7: 1 | I7: 61194.44 | J7: finance.informe_vat_gestorias_detalle
A8: 202601 | B8: SL | C8: FR | D8: FR | E8: 25562.13 | F8: EUR | G8: EUR | H8: 1 | I8: 25562.13 | J8: finance.informe_vat_gestorias_detalle
A9: 202601 | B9: SL | C9: IT | D9: IT | E9: 18488.36 | F9: EUR | G9: EUR | H9: 1 | I9: 18488.36 | J9: finance.informe_vat_gestorias_detalle
A10: 202601 | B10: SL | C10: LU | D10: LU | E10: 361.91 | F10: EUR | G10: EUR | H10: 1 | I10: 361.91 | J10: finance.informe_vat_gestorias_detalle
A11: 202601 | B11: SL | C11: NL | D11: NL | E11: 115.58 | F11: EUR | G11: EUR | H11: 1 | I11: 115.58 | J11: finance.informe_vat_gestorias_detalle
A12: 202601 | B12: SL | C12: PT | D12: PT | E12: 729.31 | F12: EUR | G12: EUR | H12: 1 | I12: 729.31 | J12: finance.informe_vat_gestorias_detalle
A13: 202601 | B13: SL | C13: SE | D13: SE | E13: 262.46 | F13: EUR | G13: EUR | H13: 1 | I13: 262.46 | J13: finance.informe_vat_gestorias_detalle
A14: 202602 | B14: SL | C14: AT | D14: AT | E14: 6064.69 | F14: EUR | G14: EUR | H14: 1 | I14: 6064.69 | J14: finance.informe_vat_gestorias_detalle
... A79: 202607 | B79: SL | C79: SE | D79: SE | E79: 2401.98 | F79: EUR | G79: EUR | H79: 1 | I79: 2401.98 | J79: finance.informe_vat_gestorias_detalle

Sheet i-marketplaces-sl
A1: <- Volver a P&G-SL
A2: yyyymm | B2: entity | C2: line_item | D2: detail | E2: amount_original | F2: currency_original | G2: reporting_currency | H2: fx_rate | I2: amount_reporting | J2: source | K2: invoice_number | L2: drive_url
A3: 202601 | B3: SL | C3: HANNUN | D3: orders | E3: 1419.7 | F3: EUR | G3: EUR | H3: 1 | I3: 1419.7 | J3: documents | K3: 2026-0008 | L3: https://drive.google.com/file/d/1SRHb07OiC_DmTMCjAnZJpaif5amIl7Fl/view?usp=drivesdk
