Workbook

Sheet P&G-INC
D1: 202501 | E1: 202502 | F1: 202503 | G1: 202504 | H1: 202505 | I1: 202506 | J1: 202507 | K1: 202508 | L1: 202509 | M1: 202510 | N1: 202511 | O1: 202512 | P1: TOTAL
A2: P&G INC 2025 | D2: Enero | E2: Febrero | F2: Marzo | G2: Abril | H2: Mayo | I2: Junio | J2: Julio | K2: Agosto | L2: Septiembre | M2: Octubre | N2: Noviembre | O2: Diciembre | P2: Total
A3: Actualizado: 30/03/2026 16:18 h
A4: Turnover | D4: =D5+D8 | E4: =E5+E8 | F4: =F5+F8 | G4: =G5+G8 | H4: =H5+H8 | I4: =I5+I8 | J4: =J5+J8 | K4: =K5+K8 | ... O4: =O5+O8 | P4: =SUM(D4:O4)
A5: Product sales | D5: =D6 | E5: =E6 | F5: =F6 | G5: =G6 | H5: =H6 | I5: =I6 | J5: =J6 | K5: =K6 | ... O5: =O6 | P5: =SUM(D5:O5)
A6: Shopify | D6: =SUM(D7:D7) | E6: =SUM(E7:E7) | F6: =SUM(F7:F7) | G6: =SUM(G7:G7) | H6: =SUM(H7:H7) | I6: =SUM(I7:I7) | J6: =SUM(J7:J7) | K6: =SUM(K7:K7) | ... O6: =SUM(O7:O7) | P6: =SUM(D6:O6) | Q6: ->
A7: US | D7: =SUMIFS('i-shopify-inc'!$I:$I,'i-shopify-inc'!$A:$A,D$1,'i-shopify-inc'!$C:$C,TRIM($A7)) | E7: =SUMIFS('i-shopify-inc'!$I:$I,'i-shopify-inc'!$A:$A,E$1,'i-shopify-inc'!$C:$C,TRIM($A7)) | F7: =SUMIFS('i-shopify-inc'!$I:$I,'i-shopify-inc'!$A:$A,F$1,'i-shopify-inc'!$C:$C,TRIM($A7)) | G7: =SUMIFS('i-shopify-inc'!$I:$I,'i-shopify-inc'!$A:$A,G$1,'i-shopify-inc'!$C:$C,TRIM($A7)) | H7: =SUMIFS('i-shopify-inc'!$I:$I,'i-shopify-inc'!$A:$A,H$1,'i-shopify-inc'!$C:$C,TRIM($A7)) | I7: =SUMIFS('i-shopify-inc'!$I:$I,'i-shopify-inc'!$A:$A,I$1,'i-shopify-inc'!$C:$C,TRIM($A7)) | J7: =SUMIFS('i-shopify-inc'!$I:$I,'i-shopify-inc'!$A:$A,J$1,'i-shopify-inc'!$C:$C,TRIM($A7)) | K7: =SUMIFS('i-shopify-inc'!$I:$I,'i-shopify-inc'!$A:$A,K$1,'i-shopify-inc'!$C:$C,TRIM($A7)) | ... O7: =SUMIFS('i-shopify-inc'!$I:$I,'i-shopify-inc'!$A:$A,O$1,'i-shopify-inc'!$C:$C,TRIM($A7)) | P7: =SUM(D7:O7) | Q7: ->
A8: Otros ingresos | P8: =SUM(D8:O8)
P9: =SUM(D9:O9)
A10: Expenses | D10: =D11+D30 | E10: =E11+E30 | F10: =F11+F30 | G10: =G11+G30 | H10: =H11+H30 | I10: =I11+I30 | J10: =J11+J30 | K10: =K11+K30 | ... O10: =O11+O30 | P10: =SUM(D10:O10)
A11: COGS | D11: =D12+D17+D20 | E11: =E12+E17+E20 | F11: =F12+F17+F20 | G11: =G12+G17+G20 | H11: =H12+H17+H20 | I11: =I12+I17+I20 | J11: =J12+J17+J20 | K11: =K12+K17+K20 | ... O11: =O12+O17+O20 | P11: =SUM(D11:O11)
A12: Manufacturing | D12: =SUM(D13:D14)+D15 | E12: =SUM(E13:E14)+E15 | F12: =SUM(F13:F14)+F15 | G12: =SUM(G13:G14)+G15 | H12: =SUM(H13:H14)+H15 | I12: =SUM(I13:I14)+I15 | J12: =SUM(J13:J14)+J15 | K12: =SUM(K13:K14)+K15 | ... O12: =SUM(O13:O14)+O15 | P12: =SUM(D12:O12) | Q12: ->
A13: JONDO | D13: =SUMIFS('g-expenses-inc'!$K:$K,'g-expenses-inc'!$A:$A,D$1,'g-expenses-inc'!$D:$D,"manufacturing",'g-expenses-inc'!$E:$E,TRIM($A13)) | E13: =SUMIFS('g-expenses-inc'!$K:$K,'g-expenses-inc'!$A:$A,E$1,'g-expenses-inc'!$D:$D,"manufacturing",'g-expenses-inc'!$E:$E,TRIM($A13)) | F13: =SUMIFS('g-expenses-inc'!$K:$K,'g-expenses-inc'!$A:$A,F$1,'g-expenses-inc'!$D:$D,"manufacturing",'g-expenses-inc'!$E:$E,TRIM($A13)) | G13: =SUMIFS('g-expenses-inc'!$K:$K,'g-expenses-inc'!$A:$A,G$1,'g-expenses-inc'!$D:$D,"manufacturing",'g-expenses-inc'!$E:$E,TRIM($A13)) | H13: =SUMIFS('g-expenses-inc'!$K:$K,'g-expenses-inc'!$A:$A,H$1,'g-expenses-inc'!$D:$D,"manufacturing",'g-expenses-inc'!$E:$E,TRIM($A13)) | I13: =SUMIFS('g-expenses-inc'!$K:$K,'g-expenses-inc'!$A:$A,I$1,'g-expenses-inc'!$D:$D,"manufacturing",'g-expenses-inc'!$E:$E,TRIM($A13)) | J13: =SUMIFS('g-expenses-inc'!$K:$K,'g-expenses-inc'!$A:$A,J$1,'g-expenses-inc'!$D:$D,"manufacturing",'g-expenses-inc'!$E:$E,TRIM($A13)) | K13: =SUMIFS('g-expenses-inc'!$K:$K,'g-expenses-inc'!$A:$A,K$1,'g-expenses-inc'!$D:$D,"manufacturing",'g-expenses-inc'!$E:$E,TRIM($A13)) | ... O13: =SUMIFS('g-expenses-inc'!$K:$K,'g-expenses-inc'!$A:$A,O$1,'g-expenses-inc'!$D:$D,"manufacturing",'g-expenses-inc'!$E:$E,TRIM($A13)) | P13: =SUM(D13:O13) | Q13: ->
A14: TGI | D14: =SUMIFS('g-expenses-inc'!$K:$K,'g-expenses-inc'!$A:$A,D$1,'g-expenses-inc'!$D:$D,"manufacturing",'g-expenses-inc'!$E:$E,TRIM($A14)) | E14: =SUMIFS('g-expenses-inc'!$K:$K,'g-expenses-inc'!$A:$A,E$1,'g-expenses-inc'!$D:$D,"manufacturing",'g-expenses-inc'!$E:$E,TRIM($A14)) | F14: =SUMIFS('g-expenses-inc'!$K:$K,'g-expenses-inc'!$A:$A,F$1,'g-expenses-inc'!$D:$D,"manufacturing",'g-expenses-inc'!$E:$E,TRIM($A14)) | G14: =SUMIFS('g-expenses-inc'!$K:$K,'g-expenses-inc'!$A:$A,G$1,'g-expenses-inc'!$D:$D,"manufacturing",'g-expenses-inc'!$E:$E,TRIM($A14)) | H14: =SUMIFS('g-expenses-inc'!$K:$K,'g-expenses-inc'!$A:$A,H$1,'g-expenses-inc'!$D:$D,"manufacturing",'g-expenses-inc'!$E:$E,TRIM($A14)) | I14: =SUMIFS('g-expenses-inc'!$K:$K,'g-expenses-inc'!$A:$A,I$1,'g-expenses-inc'!$D:$D,"manufacturing",'g-expenses-inc'!$E:$E,TRIM($A14)) | J14: =SUMIFS('g-expenses-inc'!$K:$K,'g-expenses-inc'!$A:$A,J$1,'g-expenses-inc'!$D:$D,"manufacturing",'g-expenses-inc'!$E:$E,TRIM($A14)) | K14: =SUMIFS('g-expenses-inc'!$K:$K,'g-expenses-inc'!$A:$A,K$1,'g-expenses-inc'!$D:$D,"manufacturing",'g-expenses-inc'!$E:$E,TRIM($A14)) | ... O14: =SUMIFS('g-expenses-inc'!$K:$K,'g-expenses-inc'!$A:$A,O$1,'g-expenses-inc'!$D:$D,"manufacturing",'g-expenses-inc'!$E:$E,TRIM($A14)) | P14: =SUM(D14:O14)
A15: Consumo marcos | J15: 603.18 | K15: 2121.84 | L15: 2298.62 | M15: 2391.63 | N15: 2600.76 | O15: 807.18 | P15: =SUM(D15:O15)
A16: % Manufacturing / sales | D16: =IFERROR(D12/D5,0) | E16: =IFERROR(E12/E5,0) | F16: =IFERROR(F12/F5,0) | G16: =IFERROR(G12/G5,0) | H16: =IFERROR(H12/H5,0) | I16: =IFERROR(I12/I5,0) | J16: =IFERROR(J12/J5,0) | K16: =IFERROR(K12/K5,0) | ... O16: =IFERROR(O12/O5,0) | P16: =SUM(D16:O16)
A17: Logistics | D17: =SUM(D18:D18) | E17: =SUM(E18:E18) | F17: =SUM(F18:F18) | G17: =SUM(G18:G18) | H17: =SUM(H18:H18) | I17: =SUM(I18:I18) | J17: =SUM(J18:J18) | K17: =SUM(K18:K18) | ... O17: =SUM(O18:O18) | P17: =SUM(D17:O17) | Q17: ->
A18: TGI | D18: =SUMIFS('g-expenses-inc'!$K:$K,'g-expenses-inc'!$A:$A,D$1,'g-expenses-inc'!$D:$D,"logistics",'g-expenses-inc'!$E:$E,TRIM($A18)) | E18: =SUMIFS('g-expenses-inc'!$K:$K,'g-expenses-inc'!$A:$A,E$1,'g-expenses-inc'!$D:$D,"logistics",'g-expenses-inc'!$E:$E,TRIM($A18)) | F18: =SUMIFS('g-expenses-inc'!$K:$K,'g-expenses-inc'!$A:$A,F$1,'g-expenses-inc'!$D:$D,"logistics",'g-expenses-inc'!$E:$E,TRIM($A18)) | G18: =SUMIFS('g-expenses-inc'!$K:$K,'g-expenses-inc'!$A:$A,G$1,'g-expenses-inc'!$D:$D,"logistics",'g-expenses-inc'!$E:$E,TRIM($A18)) | H18: =SUMIFS('g-expenses-inc'!$K:$K,'g-expenses-inc'!$A:$A,H$1,'g-expenses-inc'!$D:$D,"logistics",'g-expenses-inc'!$E:$E,TRIM($A18)) | I18: =SUMIFS('g-expenses-inc'!$K:$K,'g-expenses-inc'!$A:$A,I$1,'g-expenses-inc'!$D:$D,"logistics",'g-expenses-inc'!$E:$E,TRIM($A18)) | J18: =SUMIFS('g-expenses-inc'!$K:$K,'g-expenses-inc'!$A:$A,J$1,'g-expenses-inc'!$D:$D,"logistics",'g-expenses-inc'!$E:$E,TRIM($A18)) | K18: =SUMIFS('g-expenses-inc'!$K:$K,'g-expenses-inc'!$A:$A,K$1,'g-expenses-inc'!$D:$D,"logistics",'g-expenses-inc'!$E:$E,TRIM($A18)) | ... O18: =SUMIFS('g-expenses-inc'!$K:$K,'g-expenses-inc'!$A:$A,O$1,'g-expenses-inc'!$D:$D,"logistics",'g-expenses-inc'!$E:$E,TRIM($A18)) | P18: =SUM(D18:O18) | Q18: ->
A19: % Logistics / sales | D19: =IFERROR(D17/D5,0) | E19: =IFERROR(E17/E5,0) | F19: =IFERROR(F17/F5,0) | G19: =IFERROR(G17/G5,0) | H19: =IFERROR(H17/H5,0) | I19: =IFERROR(I17/I5,0) | J19: =IFERROR(J17/J5,0) | K19: =IFERROR(K17/K5,0) | ... O19: =IFERROR(O17/O5,0) | P19: =SUM(D19:O19)
A20: Payment fees | D20: =SUM(D21:D21) | E20: =SUM(E21:E21) | F20: =SUM(F21:F21) | G20: =SUM(G21:G21) | H20: =SUM(H21:H21) | I20: =SUM(I21:I21) | J20: =SUM(J21:J21) | K20: =SUM(K21:K21) | ... O20: =SUM(O21:O21) | P20: =SUM(D20:O20) | Q20: ->
A21: SHOPIFY | D21: =SUMIFS('g-payment-fees-inc'!$H:$H,'g-payment-fees-inc'!$A:$A,D$1,'g-payment-fees-inc'!$C:$C,TRIM($A21)) | E21: =SUMIFS('g-payment-fees-inc'!$H:$H,'g-payment-fees-inc'!$A:$A,E$1,'g-payment-fees-inc'!$C:$C,TRIM($A21)) | F21: =SUMIFS('g-payment-fees-inc'!$H:$H,'g-payment-fees-inc'!$A:$A,F$1,'g-payment-fees-inc'!$C:$C,TRIM($A21)) | G21: =SUMIFS('g-payment-fees-inc'!$H:$H,'g-payment-fees-inc'!$A:$A,G$1,'g-payment-fees-inc'!$C:$C,TRIM($A21)) | H21: =SUMIFS('g-payment-fees-inc'!$H:$H,'g-payment-fees-inc'!$A:$A,H$1,'g-payment-fees-inc'!$C:$C,TRIM($A21)) | I21: =SUMIFS('g-payment-fees-inc'!$H:$H,'g-payment-fees-inc'!$A:$A,I$1,'g-payment-fees-inc'!$C:$C,TRIM($A21)) | J21: =SUMIFS('g-payment-fees-inc'!$H:$H,'g-payment-fees-inc'!$A:$A,J$1,'g-payment-fees-inc'!$C:$C,TRIM($A21)) | K21: =SUMIFS('g-payment-fees-inc'!$H:$H,'g-payment-fees-inc'!$A:$A,K$1,'g-payment-fees-inc'!$C:$C,TRIM($A21)) | ... O21: =SUMIFS('g-payment-fees-inc'!$H:$H,'g-payment-fees-inc'!$A:$A,O$1,'g-payment-fees-inc'!$C:$C,TRIM($A21)) | P21: =SUM(D21:O21) | Q21: ->
P22: =SUM(D22:O22)
A23: % Payment fees / sales | D23: =IFERROR(D20/D5,0) | E23: =IFERROR(E20/E5,0) | F23: =IFERROR(F20/F5,0) | G23: =IFERROR(G20/G5,0) | H23: =IFERROR(H20/H5,0) | I23: =IFERROR(I20/I5,0) | J23: =IFERROR(J20/J5,0) | K23: =IFERROR(K20/K5,0) | ... O23: =IFERROR(O20/O5,0) | P23: =SUM(D23:O23)
P24: =SUM(D24:O24)
A25: GROSS MARGIN (SALES-MANUFACTURING) | D25: =D5-D12 | E25: =E5-E12 | F25: =F5-F12 | G25: =G5-G12 | H25: =H5-H12 | I25: =I5-I12 | J25: =J5-J12 | K25: =K5-K12 | ... O25: =O5-O12 | P25: =SUM(D25:O25)
A26: % GROSS MARGIN | D26: =IFERROR(D25/D5,0) | E26: =IFERROR(E25/E5,0) | F26: =IFERROR(F25/F5,0) | G26: =IFERROR(G25/G5,0) | H26: =IFERROR(H25/H5,0) | I26: =IFERROR(I25/I5,0) | J26: =IFERROR(J25/J5,0) | K26: =IFERROR(K25/K5,0) | ... O26: =IFERROR(O25/O5,0) | P26: =SUM(D26:O26)
A27: CONTRIBUTIVE MARGIN (TURNOVER-COGS) | D27: =D4-D11 | E27: =E4-E11 | F27: =F4-F11 | G27: =G4-G11 | H27: =H4-H11 | I27: =I4-I11 | J27: =J4-J11 | K27: =K4-K11 | ... O27: =O4-O11 | P27: =SUM(D27:O27)
A28: % CONTRIBUTIVE MARGIN | D28: =IFERROR(D27/D4,0) | E28: =IFERROR(E27/E4,0) | F28: =IFERROR(F27/F4,0) | G28: =IFERROR(G27/G4,0) | H28: =IFERROR(H27/H4,0) | I28: =IFERROR(I27/I4,0) | J28: =IFERROR(J27/J4,0) | K28: =IFERROR(K27/K4,0) | ... O28: =IFERROR(O27/O4,0) | P28: =SUM(D28:O28)
P29: =SUM(D29:O29)
A30: Opex | D30: =D31+D33+D38+D40 | E30: =E31+E33+E38+E40 | F30: =F31+F33+F38+F40 | G30: =G31+G33+G38+G40 | H30: =H31+H33+H38+H40 | I30: =I31+I33+I38+I40 | J30: =J31+J33+J38+J40 | K30: =K31+K33+K38+K40 | ... O30: =O31+O33+O38+O40 | P30: =SUM(D30:O30)
A31: Shared services | D31: =SUM(D32:D32) | E31: =SUM(E32:E32) | F31: =SUM(F32:F32) | G31: =SUM(G32:G32) | H31: =SUM(H32:H32) | I31: =SUM(I32:I32) | J31: =SUM(J32:J32) | K31: =SUM(K32:K32) | ... O31: =SUM(O32:O32) | P31: =SUM(D31:O31) | Q31: ->
A32: SHAREDSERVICESSL | D32: =SUMIFS('g-expenses-inc'!$K:$K,'g-expenses-inc'!$A:$A,D$1,'g-expenses-inc'!$D:$D,"shared_services",'g-expenses-inc'!$E:$E,TRIM($A32)) | E32: =SUMIFS('g-expenses-inc'!$K:$K,'g-expenses-inc'!$A:$A,E$1,'g-expenses-inc'!$D:$D,"shared_services",'g-expenses-inc'!$E:$E,TRIM($A32)) | F32: =SUMIFS('g-expenses-inc'!$K:$K,'g-expenses-inc'!$A:$A,F$1,'g-expenses-inc'!$D:$D,"shared_services",'g-expenses-inc'!$E:$E,TRIM($A32)) | G32: =SUMIFS('g-expenses-inc'!$K:$K,'g-expenses-inc'!$A:$A,G$1,'g-expenses-inc'!$D:$D,"shared_services",'g-expenses-inc'!$E:$E,TRIM($A32)) | H32: =SUMIFS('g-expenses-inc'!$K:$K,'g-expenses-inc'!$A:$A,H$1,'g-expenses-inc'!$D:$D,"shared_services",'g-expenses-inc'!$E:$E,TRIM($A32)) | I32: =SUMIFS('g-expenses-inc'!$K:$K,'g-expenses-inc'!$A:$A,I$1,'g-expenses-inc'!$D:$D,"shared_services",'g-expenses-inc'!$E:$E,TRIM($A32)) | J32: =SUMIFS('g-expenses-inc'!$K:$K,'g-expenses-inc'!$A:$A,J$1,'g-expenses-inc'!$D:$D,"shared_services",'g-expenses-inc'!$E:$E,TRIM($A32)) | K32: =SUMIFS('g-expenses-inc'!$K:$K,'g-expenses-inc'!$A:$A,K$1,'g-expenses-inc'!$D:$D,"shared_services",'g-expenses-inc'!$E:$E,TRIM($A32)) | ... O32: =SUMIFS('g-expenses-inc'!$K:$K,'g-expenses-inc'!$A:$A,O$1,'g-expenses-inc'!$D:$D,"shared_services",'g-expenses-inc'!$E:$E,TRIM($A32)) | P32: =SUM(D32:O32) | Q32: ->
A33: Administration | D33: =SUM(D34:D37) | E33: =SUM(E34:E37) | F33: =SUM(F34:F37) | G33: =SUM(G34:G37) | H33: =SUM(H34:H37) | I33: =SUM(I34:I37) | J33: =SUM(J34:J37) | K33: =SUM(K34:K37) | ... O33: =SUM(O34:O37) | P33: =SUM(D33:O33) | Q33: ->
A34: CONTINUUM | D34: =SUMIFS('g-expenses-inc'!$K:$K,'g-expenses-inc'!$A:$A,D$1,'g-expenses-inc'!$D:$D,"administration",'g-expenses-inc'!$E:$E,TRIM($A34)) | E34: =SUMIFS('g-expenses-inc'!$K:$K,'g-expenses-inc'!$A:$A,E$1,'g-expenses-inc'!$D:$D,"administration",'g-expenses-inc'!$E:$E,TRIM($A34)) | F34: =SUMIFS('g-expenses-inc'!$K:$K,'g-expenses-inc'!$A:$A,F$1,'g-expenses-inc'!$D:$D,"administration",'g-expenses-inc'!$E:$E,TRIM($A34)) | G34: =SUMIFS('g-expenses-inc'!$K:$K,'g-expenses-inc'!$A:$A,G$1,'g-expenses-inc'!$D:$D,"administration",'g-expenses-inc'!$E:$E,TRIM($A34)) | H34: =SUMIFS('g-expenses-inc'!$K:$K,'g-expenses-inc'!$A:$A,H$1,'g-expenses-inc'!$D:$D,"administration",'g-expenses-inc'!$E:$E,TRIM($A34)) | I34: =SUMIFS('g-expenses-inc'!$K:$K,'g-expenses-inc'!$A:$A,I$1,'g-expenses-inc'!$D:$D,"administration",'g-expenses-inc'!$E:$E,TRIM($A34)) | J34: =SUMIFS('g-expenses-inc'!$K:$K,'g-expenses-inc'!$A:$A,J$1,'g-expenses-inc'!$D:$D,"administration",'g-expenses-inc'!$E:$E,TRIM($A34)) | K34: =SUMIFS('g-expenses-inc'!$K:$K,'g-expenses-inc'!$A:$A,K$1,'g-expenses-inc'!$D:$D,"administration",'g-expenses-inc'!$E:$E,TRIM($A34)) | ... O34: =SUMIFS('g-expenses-inc'!$K:$K,'g-expenses-inc'!$A:$A,O$1,'g-expenses-inc'!$D:$D,"administration",'g-expenses-inc'!$E:$E,TRIM($A34)) | P34: =SUM(D34:O34) | Q34: ->
A35: HUSHED | D35: =SUMIFS('g-expenses-inc'!$K:$K,'g-expenses-inc'!$A:$A,D$1,'g-expenses-inc'!$D:$D,"administration",'g-expenses-inc'!$E:$E,TRIM($A35)) | E35: =SUMIFS('g-expenses-inc'!$K:$K,'g-expenses-inc'!$A:$A,E$1,'g-expenses-inc'!$D:$D,"administration",'g-expenses-inc'!$E:$E,TRIM($A35)) | F35: =SUMIFS('g-expenses-inc'!$K:$K,'g-expenses-inc'!$A:$A,F$1,'g-expenses-inc'!$D:$D,"administration",'g-expenses-inc'!$E:$E,TRIM($A35)) | G35: =SUMIFS('g-expenses-inc'!$K:$K,'g-expenses-inc'!$A:$A,G$1,'g-expenses-inc'!$D:$D,"administration",'g-expenses-inc'!$E:$E,TRIM($A35)) | H35: =SUMIFS('g-expenses-inc'!$K:$K,'g-expenses-inc'!$A:$A,H$1,'g-expenses-inc'!$D:$D,"administration",'g-expenses-inc'!$E:$E,TRIM($A35)) | I35: =SUMIFS('g-expenses-inc'!$K:$K,'g-expenses-inc'!$A:$A,I$1,'g-expenses-inc'!$D:$D,"administration",'g-expenses-inc'!$E:$E,TRIM($A35)) | J35: =SUMIFS('g-expenses-inc'!$K:$K,'g-expenses-inc'!$A:$A,J$1,'g-expenses-inc'!$D:$D,"administration",'g-expenses-inc'!$E:$E,TRIM($A35)) | K35: =SUMIFS('g-expenses-inc'!$K:$K,'g-expenses-inc'!$A:$A,K$1,'g-expenses-inc'!$D:$D,"administration",'g-expenses-inc'!$E:$E,TRIM($A35)) | ... O35: =SUMIFS('g-expenses-inc'!$K:$K,'g-expenses-inc'!$A:$A,O$1,'g-expenses-inc'!$D:$D,"administration",'g-expenses-inc'!$E:$E,TRIM($A35)) | P35: =SUM(D35:O35)
A36: IPOSTAL | D36: =SUMIFS('g-expenses-inc'!$K:$K,'g-expenses-inc'!$A:$A,D$1,'g-expenses-inc'!$D:$D,"administration",'g-expenses-inc'!$E:$E,TRIM($A36)) | E36: =SUMIFS('g-expenses-inc'!$K:$K,'g-expenses-inc'!$A:$A,E$1,'g-expenses-inc'!$D:$D,"administration",'g-expenses-inc'!$E:$E,TRIM($A36)) | F36: =SUMIFS('g-expenses-inc'!$K:$K,'g-expenses-inc'!$A:$A,F$1,'g-expenses-inc'!$D:$D,"administration",'g-expenses-inc'!$E:$E,TRIM($A36)) | G36: =SUMIFS('g-expenses-inc'!$K:$K,'g-expenses-inc'!$A:$A,G$1,'g-expenses-inc'!$D:$D,"administration",'g-expenses-inc'!$E:$E,TRIM($A36)) | H36: =SUMIFS('g-expenses-inc'!$K:$K,'g-expenses-inc'!$A:$A,H$1,'g-expenses-inc'!$D:$D,"administration",'g-expenses-inc'!$E:$E,TRIM($A36)) | I36: =SUMIFS('g-expenses-inc'!$K:$K,'g-expenses-inc'!$A:$A,I$1,'g-expenses-inc'!$D:$D,"administration",'g-expenses-inc'!$E:$E,TRIM($A36)) | J36: =SUMIFS('g-expenses-inc'!$K:$K,'g-expenses-inc'!$A:$A,J$1,'g-expenses-inc'!$D:$D,"administration",'g-expenses-inc'!$E:$E,TRIM($A36)) | K36: =SUMIFS('g-expenses-inc'!$K:$K,'g-expenses-inc'!$A:$A,K$1,'g-expenses-inc'!$D:$D,"administration",'g-expenses-inc'!$E:$E,TRIM($A36)) | ... O36: =SUMIFS('g-expenses-inc'!$K:$K,'g-expenses-inc'!$A:$A,O$1,'g-expenses-inc'!$D:$D,"administration",'g-expenses-inc'!$E:$E,TRIM($A36)) | P36: =SUM(D36:O36)
A37: REGUS | D37: =SUMIFS('g-expenses-inc'!$K:$K,'g-expenses-inc'!$A:$A,D$1,'g-expenses-inc'!$D:$D,"administration",'g-expenses-inc'!$E:$E,TRIM($A37)) | E37: =SUMIFS('g-expenses-inc'!$K:$K,'g-expenses-inc'!$A:$A,E$1,'g-expenses-inc'!$D:$D,"administration",'g-expenses-inc'!$E:$E,TRIM($A37)) | F37: =SUMIFS('g-expenses-inc'!$K:$K,'g-expenses-inc'!$A:$A,F$1,'g-expenses-inc'!$D:$D,"administration",'g-expenses-inc'!$E:$E,TRIM($A37)) | G37: =SUMIFS('g-expenses-inc'!$K:$K,'g-expenses-inc'!$A:$A,G$1,'g-expenses-inc'!$D:$D,"administration",'g-expenses-inc'!$E:$E,TRIM($A37)) | H37: =SUMIFS('g-expenses-inc'!$K:$K,'g-expenses-inc'!$A:$A,H$1,'g-expenses-inc'!$D:$D,"administration",'g-expenses-inc'!$E:$E,TRIM($A37)) | I37: =SUMIFS('g-expenses-inc'!$K:$K,'g-expenses-inc'!$A:$A,I$1,'g-expenses-inc'!$D:$D,"administration",'g-expenses-inc'!$E:$E,TRIM($A37)) | J37: =SUMIFS('g-expenses-inc'!$K:$K,'g-expenses-inc'!$A:$A,J$1,'g-expenses-inc'!$D:$D,"administration",'g-expenses-inc'!$E:$E,TRIM($A37)) | K37: =SUMIFS('g-expenses-inc'!$K:$K,'g-expenses-inc'!$A:$A,K$1,'g-expenses-inc'!$D:$D,"administration",'g-expenses-inc'!$E:$E,TRIM($A37)) | ... O37: =SUMIFS('g-expenses-inc'!$K:$K,'g-expenses-inc'!$A:$A,O$1,'g-expenses-inc'!$D:$D,"administration",'g-expenses-inc'!$E:$E,TRIM($A37)) | P37: =SUM(D37:O37)
A38: Technology | D38: =SUM(D39:D39) | E38: =SUM(E39:E39) | F38: =SUM(F39:F39) | G38: =SUM(G39:G39) | H38: =SUM(H39:H39) | I38: =SUM(I39:I39) | J38: =SUM(J39:J39) | K38: =SUM(K39:K39) | ... O38: =SUM(O39:O39) | P38: =SUM(D38:O38) | Q38: ->
A39: REVER | D39: =SUMIFS('g-expenses-inc'!$K:$K,'g-expenses-inc'!$A:$A,D$1,'g-expenses-inc'!$D:$D,"technology",'g-expenses-inc'!$E:$E,TRIM($A39)) | E39: =SUMIFS('g-expenses-inc'!$K:$K,'g-expenses-inc'!$A:$A,E$1,'g-expenses-inc'!$D:$D,"technology",'g-expenses-inc'!$E:$E,TRIM($A39)) | F39: =SUMIFS('g-expenses-inc'!$K:$K,'g-expenses-inc'!$A:$A,F$1,'g-expenses-inc'!$D:$D,"technology",'g-expenses-inc'!$E:$E,TRIM($A39)) | G39: =SUMIFS('g-expenses-inc'!$K:$K,'g-expenses-inc'!$A:$A,G$1,'g-expenses-inc'!$D:$D,"technology",'g-expenses-inc'!$E:$E,TRIM($A39)) | H39: =SUMIFS('g-expenses-inc'!$K:$K,'g-expenses-inc'!$A:$A,H$1,'g-expenses-inc'!$D:$D,"technology",'g-expenses-inc'!$E:$E,TRIM($A39)) | I39: =SUMIFS('g-expenses-inc'!$K:$K,'g-expenses-inc'!$A:$A,I$1,'g-expenses-inc'!$D:$D,"technology",'g-expenses-inc'!$E:$E,TRIM($A39)) | J39: =SUMIFS('g-expenses-inc'!$K:$K,'g-expenses-inc'!$A:$A,J$1,'g-expenses-inc'!$D:$D,"technology",'g-expenses-inc'!$E:$E,TRIM($A39)) | K39: =SUMIFS('g-expenses-inc'!$K:$K,'g-expenses-inc'!$A:$A,K$1,'g-expenses-inc'!$D:$D,"technology",'g-expenses-inc'!$E:$E,TRIM($A39)) | ... O39: =SUMIFS('g-expenses-inc'!$K:$K,'g-expenses-inc'!$A:$A,O$1,'g-expenses-inc'!$D:$D,"technology",'g-expenses-inc'!$E:$E,TRIM($A39)) | P39: =SUM(D39:O39) | Q39: ->
A40: Otros gastos | D40: =SUMIFS('g-expenses-inc'!$K:$K,'g-expenses-inc'!$A:$A,D$1,'g-expenses-inc'!$D:$D,"otros_gastos") | E40: =SUMIFS('g-expenses-inc'!$K:$K,'g-expenses-inc'!$A:$A,E$1,'g-expenses-inc'!$D:$D,"otros_gastos") | F40: =SUMIFS('g-expenses-inc'!$K:$K,'g-expenses-inc'!$A:$A,F$1,'g-expenses-inc'!$D:$D,"otros_gastos") | G40: =SUMIFS('g-expenses-inc'!$K:$K,'g-expenses-inc'!$A:$A,G$1,'g-expenses-inc'!$D:$D,"otros_gastos") | H40: =SUMIFS('g-expenses-inc'!$K:$K,'g-expenses-inc'!$A:$A,H$1,'g-expenses-inc'!$D:$D,"otros_gastos") | I40: =SUMIFS('g-expenses-inc'!$K:$K,'g-expenses-inc'!$A:$A,I$1,'g-expenses-inc'!$D:$D,"otros_gastos") | J40: =SUMIFS('g-expenses-inc'!$K:$K,'g-expenses-inc'!$A:$A,J$1,'g-expenses-inc'!$D:$D,"otros_gastos") | K40: =SUMIFS('g-expenses-inc'!$K:$K,'g-expenses-inc'!$A:$A,K$1,'g-expenses-inc'!$D:$D,"otros_gastos") | ... O40: =SUMIFS('g-expenses-inc'!$K:$K,'g-expenses-inc'!$A:$A,O$1,'g-expenses-inc'!$D:$D,"otros_gastos") | P40: =SUM(D40:O40) | Q40: ->
...

Sheet params
A1: <- Volver a P&G-INC
A2: key | B2: value
A3: entity | B3: INC
A4: reporting_currency | B4: USD
A5: year | B5: 2025
A6: generated_at_utc | B6: 2026-03-30T14:18:38Z

Sheet i-shopify-inc
A1: <- Volver a P&G-INC
A2: yyyymm | B2: entity | C2: line_item | D2: detail | E2: amount_original | F2: currency_original | G2: reporting_currency | H2: fx_rate | I2: amount_reporting | J2: source
A3: 202507 | B3: INC | C3: US | D3: US | E3: 4848.17 | F3: USD | G3: USD | H3: 1 | I3: 4848.17 | J3: finance.ventas_pyg
A4: 202508 | B4: INC | C4: US | D4: US | E4: 15774.61 | F4: USD | G4: USD | H4: 1 | I4: 15774.61 | J4: finance.ventas_pyg
A5: 202509 | B5: INC | C5: US | D5: US | E5: 14722.36 | F5: USD | G5: USD | H5: 1 | I5: 14722.36 | J5: finance.ventas_pyg
A6: 202510 | B6: INC | C6: US | D6: US | E6: 15317.44 | F6: USD | G6: USD | H6: 1 | I6: 15317.44 | J6: finance.ventas_pyg
A7: 202511 | B7: INC | C7: US | D7: US | E7: 16310.04 | F7: USD | G7: USD | H7: 1 | I7: 16310.04 | J7: finance.ventas_pyg
A8: 202512 | B8: INC | C8: US | D8: US | E8: 8082.1 | F8: USD | G8: USD | H8: 1 | I8: 8082.1 | J8: finance.ventas_pyg

Sheet g-expenses-inc
A1: <- Volver a P&G-INC
A2: yyyymm | B2: entity | C2: category | D2: subcategory | E2: supplier_code | F2: detail | G2: amount_original | H2: currency_original | I2: reporting_currency | J2: fx_rate | K2: amount_reporting | L2: source | M2: invoice_number | N2: drive_url
A3: 202503 | B3: INC | C3: opex | D3: administration | E3: HUSHED | F3: invoice | G3: 4.99 | H3: USD | I3: USD | J3: 1 | K3: 4.99 | L3: documents | M3: 2978-8256 | N3: https://drive.google.com/file/d/1mKFpn4LbqABUwoYmmXsPKyq8s0DkaSsi/view?usp=drivesdk
A4: 202504 | B4: INC | C4: opex | D4: administration | E4: HUSHED | F4: invoice | G4: 4.99 | H4: USD | I4: USD | J4: 1 | K4: 4.99 | L4: documents | M4: 2041-0252 | N4: https://drive.google.com/file/d/1Atuoi43vLrx967JbrHqvFad_G-Oge25b/view?usp=drivesdk
A5: 202504 | B5: INC | C5: opex | D5: administration | E5: IPOSTAL | F5: invoice | G5: 14.99 | H5: USD | I5: USD | J5: 1 | K5: 14.99 | L5: documents | M5: 29081161 | N5: https://drive.google.com/file/d/1z2NTUrvh34fdW8Uot-vEEnGrjpPurFa2/view?usp=drivesdk
A6: 202505 | B6: INC | C6: opex | D6: administration | E6: HUSHED | F6: invoice | G6: 4.99 | H6: USD | I6: USD | J6: 1 | K6: 4.99 | L6: documents | M6: 2312-3467 | N6: https://drive.google.com/file/d/1KLoFCF3XJmDR7TouszZ14B1HOLhx7NSc/view?usp=drivesdk
A7: 202505 | B7: INC | C7: opex | D7: administration | E7: IPOSTAL | F7: invoice | G7: 14.99 | H7: USD | I7: USD | J7: 1 | K7: 14.99 | L7: documents | M7: 29741548 | N7: https://drive.google.com/file/d/1nl75_t5qMkq6sPp3sUcTJOTnphTbjler/view?usp=drivesdk
A8: 202506 | B8: INC | C8: opex | D8: administration | E8: HUSHED | F8: invoice | G8: 4.99 | H8: USD | I8: USD | J8: 1 | K8: 4.99 | L8: documents | M8: 2151-8125 | N8: https://drive.google.com/file/d/1bkYpNbXnMTF1EUK3gZ-m0pfXO6lfs_IK/view?usp=drivesdk
A9: 202506 | B9: INC | C9: opex | D9: administration | E9: IPOSTAL | F9: invoice | G9: 14.99 | H9: USD | I9: USD | J9: 1 | K9: 14.99 | L9: documents | M9: 30430625 | N9: https://drive.google.com/file/d/1mrh7-eV5laK5K-ZWeu8Qz8riNSBcDPrz/view?usp=drivesdk
A10: 202507 | B10: INC | C10: opex | D10: administration | E10: HUSHED | F10: invoice | G10: 4.99 | H10: USD | I10: USD | J10: 1 | K10: 4.99 | L10: documents | M10: 2693-3816 | N10: https://drive.google.com/file/d/1GvSiMT7dWe7h0r6ewcUbd76aacDTs55m/view?usp=drivesdk
A11: 202507 | B11: INC | C11: opex | D11: administration | E11: IPOSTAL | F11: invoice | G11: 2.2 | H11: USD | I11: USD | J11: 1 | K11: 2.2 | L11: documents | M11: 30875555 | N11: https://drive.google.com/file/d/1gHZvZG77dIxzMh9_SrTFhWatc1Wv61Vb/view?usp=drivesdk
A12: 202507 | B12: INC | C12: opex | D12: administration | E12: IPOSTAL | F12: invoice | G12: 14.99 | H12: USD | I12: USD | J12: 1 | K12: 14.99 | L12: documents | M12: 31085773 | N12: https://drive.google.com/file/d/10HjLo7Knu7gO7UHRqzRWWqLRJLFwaepb/view?usp=drivesdk
A13: 202508 | B13: INC | C13: opex | D13: administration | E13: HUSHED | F13: invoice | G13: 4.99 | H13: USD | I13: USD | J13: 1 | K13: 4.99 | L13: documents | M13: 2961-0950 | N13: https://drive.google.com/file/d/1GQls1efpPohPk4ex-UHu8N22dVykqohV/view?usp=drivesdk
A14: 202508 | B14: INC | C14: opex | D14: administration | E14: IPOSTAL | F14: invoice | G14: 1.1 | H14: USD | I14: USD | J14: 1 | K14: 1.1 | L14: documents | M14: 31175617 | N14: https://drive.google.com/file/d/1OM97FR799Ud946UpzcBMY1HZEW_yeR00/view?usp=drivesdk
... A68: 202512 | B68: INC | C68: opex | D68: administration | E68: REGUS | F68: invoice | G68: 31.8 | H68: USD | I68: USD | J68: 1 | K68: 31.8 | L68: documents | M68: 3313-42838 | N68: https://drive.google.com/file/d/1JPw1TNvghTI6YSGC7_wDxk6ZSKSiu5UJ/view?usp=drivesdk

Sheet g-payment-fees-inc
A1: <- Volver a P&G-INC
A2: yyyymm | B2: entity | C2: supplier_code | D2: amount_original | E2: currency_original | F2: reporting_currency | G2: fx_rate | H2: amount_reporting | I2: source
A3: 202507 | B3: INC | C3: SHOPIFY | D3: 138.84 | E3: USD | F3: USD | G3: 1 | H3: 138.84 | I3: payment_fee_monthly_summary
A4: 202508 | B4: INC | C4: SHOPIFY | D4: 469.35 | E4: USD | F4: USD | G4: 1 | H4: 469.35 | I4: payment_fee_monthly_summary
A5: 202509 | B5: INC | C5: SHOPIFY | D5: 427.42 | E5: USD | F5: USD | G5: 1 | H5: 427.42 | I5: payment_fee_monthly_summary
A6: 202510 | B6: INC | C6: SHOPIFY | D6: 407.19 | E6: USD | F6: USD | G6: 1 | H6: 407.19 | I6: payment_fee_monthly_summary
A7: 202511 | B7: INC | C7: SHOPIFY | D7: 478.81 | E7: USD | F7: USD | G7: 1 | H7: 478.81 | I7: payment_fee_monthly_summary
A8: 202512 | B8: INC | C8: SHOPIFY | D8: 248.67 | E8: USD | F8: USD | G8: 1 | H8: 248.67 | I8: payment_fee_monthly_summary

Sheet fx-rates
A1: <- Volver a P&G-INC
A2: yyyymm | B2: rate_date | C2: currency_original | D2: reporting_currency | E2: reference_rate | F2: fx_rate | G2: source
A3: 202503 | B3: 2025-03-01 | C3: USD | D3: USD | E3: 1 | F3: 1 | G3: identity
A4: 202504 | B4: 2025-04-01 | C4: USD | D4: USD | E4: 1 | F4: 1 | G4: identity
A5: 202505 | B5: 2025-05-01 | C5: USD | D5: USD | E5: 1 | F5: 1 | G5: identity
A6: 202506 | B6: 2025-06-01 | C6: USD | D6: USD | E6: 1 | F6: 1 | G6: identity
A7: 202507 | B7: 2025-07-01 | C7: USD | D7: USD | E7: 1 | F7: 1 | G7: identity
A8: 202508 | B8: 2025-08-01 | C8: USD | D8: USD | E8: 1 | F8: 1 | G8: identity
A9: 202509 | B9: 2025-09-01 | C9: USD | D9: USD | E9: 1 | F9: 1 | G9: identity
A10: 202510 | B10: 2025-10-01 | C10: EUR | D10: USD | E10: 1 | F10: 1.1554 | G10: identity -> https://www.ecb.europa.eu/stats/eurofxref/eurofxref-hist.xml
A11: 202510 | B11: 2025-10-01 | C11: USD | D11: USD | E11: 1 | F11: 1 | G11: identity
A12: 202511 | B12: 2025-11-01 | C12: EUR | D12: USD | E12: 1 | F12: 1.1566 | G12: identity -> https://www.ecb.europa.eu/stats/eurofxref/eurofxref-hist.xml
A13: 202511 | B13: 2025-11-01 | C13: USD | D13: USD | E13: 1 | F13: 1 | G13: identity
A14: 202512 | B14: 2025-12-01 | C14: USD | D14: USD | E14: 1 | F14: 1 | G14: identity

Sheet catalog-inc
A1: <- Volver a P&G-INC
A2: supplier_code | B2: supplier_name | C2: current_folder | D2: destination_path | E2: notes
A3: JONDO | B3: JONDO | C3: jondo | D3: expenses/cogs/manufacturing | E3: Imported JONDO US supplier
A4: TGI | B4: TGI | C4: tgi | D4: expenses/cogs/manufacturing-logistics
A5: CONTINUUM | B5: CONTINUUM | C5: Continuum | D5: expenses/opex/administration
A6: HUSHED | B6: HUSHED | C6: hushed | D6: expenses/opex/administration
A7: IPOSTAL | B7: IPOSTAL | C7: iPostal | D7: expenses/opex/administration | E7: Virtual mailbox and mailing address service
A8: QUICKBOOKS | B8: QUICKBOOKS | C8: QuickBooks | D8: expenses/opex/administration | E8: Accounting software subscription
A9: REGUS | B9: REGUS | C9: regus | D9: expenses/opex/administration
A10: SHAREDSERVICESSL | B10: SHAREDSERVICESSL | C10: HANNUN | D10: expenses/opex/shared-services | E10: Intercompany shared services

Sheet Nº Facturas-INC
D1: 202501 | E1: 202502 | F1: 202503 | G1: 202504 | H1: 202505 | I1: 202506 | J1: 202507 | K1: 202508 | L1: 202509 | M1: 202510 | N1: 202511 | O1: 202512 | P1: TOTAL
A2: Nº Facturas INC 2025 | D2: Enero | E2: Febrero | F2: Marzo | G2: Abril | H2: Mayo | I2: Junio | J2: Julio | K2: Agosto | L2: Septiembre | M2: Octubre | N2: Noviembre | O2: Diciembre | P2: Total
A4: Turnover | D4: 0 | E4: 0 | F4: 0 | G4: 0 | H4: 0 | I4: 0 | J4: 1 | K4: 1 | L4: 1 | M4: 1 | N4: 1 | O4: 1 | P4: 6
B5: Product sales | D5: 0 | E5: 0 | F5: 0 | G5: 0 | H5: 0 | I5: 0 | J5: 1 | K5: 1 | L5: 1 | M5: 1 | N5: 1 | O5: 1 | P5: 6
C6: Shopify | D6: 0 | E6: 0 | F6: 0 | G6: 0 | H6: 0 | I6: 0 | J6: 1 | K6: 1 | L6: 1 | M6: 1 | N6: 1 | O6: 1 | P6: 6
C7: US | D7: 0 | E7: 0 | F7: 0 | G7: 0 | H7: 0 | I7: 0 | J7: 1 | K7: 1 | L7: 1 | M7: 1 | N7: 1 | O7: 1 | P7: 6
B8: Otros ingresos | D8: 0 | E8: 0 | F8: 0 | G8: 0 | H8: 0 | I8: 0 | J8: 0 | K8: 0 | L8: 0 | M8: 0 | N8: 0 | O8: 0 | P8: 0
A10: Expenses | D10: 0 | E10: 0 | F10: 1 | G10: 2 | H10: 2 | I10: 2 | J10: 4 | K10: 7 | L10: 6 | M10: 6 | N10: 12 | O10: 25 | P10: 67
B11: COGS | D11: 0 | E11: 0 | F11: 0 | G11: 0 | H11: 0 | I11: 0 | J11: 1 | K11: 1 | L11: 1 | M11: 1 | N11: 4 | O11: 13 | P11: 21
C12: Manufacturing | D12: 0 | E12: 0 | F12: 0 | G12: 0 | H12: 0 | I12: 0 | J12: 0 | K12: 0 | L12: 0 | M12: 0 | N12: 3 | O12: 12 | P12: 15
C13: JONDO | D13: 0 | E13: 0 | F13: 0 | G13: 0 | H13: 0 | I13: 0 | J13: 0 | K13: 0 | L13: 0 | M13: 0 | N13: 3 | O13: 12 | P13: 15
C14: TGI | D14: 0 | E14: 0 | F14: 0 | G14: 0 | H14: 0 | I14: 0 | J14: 0 | K14: 0 | L14: 0 | M14: 0 | N14: 0 | O14: 0 | P14: 0
C15: Logistics | D15: 0 | E15: 0 | F15: 0 | G15: 0 | H15: 0 | I15: 0 | J15: 0 | K15: 0 | L15: 0 | M15: 0 | N15: 0 | O15: 0 | P15: 0
C16: TGI | D16: 0 | E16: 0 | F16: 0 | G16: 0 | H16: 0 | I16: 0 | J16: 0 | K16: 0 | L16: 0 | M16: 0 | N16: 0 | O16: 0 | P16: 0
C17: Payment fees | D17: 0 | E17: 0 | F17: 0 | G17: 0 | H17: 0 | I17: 0 | J17: 1 | K17: 1 | L17: 1 | M17: 1 | N17: 1 | O17: 1 | P17: 6
C18: SHOPIFY | D18: 0 | E18: 0 | F18: 0 | G18: 0 | H18: 0 | I18: 0 | J18: 1 | K18: 1 | L18: 1 | M18: 1 | N18: 1 | O18: 1 | P18: 6
B20: Opex | D20: 0 | E20: 0 | F20: 1 | G20: 2 | H20: 2 | I20: 2 | J20: 3 | K20: 6 | L20: 5 | M20: 5 | N20: 8 | O20: 12 | P20: 46
C21: Shared services | D21: 0 | E21: 0 | F21: 0 | G21: 0 | H21: 0 | I21: 0 | J21: 0 | K21: 0 | L21: 0 | M21: 1 | N21: 1 | O21: 0 | P21: 2
C22: SHAREDSERVICESSL | D22: 0 | E22: 0 | F22: 0 | G22: 0 | H22: 0 | I22: 0 | J22: 0 | K22: 0 | L22: 0 | M22: 1 | N22: 1 | O22: 0 | P22: 2
C23: Administration | D23: 0 | E23: 0 | F23: 1 | G23: 2 | H23: 2 | I23: 2 | J23: 3 | K23: 6 | L23: 5 | M23: 4 | N23: 7 | O23: 12 | P23: 44
C24: CONTINUUM | D24: 0 | E24: 0 | F24: 0 | G24: 0 | H24: 0 | I24: 0 | J24: 0 | K24: 0 | L24: 0 | M24: 0 | N24: 0 | O24: 1 | P24: 1
C25: HUSHED | D25: 0 | E25: 0 | F25: 1 | G25: 1 | H25: 1 | I25: 1 | J25: 1 | K25: 1 | L25: 1 | M25: 1 | N25: 1 | O25: 1 | P25: 10
C26: IPOSTAL | D26: 0 | E26: 0 | F26: 0 | G26: 1 | H26: 1 | I26: 1 | J26: 2 | K26: 5 | L26: 4 | M26: 3 | N26: 5 | O26: 9 | P26: 31
C27: REGUS | D27: 0 | E27: 0 | F27: 0 | G27: 0 | H27: 0 | I27: 0 | J27: 0 | K27: 0 | L27: 0 | M27: 0 | N27: 1 | O27: 1 | P27: 2
C28: Technology | D28: 0 | E28: 0 | F28: 0 | G28: 0 | H28: 0 | I28: 0 | J28: 0 | K28: 0 | L28: 0 | M28: 0 | N28: 0 | O28: 0 | P28: 0
C29: REVER | D29: 0 | E29: 0 | F29: 0 | G29: 0 | H29: 0 | I29: 0 | J29: 0 | K29: 0 | L29: 0 | M29: 0 | N29: 0 | O29: 0 | P29: 0
C30: Otros gastos | D30: 0 | E30: 0 | F30: 0 | G30: 0 | H30: 0 | I30: 0 | J30: 0 | K30: 0 | L30: 0 | M30: 0 | N30: 0 | O30: 0 | P30: 0
B31: Diferencias divisas | D31: 0 | E31: 0 | F31: 0 | G31: 0 | H31: 0 | I31: 0 | J31: 0 | K31: 0 | L31: 0 | M31: 0 | N31: 0 | O31: 0 | P31: 0
