Workbook

Sheet P&G-LTD
D1: 202701 | E1: 202702 | F1: 202703 | G1: 202704 | H1: 202705 | I1: 202706 | J1: 202707 | K1: 202708 | L1: 202709 | M1: 202710 | N1: 202711 | O1: 202712 | P1: TOTAL
A2: P&G LTD 2027 | D2: Enero | E2: Febrero | F2: Marzo | G2: Abril | H2: Mayo | I2: Junio | J2: Julio | K2: Agosto | L2: Septiembre | M2: Octubre | N2: Noviembre | O2: Diciembre | P2: Total
A3: Actualizado: 30/03/2026 17:09 h
A4: Turnover | D4: =D5+D8 | E4: =E5+E8 | F4: =F5+F8 | G4: =G5+G8 | H4: =H5+H8 | I4: =I5+I8 | J4: =J5+J8 | K4: =K5+K8 | ... O4: =O5+O8 | P4: =SUM(D4:O4)
A5: Product sales | D5: =D6 | E5: =E6 | F5: =F6 | G5: =G6 | H5: =H6 | I5: =I6 | J5: =J6 | K5: =K6 | ... O5: =O6 | P5: =SUM(D5:O5)
A6: Shopify | D6: =SUM(D7:D7) | E6: =SUM(E7:E7) | F6: =SUM(F7:F7) | G6: =SUM(G7:G7) | H6: =SUM(H7:H7) | I6: =SUM(I7:I7) | J6: =SUM(J7:J7) | K6: =SUM(K7:K7) | ... O6: =SUM(O7:O7) | P6: =SUM(D6:O6) | Q6: ->
A7: GB | D7: =SUMIFS('i-shopify-ltd'!$I:$I,'i-shopify-ltd'!$A:$A,D$1,'i-shopify-ltd'!$C:$C,TRIM($A7)) | E7: =SUMIFS('i-shopify-ltd'!$I:$I,'i-shopify-ltd'!$A:$A,E$1,'i-shopify-ltd'!$C:$C,TRIM($A7)) | F7: =SUMIFS('i-shopify-ltd'!$I:$I,'i-shopify-ltd'!$A:$A,F$1,'i-shopify-ltd'!$C:$C,TRIM($A7)) | G7: =SUMIFS('i-shopify-ltd'!$I:$I,'i-shopify-ltd'!$A:$A,G$1,'i-shopify-ltd'!$C:$C,TRIM($A7)) | H7: =SUMIFS('i-shopify-ltd'!$I:$I,'i-shopify-ltd'!$A:$A,H$1,'i-shopify-ltd'!$C:$C,TRIM($A7)) | I7: =SUMIFS('i-shopify-ltd'!$I:$I,'i-shopify-ltd'!$A:$A,I$1,'i-shopify-ltd'!$C:$C,TRIM($A7)) | J7: =SUMIFS('i-shopify-ltd'!$I:$I,'i-shopify-ltd'!$A:$A,J$1,'i-shopify-ltd'!$C:$C,TRIM($A7)) | K7: =SUMIFS('i-shopify-ltd'!$I:$I,'i-shopify-ltd'!$A:$A,K$1,'i-shopify-ltd'!$C:$C,TRIM($A7)) | ... O7: =SUMIFS('i-shopify-ltd'!$I:$I,'i-shopify-ltd'!$A:$A,O$1,'i-shopify-ltd'!$C:$C,TRIM($A7)) | P7: =SUM(D7:O7) | Q7: ->
A8: Otros ingresos | P8: =SUM(D8:O8)
P9: =SUM(D9:O9)
A10: Expenses | D10: =D11+D32 | E10: =E11+E32 | F10: =F11+F32 | G10: =G11+G32 | H10: =H11+H32 | I10: =I11+I32 | J10: =J11+J32 | K10: =K11+K32 | ... O10: =O11+O32 | P10: =SUM(D10:O10)
A11: COGS | D11: =D12+D18+D22 | E11: =E12+E18+E22 | F11: =F12+F18+F22 | G11: =G12+G18+G22 | H11: =H12+H18+H22 | I11: =I12+I18+I22 | J11: =J12+J18+J22 | K11: =K12+K18+K22 | ... O11: =O12+O18+O22 | P11: =SUM(D11:O11)
A12: Manufacturing | D12: =SUM(D13:D15)+D16 | E12: =SUM(E13:E15)+E16 | F12: =SUM(F13:F15)+F16 | G12: =SUM(G13:G15)+G16 | H12: =SUM(H13:H15)+H16 | I12: =SUM(I13:I15)+I16 | J12: =SUM(J13:J15)+J16 | K12: =SUM(K13:K15)+K16 | ... O12: =SUM(O13:O15)+O16 | P12: =SUM(D12:O12) | Q12: ->
A13: ARTLINK | D13: =SUMIFS('g-expenses-ltd'!$K:$K,'g-expenses-ltd'!$A:$A,D$1,'g-expenses-ltd'!$D:$D,"manufacturing",'g-expenses-ltd'!$E:$E,TRIM($A13)) | E13: =SUMIFS('g-expenses-ltd'!$K:$K,'g-expenses-ltd'!$A:$A,E$1,'g-expenses-ltd'!$D:$D,"manufacturing",'g-expenses-ltd'!$E:$E,TRIM($A13)) | F13: =SUMIFS('g-expenses-ltd'!$K:$K,'g-expenses-ltd'!$A:$A,F$1,'g-expenses-ltd'!$D:$D,"manufacturing",'g-expenses-ltd'!$E:$E,TRIM($A13)) | G13: =SUMIFS('g-expenses-ltd'!$K:$K,'g-expenses-ltd'!$A:$A,G$1,'g-expenses-ltd'!$D:$D,"manufacturing",'g-expenses-ltd'!$E:$E,TRIM($A13)) | H13: =SUMIFS('g-expenses-ltd'!$K:$K,'g-expenses-ltd'!$A:$A,H$1,'g-expenses-ltd'!$D:$D,"manufacturing",'g-expenses-ltd'!$E:$E,TRIM($A13)) | I13: =SUMIFS('g-expenses-ltd'!$K:$K,'g-expenses-ltd'!$A:$A,I$1,'g-expenses-ltd'!$D:$D,"manufacturing",'g-expenses-ltd'!$E:$E,TRIM($A13)) | J13: =SUMIFS('g-expenses-ltd'!$K:$K,'g-expenses-ltd'!$A:$A,J$1,'g-expenses-ltd'!$D:$D,"manufacturing",'g-expenses-ltd'!$E:$E,TRIM($A13)) | K13: =SUMIFS('g-expenses-ltd'!$K:$K,'g-expenses-ltd'!$A:$A,K$1,'g-expenses-ltd'!$D:$D,"manufacturing",'g-expenses-ltd'!$E:$E,TRIM($A13)) | ... O13: =SUMIFS('g-expenses-ltd'!$K:$K,'g-expenses-ltd'!$A:$A,O$1,'g-expenses-ltd'!$D:$D,"manufacturing",'g-expenses-ltd'!$E:$E,TRIM($A13)) | P13: =SUM(D13:O13) | Q13: ->
A14: JONDO | D14: =SUMIFS('g-expenses-ltd'!$K:$K,'g-expenses-ltd'!$A:$A,D$1,'g-expenses-ltd'!$D:$D,"manufacturing",'g-expenses-ltd'!$E:$E,TRIM($A14)) | E14: =SUMIFS('g-expenses-ltd'!$K:$K,'g-expenses-ltd'!$A:$A,E$1,'g-expenses-ltd'!$D:$D,"manufacturing",'g-expenses-ltd'!$E:$E,TRIM($A14)) | F14: =SUMIFS('g-expenses-ltd'!$K:$K,'g-expenses-ltd'!$A:$A,F$1,'g-expenses-ltd'!$D:$D,"manufacturing",'g-expenses-ltd'!$E:$E,TRIM($A14)) | G14: =SUMIFS('g-expenses-ltd'!$K:$K,'g-expenses-ltd'!$A:$A,G$1,'g-expenses-ltd'!$D:$D,"manufacturing",'g-expenses-ltd'!$E:$E,TRIM($A14)) | H14: =SUMIFS('g-expenses-ltd'!$K:$K,'g-expenses-ltd'!$A:$A,H$1,'g-expenses-ltd'!$D:$D,"manufacturing",'g-expenses-ltd'!$E:$E,TRIM($A14)) | I14: =SUMIFS('g-expenses-ltd'!$K:$K,'g-expenses-ltd'!$A:$A,I$1,'g-expenses-ltd'!$D:$D,"manufacturing",'g-expenses-ltd'!$E:$E,TRIM($A14)) | J14: =SUMIFS('g-expenses-ltd'!$K:$K,'g-expenses-ltd'!$A:$A,J$1,'g-expenses-ltd'!$D:$D,"manufacturing",'g-expenses-ltd'!$E:$E,TRIM($A14)) | K14: =SUMIFS('g-expenses-ltd'!$K:$K,'g-expenses-ltd'!$A:$A,K$1,'g-expenses-ltd'!$D:$D,"manufacturing",'g-expenses-ltd'!$E:$E,TRIM($A14)) | ... O14: =SUMIFS('g-expenses-ltd'!$K:$K,'g-expenses-ltd'!$A:$A,O$1,'g-expenses-ltd'!$D:$D,"manufacturing",'g-expenses-ltd'!$E:$E,TRIM($A14)) | P14: =SUM(D14:O14)
A15: PROCO | D15: =SUMIFS('g-expenses-ltd'!$K:$K,'g-expenses-ltd'!$A:$A,D$1,'g-expenses-ltd'!$D:$D,"manufacturing",'g-expenses-ltd'!$E:$E,TRIM($A15)) | E15: =SUMIFS('g-expenses-ltd'!$K:$K,'g-expenses-ltd'!$A:$A,E$1,'g-expenses-ltd'!$D:$D,"manufacturing",'g-expenses-ltd'!$E:$E,TRIM($A15)) | F15: =SUMIFS('g-expenses-ltd'!$K:$K,'g-expenses-ltd'!$A:$A,F$1,'g-expenses-ltd'!$D:$D,"manufacturing",'g-expenses-ltd'!$E:$E,TRIM($A15)) | G15: =SUMIFS('g-expenses-ltd'!$K:$K,'g-expenses-ltd'!$A:$A,G$1,'g-expenses-ltd'!$D:$D,"manufacturing",'g-expenses-ltd'!$E:$E,TRIM($A15)) | H15: =SUMIFS('g-expenses-ltd'!$K:$K,'g-expenses-ltd'!$A:$A,H$1,'g-expenses-ltd'!$D:$D,"manufacturing",'g-expenses-ltd'!$E:$E,TRIM($A15)) | I15: =SUMIFS('g-expenses-ltd'!$K:$K,'g-expenses-ltd'!$A:$A,I$1,'g-expenses-ltd'!$D:$D,"manufacturing",'g-expenses-ltd'!$E:$E,TRIM($A15)) | J15: =SUMIFS('g-expenses-ltd'!$K:$K,'g-expenses-ltd'!$A:$A,J$1,'g-expenses-ltd'!$D:$D,"manufacturing",'g-expenses-ltd'!$E:$E,TRIM($A15)) | K15: =SUMIFS('g-expenses-ltd'!$K:$K,'g-expenses-ltd'!$A:$A,K$1,'g-expenses-ltd'!$D:$D,"manufacturing",'g-expenses-ltd'!$E:$E,TRIM($A15)) | ... O15: =SUMIFS('g-expenses-ltd'!$K:$K,'g-expenses-ltd'!$A:$A,O$1,'g-expenses-ltd'!$D:$D,"manufacturing",'g-expenses-ltd'!$E:$E,TRIM($A15)) | P15: =SUM(D15:O15)
A16: Consumo marcos | P16: =SUM(D16:O16)
A17: % Manufacturing / sales | D17: =IFERROR(D12/D5,0) | E17: =IFERROR(E12/E5,0) | F17: =IFERROR(F12/F5,0) | G17: =IFERROR(G12/G5,0) | H17: =IFERROR(H12/H5,0) | I17: =IFERROR(I12/I5,0) | J17: =IFERROR(J12/J5,0) | K17: =IFERROR(K12/K5,0) | ... O17: =IFERROR(O12/O5,0) | P17: =SUM(D17:O17)
A18: Logistics | D18: =SUM(D19:D20) | E18: =SUM(E19:E20) | F18: =SUM(F19:F20) | G18: =SUM(G19:G20) | H18: =SUM(H19:H20) | I18: =SUM(I19:I20) | J18: =SUM(J19:J20) | K18: =SUM(K19:K20) | ... O18: =SUM(O19:O20) | P18: =SUM(D18:O18) | Q18: ->
A19: PROCO | D19: =SUMIFS('g-expenses-ltd'!$K:$K,'g-expenses-ltd'!$A:$A,D$1,'g-expenses-ltd'!$D:$D,"logistics",'g-expenses-ltd'!$E:$E,TRIM($A19)) | E19: =SUMIFS('g-expenses-ltd'!$K:$K,'g-expenses-ltd'!$A:$A,E$1,'g-expenses-ltd'!$D:$D,"logistics",'g-expenses-ltd'!$E:$E,TRIM($A19)) | F19: =SUMIFS('g-expenses-ltd'!$K:$K,'g-expenses-ltd'!$A:$A,F$1,'g-expenses-ltd'!$D:$D,"logistics",'g-expenses-ltd'!$E:$E,TRIM($A19)) | G19: =SUMIFS('g-expenses-ltd'!$K:$K,'g-expenses-ltd'!$A:$A,G$1,'g-expenses-ltd'!$D:$D,"logistics",'g-expenses-ltd'!$E:$E,TRIM($A19)) | H19: =SUMIFS('g-expenses-ltd'!$K:$K,'g-expenses-ltd'!$A:$A,H$1,'g-expenses-ltd'!$D:$D,"logistics",'g-expenses-ltd'!$E:$E,TRIM($A19)) | I19: =SUMIFS('g-expenses-ltd'!$K:$K,'g-expenses-ltd'!$A:$A,I$1,'g-expenses-ltd'!$D:$D,"logistics",'g-expenses-ltd'!$E:$E,TRIM($A19)) | J19: =SUMIFS('g-expenses-ltd'!$K:$K,'g-expenses-ltd'!$A:$A,J$1,'g-expenses-ltd'!$D:$D,"logistics",'g-expenses-ltd'!$E:$E,TRIM($A19)) | K19: =SUMIFS('g-expenses-ltd'!$K:$K,'g-expenses-ltd'!$A:$A,K$1,'g-expenses-ltd'!$D:$D,"logistics",'g-expenses-ltd'!$E:$E,TRIM($A19)) | ... O19: =SUMIFS('g-expenses-ltd'!$K:$K,'g-expenses-ltd'!$A:$A,O$1,'g-expenses-ltd'!$D:$D,"logistics",'g-expenses-ltd'!$E:$E,TRIM($A19)) | P19: =SUM(D19:O19) | Q19: ->
A20: PORTCLEARANCE | D20: =SUMIFS('g-expenses-ltd'!$K:$K,'g-expenses-ltd'!$A:$A,D$1,'g-expenses-ltd'!$D:$D,"logistics",'g-expenses-ltd'!$E:$E,TRIM($A20)) | E20: =SUMIFS('g-expenses-ltd'!$K:$K,'g-expenses-ltd'!$A:$A,E$1,'g-expenses-ltd'!$D:$D,"logistics",'g-expenses-ltd'!$E:$E,TRIM($A20)) | F20: =SUMIFS('g-expenses-ltd'!$K:$K,'g-expenses-ltd'!$A:$A,F$1,'g-expenses-ltd'!$D:$D,"logistics",'g-expenses-ltd'!$E:$E,TRIM($A20)) | G20: =SUMIFS('g-expenses-ltd'!$K:$K,'g-expenses-ltd'!$A:$A,G$1,'g-expenses-ltd'!$D:$D,"logistics",'g-expenses-ltd'!$E:$E,TRIM($A20)) | H20: =SUMIFS('g-expenses-ltd'!$K:$K,'g-expenses-ltd'!$A:$A,H$1,'g-expenses-ltd'!$D:$D,"logistics",'g-expenses-ltd'!$E:$E,TRIM($A20)) | I20: =SUMIFS('g-expenses-ltd'!$K:$K,'g-expenses-ltd'!$A:$A,I$1,'g-expenses-ltd'!$D:$D,"logistics",'g-expenses-ltd'!$E:$E,TRIM($A20)) | J20: =SUMIFS('g-expenses-ltd'!$K:$K,'g-expenses-ltd'!$A:$A,J$1,'g-expenses-ltd'!$D:$D,"logistics",'g-expenses-ltd'!$E:$E,TRIM($A20)) | K20: =SUMIFS('g-expenses-ltd'!$K:$K,'g-expenses-ltd'!$A:$A,K$1,'g-expenses-ltd'!$D:$D,"logistics",'g-expenses-ltd'!$E:$E,TRIM($A20)) | ... O20: =SUMIFS('g-expenses-ltd'!$K:$K,'g-expenses-ltd'!$A:$A,O$1,'g-expenses-ltd'!$D:$D,"logistics",'g-expenses-ltd'!$E:$E,TRIM($A20)) | P20: =SUM(D20:O20)
A21: % Logistics / sales | D21: =IFERROR(D18/D5,0) | E21: =IFERROR(E18/E5,0) | F21: =IFERROR(F18/F5,0) | G21: =IFERROR(G18/G5,0) | H21: =IFERROR(H18/H5,0) | I21: =IFERROR(I18/I5,0) | J21: =IFERROR(J18/J5,0) | K21: =IFERROR(K18/K5,0) | ... O21: =IFERROR(O18/O5,0) | P21: =SUM(D21:O21)
A22: Payment fees | D22: =SUM(D23:D23) | E22: =SUM(E23:E23) | F22: =SUM(F23:F23) | G22: =SUM(G23:G23) | H22: =SUM(H23:H23) | I22: =SUM(I23:I23) | J22: =SUM(J23:J23) | K22: =SUM(K23:K23) | ... O22: =SUM(O23:O23) | P22: =SUM(D22:O22) | Q22: ->
A23: SHOPIFY | D23: =SUMIFS('g-payment-fees-ltd'!$H:$H,'g-payment-fees-ltd'!$A:$A,D$1,'g-payment-fees-ltd'!$C:$C,TRIM($A23)) | E23: =SUMIFS('g-payment-fees-ltd'!$H:$H,'g-payment-fees-ltd'!$A:$A,E$1,'g-payment-fees-ltd'!$C:$C,TRIM($A23)) | F23: =SUMIFS('g-payment-fees-ltd'!$H:$H,'g-payment-fees-ltd'!$A:$A,F$1,'g-payment-fees-ltd'!$C:$C,TRIM($A23)) | G23: =SUMIFS('g-payment-fees-ltd'!$H:$H,'g-payment-fees-ltd'!$A:$A,G$1,'g-payment-fees-ltd'!$C:$C,TRIM($A23)) | H23: =SUMIFS('g-payment-fees-ltd'!$H:$H,'g-payment-fees-ltd'!$A:$A,H$1,'g-payment-fees-ltd'!$C:$C,TRIM($A23)) | I23: =SUMIFS('g-payment-fees-ltd'!$H:$H,'g-payment-fees-ltd'!$A:$A,I$1,'g-payment-fees-ltd'!$C:$C,TRIM($A23)) | J23: =SUMIFS('g-payment-fees-ltd'!$H:$H,'g-payment-fees-ltd'!$A:$A,J$1,'g-payment-fees-ltd'!$C:$C,TRIM($A23)) | K23: =SUMIFS('g-payment-fees-ltd'!$H:$H,'g-payment-fees-ltd'!$A:$A,K$1,'g-payment-fees-ltd'!$C:$C,TRIM($A23)) | ... O23: =SUMIFS('g-payment-fees-ltd'!$H:$H,'g-payment-fees-ltd'!$A:$A,O$1,'g-payment-fees-ltd'!$C:$C,TRIM($A23)) | P23: =SUM(D23:O23) | Q23: ->
P24: =SUM(D24:O24)
A25: % Payment fees / sales | D25: =IFERROR(D22/D5,0) | E25: =IFERROR(E22/E5,0) | F25: =IFERROR(F22/F5,0) | G25: =IFERROR(G22/G5,0) | H25: =IFERROR(H22/H5,0) | I25: =IFERROR(I22/I5,0) | J25: =IFERROR(J22/J5,0) | K25: =IFERROR(K22/K5,0) | ... O25: =IFERROR(O22/O5,0) | P25: =SUM(D25:O25)
P26: =SUM(D26:O26)
A27: GROSS MARGIN (SALES-MANUFACTURING) | D27: =D5-D12 | E27: =E5-E12 | F27: =F5-F12 | G27: =G5-G12 | H27: =H5-H12 | I27: =I5-I12 | J27: =J5-J12 | K27: =K5-K12 | ... O27: =O5-O12 | P27: =SUM(D27:O27)
A28: % GROSS MARGIN | D28: =IFERROR(D27/D5,0) | E28: =IFERROR(E27/E5,0) | F28: =IFERROR(F27/F5,0) | G28: =IFERROR(G27/G5,0) | H28: =IFERROR(H27/H5,0) | I28: =IFERROR(I27/I5,0) | J28: =IFERROR(J27/J5,0) | K28: =IFERROR(K27/K5,0) | ... O28: =IFERROR(O27/O5,0) | P28: =SUM(D28:O28)
A29: CONTRIBUTIVE MARGIN (TURNOVER-COGS) | D29: =D4-D11 | E29: =E4-E11 | F29: =F4-F11 | G29: =G4-G11 | H29: =H4-H11 | I29: =I4-I11 | J29: =J4-J11 | K29: =K4-K11 | ... O29: =O4-O11 | P29: =SUM(D29:O29)
A30: % CONTRIBUTIVE MARGIN | D30: =IFERROR(D29/D4,0) | E30: =IFERROR(E29/E4,0) | F30: =IFERROR(F29/F4,0) | G30: =IFERROR(G29/G4,0) | H30: =IFERROR(H29/H4,0) | I30: =IFERROR(I29/I4,0) | J30: =IFERROR(J29/J4,0) | K30: =IFERROR(K29/K4,0) | ... O30: =IFERROR(O29/O4,0) | P30: =SUM(D30:O30)
P31: =SUM(D31:O31)
A32: Opex | D32: =D33+D35+D37+D39 | E32: =E33+E35+E37+E39 | F32: =F33+F35+F37+F39 | G32: =G33+G35+G37+G39 | H32: =H33+H35+H37+H39 | I32: =I33+I35+I37+I39 | J32: =J33+J35+J37+J39 | K32: =K33+K35+K37+K39 | ... O32: =O33+O35+O37+O39 | P32: =SUM(D32:O32)
A33: Shared services | D33: =SUM(D34:D34) | E33: =SUM(E34:E34) | F33: =SUM(F34:F34) | G33: =SUM(G34:G34) | H33: =SUM(H34:H34) | I33: =SUM(I34:I34) | J33: =SUM(J34:J34) | K33: =SUM(K34:K34) | ... O33: =SUM(O34:O34) | P33: =SUM(D33:O33) | Q33: ->
A34: SHAREDSERVICESSL | D34: =SUMIFS('g-expenses-ltd'!$K:$K,'g-expenses-ltd'!$A:$A,D$1,'g-expenses-ltd'!$D:$D,"shared_services",'g-expenses-ltd'!$E:$E,TRIM($A34)) | E34: =SUMIFS('g-expenses-ltd'!$K:$K,'g-expenses-ltd'!$A:$A,E$1,'g-expenses-ltd'!$D:$D,"shared_services",'g-expenses-ltd'!$E:$E,TRIM($A34)) | F34: =SUMIFS('g-expenses-ltd'!$K:$K,'g-expenses-ltd'!$A:$A,F$1,'g-expenses-ltd'!$D:$D,"shared_services",'g-expenses-ltd'!$E:$E,TRIM($A34)) | G34: =SUMIFS('g-expenses-ltd'!$K:$K,'g-expenses-ltd'!$A:$A,G$1,'g-expenses-ltd'!$D:$D,"shared_services",'g-expenses-ltd'!$E:$E,TRIM($A34)) | H34: =SUMIFS('g-expenses-ltd'!$K:$K,'g-expenses-ltd'!$A:$A,H$1,'g-expenses-ltd'!$D:$D,"shared_services",'g-expenses-ltd'!$E:$E,TRIM($A34)) | I34: =SUMIFS('g-expenses-ltd'!$K:$K,'g-expenses-ltd'!$A:$A,I$1,'g-expenses-ltd'!$D:$D,"shared_services",'g-expenses-ltd'!$E:$E,TRIM($A34)) | J34: =SUMIFS('g-expenses-ltd'!$K:$K,'g-expenses-ltd'!$A:$A,J$1,'g-expenses-ltd'!$D:$D,"shared_services",'g-expenses-ltd'!$E:$E,TRIM($A34)) | K34: =SUMIFS('g-expenses-ltd'!$K:$K,'g-expenses-ltd'!$A:$A,K$1,'g-expenses-ltd'!$D:$D,"shared_services",'g-expenses-ltd'!$E:$E,TRIM($A34)) | ... O34: =SUMIFS('g-expenses-ltd'!$K:$K,'g-expenses-ltd'!$A:$A,O$1,'g-expenses-ltd'!$D:$D,"shared_services",'g-expenses-ltd'!$E:$E,TRIM($A34)) | P34: =SUM(D34:O34) | Q34: ->
A35: Administration | D35: =SUM(D36:D36) | E35: =SUM(E36:E36) | F35: =SUM(F36:F36) | G35: =SUM(G36:G36) | H35: =SUM(H36:H36) | I35: =SUM(I36:I36) | J35: =SUM(J36:J36) | K35: =SUM(K36:K36) | ... O35: =SUM(O36:O36) | P35: =SUM(D35:O35) | Q35: ->
A36: YOURACCOUNTSTAXES | D36: =SUMIFS('g-expenses-ltd'!$K:$K,'g-expenses-ltd'!$A:$A,D$1,'g-expenses-ltd'!$D:$D,"administration",'g-expenses-ltd'!$E:$E,TRIM($A36)) | E36: =SUMIFS('g-expenses-ltd'!$K:$K,'g-expenses-ltd'!$A:$A,E$1,'g-expenses-ltd'!$D:$D,"administration",'g-expenses-ltd'!$E:$E,TRIM($A36)) | F36: =SUMIFS('g-expenses-ltd'!$K:$K,'g-expenses-ltd'!$A:$A,F$1,'g-expenses-ltd'!$D:$D,"administration",'g-expenses-ltd'!$E:$E,TRIM($A36)) | G36: =SUMIFS('g-expenses-ltd'!$K:$K,'g-expenses-ltd'!$A:$A,G$1,'g-expenses-ltd'!$D:$D,"administration",'g-expenses-ltd'!$E:$E,TRIM($A36)) | H36: =SUMIFS('g-expenses-ltd'!$K:$K,'g-expenses-ltd'!$A:$A,H$1,'g-expenses-ltd'!$D:$D,"administration",'g-expenses-ltd'!$E:$E,TRIM($A36)) | I36: =SUMIFS('g-expenses-ltd'!$K:$K,'g-expenses-ltd'!$A:$A,I$1,'g-expenses-ltd'!$D:$D,"administration",'g-expenses-ltd'!$E:$E,TRIM($A36)) | J36: =SUMIFS('g-expenses-ltd'!$K:$K,'g-expenses-ltd'!$A:$A,J$1,'g-expenses-ltd'!$D:$D,"administration",'g-expenses-ltd'!$E:$E,TRIM($A36)) | K36: =SUMIFS('g-expenses-ltd'!$K:$K,'g-expenses-ltd'!$A:$A,K$1,'g-expenses-ltd'!$D:$D,"administration",'g-expenses-ltd'!$E:$E,TRIM($A36)) | ... O36: =SUMIFS('g-expenses-ltd'!$K:$K,'g-expenses-ltd'!$A:$A,O$1,'g-expenses-ltd'!$D:$D,"administration",'g-expenses-ltd'!$E:$E,TRIM($A36)) | P36: =SUM(D36:O36) | Q36: ->
A37: Technology | D37: =SUM(D38:D38) | E37: =SUM(E38:E38) | F37: =SUM(F38:F38) | G37: =SUM(G38:G38) | H37: =SUM(H38:H38) | I37: =SUM(I38:I38) | J37: =SUM(J38:J38) | K37: =SUM(K38:K38) | ... O37: =SUM(O38:O38) | P37: =SUM(D37:O37) | Q37: ->
A38: REVER | D38: =SUMIFS('g-expenses-ltd'!$K:$K,'g-expenses-ltd'!$A:$A,D$1,'g-expenses-ltd'!$D:$D,"technology",'g-expenses-ltd'!$E:$E,TRIM($A38)) | E38: =SUMIFS('g-expenses-ltd'!$K:$K,'g-expenses-ltd'!$A:$A,E$1,'g-expenses-ltd'!$D:$D,"technology",'g-expenses-ltd'!$E:$E,TRIM($A38)) | F38: =SUMIFS('g-expenses-ltd'!$K:$K,'g-expenses-ltd'!$A:$A,F$1,'g-expenses-ltd'!$D:$D,"technology",'g-expenses-ltd'!$E:$E,TRIM($A38)) | G38: =SUMIFS('g-expenses-ltd'!$K:$K,'g-expenses-ltd'!$A:$A,G$1,'g-expenses-ltd'!$D:$D,"technology",'g-expenses-ltd'!$E:$E,TRIM($A38)) | H38: =SUMIFS('g-expenses-ltd'!$K:$K,'g-expenses-ltd'!$A:$A,H$1,'g-expenses-ltd'!$D:$D,"technology",'g-expenses-ltd'!$E:$E,TRIM($A38)) | I38: =SUMIFS('g-expenses-ltd'!$K:$K,'g-expenses-ltd'!$A:$A,I$1,'g-expenses-ltd'!$D:$D,"technology",'g-expenses-ltd'!$E:$E,TRIM($A38)) | J38: =SUMIFS('g-expenses-ltd'!$K:$K,'g-expenses-ltd'!$A:$A,J$1,'g-expenses-ltd'!$D:$D,"technology",'g-expenses-ltd'!$E:$E,TRIM($A38)) | K38: =SUMIFS('g-expenses-ltd'!$K:$K,'g-expenses-ltd'!$A:$A,K$1,'g-expenses-ltd'!$D:$D,"technology",'g-expenses-ltd'!$E:$E,TRIM($A38)) | ... O38: =SUMIFS('g-expenses-ltd'!$K:$K,'g-expenses-ltd'!$A:$A,O$1,'g-expenses-ltd'!$D:$D,"technology",'g-expenses-ltd'!$E:$E,TRIM($A38)) | P38: =SUM(D38:O38) | Q38: ->
A39: Otros gastos | D39: =SUMIFS('g-expenses-ltd'!$K:$K,'g-expenses-ltd'!$A:$A,D$1,'g-expenses-ltd'!$D:$D,"otros_gastos") | E39: =SUMIFS('g-expenses-ltd'!$K:$K,'g-expenses-ltd'!$A:$A,E$1,'g-expenses-ltd'!$D:$D,"otros_gastos") | F39: =SUMIFS('g-expenses-ltd'!$K:$K,'g-expenses-ltd'!$A:$A,F$1,'g-expenses-ltd'!$D:$D,"otros_gastos") | G39: =SUMIFS('g-expenses-ltd'!$K:$K,'g-expenses-ltd'!$A:$A,G$1,'g-expenses-ltd'!$D:$D,"otros_gastos") | H39: =SUMIFS('g-expenses-ltd'!$K:$K,'g-expenses-ltd'!$A:$A,H$1,'g-expenses-ltd'!$D:$D,"otros_gastos") | I39: =SUMIFS('g-expenses-ltd'!$K:$K,'g-expenses-ltd'!$A:$A,I$1,'g-expenses-ltd'!$D:$D,"otros_gastos") | J39: =SUMIFS('g-expenses-ltd'!$K:$K,'g-expenses-ltd'!$A:$A,J$1,'g-expenses-ltd'!$D:$D,"otros_gastos") | K39: =SUMIFS('g-expenses-ltd'!$K:$K,'g-expenses-ltd'!$A:$A,K$1,'g-expenses-ltd'!$D:$D,"otros_gastos") | ... O39: =SUMIFS('g-expenses-ltd'!$K:$K,'g-expenses-ltd'!$A:$A,O$1,'g-expenses-ltd'!$D:$D,"otros_gastos") | P39: =SUM(D39:O39) | Q39: ->
A40: Diferencias divisas | P40: =SUM(D40:O40)
...

Sheet params
A1: <- Volver a P&G-LTD
A2: key | B2: value
A3: entity | B3: LTD
A4: reporting_currency | B4: GBP
A5: year | B5: 2027
A6: generated_at_utc | B6: 2026-03-30T15:09:50Z

Sheet i-shopify-ltd
A1: <- Volver a P&G-LTD
A2: yyyymm | B2: entity | C2: line_item | D2: detail | E2: amount_original | F2: currency_original | G2: reporting_currency | H2: fx_rate | I2: amount_reporting | J2: source

Sheet g-expenses-ltd
A1: <- Volver a P&G-LTD
A2: yyyymm | B2: entity | C2: category | D2: subcategory | E2: supplier_code | F2: detail | G2: amount_original | H2: currency_original | I2: reporting_currency | J2: fx_rate | K2: amount_reporting | L2: source | M2: invoice_number | N2: drive_url
A3: 202701 | B3: LTD | C3: opex | D3: administration | E3: YOURACCOUNTSTAXES | F3: invoice | G3: 55 | H3: GBP | I3: GBP | J3: 1 | K3: 55 | L3: documents | M3: INV-0681_PERIODIFICADA_12_12 | N3: https://drive.google.com/file/d/1OHftZDVQsfubhNFSoSD7IPplIl-waEKz/view?usp=drivesdk

Sheet g-payment-fees-ltd
A1: <- Volver a P&G-LTD
A2: yyyymm | B2: entity | C2: supplier_code | D2: amount_original | E2: currency_original | F2: reporting_currency | G2: fx_rate | H2: amount_reporting | I2: source

Sheet fx-rates
A1: <- Volver a P&G-LTD
A2: yyyymm | B2: rate_date | C2: currency_original | D2: reporting_currency | E2: reference_rate | F2: fx_rate | G2: source
A3: 202701 | B3: 2027-01-01 | C3: GBP | D3: GBP | E3: 1 | F3: 1 | G3: identity

Sheet catalog-ltd
A1: <- Volver a P&G-LTD
A2: supplier_code | B2: supplier_name | C2: current_folder | D2: destination_path | E2: notes
A3: ARTLINK | B3: ARTLINK | C3: Artlink | D3: expenses/cogs/manufacturing | E3: Frame purchases and related freight are treated as manufacturing
A4: PORTCLEARANCE | B4: PORTCLEARANCE | C4: port clearence | D4: expenses/cogs/manufacturing | E4: Import customs and clearance for frame purchases
A5: JONDO | B5: JONDO | C5: 202602_jondogo | D5: expenses/cogs/manufacturing-logistics
A6: PROCO | B6: PROCO | C6: Proco | D6: expenses/cogs/manufacturing-logistics | E6: Trading name PROCO
A7: YOURACCOUNTSTAXES | B7: YOURACCOUNTSTAXES | C7: Your Accounts and Taxes | D7: expenses/opex/administration | E7: UK accountancy and tax services
A8: SHAREDSERVICESSL | B8: SHAREDSERVICESSL | C8: Shared Services | D8: expenses/opex/shared-services | E8: Intercompany
A9: REVER | B9: REVER | C9: REVER | D9: expenses/opex/technology

Sheet Nº Facturas-LTD
D1: 202701 | E1: 202702 | F1: 202703 | G1: 202704 | H1: 202705 | I1: 202706 | J1: 202707 | K1: 202708 | L1: 202709 | M1: 202710 | N1: 202711 | O1: 202712 | P1: TOTAL
A2: Nº Facturas LTD 2027 | D2: Enero | E2: Febrero | F2: Marzo | G2: Abril | H2: Mayo | I2: Junio | J2: Julio | K2: Agosto | L2: Septiembre | M2: Octubre | N2: Noviembre | O2: Diciembre | P2: Total
A4: Turnover | D4: 0 | E4: 0 | F4: 0 | G4: 0 | H4: 0 | I4: 0 | J4: 0 | K4: 0 | L4: 0 | M4: 0 | N4: 0 | O4: 0 | P4: 0
B5: Product sales | D5: 0 | E5: 0 | F5: 0 | G5: 0 | H5: 0 | I5: 0 | J5: 0 | K5: 0 | L5: 0 | M5: 0 | N5: 0 | O5: 0 | P5: 0
C6: Shopify | D6: 0 | E6: 0 | F6: 0 | G6: 0 | H6: 0 | I6: 0 | J6: 0 | K6: 0 | L6: 0 | M6: 0 | N6: 0 | O6: 0 | P6: 0
C7: GB | D7: 0 | E7: 0 | F7: 0 | G7: 0 | H7: 0 | I7: 0 | J7: 0 | K7: 0 | L7: 0 | M7: 0 | N7: 0 | O7: 0 | P7: 0
B8: Otros ingresos | D8: 0 | E8: 0 | F8: 0 | G8: 0 | H8: 0 | I8: 0 | J8: 0 | K8: 0 | L8: 0 | M8: 0 | N8: 0 | O8: 0 | P8: 0
A10: Expenses | D10: 1 | E10: 0 | F10: 0 | G10: 0 | H10: 0 | I10: 0 | J10: 0 | K10: 0 | L10: 0 | M10: 0 | N10: 0 | O10: 0 | P10: 1
B11: COGS | D11: 0 | E11: 0 | F11: 0 | G11: 0 | H11: 0 | I11: 0 | J11: 0 | K11: 0 | L11: 0 | M11: 0 | N11: 0 | O11: 0 | P11: 0
C12: Manufacturing | D12: 0 | E12: 0 | F12: 0 | G12: 0 | H12: 0 | I12: 0 | J12: 0 | K12: 0 | L12: 0 | M12: 0 | N12: 0 | O12: 0 | P12: 0
C13: ARTLINK | D13: 0 | E13: 0 | F13: 0 | G13: 0 | H13: 0 | I13: 0 | J13: 0 | K13: 0 | L13: 0 | M13: 0 | N13: 0 | O13: 0 | P13: 0
C14: JONDO | D14: 0 | E14: 0 | F14: 0 | G14: 0 | H14: 0 | I14: 0 | J14: 0 | K14: 0 | L14: 0 | M14: 0 | N14: 0 | O14: 0 | P14: 0
C15: PROCO | D15: 0 | E15: 0 | F15: 0 | G15: 0 | H15: 0 | I15: 0 | J15: 0 | K15: 0 | L15: 0 | M15: 0 | N15: 0 | O15: 0 | P15: 0
C16: Logistics | D16: 0 | E16: 0 | F16: 0 | G16: 0 | H16: 0 | I16: 0 | J16: 0 | K16: 0 | L16: 0 | M16: 0 | N16: 0 | O16: 0 | P16: 0
C17: PROCO | D17: 0 | E17: 0 | F17: 0 | G17: 0 | H17: 0 | I17: 0 | J17: 0 | K17: 0 | L17: 0 | M17: 0 | N17: 0 | O17: 0 | P17: 0
C18: PORTCLEARANCE | D18: 0 | E18: 0 | F18: 0 | G18: 0 | H18: 0 | I18: 0 | J18: 0 | K18: 0 | L18: 0 | M18: 0 | N18: 0 | O18: 0 | P18: 0
C19: Payment fees | D19: 0 | E19: 0 | F19: 0 | G19: 0 | H19: 0 | I19: 0 | J19: 0 | K19: 0 | L19: 0 | M19: 0 | N19: 0 | O19: 0 | P19: 0
C20: SHOPIFY | D20: 0 | E20: 0 | F20: 0 | G20: 0 | H20: 0 | I20: 0 | J20: 0 | K20: 0 | L20: 0 | M20: 0 | N20: 0 | O20: 0 | P20: 0
B22: Opex | D22: 1 | E22: 0 | F22: 0 | G22: 0 | H22: 0 | I22: 0 | J22: 0 | K22: 0 | L22: 0 | M22: 0 | N22: 0 | O22: 0 | P22: 1
C23: Shared services | D23: 0 | E23: 0 | F23: 0 | G23: 0 | H23: 0 | I23: 0 | J23: 0 | K23: 0 | L23: 0 | M23: 0 | N23: 0 | O23: 0 | P23: 0
C24: SHAREDSERVICESSL | D24: 0 | E24: 0 | F24: 0 | G24: 0 | H24: 0 | I24: 0 | J24: 0 | K24: 0 | L24: 0 | M24: 0 | N24: 0 | O24: 0 | P24: 0
C25: Administration | D25: 1 | E25: 0 | F25: 0 | G25: 0 | H25: 0 | I25: 0 | J25: 0 | K25: 0 | L25: 0 | M25: 0 | N25: 0 | O25: 0 | P25: 1
C26: YOURACCOUNTSTAXES | D26: 1 | E26: 0 | F26: 0 | G26: 0 | H26: 0 | I26: 0 | J26: 0 | K26: 0 | L26: 0 | M26: 0 | N26: 0 | O26: 0 | P26: 1
C27: Technology | D27: 0 | E27: 0 | F27: 0 | G27: 0 | H27: 0 | I27: 0 | J27: 0 | K27: 0 | L27: 0 | M27: 0 | N27: 0 | O27: 0 | P27: 0
C28: REVER | D28: 0 | E28: 0 | F28: 0 | G28: 0 | H28: 0 | I28: 0 | J28: 0 | K28: 0 | L28: 0 | M28: 0 | N28: 0 | O28: 0 | P28: 0
C29: Otros gastos | D29: 0 | E29: 0 | F29: 0 | G29: 0 | H29: 0 | I29: 0 | J29: 0 | K29: 0 | L29: 0 | M29: 0 | N29: 0 | O29: 0 | P29: 0
B30: Diferencias divisas | D30: 0 | E30: 0 | F30: 0 | G30: 0 | H30: 0 | I30: 0 | J30: 0 | K30: 0 | L30: 0 | M30: 0 | N30: 0 | O30: 0 | P30: 0
