Workbook

Sheet val_pyg_old_vs_new_por
A4: Sales
A5: #VALUE! | B5: Spain | E5: =+('P&G-SL'!I6-data_pyg_old!B3)/data_pyg_old!B3 -> -0.42854758 | F5: =+('P&G-SL'!J6-data_pyg_old!C3)/data_pyg_old!C3 -> -0.019304881 | G5: =+('P&G-SL'!K6-data_pyg_old!D3)/data_pyg_old!D3 -> -0.39952653 | H5: =+('P&G-SL'!L6-data_pyg_old!E3)/data_pyg_old!E3 -> -1 | I5: =+('P&G-SL'!M6-data_pyg_old!F3)/data_pyg_old!F3 -> -1 | J5: =+('P&G-SL'!N6-data_pyg_old!G3)/data_pyg_old!G3 -> -1 | K5: =+('P&G-SL'!O6-data_pyg_old!H3)/data_pyg_old!H3 -> -1 | L5: =+('P&G-SL'!P6-data_pyg_old!I3)/data_pyg_old!I3 -> -1 | ... P5: =+('P&G-SL'!T6-data_pyg_old!M3)/data_pyg_old!M3 -> #VALUE!
A6: #VALUE! | B6: Germany | E6: =+('P&G-SL'!I7-data_pyg_old!B22)/data_pyg_old!B22 -> -0.22947362 | F6: =+('P&G-SL'!J7-data_pyg_old!C22)/data_pyg_old!C22 -> -0.20288045 | G6: =+('P&G-SL'!K7-data_pyg_old!D22)/data_pyg_old!D22 -> -0.38898447 | H6: =+('P&G-SL'!L7-data_pyg_old!E22)/data_pyg_old!E22 -> -1 | I6: =+('P&G-SL'!M7-data_pyg_old!F22)/data_pyg_old!F22 -> -1 | J6: =+('P&G-SL'!N7-data_pyg_old!G22)/data_pyg_old!G22 -> -1 | K6: =+('P&G-SL'!O7-data_pyg_old!H22)/data_pyg_old!H22 -> -1 | L6: =+('P&G-SL'!P7-data_pyg_old!I22)/data_pyg_old!I22 -> -1 | ... P6: =+('P&G-SL'!T7-data_pyg_old!M22)/data_pyg_old!M22 -> #VALUE!
A7: #VALUE! | B7: France | E7: =(+'P&G-SL'!I8-data_pyg_old!B37)/data_pyg_old!B37 -> -0.27458723 | F7: =(+'P&G-SL'!J8-data_pyg_old!C37)/data_pyg_old!C37 -> 1.0280014 | G7: =(+'P&G-SL'!K8-data_pyg_old!D37)/data_pyg_old!D37 -> 0.35204661 | H7: =(+'P&G-SL'!L8-data_pyg_old!E37)/data_pyg_old!E37 -> -1 | I7: =(+'P&G-SL'!M8-data_pyg_old!F37)/data_pyg_old!F37 -> -1 | J7: =(+'P&G-SL'!N8-data_pyg_old!G37)/data_pyg_old!G37 -> -1 | K7: =(+'P&G-SL'!O8-data_pyg_old!H37)/data_pyg_old!H37 -> -1 | L7: =(+'P&G-SL'!P8-data_pyg_old!I37)/data_pyg_old!I37 -> -1 | ... P7: =(+'P&G-SL'!T8-data_pyg_old!M37)/data_pyg_old!M37 -> #VALUE!
A8: #VALUE! | B8: Italy | E8: =+('P&G-SL'!I9-data_pyg_old!B52)/data_pyg_old!B52 -> 3.4047303 | F8: =+('P&G-SL'!J9-data_pyg_old!C52)/data_pyg_old!C52 -> 3.548509 | G8: =+('P&G-SL'!K9-data_pyg_old!D52)/data_pyg_old!D52 -> 0.75869978 | H8: =+('P&G-SL'!L9-data_pyg_old!E52)/data_pyg_old!E52 -> -1 | I8: =+('P&G-SL'!M9-data_pyg_old!F52)/data_pyg_old!F52 -> -1 | J8: =+('P&G-SL'!N9-data_pyg_old!G52)/data_pyg_old!G52 -> -1 | K8: =+('P&G-SL'!O9-data_pyg_old!H52)/data_pyg_old!H52 -> -1 | L8: =+('P&G-SL'!P9-data_pyg_old!I52)/data_pyg_old!I52 -> -1 | ... P8: =+('P&G-SL'!T9-data_pyg_old!M52)/data_pyg_old!M52 -> #VALUE!
A9: #VALUE! | B9: Austria | E9: =+('P&G-SL'!I10-data_pyg_old!B98)/data_pyg_old!B98 -> 9.8625889 | F9: =+('P&G-SL'!J10-data_pyg_old!C98)/data_pyg_old!C98 -> 22.318396 | G9: =+('P&G-SL'!K10-data_pyg_old!D98)/data_pyg_old!D98 -> 3.1233172 | H9: =+('P&G-SL'!L10-data_pyg_old!E98)/data_pyg_old!E98 -> -1 | I9: =+('P&G-SL'!M10-data_pyg_old!F98)/data_pyg_old!F98 -> -1 | J9: =+('P&G-SL'!N10-data_pyg_old!G98)/data_pyg_old!G98 -> -1 | K9: =+('P&G-SL'!O10-data_pyg_old!H98)/data_pyg_old!H98 -> -1 | L9: =+('P&G-SL'!P10-data_pyg_old!I98)/data_pyg_old!I98 -> -1 | ... P9: =+('P&G-SL'!T10-data_pyg_old!M98)/data_pyg_old!M98 -> #VALUE!

Sheet data_pyg_old
A1: Turnover | B1: 190037.6 | C1: 134163.24 | D1: 166288.41 | E1: 110118.52 | F1: 145019.23 | G1: 112800.06 | H1: 145105.3 | I1: 131261.64 | J1: - € | K1: - € | L1: - € | M1: - € | N1: 1134794
A2: Sales | B2: 174998.39 | C2: 118201.5 | D2: 126289.62 | E2: 96766.19 | F2: 132420.92 | G2: 98426.07 | H2: 122634.13 | I2: 111690.24 | J2: - € | K2: - € | L2: - € | M2: - € | N2: 981427.06 | Q2: January | R2: February | S2: March | T2: April | U2: May | V2: June | W2: July | X2: August | Y2: September | Z2: October | AA2: November | AB2: December | AC2: TOTAL
A3: Spain | B3: 107085.8 | C3: 74793.52 | D3: 76591.76 | E3: 60258.69 | F3: 72717.13 | G3: 66400.2 | H3: 78448.45 | I3: 56561.37 | J3: - € | K3: - € | L3: - € | M3: - € | N3: 592856.92 | P3: Turnover | Q3: 28261.01 | R3: 31634.75 | S3: 32185.53 | T3: 25510.99 | U3: 25273.31 | V3: 27123.55 | W3: 26037.43 | X3: 22881.03 | Y3: - | Z3: - | AA3: - | AB3: - | AC3: 218907.6
A4: Share % | B4: 0.61 | C4: 0.63 | D4: 0.61 | E4: 0.62 | F4: 0.55 | G4: 0.63 | H4: 0.64 | I4: 0.51 | J4: #DIV/0! | K4: #DIV/0! | L4: #DIV/0! | M4: #DIV/0! | N4: 0.6 | P4: the UK | Q4: 28261.01 | R4: 31634.75 | S4: 32185.53 | T4: 25510.99 | U4: 25273.31 | V4: 27123.55 | W4: 26037.43 | X4: 22881.03 | Y4: - | Z4: - | AA4: - | AB4: - | AC4: 218907.6
A5: Web | B5: 101430.37 | C5: 65195.15 | D5: 66244.47 | E5: - € | F5: - € | G5: - € | I5: - € | J5: - € | K5: - € | L5: - € | M5: - € | N5: 232869.99 | P5: Web | Q5: 28135.76 | R5: 31521 | S5: 28707.38 | T5: 25470.24 | U5: 25232.56 | V5: 821.82 | W5: - | X5: - | Y5: - | Z5: - | AA5: - | AB5: - | AC5: 139888.76
A6: Shopify | B6: 87370.09 | C6: 52964.62 | D6: 53946.7 | E6: - € | F6: - € | G6: - € | I6: - € | J6: - € | K6: - € | L6: - € | M6: - € | N6: 194281.41 | P6: Shopify | Q6: 23454.86 | R6: 26313.42 | S6: 26810.64 | T6: 22279.23 | U6: 21676.29 | V6: - | W6: - | X6: - | Y6: - | Z6: - | AA6: - | AB6: - | AC6: 120534.44
A7: Paypal | B7: 10946.77 | C7: 8806.36 | D7: 9617.1 | E7: - € | F7: - € | G7: - € | I7: - € | J7: - € | K7: - € | L7: - € | M7: - € | N7: 29370.23 | P7: Paypal | Q7: 3973.2 | R7: 4626.66 | S7: 936.91 | T7: 2479.59 | U7: 3178.86 | V7: - | W7: - | X7: - | Y7: - | Z7: - | AA7: - | AB7: - | AC7: 15195.22
A8: Amazon Pay | B8: - € | C8: - € | E8: - € | F8: - € | G8: - € | I8: - € | J8: - € | K8: - € | L8: - € | M8: - € | N8: - € | P8: Amazon Pay | Q8: - | R8: - | S8: - | T8: - | U8: - | V8: - | W8: - | X8: - | Y8: - | Z8: - | AA8: - | AB8: - | AC8: -
A9: Klarna | B9: 1477.01 | C9: 1523.75 | D9: 1731.8 | E9: - € | F9: - € | G9: - € | I9: - € | J9: - € | K9: - € | L9: - € | M9: - € | N9: 4732.56 | P9: Klarna | Q9: 707.7 | R9: 580.92 | S9: 959.83 | T9: 639.97 | U9: 377.41 | V9: 821.82 | W9: - | X9: - | Y9: - | Z9: - | AA9: - | AB9: - | AC9: 4087.65
A10: Revolut | B10: 482.29 | C10: 347.84 | D10: 50.5 | E10: - € | F10: - € | G10: - € | I10: - € | J10: - € | K10: - € | L10: - € | M10: - € | N10: 880.63 | P10: Revolut | R10: - | S10: - | T10: - | U10: - | V10: - | W10: - | X10: - | Y10: - | Z10: - | AA10: - | AB10: - | AC10: -
A11: SeQura | B11: - € | C11: - € | D11: - € | E11: - € | F11: - € | G11: - € | I11: - € | J11: - € | K11: - € | L11: - € | M11: - € | N11: - € | P11: Bank transfer | Q11: - | R11: - | S11: - | T11: 71.45 | U11: - | V11: - | W11: - | X11: - | Y11: - | Z11: - | AA11: - | AB11: - | AC11: 71.45
A12: Hannun | B12: 1154.21 | C12: 1552.58 | D12: 898.37 | E12: - € | F12: - € | G12: - € | I12: - € | J12: - € | K12: - € | L12: - € | M12: - € | N12: 3605.16 | P12: Marketplace | Q12: 125.25 | R12: 113.75 | S12: - | T12: 40.75 | U12: 40.75 | V12: - | W12: - | X12: - | Y12: - | Z12: - | AA12: - | AB12: - | AC12: 320.5
A13: B2B | B13: 4386.25 | C13: 8435.65 | D13: 9467.3 | E13: - € | F13: - € | G13: - € | I13: - € | J13: - € | K13: - € | L13: - € | M13: - € | N13: 22289.2 | P13: Amazon Seller | Q13: 125.25 | R13: 113.75 | S13: - | T13: 40.75 | U13: 40.75 | V13: - | W13: - | X13: - | Y13: - | Z13: - | AA13: - | AB13: - | AC13: 320.5
A14: Bank transfer | B14: 4386.25 | C14: 8435.65 | D14: 9467.3 | E14: - € | F14: - € | G14: - € | I14: - € | J14: - € | K14: - € | L14: - € | M14: - € | N14: 22289.2 | P14: B2B | Q14: - | R14: - | S14: 3478.15 | T14: - € | U14: - € | V14: - € | W14: - € | X14: - € | Y14: - € | Z14: - € | AA14: - € | AB14: - € | AC14: 3478.15
A15: Web | B15: - € | C15: - € | E15: - € | F15: - € | G15: - € | I15: - € | J15: - € | K15: - € | L15: - € | M15: - € | N15: - € | P15: Bank transfer | Q15: - | R15: - | S15: - | T15: - € | U15: - € | V15: - € | W15: - € | X15: - € | Y15: - € | Z15: - € | AA15: - € | AB15: - € | AC15: - €
A16: Paypal | P16: Web | Q16: - | R16: - | S16: 2459.35 | T16: - € | U16: - € | V16: - € | W16: - € | X16: - € | Y16: - € | Z16: - € | AA16: - € | AB16: - € | AC16: 2459.35
A17: Marketplace | B17: 1269.18 | C17: 1162.72 | D17: 879.99 | E17: - € | F17: - € | G17: - € | I17: - € | J17: - € | K17: - € | L17: - € | M17: - € | N17: 3190.12 | P17: Paypal | S17: £ 1.018,80
A18: Amazon Seller | B18: 223.01 | C18: 256.19 | D18: 174.5 | E18: - € | F18: - € | G18: - € | I18: - € | J18: - € | K18: - € | L18: - € | M18: - € | N18: 653.7
A19: Maisons du Monde | B19: 979.43 | C19: 906.53 | D19: 650.46 | E19: - € | F19: - € | G19: - € | I19: - € | J19: - € | K19: - € | L19: - € | M19: - € | N19: 2536.42
A20: Leroy Merlin | B20: 66.74 | C20: - € | D20: 55.03 | E20: - € | F20: - € | G20: - € | I20: - € | J20: - € | K20: - € | L20: - € | M20: - € | N20: 121.77
A22: Germany | B22: 27155.67 | C22: 24289.28 | D22: 25631.82 | E22: 24271.09 | F22: 22639.29 | G22: 23154.4 | H22: 17733.42 | I22: 17029.18 | J22: - € | K22: - € | L22: - € | M22: - € | N22: 181904.15
A23: Share % | B23: 0.16 | C23: 0.21 | D23: 0.2 | E23: 0.25 | F23: 0.17 | G23: 0.22 | I23: 0.15 | J23: #DIV/0! | K23: #DIV/0! | L23: #DIV/0! | M23: #DIV/0! | N23: 0.19
A24: Web | B24: 25515.08 | C24: 22629.75 | D24: 24618.7 | E24: - € | F24: - € | G24: - € | I24: - € | J24: - € | K24: - € | L24: - € | M24: - € | N24: 72763.53
A25: Shopify | B25: 7756.93 | C25: 8263.46 | D25: 10156.8 | E25: - € | F25: - € | G25: - € | I25: - € | J25: - € | K25: - € | L25: - € | M25: - € | N25: 26177.19
A26: Paypal | B26: 17758.15 | C26: 14205.5 | D26: 13052.4 | E26: - € | F26: - € | G26: - € | I26: - € | J26: - € | K26: - € | L26: - € | M26: - € | N26: 45016.05
A27: Amazon Pay | B27: - € | C27: - € | D27: - € | E27: - € | F27: - € | G27: - € | I27: - € | J27: - € | K27: - € | L27: - € | M27: - € | N27: - €
A28: Klarna | B28: - € | C28: - € | D28: - € | E28: - € | F28: - € | G28: - € | I28: - € | J28: - € | K28: - € | L28: - € | M28: - € | N28: - €
A29: Revolut | B29: - € | C29: - € | D29: - € | E29: - € | F29: - € | G29: - € | I29: - € | J29: - € | K29: - € | L29: - € | M29: - € | N29: - €
A30: Bank transfer | B30: - € | C30: 160.79 | D30: 1409.5 | E30: - € | F30: - € | G30: - € | I30: - € | J30: - € | K30: - € | L30: - € | M30: - € | N30: 1570.29
A31: Marketplace | B31: 1640.59 | C31: 1659.53 | D31: 1013.12 | E31: - € | F31: - € | G31: - € | I31: - € | J31: - € | K31: - € | L31: - € | M31: - € | N31: 792.23
A32: Amazon Seller | B32: 310.91 | C32: 203.62 | D32: 277.7 | E32: - € | F32: - € | G32: - € | I32: - € | J32: - € | K32: - € | L32: - € | M32: - € | N32: 792.23
A33: Maisons du Monde | B33: 1329.68 | C33: 1350.25 | D33: 340.2 | E33: - € | F33: - € | G33: - € | I33: - € | J33: - € | K33: - € | L33: - € | M33: - € | N33: - €
A34: Leroy Merlin | B34: - € | C34: - € | D34: - € | E34: - € | F34: - € | G34: - € | I34: - € | J34: - € | K34: - € | L34: - € | M34: - € | N34: - €
A35: Home24 | B35: - € | C35: 105.66 | D35: 395.22 | E35: - € | F35: - € | G35: - € | I35: - € | J35: - € | K35: - € | L35: - € | M35: - € | N35: 500.88
A37: France | B37: 35276.95 | C37: 13561.45 | D37: 16399.05 | E37: 8456.84 | F37: 32386.23 | G37: 6207.97 | H37: 14615.31 | I37: 18120.88 | J37: - € | K37: - € | L37: - € | M37: - € | N37: 145024.68
A38: Web | B38: 15640.02 | C38: 13561.45 | D38: 13617.4 | E38: - € | F38: 11538.53 | G38: 13612.1 | I38: - € | J38: - € | K38: - € | L38: - € | M38: - € | N38: 67969.5
A39: Shopify | B39: 12765.42 | C39: 10947.48 | D39: 11594.3 | E39: - € | F39: - € | G39: - € | I39: - € | J39: - € | K39: - € | L39: - € | M39: - € | N39: 35307.2
A40: Paypal | B40: 2874.6 | C40: 2463.75 | D40: 1875.4 | E40: - € | F40: - € | G40: - € | I40: - € | J40: - € | K40: - € | L40: - € | M40: - € | N40: 7213.75
A41: Amazon Pay | B41: - € | C41: - € | D41: - € | E41: - € | F41: - € | G41: - € | I41: - € | J41: - € | K41: - € | L41: - € | M41: - € | N41: - €
A42: Klarna | B42: - € | C42: - € | D42: - € | E42: - € | F42: - € | G42: - € | I42: - € | J42: - € | K42: - € | L42: - € | M42: - € | N42: - €
...

Sheet val_pyg_old_vs_new_imp
A4: Sales
A5: #VALUE! | B5: Spain | C5: =+'P&G-SL'!I6-data_pyg_old!B3 -> -45891.36 | D5: =+'P&G-SL'!J6-data_pyg_old!C3 -> -1443.88 | E5: =+'P&G-SL'!K6-data_pyg_old!D3 -> -30600.44 | F5: =+'P&G-SL'!L6-data_pyg_old!E3 -> -60258.69 | G5: =+'P&G-SL'!M6-data_pyg_old!F3 -> -72717.13 | H5: =+'P&G-SL'!N6-data_pyg_old!G3 -> -66400.2 | I5: =+'P&G-SL'!O6-data_pyg_old!H3 -> -78448.45 | J5: =+'P&G-SL'!P6-data_pyg_old!I3 -> -56561.37
A6: #VALUE! | B6: Germany | C6: =+'P&G-SL'!I7-data_pyg_old!B22 -> -6231.51 | D6: =+'P&G-SL'!J7-data_pyg_old!C22 -> -4927.82 | E6: =+'P&G-SL'!K7-data_pyg_old!D22 -> -9970.38 | F6: =+'P&G-SL'!L7-data_pyg_old!E22 -> -24271.09 | G6: =+'P&G-SL'!M7-data_pyg_old!F22 -> -22639.29 | H6: =+'P&G-SL'!N7-data_pyg_old!G22 -> -23154.4 | I6: =+'P&G-SL'!O7-data_pyg_old!H22 -> -17733.42 | J6: =+'P&G-SL'!P7-data_pyg_old!I22 -> -17029.18
A7: #VALUE! | B7: France | C7: =+'P&G-SL'!I8-data_pyg_old!B37 -> -9686.6 | D7: =+'P&G-SL'!J8-data_pyg_old!C37 -> 13941.19 | E7: =+'P&G-SL'!K8-data_pyg_old!D37 -> 5773.23 | F7: =+'P&G-SL'!L8-data_pyg_old!E37 -> -8456.84 | G7: =+'P&G-SL'!M8-data_pyg_old!F37 -> -32386.23 | H7: =+'P&G-SL'!N8-data_pyg_old!G37 -> -6207.97 | I7: =+'P&G-SL'!O8-data_pyg_old!H37 -> -14615.31 | J7: =+'P&G-SL'!P8-data_pyg_old!I37 -> -18120.88
A8: #VALUE! | B8: Italy | C8: =+'P&G-SL'!I9-data_pyg_old!B52 -> 14287.44 | D8: =+'P&G-SL'!J9-data_pyg_old!C52 -> 15637.96 | E8: =+'P&G-SL'!K9-data_pyg_old!D52 -> 4608.13 | F8: =+'P&G-SL'!L9-data_pyg_old!E52 -> -2936.99 | G8: =+'P&G-SL'!M9-data_pyg_old!F52 -> -2074.75 | H8: =+'P&G-SL'!N9-data_pyg_old!G52 -> -2056.2 | I8: =+'P&G-SL'!O9-data_pyg_old!H52 -> -9924.85 | J8: =+'P&G-SL'!P9-data_pyg_old!I52 -> -13695.03
A9: #VALUE! | B9: Austria | C9: =+'P&G-SL'!I10-data_pyg_old!B98 -> 4977.55 | D9: =+'P&G-SL'!J10-data_pyg_old!C98 -> 5817.29 | E9: =+'P&G-SL'!K10-data_pyg_old!D98 -> 2709.79 | F9: =+'P&G-SL'!L10-data_pyg_old!E98 -> -291.64 | G9: =+'P&G-SL'!M10-data_pyg_old!F98 -> -511.26 | H9: =+'P&G-SL'!N10-data_pyg_old!G98 -> -383.1 | I9: =+'P&G-SL'!O10-data_pyg_old!H98 -> -1508.86 | J9: =+'P&G-SL'!P10-data_pyg_old!I98 -> -4924.93
A10: #VALUE! | B10: the Netherlands | C10: =+'P&G-SL'!I12-data_pyg_old!B64 -> -259.07 | D10: =+'P&G-SL'!J12-data_pyg_old!C64 -> -78.21 | E10: =+'P&G-SL'!K12-data_pyg_old!D64 -> 8.52 | F10: =+'P&G-SL'!L12-data_pyg_old!E64 -> -14.83 | G10: =+'P&G-SL'!M12-data_pyg_old!F64 -> -49.5 | H10: =+'P&G-SL'!N12-data_pyg_old!G64 -> -57.9 | I10: =+'P&G-SL'!O12-data_pyg_old!H64 -> -150.99 | J10: =+'P&G-SL'!P12-data_pyg_old!I64 -> -416.82
A11: #VALUE! | B11: Belgium | C11: =+'P&G-SL'!I11-data_pyg_old!B75 -> 187.1 | D11: =+'P&G-SL'!J11-data_pyg_old!C75 -> 948.39 | E11: =+'P&G-SL'!K11-data_pyg_old!D75 -> -50.34 | F11: =+'P&G-SL'!L11-data_pyg_old!E75 -> -232.18 | G11: =+'P&G-SL'!M11-data_pyg_old!F75 -> -533.77 | H11: =+'P&G-SL'!N11-data_pyg_old!G75 -> -54.2 | I11: =+'P&G-SL'!O11-data_pyg_old!H75 -> -54.2 | J11: =+'P&G-SL'!P11-data_pyg_old!I75 -> -461.61
A12: #VALUE! | B12: Portugal | C12: =+'P&G-SL'!I13-data_pyg_old!B87 -> 634.87 | D12: =+'P&G-SL'!J13-data_pyg_old!C87 -> 1236.05 | E12: =+'P&G-SL'!K13-data_pyg_old!D87 -> -28.8 | F12: =+'P&G-SL'!L13-data_pyg_old!E87 -> -67.69 | G12: =+'P&G-SL'!M13-data_pyg_old!F87 -> -46.59 | H12: =+'P&G-SL'!N13-data_pyg_old!G87 -> -57.9 | I12: =+'P&G-SL'!O13-data_pyg_old!H87 -> -92.15 | J12: =+'P&G-SL'!P13-data_pyg_old!I87 -> -386.5
A13: #VALUE! | B13: Other markets | C13: =+'P&G-SL'!I14-data_pyg_old!B109 -> 616.96 | D13: =+'P&G-SL'!J14-data_pyg_old!C109 -> -275.39 | E13: =+'P&G-SL'!K14-data_pyg_old!D109 -> -361.88 | F13: =+'P&G-SL'!L14-data_pyg_old!E109 -> -236.24 | G13: =+'P&G-SL'!M14-data_pyg_old!F109 -> -1462.4 | H13: =+'P&G-SL'!N14-data_pyg_old!G109 -> -54.2 | I13: =+'P&G-SL'!O14-data_pyg_old!H109 -> -105.9 | J13: =+'P&G-SL'!P14-data_pyg_old!I109 -> -93.92
A14: #VALUE! | B14: United Kingdom | C14: =+'P&G-Ltd'!H5-data_pyg_old!Q3 -> -12558.35 | D14: =+'P&G-Ltd'!I5-data_pyg_old!R3 -> -12205.5 | E14: =+'P&G-Ltd'!J5-data_pyg_old!S3 -> -18542.89 | F14: =+'P&G-Ltd'!K5-data_pyg_old!T3 -> -25510.99 | G14: =+'P&G-Ltd'!L5-data_pyg_old!U3 -> -25273.31 | H14: =+'P&G-Ltd'!M5-data_pyg_old!V3 -> -27123.55 | I14: =+'P&G-Ltd'!N5-data_pyg_old!W3 -> -26037.43 | J14: =+'P&G-Ltd'!O5-data_pyg_old!X3 -> -22881.03

Sheet Val_FR_202501
A1: Sales channel | B1: Order name | C1: Total sales | D1: Orders | E1: Gross sales | F1: Discounts | G1: Returns | H1: Net sales | I1: Shipping charges | J1: Duties | K1: Additional fees | L1: Taxes
A2: Online Store | B2: ES-69606 | C2: 632.52 | D2: 1 | E2: 585.59 | F2: -58.49 | G2: 0 | H2: 527.1 | I2: 0 | J2: 0 | K2: 0 | L2: 105.42
A3: Online Store | B3: ES-67388 | C3: 618.48 | D3: 1 | E3: 572.62 | F3: -57.22 | G3: 0 | H3: 515.4 | I3: 0 | J3: 0 | K3: 0 | L3: 103.08
A4: Online Store | B4: ES-68305 | C4: 314.4 | D4: 1 | E4: 262 | F4: 0 | G4: 0 | H4: 262 | I4: 0 | J4: 0 | K4: 0 | L4: 52.4
A5: Online Store | B5: ES-69281 | C5: 305.46 | D5: 1 | E5: 282.79 | F5: -28.24 | G5: 0 | H5: 254.55 | I5: 0 | J5: 0 | K5: 0 | L5: 50.91
A6: Online Store | B6: ES-69525 | C6: 275.55 | D6: 1 | E6: 229.62 | F6: 0 | G6: 0 | H6: 229.62 | I6: 0 | J6: 0 | K6: 0 | L6: 45.93
A7: Online Store | B7: ES-67042 | C7: 272.5 | D7: 1 | E7: 227.08 | F7: 0 | G7: 0 | H7: 227.08 | I7: 0 | J7: 0 | K7: 0 | L7: 45.42
A8: Online Store | B8: ES-69264 | C8: 265.5 | D8: 1 | E8: 221.25 | F8: 0 | G8: 0 | H8: 221.25 | I8: 0 | J8: 0 | K8: 0 | L8: 44.25
A9: Online Store | B9: ES-69047 | C9: 242.6 | D9: 1 | E9: 202.17 | F9: 0 | G9: 0 | H9: 202.17 | I9: 0 | J9: 0 | K9: 0 | L9: 40.43
A10: Online Store | B10: ES-68426 | C10: 233.64 | D10: 1 | E10: 216.3 | F10: -21.6 | G10: 0 | H10: 194.7 | I10: 0 | J10: 0 | K10: 0 | L10: 38.94
A11: Online Store | B11: ES-69526 | C11: 230.5 | D11: 1 | E11: 192.08 | F11: 0 | G11: 0 | H11: 192.08 | I11: 0 | J11: 0 | K11: 0 | L11: 38.42
A12: Online Store | B12: ES-68010 | C12: 223.5 | D12: 1 | E12: 186.25 | F12: 0 | G12: 0 | H12: 186.25 | I12: 0 | J12: 0 | K12: 0 | L12: 37.25
A13: Online Store | B13: ES-69205 | C13: 206.1 | D13: 1 | E13: 171.75 | F13: 0 | G13: 0 | H13: 171.75 | I13: 0 | J13: 0 | K13: 0 | L13: 34.35
... A309: Online Store | B309: ES-64976 | C309: -245.7 | D309: 0 | E309: 0 | F309: 0 | G309: -204.75 | H309: -204.75 | I309: 0 | J309: 0 | K309: 0 | L309: -40.95

Sheet P&G-SL
I1: =+params!B4 -> 202601 | J1: =+params!C4 -> 202602 | K1: =+params!D4 -> 202603 | L1: =+params!E4 -> 202604 | M1: =+params!F4 -> 202605 | N1: =+params!G4 -> 202606 | O1: =+params!H4 -> 202607 | P1: =+params!I4 -> 202608 | ... T1: =+params!M4 -> 202612
E2: 2026 | I2: Enero | J2: Febrero | K2: Marzo | L2: Abril | M2: Mayo | N2: Junio | O2: Julio | P2: Agosto | Q2: Septiembre | R2: Octubre | S2: Noviembre | T2: Diciembre | U2: Total
D3: Turnover | I3: =+I4+I30 -> 152677.71 | J3: =+J4+J30 -> 174132.08 | K3: =+K4+K30 -> 113987.41 | L3: =+L4+L30 -> 0 | M3: =+M4+M30 -> 0 | N3: =+N4+N30 -> 0 | O3: =+O4+O30 -> 0 | P3: =+P4+P30 -> 0 | ... T3: =+T4+T30 -> 0 | U3: =SUM(I3:T3) -> 440797.2
D4: SALES | I4: =+I5+I16+I21+I23 -> 131758.06 | J4: =+J5+J16+J21+J23 -> 151409.56 | K4: =+K5+K16+K21+K23 -> 113987.41 | L4: =+L5+L16+L21+L23 -> 0 | M4: =+M5+M16+M21+M23 -> 0 | N4: =+N5+N16+N21+N23 -> 0 | O4: =+O5+O16+O21+O23 -> 0 | P4: =+P5+P16+P21+P23 -> 0 | ... T4: =+T5+T16+T21+T23 -> 0 | U4: =SUM(I4:T4) -> 397155.03
A5: Hannun | B5: Mirakl | C5: Country | E5: Shopify | I5: =SUM(I6:I14) -> 133633.77 | J5: =SUM(J6:J14) -> 149057.08 | K5: =SUM(K6:K14) -> 98377.45 | L5: =SUM(L6:L14) -> 0 | M5: =SUM(M6:M14) -> 0 | N5: =SUM(N6:N14) -> 0 | O5: =SUM(O6:O14) -> 0 | P5: =SUM(P6:P14) -> 0 | ... T5: =SUM(T6:T14) -> 0 | U5: =SUM(I5:T5) -> 381068.3
A6: 0 | B6: 0 | C6: ES | E6: #VALUE! | F6: Spain | I6: =SUMIFS('i-sales'!$K:$K, 'i-sales'!$C:$C,'P&G-SL'!I$1, 'i-sales'!$D:$D,'P&G-SL'!$C6, 'i-sales'!$G:$G,'P&G-SL'!$A6, 'i-sales'!$H:$H,'P&G-SL'!$B6 ) -> 61194.44 | J6: =SUMIFS('i-sales'!$K:$K, 'i-sales'!$C:$C,'P&G-SL'!J$1, 'i-sales'!$D:$D,'P&G-SL'!$C6, 'i-sales'!$G:$G,'P&G-SL'!$A6, 'i-sales'!$H:$H,'P&G-SL'!$B6 ) -> 73349.64 | K6: =SUMIFS('i-sales'!$K:$K, 'i-sales'!$C:$C,'P&G-SL'!K$1, 'i-sales'!$D:$D,'P&G-SL'!$C6, 'i-sales'!$G:$G,'P&G-SL'!$A6, 'i-sales'!$H:$H,'P&G-SL'!$B6 ) -> 45991.32 | L6: =SUMIFS('i-sales'!$K:$K, 'i-sales'!$C:$C,'P&G-SL'!L$1, 'i-sales'!$D:$D,'P&G-SL'!$C6, 'i-sales'!$G:$G,'P&G-SL'!$A6, 'i-sales'!$H:$H,'P&G-SL'!$B6 ) -> 0 | M6: =SUMIFS('i-sales'!$K:$K, 'i-sales'!$C:$C,'P&G-SL'!M$1, 'i-sales'!$D:$D,'P&G-SL'!$C6, 'i-sales'!$G:$G,'P&G-SL'!$A6, 'i-sales'!$H:$H,'P&G-SL'!$B6 ) -> 0 | N6: =SUMIFS('i-sales'!$K:$K, 'i-sales'!$C:$C,'P&G-SL'!N$1, 'i-sales'!$D:$D,'P&G-SL'!$C6, 'i-sales'!$G:$G,'P&G-SL'!$A6, 'i-sales'!$H:$H,'P&G-SL'!$B6 ) -> 0 | O6: =SUMIFS('i-sales'!$K:$K, 'i-sales'!$C:$C,'P&G-SL'!O$1, 'i-sales'!$D:$D,'P&G-SL'!$C6, 'i-sales'!$G:$G,'P&G-SL'!$A6, 'i-sales'!$H:$H,'P&G-SL'!$B6 ) -> 0 | P6: =SUMIFS('i-sales'!$K:$K, 'i-sales'!$C:$C,'P&G-SL'!P$1, 'i-sales'!$D:$D,'P&G-SL'!$C6, 'i-sales'!$G:$G,'P&G-SL'!$A6, 'i-sales'!$H:$H,'P&G-SL'!$B6 ) -> 0 | ... T6: =SUMIFS('i-sales'!$K:$K, 'i-sales'!$C:$C,'P&G-SL'!T$1, 'i-sales'!$D:$D,'P&G-SL'!$C6, 'i-sales'!$G:$G,'P&G-SL'!$A6, 'i-sales'!$H:$H,'P&G-SL'!$B6 ) -> 0 | U6: =SUM(I6:T6) -> 180535.4
A7: 0 | B7: 0 | C7: DE | E7: #VALUE! | F7: Germany | I7: =SUMIFS('i-sales'!$K:$K, 'i-sales'!$C:$C,'P&G-SL'!I$1, 'i-sales'!$D:$D,'P&G-SL'!$C7, 'i-sales'!$G:$G,'P&G-SL'!$A7, 'i-sales'!$H:$H,'P&G-SL'!$B7 ) -> 20924.16 | J7: =SUMIFS('i-sales'!$K:$K, 'i-sales'!$C:$C,'P&G-SL'!J$1, 'i-sales'!$D:$D,'P&G-SL'!$C7, 'i-sales'!$G:$G,'P&G-SL'!$A7, 'i-sales'!$H:$H,'P&G-SL'!$B7 ) -> 19361.46 | K7: =SUMIFS('i-sales'!$K:$K, 'i-sales'!$C:$C,'P&G-SL'!K$1, 'i-sales'!$D:$D,'P&G-SL'!$C7, 'i-sales'!$G:$G,'P&G-SL'!$A7, 'i-sales'!$H:$H,'P&G-SL'!$B7 ) -> 15661.44 | L7: =SUMIFS('i-sales'!$K:$K, 'i-sales'!$C:$C,'P&G-SL'!L$1, 'i-sales'!$D:$D,'P&G-SL'!$C7, 'i-sales'!$G:$G,'P&G-SL'!$A7, 'i-sales'!$H:$H,'P&G-SL'!$B7 ) -> 0 | M7: =SUMIFS('i-sales'!$K:$K, 'i-sales'!$C:$C,'P&G-SL'!M$1, 'i-sales'!$D:$D,'P&G-SL'!$C7, 'i-sales'!$G:$G,'P&G-SL'!$A7, 'i-sales'!$H:$H,'P&G-SL'!$B7 ) -> 0 | N7: =SUMIFS('i-sales'!$K:$K, 'i-sales'!$C:$C,'P&G-SL'!N$1, 'i-sales'!$D:$D,'P&G-SL'!$C7, 'i-sales'!$G:$G,'P&G-SL'!$A7, 'i-sales'!$H:$H,'P&G-SL'!$B7 ) -> 0 | O7: =SUMIFS('i-sales'!$K:$K, 'i-sales'!$C:$C,'P&G-SL'!O$1, 'i-sales'!$D:$D,'P&G-SL'!$C7, 'i-sales'!$G:$G,'P&G-SL'!$A7, 'i-sales'!$H:$H,'P&G-SL'!$B7 ) -> 0 | P7: =SUMIFS('i-sales'!$K:$K, 'i-sales'!$C:$C,'P&G-SL'!P$1, 'i-sales'!$D:$D,'P&G-SL'!$C7, 'i-sales'!$G:$G,'P&G-SL'!$A7, 'i-sales'!$H:$H,'P&G-SL'!$B7 ) -> 0 | ... T7: =SUMIFS('i-sales'!$K:$K, 'i-sales'!$C:$C,'P&G-SL'!T$1, 'i-sales'!$D:$D,'P&G-SL'!$C7, 'i-sales'!$G:$G,'P&G-SL'!$A7, 'i-sales'!$H:$H,'P&G-SL'!$B7 ) -> 0 | U7: =SUM(I7:T7) -> 55947.06
A8: 0 | B8: 0 | C8: FR | E8: #VALUE! | F8: France | I8: =SUMIFS('i-sales'!$K:$K, 'i-sales'!$C:$C,'P&G-SL'!I$1, 'i-sales'!$D:$D,'P&G-SL'!$C8, 'i-sales'!$G:$G,'P&G-SL'!$A8, 'i-sales'!$H:$H,'P&G-SL'!$B8 ) -> 25590.35 | J8: =SUMIFS('i-sales'!$K:$K, 'i-sales'!$C:$C,'P&G-SL'!J$1, 'i-sales'!$D:$D,'P&G-SL'!$C8, 'i-sales'!$G:$G,'P&G-SL'!$A8, 'i-sales'!$H:$H,'P&G-SL'!$B8 ) -> 27502.64 | K8: =SUMIFS('i-sales'!$K:$K, 'i-sales'!$C:$C,'P&G-SL'!K$1, 'i-sales'!$D:$D,'P&G-SL'!$C8, 'i-sales'!$G:$G,'P&G-SL'!$A8, 'i-sales'!$H:$H,'P&G-SL'!$B8 ) -> 22172.28 | L8: =SUMIFS('i-sales'!$K:$K, 'i-sales'!$C:$C,'P&G-SL'!L$1, 'i-sales'!$D:$D,'P&G-SL'!$C8, 'i-sales'!$G:$G,'P&G-SL'!$A8, 'i-sales'!$H:$H,'P&G-SL'!$B8 ) -> 0 | M8: =SUMIFS('i-sales'!$K:$K, 'i-sales'!$C:$C,'P&G-SL'!M$1, 'i-sales'!$D:$D,'P&G-SL'!$C8, 'i-sales'!$G:$G,'P&G-SL'!$A8, 'i-sales'!$H:$H,'P&G-SL'!$B8 ) -> 0 | N8: =SUMIFS('i-sales'!$K:$K, 'i-sales'!$C:$C,'P&G-SL'!N$1, 'i-sales'!$D:$D,'P&G-SL'!$C8, 'i-sales'!$G:$G,'P&G-SL'!$A8, 'i-sales'!$H:$H,'P&G-SL'!$B8 ) -> 0 | O8: =SUMIFS('i-sales'!$K:$K, 'i-sales'!$C:$C,'P&G-SL'!O$1, 'i-sales'!$D:$D,'P&G-SL'!$C8, 'i-sales'!$G:$G,'P&G-SL'!$A8, 'i-sales'!$H:$H,'P&G-SL'!$B8 ) -> 0 | P8: =SUMIFS('i-sales'!$K:$K, 'i-sales'!$C:$C,'P&G-SL'!P$1, 'i-sales'!$D:$D,'P&G-SL'!$C8, 'i-sales'!$G:$G,'P&G-SL'!$A8, 'i-sales'!$H:$H,'P&G-SL'!$B8 ) -> 0 | ... T8: =SUMIFS('i-sales'!$K:$K, 'i-sales'!$C:$C,'P&G-SL'!T$1, 'i-sales'!$D:$D,'P&G-SL'!$C8, 'i-sales'!$G:$G,'P&G-SL'!$A8, 'i-sales'!$H:$H,'P&G-SL'!$B8 ) -> 0 | U8: =SUM(I8:T8) -> 75265.27
A9: 0 | B9: 0 | C9: IT | E9: #VALUE! | F9: Italy | I9: =SUMIFS('i-sales'!$K:$K, 'i-sales'!$C:$C,'P&G-SL'!I$1, 'i-sales'!$D:$D,'P&G-SL'!$C9, 'i-sales'!$G:$G,'P&G-SL'!$A9, 'i-sales'!$H:$H,'P&G-SL'!$B9 ) -> 18483.79 | J9: =SUMIFS('i-sales'!$K:$K, 'i-sales'!$C:$C,'P&G-SL'!J$1, 'i-sales'!$D:$D,'P&G-SL'!$C9, 'i-sales'!$G:$G,'P&G-SL'!$A9, 'i-sales'!$H:$H,'P&G-SL'!$B9 ) -> 20044.87 | K9: =SUMIFS('i-sales'!$K:$K, 'i-sales'!$C:$C,'P&G-SL'!K$1, 'i-sales'!$D:$D,'P&G-SL'!$C9, 'i-sales'!$G:$G,'P&G-SL'!$A9, 'i-sales'!$H:$H,'P&G-SL'!$B9 ) -> 10681.85 | L9: =SUMIFS('i-sales'!$K:$K, 'i-sales'!$C:$C,'P&G-SL'!L$1, 'i-sales'!$D:$D,'P&G-SL'!$C9, 'i-sales'!$G:$G,'P&G-SL'!$A9, 'i-sales'!$H:$H,'P&G-SL'!$B9 ) -> 0 | M9: =SUMIFS('i-sales'!$K:$K, 'i-sales'!$C:$C,'P&G-SL'!M$1, 'i-sales'!$D:$D,'P&G-SL'!$C9, 'i-sales'!$G:$G,'P&G-SL'!$A9, 'i-sales'!$H:$H,'P&G-SL'!$B9 ) -> 0 | N9: =SUMIFS('i-sales'!$K:$K, 'i-sales'!$C:$C,'P&G-SL'!N$1, 'i-sales'!$D:$D,'P&G-SL'!$C9, 'i-sales'!$G:$G,'P&G-SL'!$A9, 'i-sales'!$H:$H,'P&G-SL'!$B9 ) -> 0 | O9: =SUMIFS('i-sales'!$K:$K, 'i-sales'!$C:$C,'P&G-SL'!O$1, 'i-sales'!$D:$D,'P&G-SL'!$C9, 'i-sales'!$G:$G,'P&G-SL'!$A9, 'i-sales'!$H:$H,'P&G-SL'!$B9 ) -> 0 | P9: =SUMIFS('i-sales'!$K:$K, 'i-sales'!$C:$C,'P&G-SL'!P$1, 'i-sales'!$D:$D,'P&G-SL'!$C9, 'i-sales'!$G:$G,'P&G-SL'!$A9, 'i-sales'!$H:$H,'P&G-SL'!$B9 ) -> 0 | ... T9: =SUMIFS('i-sales'!$K:$K, 'i-sales'!$C:$C,'P&G-SL'!T$1, 'i-sales'!$D:$D,'P&G-SL'!$C9, 'i-sales'!$G:$G,'P&G-SL'!$A9, 'i-sales'!$H:$H,'P&G-SL'!$B9 ) -> 0 | U9: =SUM(I9:T9) -> 49210.51
A10: 0 | B10: 0 | C10: AT | E10: #VALUE! | F10: Austria | I10: =SUMIFS('i-sales'!$K:$K, 'i-sales'!$C:$C,'P&G-SL'!I$1, 'i-sales'!$D:$D,'P&G-SL'!$C10, 'i-sales'!$G:$G,'P&G-SL'!$A10, 'i-sales'!$H:$H,'P&G-SL'!$B10 ) -> 5482.24 | J10: =SUMIFS('i-sales'!$K:$K, 'i-sales'!$C:$C,'P&G-SL'!J$1, 'i-sales'!$D:$D,'P&G-SL'!$C10, 'i-sales'!$G:$G,'P&G-SL'!$A10, 'i-sales'!$H:$H,'P&G-SL'!$B10 ) -> 6077.94 | K10: =SUMIFS('i-sales'!$K:$K, 'i-sales'!$C:$C,'P&G-SL'!K$1, 'i-sales'!$D:$D,'P&G-SL'!$C10, 'i-sales'!$G:$G,'P&G-SL'!$A10, 'i-sales'!$H:$H,'P&G-SL'!$B10 ) -> 3577.39 | L10: =SUMIFS('i-sales'!$K:$K, 'i-sales'!$C:$C,'P&G-SL'!L$1, 'i-sales'!$D:$D,'P&G-SL'!$C10, 'i-sales'!$G:$G,'P&G-SL'!$A10, 'i-sales'!$H:$H,'P&G-SL'!$B10 ) -> 0 | M10: =SUMIFS('i-sales'!$K:$K, 'i-sales'!$C:$C,'P&G-SL'!M$1, 'i-sales'!$D:$D,'P&G-SL'!$C10, 'i-sales'!$G:$G,'P&G-SL'!$A10, 'i-sales'!$H:$H,'P&G-SL'!$B10 ) -> 0 | N10: =SUMIFS('i-sales'!$K:$K, 'i-sales'!$C:$C,'P&G-SL'!N$1, 'i-sales'!$D:$D,'P&G-SL'!$C10, 'i-sales'!$G:$G,'P&G-SL'!$A10, 'i-sales'!$H:$H,'P&G-SL'!$B10 ) -> 0 | O10: =SUMIFS('i-sales'!$K:$K, 'i-sales'!$C:$C,'P&G-SL'!O$1, 'i-sales'!$D:$D,'P&G-SL'!$C10, 'i-sales'!$G:$G,'P&G-SL'!$A10, 'i-sales'!$H:$H,'P&G-SL'!$B10 ) -> 0 | P10: =SUMIFS('i-sales'!$K:$K, 'i-sales'!$C:$C,'P&G-SL'!P$1, 'i-sales'!$D:$D,'P&G-SL'!$C10, 'i-sales'!$G:$G,'P&G-SL'!$A10, 'i-sales'!$H:$H,'P&G-SL'!$B10 ) -> 0 | ... T10: =SUMIFS('i-sales'!$K:$K, 'i-sales'!$C:$C,'P&G-SL'!T$1, 'i-sales'!$D:$D,'P&G-SL'!$C10, 'i-sales'!$G:$G,'P&G-SL'!$A10, 'i-sales'!$H:$H,'P&G-SL'!$B10 ) -> 0 | U10: =SUM(I10:T10) -> 15137.57
A11: 0 | B11: 0 | C11: BE | E11: #VALUE! | F11: Belgium | I11: =SUMIFS('i-sales'!$K:$K, 'i-sales'!$C:$C,'P&G-SL'!I$1, 'i-sales'!$D:$D,'P&G-SL'!$C11, 'i-sales'!$G:$G,'P&G-SL'!$A11, 'i-sales'!$H:$H,'P&G-SL'!$B11 ) -> 422.71 | J11: =SUMIFS('i-sales'!$K:$K, 'i-sales'!$C:$C,'P&G-SL'!J$1, 'i-sales'!$D:$D,'P&G-SL'!$C11, 'i-sales'!$G:$G,'P&G-SL'!$A11, 'i-sales'!$H:$H,'P&G-SL'!$B11 ) -> 998.68 | K11: =SUMIFS('i-sales'!$K:$K, 'i-sales'!$C:$C,'P&G-SL'!K$1, 'i-sales'!$D:$D,'P&G-SL'!$C11, 'i-sales'!$G:$G,'P&G-SL'!$A11, 'i-sales'!$H:$H,'P&G-SL'!$B11 ) -> 26.36 | L11: =SUMIFS('i-sales'!$K:$K, 'i-sales'!$C:$C,'P&G-SL'!L$1, 'i-sales'!$D:$D,'P&G-SL'!$C11, 'i-sales'!$G:$G,'P&G-SL'!$A11, 'i-sales'!$H:$H,'P&G-SL'!$B11 ) -> 0 | M11: =SUMIFS('i-sales'!$K:$K, 'i-sales'!$C:$C,'P&G-SL'!M$1, 'i-sales'!$D:$D,'P&G-SL'!$C11, 'i-sales'!$G:$G,'P&G-SL'!$A11, 'i-sales'!$H:$H,'P&G-SL'!$B11 ) -> 0 | N11: =SUMIFS('i-sales'!$K:$K, 'i-sales'!$C:$C,'P&G-SL'!N$1, 'i-sales'!$D:$D,'P&G-SL'!$C11, 'i-sales'!$G:$G,'P&G-SL'!$A11, 'i-sales'!$H:$H,'P&G-SL'!$B11 ) -> 0 | O11: =SUMIFS('i-sales'!$K:$K, 'i-sales'!$C:$C,'P&G-SL'!O$1, 'i-sales'!$D:$D,'P&G-SL'!$C11, 'i-sales'!$G:$G,'P&G-SL'!$A11, 'i-sales'!$H:$H,'P&G-SL'!$B11 ) -> 0 | P11: =SUMIFS('i-sales'!$K:$K, 'i-sales'!$C:$C,'P&G-SL'!P$1, 'i-sales'!$D:$D,'P&G-SL'!$C11, 'i-sales'!$G:$G,'P&G-SL'!$A11, 'i-sales'!$H:$H,'P&G-SL'!$B11 ) -> 0 | ... T11: =SUMIFS('i-sales'!$K:$K, 'i-sales'!$C:$C,'P&G-SL'!T$1, 'i-sales'!$D:$D,'P&G-SL'!$C11, 'i-sales'!$G:$G,'P&G-SL'!$A11, 'i-sales'!$H:$H,'P&G-SL'!$B11 ) -> 0 | U11: =SUM(I11:T11) -> 1447.75
A12: 0 | B12: 0 | C12: NL | E12: #VALUE! | F12: the Netherlands | I12: =SUMIFS('i-sales'!$K:$K, 'i-sales'!$C:$C,'P&G-SL'!I$1, 'i-sales'!$D:$D,'P&G-SL'!$C12, 'i-sales'!$G:$G,'P&G-SL'!$A12, 'i-sales'!$H:$H,'P&G-SL'!$B12 ) -> 115.58 | J12: =SUMIFS('i-sales'!$K:$K, 'i-sales'!$C:$C,'P&G-SL'!J$1, 'i-sales'!$D:$D,'P&G-SL'!$C12, 'i-sales'!$G:$G,'P&G-SL'!$A12, 'i-sales'!$H:$H,'P&G-SL'!$B12 ) -> 175.87 | K12: =SUMIFS('i-sales'!$K:$K, 'i-sales'!$C:$C,'P&G-SL'!K$1, 'i-sales'!$D:$D,'P&G-SL'!$C12, 'i-sales'!$G:$G,'P&G-SL'!$A12, 'i-sales'!$H:$H,'P&G-SL'!$B12 ) -> 39.59 | L12: =SUMIFS('i-sales'!$K:$K, 'i-sales'!$C:$C,'P&G-SL'!L$1, 'i-sales'!$D:$D,'P&G-SL'!$C12, 'i-sales'!$G:$G,'P&G-SL'!$A12, 'i-sales'!$H:$H,'P&G-SL'!$B12 ) -> 0 | M12: =SUMIFS('i-sales'!$K:$K, 'i-sales'!$C:$C,'P&G-SL'!M$1, 'i-sales'!$D:$D,'P&G-SL'!$C12, 'i-sales'!$G:$G,'P&G-SL'!$A12, 'i-sales'!$H:$H,'P&G-SL'!$B12 ) -> 0 | N12: =SUMIFS('i-sales'!$K:$K, 'i-sales'!$C:$C,'P&G-SL'!N$1, 'i-sales'!$D:$D,'P&G-SL'!$C12, 'i-sales'!$G:$G,'P&G-SL'!$A12, 'i-sales'!$H:$H,'P&G-SL'!$B12 ) -> 0 | O12: =SUMIFS('i-sales'!$K:$K, 'i-sales'!$C:$C,'P&G-SL'!O$1, 'i-sales'!$D:$D,'P&G-SL'!$C12, 'i-sales'!$G:$G,'P&G-SL'!$A12, 'i-sales'!$H:$H,'P&G-SL'!$B12 ) -> 0 | P12: =SUMIFS('i-sales'!$K:$K, 'i-sales'!$C:$C,'P&G-SL'!P$1, 'i-sales'!$D:$D,'P&G-SL'!$C12, 'i-sales'!$G:$G,'P&G-SL'!$A12, 'i-sales'!$H:$H,'P&G-SL'!$B12 ) -> 0 | ... T12: =SUMIFS('i-sales'!$K:$K, 'i-sales'!$C:$C,'P&G-SL'!T$1, 'i-sales'!$D:$D,'P&G-SL'!$C12, 'i-sales'!$G:$G,'P&G-SL'!$A12, 'i-sales'!$H:$H,'P&G-SL'!$B12 ) -> 0 | U12: =SUM(I12:T12) -> 331.04
A13: 0 | B13: 0 | C13: PT | E13: #VALUE! | F13: Portugal | I13: =SUMIFS('i-sales'!$K:$K, 'i-sales'!$C:$C,'P&G-SL'!I$1, 'i-sales'!$D:$D,'P&G-SL'!$C13, 'i-sales'!$G:$G,'P&G-SL'!$A13, 'i-sales'!$H:$H,'P&G-SL'!$B13 ) -> 729.31 | J13: =SUMIFS('i-sales'!$K:$K, 'i-sales'!$C:$C,'P&G-SL'!J$1, 'i-sales'!$D:$D,'P&G-SL'!$C13, 'i-sales'!$G:$G,'P&G-SL'!$A13, 'i-sales'!$H:$H,'P&G-SL'!$B13 ) -> 1281.5 | K13: =SUMIFS('i-sales'!$K:$K, 'i-sales'!$C:$C,'P&G-SL'!K$1, 'i-sales'!$D:$D,'P&G-SL'!$C13, 'i-sales'!$G:$G,'P&G-SL'!$A13, 'i-sales'!$H:$H,'P&G-SL'!$B13 ) -> 0 | L13: =SUMIFS('i-sales'!$K:$K, 'i-sales'!$C:$C,'P&G-SL'!L$1, 'i-sales'!$D:$D,'P&G-SL'!$C13, 'i-sales'!$G:$G,'P&G-SL'!$A13, 'i-sales'!$H:$H,'P&G-SL'!$B13 ) -> 0 | M13: =SUMIFS('i-sales'!$K:$K, 'i-sales'!$C:$C,'P&G-SL'!M$1, 'i-sales'!$D:$D,'P&G-SL'!$C13, 'i-sales'!$G:$G,'P&G-SL'!$A13, 'i-sales'!$H:$H,'P&G-SL'!$B13 ) -> 0 | N13: =SUMIFS('i-sales'!$K:$K, 'i-sales'!$C:$C,'P&G-SL'!N$1, 'i-sales'!$D:$D,'P&G-SL'!$C13, 'i-sales'!$G:$G,'P&G-SL'!$A13, 'i-sales'!$H:$H,'P&G-SL'!$B13 ) -> 0 | O13: =SUMIFS('i-sales'!$K:$K, 'i-sales'!$C:$C,'P&G-SL'!O$1, 'i-sales'!$D:$D,'P&G-SL'!$C13, 'i-sales'!$G:$G,'P&G-SL'!$A13, 'i-sales'!$H:$H,'P&G-SL'!$B13 ) -> 0 | P13: =SUMIFS('i-sales'!$K:$K, 'i-sales'!$C:$C,'P&G-SL'!P$1, 'i-sales'!$D:$D,'P&G-SL'!$C13, 'i-sales'!$G:$G,'P&G-SL'!$A13, 'i-sales'!$H:$H,'P&G-SL'!$B13 ) -> 0 | ... T13: =SUMIFS('i-sales'!$K:$K, 'i-sales'!$C:$C,'P&G-SL'!T$1, 'i-sales'!$D:$D,'P&G-SL'!$C13, 'i-sales'!$G:$G,'P&G-SL'!$A13, 'i-sales'!$H:$H,'P&G-SL'!$B13 ) -> 0 | U13: =SUM(I13:T13) -> 2010.81
A14: 0 | B14: 0 | C14: XX | E14: #VALUE! | F14: Other markets | I14: =SUMIFS('i-sales'!$K:$K, 'i-sales'!$C:$C,'P&G-SL'!I$1, 'i-sales'!$D:$D,'P&G-SL'!$C14, 'i-sales'!$G:$G,'P&G-SL'!$A14, 'i-sales'!$H:$H,'P&G-SL'!$B14 ) -> 691.19 | J14: =SUMIFS('i-sales'!$K:$K, 'i-sales'!$C:$C,'P&G-SL'!J$1, 'i-sales'!$D:$D,'P&G-SL'!$C14, 'i-sales'!$G:$G,'P&G-SL'!$A14, 'i-sales'!$H:$H,'P&G-SL'!$B14 ) -> 264.48 | K14: =SUMIFS('i-sales'!$K:$K, 'i-sales'!$C:$C,'P&G-SL'!K$1, 'i-sales'!$D:$D,'P&G-SL'!$C14, 'i-sales'!$G:$G,'P&G-SL'!$A14, 'i-sales'!$H:$H,'P&G-SL'!$B14 ) -> 227.22 | L14: =SUMIFS('i-sales'!$K:$K, 'i-sales'!$C:$C,'P&G-SL'!L$1, 'i-sales'!$D:$D,'P&G-SL'!$C14, 'i-sales'!$G:$G,'P&G-SL'!$A14, 'i-sales'!$H:$H,'P&G-SL'!$B14 ) -> 0 | M14: =SUMIFS('i-sales'!$K:$K, 'i-sales'!$C:$C,'P&G-SL'!M$1, 'i-sales'!$D:$D,'P&G-SL'!$C14, 'i-sales'!$G:$G,'P&G-SL'!$A14, 'i-sales'!$H:$H,'P&G-SL'!$B14 ) -> 0 | N14: =SUMIFS('i-sales'!$K:$K, 'i-sales'!$C:$C,'P&G-SL'!N$1, 'i-sales'!$D:$D,'P&G-SL'!$C14, 'i-sales'!$G:$G,'P&G-SL'!$A14, 'i-sales'!$H:$H,'P&G-SL'!$B14 ) -> 0 | O14: =SUMIFS('i-sales'!$K:$K, 'i-sales'!$C:$C,'P&G-SL'!O$1, 'i-sales'!$D:$D,'P&G-SL'!$C14, 'i-sales'!$G:$G,'P&G-SL'!$A14, 'i-sales'!$H:$H,'P&G-SL'!$B14 ) -> 0 | P14: =SUMIFS('i-sales'!$K:$K, 'i-sales'!$C:$C,'P&G-SL'!P$1, 'i-sales'!$D:$D,'P&G-SL'!$C14, 'i-sales'!$G:$G,'P&G-SL'!$A14, 'i-sales'!$H:$H,'P&G-SL'!$B14 ) -> 0 | ... T14: =SUMIFS('i-sales'!$K:$K, 'i-sales'!$C:$C,'P&G-SL'!T$1, 'i-sales'!$D:$D,'P&G-SL'!$C14, 'i-sales'!$G:$G,'P&G-SL'!$A14, 'i-sales'!$H:$H,'P&G-SL'!$B14 ) -> 0 | U14: =SUM(I14:T14) -> 1182.89
E16: Marketplaces | I16: =SUM(I17:I19) -> 1419.7 | J16: =SUM(J17:J19) -> 2875.02 | K16: =SUM(K17:K19) -> 15609.96 | L16: =SUM(L17:L19) -> 0 | M16: =SUM(M17:M19) -> 0 | N16: =SUM(N17:N19) -> 0 | O16: =SUM(O17:O19) -> 0 | P16: =SUM(P17:P19) -> 0 | ... T16: =SUM(T17:T19) -> 0 | U16: =SUM(I16:T16) -> 19904.68
E17: H | F17: Hannun | I17: =SUMIFS(i_marketplaces_sl[[net]:[net]],i_marketplaces_sl[[yyyymm]:[yyyymm]],I$1,i_marketplaces_sl[[client_name]:[client_name]],$F17) -> 1419.7 | J17: =SUMIFS(i_marketplaces_sl[[net]:[net]],i_marketplaces_sl[[yyyymm]:[yyyymm]],J$1,i_marketplaces_sl[[client_name]:[client_name]],$F17) -> 1128.42 | K17: =SUMIFS(i_marketplaces_sl[[net]:[net]],i_marketplaces_sl[[yyyymm]:[yyyymm]],K$1,i_marketplaces_sl[[client_name]:[client_name]],$F17) -> 0 | L17: =SUMIFS(i_marketplaces_sl[[net]:[net]],i_marketplaces_sl[[yyyymm]:[yyyymm]],L$1,i_marketplaces_sl[[client_name]:[client_name]],$F17) -> 0 | M17: =SUMIFS(i_marketplaces_sl[[net]:[net]],i_marketplaces_sl[[yyyymm]:[yyyymm]],M$1,i_marketplaces_sl[[client_name]:[client_name]],$F17) -> 0 | N17: =SUMIFS(i_marketplaces_sl[[net]:[net]],i_marketplaces_sl[[yyyymm]:[yyyymm]],N$1,i_marketplaces_sl[[client_name]:[client_name]],$F17) -> 0 | O17: =SUMIFS(i_marketplaces_sl[[net]:[net]],i_marketplaces_sl[[yyyymm]:[yyyymm]],O$1,i_marketplaces_sl[[client_name]:[client_name]],$F17) -> 0 | P17: =SUMIFS(i_marketplaces_sl[[net]:[net]],i_marketplaces_sl[[yyyymm]:[yyyymm]],P$1,i_marketplaces_sl[[client_name]:[client_name]],$F17) -> 0 | ... T17: =SUMIFS(i_marketplaces_sl[[net]:[net]],i_marketplaces_sl[[yyyymm]:[yyyymm]],T$1,i_marketplaces_sl[[client_name]:[client_name]],$F17) -> 0 | U17: =SUM(I17:T17) -> 2548.12
E18: #VALUE! | F18: Choose | I18: =SUMIFS(i_marketplaces_sl[[net]:[net]],i_marketplaces_sl[[yyyymm]:[yyyymm]],I$1,i_marketplaces_sl[[client_name]:[client_name]],$F18) -> 0 | J18: =SUMIFS(i_marketplaces_sl[[net]:[net]],i_marketplaces_sl[[yyyymm]:[yyyymm]],J$1,i_marketplaces_sl[[client_name]:[client_name]],$F18) -> 0 | K18: =SUMIFS(i_marketplaces_sl[[net]:[net]],i_marketplaces_sl[[yyyymm]:[yyyymm]],K$1,i_marketplaces_sl[[client_name]:[client_name]],$F18) -> 15609.96 | L18: =SUMIFS(i_marketplaces_sl[[net]:[net]],i_marketplaces_sl[[yyyymm]:[yyyymm]],L$1,i_marketplaces_sl[[client_name]:[client_name]],$F18) -> 0 | M18: =SUMIFS(i_marketplaces_sl[[net]:[net]],i_marketplaces_sl[[yyyymm]:[yyyymm]],M$1,i_marketplaces_sl[[client_name]:[client_name]],$F18) -> 0 | N18: =SUMIFS(i_marketplaces_sl[[net]:[net]],i_marketplaces_sl[[yyyymm]:[yyyymm]],N$1,i_marketplaces_sl[[client_name]:[client_name]],$F18) -> 0 | O18: =SUMIFS(i_marketplaces_sl[[net]:[net]],i_marketplaces_sl[[yyyymm]:[yyyymm]],O$1,i_marketplaces_sl[[client_name]:[client_name]],$F18) -> 0 | P18: =SUMIFS(i_marketplaces_sl[[net]:[net]],i_marketplaces_sl[[yyyymm]:[yyyymm]],P$1,i_marketplaces_sl[[client_name]:[client_name]],$F18) -> 0 | ... T18: =SUMIFS(i_marketplaces_sl[[net]:[net]],i_marketplaces_sl[[yyyymm]:[yyyymm]],T$1,i_marketplaces_sl[[client_name]:[client_name]],$F18) -> 0 | U18: =SUM(I18:T18) -> 15609.96
E19: #VALUE! | F19: Toasty | I19: =SUMIFS(i_marketplaces_sl[[net]:[net]],i_marketplaces_sl[[yyyymm]:[yyyymm]],I$1,i_marketplaces_sl[[client_name]:[client_name]],$F19) -> 0 | J19: =SUMIFS(i_marketplaces_sl[[net]:[net]],i_marketplaces_sl[[yyyymm]:[yyyymm]],J$1,i_marketplaces_sl[[client_name]:[client_name]],$F19) -> 1746.6 | K19: =SUMIFS(i_marketplaces_sl[[net]:[net]],i_marketplaces_sl[[yyyymm]:[yyyymm]],K$1,i_marketplaces_sl[[client_name]:[client_name]],$F19) -> 0 | L19: =SUMIFS(i_marketplaces_sl[[net]:[net]],i_marketplaces_sl[[yyyymm]:[yyyymm]],L$1,i_marketplaces_sl[[client_name]:[client_name]],$F19) -> 0 | M19: =SUMIFS(i_marketplaces_sl[[net]:[net]],i_marketplaces_sl[[yyyymm]:[yyyymm]],M$1,i_marketplaces_sl[[client_name]:[client_name]],$F19) -> 0 | N19: =SUMIFS(i_marketplaces_sl[[net]:[net]],i_marketplaces_sl[[yyyymm]:[yyyymm]],N$1,i_marketplaces_sl[[client_name]:[client_name]],$F19) -> 0 | O19: =SUMIFS(i_marketplaces_sl[[net]:[net]],i_marketplaces_sl[[yyyymm]:[yyyymm]],O$1,i_marketplaces_sl[[client_name]:[client_name]],$F19) -> 0 | P19: =SUMIFS(i_marketplaces_sl[[net]:[net]],i_marketplaces_sl[[yyyymm]:[yyyymm]],P$1,i_marketplaces_sl[[client_name]:[client_name]],$F19) -> 0 | ... T19: =SUMIFS(i_marketplaces_sl[[net]:[net]],i_marketplaces_sl[[yyyymm]:[yyyymm]],T$1,i_marketplaces_sl[[client_name]:[client_name]],$F19) -> 0 | U19: =SUM(I19:T19) -> 1746.6
E21: Rever Supplies | I21: =SUMIFS(i_suplidos_sl[[net]:[net]],i_suplidos_sl[[yyyymm]:[yyyymm]],I$1) -> -2176.46 | J21: =SUMIFS(i_suplidos_sl[[net]:[net]],i_suplidos_sl[[yyyymm]:[yyyymm]],J$1) -> -522.54 | K21: =SUMIFS(i_suplidos_sl[[net]:[net]],i_suplidos_sl[[yyyymm]:[yyyymm]],K$1) -> 0 | L21: =SUMIFS(i_suplidos_sl[[net]:[net]],i_suplidos_sl[[yyyymm]:[yyyymm]],L$1) -> 0 | M21: =SUMIFS(i_suplidos_sl[[net]:[net]],i_suplidos_sl[[yyyymm]:[yyyymm]],M$1) -> 0 | N21: =SUMIFS(i_suplidos_sl[[net]:[net]],i_suplidos_sl[[yyyymm]:[yyyymm]],N$1) -> 0 | O21: =SUMIFS(i_suplidos_sl[[net]:[net]],i_suplidos_sl[[yyyymm]:[yyyymm]],O$1) -> 0 | P21: =SUMIFS(i_suplidos_sl[[net]:[net]],i_suplidos_sl[[yyyymm]:[yyyymm]],P$1) -> 0 | ... T21: =SUMIFS(i_suplidos_sl[[net]:[net]],i_suplidos_sl[[yyyymm]:[yyyymm]],T$1) -> 0
E23: Sales Rappels (B2B) | I23: =SUMIFS(i_rapels_sl[[net]:[net]],i_rapels_sl[[yyyymm]:[yyyymm]],I$1) -> -1118.95 | J23: =SUMIFS(i_rapels_sl[[net]:[net]],i_rapels_sl[[yyyymm]:[yyyymm]],J$1) -> 0 | K23: =SUMIFS(i_rapels_sl[[net]:[net]],i_rapels_sl[[yyyymm]:[yyyymm]],K$1) -> 0 | L23: =SUMIFS(i_rapels_sl[[net]:[net]],i_rapels_sl[[yyyymm]:[yyyymm]],L$1) -> 0 | M23: =SUMIFS(i_rapels_sl[[net]:[net]],i_rapels_sl[[yyyymm]:[yyyymm]],M$1) -> 0 | N23: =SUMIFS(i_rapels_sl[[net]:[net]],i_rapels_sl[[yyyymm]:[yyyymm]],N$1) -> 0 | O23: =SUMIFS(i_rapels_sl[[net]:[net]],i_rapels_sl[[yyyymm]:[yyyymm]],O$1) -> 0 | P23: =SUMIFS(i_rapels_sl[[net]:[net]],i_rapels_sl[[yyyymm]:[yyyymm]],P$1) -> 0 | ... T23: =SUMIFS(i_rapels_sl[[net]:[net]],i_rapels_sl[[yyyymm]:[yyyymm]],T$1) -> 0 | U23: =SUM(I23:T23) -> -1118.95
E25: Sales Adjustments | I25: =SUM(I26:I28) -> 23.483436 | J25: =SUM(J26:J28) -> -152.16827 | K25: =SUM(K26:K28) -> 0 | L25: =SUM(L26:L28) -> 0 | M25: =SUM(M26:M28) -> 0 | N25: =SUM(N26:N28) -> 0 | O25: =SUM(O26:O28) -> 0 | P25: =SUM(P26:P28) -> 0 | ... T25: =SUM(T26:T28) -> 0 | U25: =SUM(I25:T25) -> -128.68484
F26: Chargeback Shopify | I26: =SUMIFS(i_adjustments_sl[[net]:[net]],i_adjustments_sl[[yyyymm]:[yyyymm]],I$1,i_adjustments_sl[[type]:[type]],$F26) -> -97.252101 | J26: =SUMIFS(i_adjustments_sl[[net]:[net]],i_adjustments_sl[[yyyymm]:[yyyymm]],J$1,i_adjustments_sl[[type]:[type]],$F26) -> 47.823529 | K26: =SUMIFS(i_adjustments_sl[[net]:[net]],i_adjustments_sl[[yyyymm]:[yyyymm]],K$1,i_adjustments_sl[[type]:[type]],$F26) -> 0 | L26: =SUMIFS(i_adjustments_sl[[net]:[net]],i_adjustments_sl[[yyyymm]:[yyyymm]],L$1,i_adjustments_sl[[type]:[type]],$F26) -> 0 | M26: =SUMIFS(i_adjustments_sl[[net]:[net]],i_adjustments_sl[[yyyymm]:[yyyymm]],M$1,i_adjustments_sl[[type]:[type]],$F26) -> 0 | N26: =SUMIFS(i_adjustments_sl[[net]:[net]],i_adjustments_sl[[yyyymm]:[yyyymm]],N$1,i_adjustments_sl[[type]:[type]],$F26) -> 0 | O26: =SUMIFS(i_adjustments_sl[[net]:[net]],i_adjustments_sl[[yyyymm]:[yyyymm]],O$1,i_adjustments_sl[[type]:[type]],$F26) -> 0 | P26: =SUMIFS(i_adjustments_sl[[net]:[net]],i_adjustments_sl[[yyyymm]:[yyyymm]],P$1,i_adjustments_sl[[type]:[type]],$F26) -> 0 | ... T26: =SUMIFS(i_adjustments_sl[[net]:[net]],i_adjustments_sl[[yyyymm]:[yyyymm]],T$1,i_adjustments_sl[[type]:[type]],$F26) -> 0 | U26: =SUM(I26:T26) -> -49.428571
F27: Chargeback Paypal | I27: =SUMIFS(i_adjustments_sl[[net]:[net]],i_adjustments_sl[[yyyymm]:[yyyymm]],I$1,i_adjustments_sl[[type]:[type]],$F27) -> 120.73554 | J27: =SUMIFS(i_adjustments_sl[[net]:[net]],i_adjustments_sl[[yyyymm]:[yyyymm]],J$1,i_adjustments_sl[[type]:[type]],$F27) -> -199.9918 | K27: =SUMIFS(i_adjustments_sl[[net]:[net]],i_adjustments_sl[[yyyymm]:[yyyymm]],K$1,i_adjustments_sl[[type]:[type]],$F27) -> 0 | L27: =SUMIFS(i_adjustments_sl[[net]:[net]],i_adjustments_sl[[yyyymm]:[yyyymm]],L$1,i_adjustments_sl[[type]:[type]],$F27) -> 0 | M27: =SUMIFS(i_adjustments_sl[[net]:[net]],i_adjustments_sl[[yyyymm]:[yyyymm]],M$1,i_adjustments_sl[[type]:[type]],$F27) -> 0 | N27: =SUMIFS(i_adjustments_sl[[net]:[net]],i_adjustments_sl[[yyyymm]:[yyyymm]],N$1,i_adjustments_sl[[type]:[type]],$F27) -> 0 | O27: =SUMIFS(i_adjustments_sl[[net]:[net]],i_adjustments_sl[[yyyymm]:[yyyymm]],O$1,i_adjustments_sl[[type]:[type]],$F27) -> 0 | P27: =SUMIFS(i_adjustments_sl[[net]:[net]],i_adjustments_sl[[yyyymm]:[yyyymm]],P$1,i_adjustments_sl[[type]:[type]],$F27) -> 0 | ... T27: =SUMIFS(i_adjustments_sl[[net]:[net]],i_adjustments_sl[[yyyymm]:[yyyymm]],T$1,i_adjustments_sl[[type]:[type]],$F27) -> 0 | U27: =SUM(I27:T27) -> -79.256266
F28: Impagos | I28: =SUMIFS(i_adjustments_sl[[net]:[net]],i_adjustments_sl[[yyyymm]:[yyyymm]],I$1,i_adjustments_sl[[type]:[type]],$F28) -> 0 | J28: =SUMIFS(i_adjustments_sl[[net]:[net]],i_adjustments_sl[[yyyymm]:[yyyymm]],J$1,i_adjustments_sl[[type]:[type]],$F28) -> 0 | K28: =SUMIFS(i_adjustments_sl[[net]:[net]],i_adjustments_sl[[yyyymm]:[yyyymm]],K$1,i_adjustments_sl[[type]:[type]],$F28) -> 0 | L28: =SUMIFS(i_adjustments_sl[[net]:[net]],i_adjustments_sl[[yyyymm]:[yyyymm]],L$1,i_adjustments_sl[[type]:[type]],$F28) -> 0 | M28: =SUMIFS(i_adjustments_sl[[net]:[net]],i_adjustments_sl[[yyyymm]:[yyyymm]],M$1,i_adjustments_sl[[type]:[type]],$F28) -> 0 | N28: =SUMIFS(i_adjustments_sl[[net]:[net]],i_adjustments_sl[[yyyymm]:[yyyymm]],N$1,i_adjustments_sl[[type]:[type]],$F28) -> 0 | O28: =SUMIFS(i_adjustments_sl[[net]:[net]],i_adjustments_sl[[yyyymm]:[yyyymm]],O$1,i_adjustments_sl[[type]:[type]],$F28) -> 0 | P28: =SUMIFS(i_adjustments_sl[[net]:[net]],i_adjustments_sl[[yyyymm]:[yyyymm]],P$1,i_adjustments_sl[[type]:[type]],$F28) -> 0 | ... T28: =SUMIFS(i_adjustments_sl[[net]:[net]],i_adjustments_sl[[yyyymm]:[yyyymm]],T$1,i_adjustments_sl[[type]:[type]],$F28) -> 0 | U28: =SUM(I28:T28) -> 0
D30: PRESTACION SERVICIOS | I30: =+I31 -> 20919.65 | J30: =+J31 -> 22722.52 | K30: =+K31 -> 0 | L30: =+L31 -> 0 | M30: =+M31 -> 0 | N30: =+N31 -> 0 | O30: =+O31 -> 0 | P30: =+P31 -> 0 | ... T30: =+T31 -> 0 | U30: =SUM(I30:T30) -> 43642.17
E31: Shared Services | I31: =+I37+I45+I48 -> 20919.65 | J31: =+J37+J45+J48 -> 22722.52 | K31: =+K37+K45+K48 -> 0 | L31: =+L37+L45+L48 -> 0 | M31: =+M37+M45+M48 -> 0 | N31: =+N37+N45+N48 -> 0 | O31: =+O37+O45+O48 -> 0 | P31: =+P37+P45+P48 -> 0 | ... T31: =+T37+T45+T48 -> 0 | U31: =SUM(I31:T31) -> 43642.17
E32: #VALUE! | F32: UK € - Theorical | I32: =SUM(I33:I36) -> 11560.246 | J32: =SUM(J33:J36) -> 13751.863 | K32: =SUM(K33:K36) -> 0 | L32: =SUM(L33:L36) -> 0 | M32: =SUM(M33:M36) -> 0 | N32: =SUM(N33:N36) -> 0 | O32: =SUM(O33:O36) -> 0 | P32: =SUM(P33:P36) -> 0 | ... T32: =SUM(T33:T36) -> 0 | U32: =SUM(I32:T32) -> 25312.109
G33: Royalties (Real) | I33: =+I72 -> 1272 | J33: =+J72 -> 1596 | K33: =+K72 -> 0 | L33: =+L72 -> 0 | M33: =+M72 -> 0 | N33: =+N72 -> 0 | O33: =+O72 -> 0 | P33: =+P72 -> 0 | ... T33: =+T72 -> 0 | U33: =SUM(I33:T33) -> 2868
G34: Staff (20%) | I34: =+I109 -> 2946.368 | J34: =+J109 -> 2983.136 | K34: =+K109 -> 0 | L34: =+L109 -> 0 | M34: =+M109 -> 0 | N34: =+N109 -> 0 | O34: =+O109 -> 0 | P34: =+P109 -> 0 | ... T34: =+T109 -> 0 | U34: =SUM(I34:T34) -> 5929.504
G35: Marketing (Real) | I35: =+I95 -> 6005.65 | J35: =+J95 -> 7802.34 | K35: =+K95 -> 0 | L35: =+L95 -> 0 | M35: =+M95 -> 0 | N35: =+N95 -> 0 | O35: =+O95 -> 0 | P35: =+P95 -> 0 | ... T35: =+T95 -> 0 | U35: =SUM(I35:T35) -> 13807.99
G36: Administrative (20%) | I36: =+I142 -> 1336.228 | J36: =+J142 -> 1370.3873 | K36: =+K142 -> 0 | L36: =+L142 -> 0 | M36: =+M142 -> 0 | N36: =+N142 -> 0 | O36: =+O142 -> 0 | P36: =+P142 -> 0 | ... T36: =+T142 -> 0 | U36: =SUM(I36:T36) -> 2706.6153
E37: #VALUE! | F37: UK € - Invoice | I37: =SUMIFS(i_sharedservices_sl[[net]:[net]],i_sharedservices_sl[[yyyymm]:[yyyymm]],I$1,i_sharedservices_sl[[type]:[type]],LEFT($F$37,2)) -> 10732.87 | J37: =SUMIFS(i_sharedservices_sl[[net]:[net]],i_sharedservices_sl[[yyyymm]:[yyyymm]],J$1,i_sharedservices_sl[[type]:[type]],LEFT($F$37,2)) -> 13068.98 | K37: =SUMIFS(i_sharedservices_sl[[net]:[net]],i_sharedservices_sl[[yyyymm]:[yyyymm]],K$1,i_sharedservices_sl[[type]:[type]],LEFT($F$37,2)) -> 0 | L37: =SUMIFS(i_sharedservices_sl[[net]:[net]],i_sharedservices_sl[[yyyymm]:[yyyymm]],L$1,i_sharedservices_sl[[type]:[type]],LEFT($F$37,2)) -> 0 | M37: =SUMIFS(i_sharedservices_sl[[net]:[net]],i_sharedservices_sl[[yyyymm]:[yyyymm]],M$1,i_sharedservices_sl[[type]:[type]],LEFT($F$37,2)) -> 0 | N37: =SUMIFS(i_sharedservices_sl[[net]:[net]],i_sharedservices_sl[[yyyymm]:[yyyymm]],N$1,i_sharedservices_sl[[type]:[type]],LEFT($F$37,2)) -> 0 | O37: =SUMIFS(i_sharedservices_sl[[net]:[net]],i_sharedservices_sl[[yyyymm]:[yyyymm]],O$1,i_sharedservices_sl[[type]:[type]],LEFT($F$37,2)) -> 0 | P37: =SUMIFS(i_sharedservices_sl[[net]:[net]],i_sharedservices_sl[[yyyymm]:[yyyymm]],P$1,i_sharedservices_sl[[type]:[type]],LEFT($F$37,2)) -> 0 | ... T37: =SUMIFS(i_sharedservices_sl[[net]:[net]],i_sharedservices_sl[[yyyymm]:[yyyymm]],T$1,i_sharedservices_sl[[type]:[type]],LEFT($F$37,2)) -> 0 | U37: =SUM(I37:T37) -> 23801.85
F38: UK £ - Invoice | I38: =+I37/exchange_rates!$B2 -> 9332.9304 | J38: =+J37/exchange_rates!$B2 -> 11364.33 | K38: =+K37/exchange_rates!$B2 -> 0 | L38: =+L37/exchange_rates!$B2 -> 0 | M38: =+M37/exchange_rates!$B2 -> 0 | N38: =+N37/exchange_rates!$B2 -> 0 | O38: =+O37/exchange_rates!$B2 -> 0 | P38: =+P37/exchange_rates!$B2 -> 0 | ... T38: =+T37/exchange_rates!$B2 -> 0 | U38: =SUM(I38:T38) -> 20697.261
E40: #VALUE! | F40: US € - Theorical | I40: =SUM(I41:I44) -> 7344.8521 | J40: =SUM(J41:J44) -> 8501.744 | K40: =SUM(K41:K44) -> 0 | L40: =SUM(L41:L44) -> 0 | M40: =SUM(M41:M44) -> 0 | N40: =SUM(N41:N44) -> 0 | O40: =SUM(O41:O44) -> 0 | P40: =SUM(P41:P44) -> 0 | ... T40: =SUM(T41:T44) -> 0 | U40: =SUM(I40:T40) -> 15846.596
G41: Royalties (Real) | I41: =+I73 -> 471 | J41: =+J73 -> 744 | K41: =+K73 -> 0 | L41: =+L73 -> 0 | M41: =+M73 -> 0 | N41: =+N73 -> 0 | O41: =+O73 -> 0 | P41: =+P73 -> 0 | ... T41: =+T73 -> 0 | U41: =SUM(I41:T41) -> 1215
G42: Staff (20%) | I42: =+I110 -> 2946.368 | J42: =+J110 -> 2983.136 | K42: =+K110 -> 0 | L42: =+L110 -> 0 | M42: =+M110 -> 0 | N42: =+N110 -> 0 | O42: =+O110 -> 0 | P42: =+P110 -> 0 | ... T42: =+T110 -> 0 | U42: =SUM(I42:T42) -> 5929.504
G43: Marketing (Real) | I43: =+I98 -> 3899.81 | J43: =+J98 -> 4744.08 | K43: =+K98 -> 0 | L43: =+L98 -> 0 | M43: =+M98 -> 0 | N43: =+N98 -> 0 | O43: =+O98 -> 0 | P43: =+P98 -> 0 | ... T43: =+T98 -> 0 | U43: =SUM(I43:T43) -> 8643.89
G44: Administrative (20%) | I44: =+I143 -> 27.6741 | J44: =+J143 -> 30.528 | K44: =+K143 -> 0 | L44: =+L143 -> 0 | M44: =+M143 -> 0 | N44: =+N143 -> 0 | O44: =+O143 -> 0 | P44: =+P143 -> 0 | ... T44: =+T143 -> 0 | U44: =SUM(I44:T44) -> 58.2021
E45: #VALUE! | F45: US € - Invoice | I45: =SUMIFS(i_sharedservices_sl[[net]:[net]],i_sharedservices_sl[[yyyymm]:[yyyymm]],I$1,i_sharedservices_sl[[type]:[type]],LEFT($F$45,2)) -> 7334.44 | J45: =SUMIFS(i_sharedservices_sl[[net]:[net]],i_sharedservices_sl[[yyyymm]:[yyyymm]],J$1,i_sharedservices_sl[[type]:[type]],LEFT($F$45,2)) -> 8462.36 | K45: =SUMIFS(i_sharedservices_sl[[net]:[net]],i_sharedservices_sl[[yyyymm]:[yyyymm]],K$1,i_sharedservices_sl[[type]:[type]],LEFT($F$45,2)) -> 0 | L45: =SUMIFS(i_sharedservices_sl[[net]:[net]],i_sharedservices_sl[[yyyymm]:[yyyymm]],L$1,i_sharedservices_sl[[type]:[type]],LEFT($F$45,2)) -> 0 | M45: =SUMIFS(i_sharedservices_sl[[net]:[net]],i_sharedservices_sl[[yyyymm]:[yyyymm]],M$1,i_sharedservices_sl[[type]:[type]],LEFT($F$45,2)) -> 0 | N45: =SUMIFS(i_sharedservices_sl[[net]:[net]],i_sharedservices_sl[[yyyymm]:[yyyymm]],N$1,i_sharedservices_sl[[type]:[type]],LEFT($F$45,2)) -> 0 | O45: =SUMIFS(i_sharedservices_sl[[net]:[net]],i_sharedservices_sl[[yyyymm]:[yyyymm]],O$1,i_sharedservices_sl[[type]:[type]],LEFT($F$45,2)) -> 0 | P45: =SUMIFS(i_sharedservices_sl[[net]:[net]],i_sharedservices_sl[[yyyymm]:[yyyymm]],P$1,i_sharedservices_sl[[type]:[type]],LEFT($F$45,2)) -> 0 | ... T45: =SUMIFS(i_sharedservices_sl[[net]:[net]],i_sharedservices_sl[[yyyymm]:[yyyymm]],T$1,i_sharedservices_sl[[type]:[type]],LEFT($F$45,2)) -> 0 | U45: =SUM(I45:T45) -> 15796.8
F46: US $ - Invoice | I46: =IFERROR(+I45/exchange_rates!B$3,0) -> 8731.4762 | J46: =IFERROR(+J45/exchange_rates!C$3,0) -> 9955.7176 | K46: =IFERROR(+K45/exchange_rates!D$3,0) -> 0 | L46: =IFERROR(+L45/exchange_rates!E$3,0) -> 0 | M46: =IFERROR(+M45/exchange_rates!F$3,0) -> 0 | N46: =IFERROR(+N45/exchange_rates!G$3,0) -> 0 | O46: =IFERROR(+O45/exchange_rates!H$3,0) -> 0 | P46: =IFERROR(+P45/exchange_rates!I$3,0) -> 0 | ... T46: =IFERROR(+T45/exchange_rates!M$3,0) -> 0 | U46: =SUM(I46:T46) -> 18687.194
...

Sheet P&G-Ltd
H1: 202601 | I1: 202602 | J1: 202603 | K1: 202604 | L1: 202605 | M1: 202606 | N1: 202607 | O1: 202608 | P1: 202609 | Q1: 202610 | R1: 202611 | S1: 202612
D2: =+#REF!&"-"&#REF! -> #REF! | H2: Enero | I2: Febrero | J2: Marzo | K2: Abril | L2: Mayo | M2: Junio | N2: Julio | O2: Agosto | P2: Septiembre | Q2: Octubre | R2: Noviembre | S2: Diciembre | T2: Total
D3: Turnover | H3: =+H4 -> 15702.66 | I3: =+I4 -> 19429.25 | J3: =+J4 -> 13642.64 | K3: =+K4 -> 0 | L3: =+L4 -> 0 | M3: =+M4 -> 0 | N3: =+N4 -> 0 | O3: =+O4 -> 0 | ... S3: =+S4 -> 0 | T3: =SUM(H3:S3) -> 48774.55
A4: Hannun | B4: Mirakl | C4: Country | D4: Sales | H4: =+H5 -> 15702.66 | I4: =+I5 -> 19429.25 | J4: =+J5 -> 13642.64 | K4: =+K5 -> 0 | L4: =+L5 -> 0 | M4: =+M5 -> 0 | N4: =+N5 -> 0 | O4: =+O5 -> 0 | ... S4: =+S5 -> 0 | T4: =SUM(H4:S4) -> 48774.55
D5: #VALUE! | E5: United Kingdom | H5: =+H7+H8 -> 15702.66 | I5: =+I7+I8 -> 19429.25 | J5: =+J7+J8 -> 13642.64 | K5: =+K7+K8 -> 0 | L5: =+L7+L8 -> 0 | M5: =+M7+M8 -> 0 | N5: =+N7+N8 -> 0 | O5: =+O7+O8 -> 0 | ... S5: =+S7+S8 -> 0 | T5: =SUM(H5:S5) -> 48774.55
G6: Share % | H6: =IFERROR(+H5/H$4,0) -> 1 | I6: =IFERROR(+I5/I$4,0) -> 1 | J6: =IFERROR(+J5/J$4,0) -> 1 | K6: =IFERROR(+K5/K$4,0) -> 0 | L6: =IFERROR(+L5/L$4,0) -> 0 | M6: =IFERROR(+M5/M$4,0) -> 0 | N6: =IFERROR(+N5/N$4,0) -> 0 | O6: =IFERROR(+O5/O$4,0) -> 0 | ... T6: =IFERROR(+T5/T$4,0) -> 1
A7: 0 | B7: 0 | C7: GB | F7: Shopify | H7: =SUMIFS('i-sales'!$K:$K, 'i-sales'!$C:$C,'P&G-Ltd'!H$1, 'i-sales'!$D:$D,'P&G-Ltd'!$C7, 'i-sales'!$G:$G,'P&G-Ltd'!$A7, 'i-sales'!$H:$H,'P&G-Ltd'!$B7 ) -> 15702.66 | I7: =SUMIFS('i-sales'!$K:$K, 'i-sales'!$C:$C,'P&G-Ltd'!I$1, 'i-sales'!$D:$D,'P&G-Ltd'!$C7, 'i-sales'!$G:$G,'P&G-Ltd'!$A7, 'i-sales'!$H:$H,'P&G-Ltd'!$B7 ) -> 19429.25 | J7: =SUMIFS('i-sales'!$K:$K, 'i-sales'!$C:$C,'P&G-Ltd'!J$1, 'i-sales'!$D:$D,'P&G-Ltd'!$C7, 'i-sales'!$G:$G,'P&G-Ltd'!$A7, 'i-sales'!$H:$H,'P&G-Ltd'!$B7 ) -> 13642.64 | K7: =SUMIFS('i-sales'!$K:$K, 'i-sales'!$C:$C,'P&G-Ltd'!K$1, 'i-sales'!$D:$D,'P&G-Ltd'!$C7, 'i-sales'!$G:$G,'P&G-Ltd'!$A7, 'i-sales'!$H:$H,'P&G-Ltd'!$B7 ) -> 0 | L7: =SUMIFS('i-sales'!$K:$K, 'i-sales'!$C:$C,'P&G-Ltd'!L$1, 'i-sales'!$D:$D,'P&G-Ltd'!$C7, 'i-sales'!$G:$G,'P&G-Ltd'!$A7, 'i-sales'!$H:$H,'P&G-Ltd'!$B7 ) -> 0 | M7: =SUMIFS('i-sales'!$K:$K, 'i-sales'!$C:$C,'P&G-Ltd'!M$1, 'i-sales'!$D:$D,'P&G-Ltd'!$C7, 'i-sales'!$G:$G,'P&G-Ltd'!$A7, 'i-sales'!$H:$H,'P&G-Ltd'!$B7 ) -> 0 | N7: =SUMIFS('i-sales'!$K:$K, 'i-sales'!$C:$C,'P&G-Ltd'!N$1, 'i-sales'!$D:$D,'P&G-Ltd'!$C7, 'i-sales'!$G:$G,'P&G-Ltd'!$A7, 'i-sales'!$H:$H,'P&G-Ltd'!$B7 ) -> 0 | O7: =SUMIFS('i-sales'!$K:$K, 'i-sales'!$C:$C,'P&G-Ltd'!O$1, 'i-sales'!$D:$D,'P&G-Ltd'!$C7, 'i-sales'!$G:$G,'P&G-Ltd'!$A7, 'i-sales'!$H:$H,'P&G-Ltd'!$B7 ) -> 0 | ... S7: =SUMIFS('i-sales'!$K:$K, 'i-sales'!$C:$C,'P&G-Ltd'!S$1, 'i-sales'!$D:$D,'P&G-Ltd'!$C7, 'i-sales'!$G:$G,'P&G-Ltd'!$A7, 'i-sales'!$H:$H,'P&G-Ltd'!$B7 ) -> 0 | T7: =SUM(H7:S7) -> 48774.55
F8: Marketplaces | H8: =SUM(H9:H14) -> 0 | I8: =SUM(I9:I14) -> 0 | J8: =SUM(J9:J14) -> 0 | K8: =SUM(K9:K14) -> 0 | L8: =SUM(L9:L14) -> 0 | M8: =SUM(M9:M14) -> 0 | N8: =SUM(N9:N14) -> 0 | O8: =SUM(O9:O14) -> 0 | ... S8: =SUM(S9:S14) -> 0 | T8: =SUM(H8:S8) -> 0
G9: Amazon Seller | T9: =SUM(H9:S9) -> 0
G10: Choose | T10: =SUM(H10:S10) -> 0
A11: 1 | B11: 0 | C11: GB | G11: Hannun | H11: =SUMIFS('i-sales'!$K:$K, 'i-sales'!$C:$C,'P&G-Ltd'!H$1, 'i-sales'!$D:$D,'P&G-Ltd'!$C11, 'i-sales'!$G:$G,'P&G-Ltd'!$A11, 'i-sales'!$H:$H,'P&G-Ltd'!$B11 ) -> 0 | I11: =SUMIFS('i-sales'!$K:$K, 'i-sales'!$C:$C,'P&G-Ltd'!I$1, 'i-sales'!$D:$D,'P&G-Ltd'!$C11, 'i-sales'!$G:$G,'P&G-Ltd'!$A11, 'i-sales'!$H:$H,'P&G-Ltd'!$B11 ) -> 0 | J11: =SUMIFS('i-sales'!$K:$K, 'i-sales'!$C:$C,'P&G-Ltd'!J$1, 'i-sales'!$D:$D,'P&G-Ltd'!$C11, 'i-sales'!$G:$G,'P&G-Ltd'!$A11, 'i-sales'!$H:$H,'P&G-Ltd'!$B11 ) -> 0 | K11: =SUMIFS('i-sales'!$K:$K, 'i-sales'!$C:$C,'P&G-Ltd'!K$1, 'i-sales'!$D:$D,'P&G-Ltd'!$C11, 'i-sales'!$G:$G,'P&G-Ltd'!$A11, 'i-sales'!$H:$H,'P&G-Ltd'!$B11 ) -> 0 | L11: =SUMIFS('i-sales'!$K:$K, 'i-sales'!$C:$C,'P&G-Ltd'!L$1, 'i-sales'!$D:$D,'P&G-Ltd'!$C11, 'i-sales'!$G:$G,'P&G-Ltd'!$A11, 'i-sales'!$H:$H,'P&G-Ltd'!$B11 ) -> 0 | M11: =SUMIFS('i-sales'!$K:$K, 'i-sales'!$C:$C,'P&G-Ltd'!M$1, 'i-sales'!$D:$D,'P&G-Ltd'!$C11, 'i-sales'!$G:$G,'P&G-Ltd'!$A11, 'i-sales'!$H:$H,'P&G-Ltd'!$B11 ) -> 0 | N11: =SUMIFS('i-sales'!$K:$K, 'i-sales'!$C:$C,'P&G-Ltd'!N$1, 'i-sales'!$D:$D,'P&G-Ltd'!$C11, 'i-sales'!$G:$G,'P&G-Ltd'!$A11, 'i-sales'!$H:$H,'P&G-Ltd'!$B11 ) -> 0 | O11: =SUMIFS('i-sales'!$K:$K, 'i-sales'!$C:$C,'P&G-Ltd'!O$1, 'i-sales'!$D:$D,'P&G-Ltd'!$C11, 'i-sales'!$G:$G,'P&G-Ltd'!$A11, 'i-sales'!$H:$H,'P&G-Ltd'!$B11 ) -> 0 | ... S11: =SUMIFS('i-sales'!$K:$K, 'i-sales'!$C:$C,'P&G-Ltd'!S$1, 'i-sales'!$D:$D,'P&G-Ltd'!$C11, 'i-sales'!$G:$G,'P&G-Ltd'!$A11, 'i-sales'!$H:$H,'P&G-Ltd'!$B11 ) -> 0 | T11: =SUM(H11:S11) -> 0
G12: Home24 | T12: =SUM(H12:S12) -> 0
G13: Leroy Merlin | T13: =SUM(H13:S13) -> 0
A14: 0 | B14: 1 | C14: GB | G14: Maisons du Monde | H14: =SUMIFS('i-sales'!$K:$K, 'i-sales'!$C:$C,'P&G-Ltd'!H$1, 'i-sales'!$D:$D,'P&G-Ltd'!$C14, 'i-sales'!$G:$G,'P&G-Ltd'!$A14, 'i-sales'!$H:$H,'P&G-Ltd'!$B14 )/1.21 -> 0 | I14: =SUMIFS('i-sales'!$K:$K, 'i-sales'!$C:$C,'P&G-Ltd'!I$1, 'i-sales'!$D:$D,'P&G-Ltd'!$C14, 'i-sales'!$G:$G,'P&G-Ltd'!$A14, 'i-sales'!$H:$H,'P&G-Ltd'!$B14 )/1.21 -> 0 | J14: =SUMIFS('i-sales'!$K:$K, 'i-sales'!$C:$C,'P&G-Ltd'!J$1, 'i-sales'!$D:$D,'P&G-Ltd'!$C14, 'i-sales'!$G:$G,'P&G-Ltd'!$A14, 'i-sales'!$H:$H,'P&G-Ltd'!$B14 )/1.21 -> 0 | K14: =SUMIFS('i-sales'!$K:$K, 'i-sales'!$C:$C,'P&G-Ltd'!K$1, 'i-sales'!$D:$D,'P&G-Ltd'!$C14, 'i-sales'!$G:$G,'P&G-Ltd'!$A14, 'i-sales'!$H:$H,'P&G-Ltd'!$B14 )/1.21 -> 0 | L14: =SUMIFS('i-sales'!$K:$K, 'i-sales'!$C:$C,'P&G-Ltd'!L$1, 'i-sales'!$D:$D,'P&G-Ltd'!$C14, 'i-sales'!$G:$G,'P&G-Ltd'!$A14, 'i-sales'!$H:$H,'P&G-Ltd'!$B14 )/1.21 -> 0 | M14: =SUMIFS('i-sales'!$K:$K, 'i-sales'!$C:$C,'P&G-Ltd'!M$1, 'i-sales'!$D:$D,'P&G-Ltd'!$C14, 'i-sales'!$G:$G,'P&G-Ltd'!$A14, 'i-sales'!$H:$H,'P&G-Ltd'!$B14 )/1.21 -> 0 | N14: =SUMIFS('i-sales'!$K:$K, 'i-sales'!$C:$C,'P&G-Ltd'!N$1, 'i-sales'!$D:$D,'P&G-Ltd'!$C14, 'i-sales'!$G:$G,'P&G-Ltd'!$A14, 'i-sales'!$H:$H,'P&G-Ltd'!$B14 )/1.21 -> 0 | O14: =SUMIFS('i-sales'!$K:$K, 'i-sales'!$C:$C,'P&G-Ltd'!O$1, 'i-sales'!$D:$D,'P&G-Ltd'!$C14, 'i-sales'!$G:$G,'P&G-Ltd'!$A14, 'i-sales'!$H:$H,'P&G-Ltd'!$B14 )/1.21 -> 0 | ... S14: =SUMIFS('i-sales'!$K:$K, 'i-sales'!$C:$C,'P&G-Ltd'!S$1, 'i-sales'!$D:$D,'P&G-Ltd'!$C14, 'i-sales'!$G:$G,'P&G-Ltd'!$A14, 'i-sales'!$H:$H,'P&G-Ltd'!$B14 )/1.21 -> 0 | T14: =SUM(H14:S14) -> 0
D16: Cost of sales | H16: =+H17+H26+H31+H34+H41 -> #REF! | I16: =+I17+I26+I31+I34+I41 -> #REF! | J16: =+J17+J26+J31+J34+J41 -> #REF! | K16: =+K17+K26+K31+K34+K41 -> #REF! | L16: =+L17+L26+L31+L34+L41 -> #REF! | M16: =+M17+M26+M31+M34+M41 -> #REF! | N16: =+N17+N26+N31+N34+N41 -> #REF! | O16: =+O17+O26+O31+O34+O41 -> #REF! | ... S16: =+S17+S26+S31+S34+S41 -> #REF! | T16: =SUM(H16:S16) -> #REF!
D17: Manufacturing | H17: =SUM(H18:H24) -> 4754.19 | I17: =SUM(I18:I24) -> 4593.8 | J17: =SUM(J18:J24) -> 0 | K17: =SUM(K18:K24) -> 0 | L17: =SUM(L18:L24) -> 0 | M17: =SUM(M18:M24) -> 0 | N17: =SUM(N18:N24) -> 0 | O17: =SUM(O18:O24) -> 0 | ... S17: =SUM(S18:S24) -> 0 | T17: =SUM(H17:S17) -> 9347.99
C18: manufacturing - Proco print -> Ltd | E18: #VALUE! | F18: Proco - Print | H18: =SUMIFS( INDIRECT("input_invoice[net]"), INDIRECT("input_invoice[yyyymm]"), 'P&G-Ltd'!H$1, INDIRECT("input_invoice[concept/supplier]"), 'P&G-Ltd'!$C18 ) -> 964.48 | I18: =SUMIFS( INDIRECT("input_invoice[net]"), INDIRECT("input_invoice[yyyymm]"), 'P&G-Ltd'!I$1, INDIRECT("input_invoice[concept/supplier]"), 'P&G-Ltd'!$C18 ) -> 1235.84 | J18: =SUMIFS( INDIRECT("input_invoice[net]"), INDIRECT("input_invoice[yyyymm]"), 'P&G-Ltd'!J$1, INDIRECT("input_invoice[concept/supplier]"), 'P&G-Ltd'!$C18 ) -> 0 | K18: =SUMIFS( INDIRECT("input_invoice[net]"), INDIRECT("input_invoice[yyyymm]"), 'P&G-Ltd'!K$1, INDIRECT("input_invoice[concept/supplier]"), 'P&G-Ltd'!$C18 ) -> 0 | L18: =SUMIFS( INDIRECT("input_invoice[net]"), INDIRECT("input_invoice[yyyymm]"), 'P&G-Ltd'!L$1, INDIRECT("input_invoice[concept/supplier]"), 'P&G-Ltd'!$C18 ) -> 0 | M18: =SUMIFS( INDIRECT("input_invoice[net]"), INDIRECT("input_invoice[yyyymm]"), 'P&G-Ltd'!M$1, INDIRECT("input_invoice[concept/supplier]"), 'P&G-Ltd'!$C18 ) -> 0 | N18: =SUMIFS( INDIRECT("input_invoice[net]"), INDIRECT("input_invoice[yyyymm]"), 'P&G-Ltd'!N$1, INDIRECT("input_invoice[concept/supplier]"), 'P&G-Ltd'!$C18 ) -> 0 | O18: =SUMIFS( INDIRECT("input_invoice[net]"), INDIRECT("input_invoice[yyyymm]"), 'P&G-Ltd'!O$1, INDIRECT("input_invoice[concept/supplier]"), 'P&G-Ltd'!$C18 ) -> 0 | ... S18: =SUMIFS( INDIRECT("input_invoice[net]"), INDIRECT("input_invoice[yyyymm]"), 'P&G-Ltd'!S$1, INDIRECT("input_invoice[concept/supplier]"), 'P&G-Ltd'!$C18 ) -> 0 | T18: =SUM(H18:S18) -> 2200.32
