Workbook

Sheet P&G-SL
D1: 202601 | E1: 202602 | F1: 202603 | G1: 202604 | H1: 202605 | I1: 202606 | J1: 202607 | K1: 202608 | L1: 202609 | M1: 202610 | N1: 202611 | O1: 202612 | P1: TOTAL
A2: P&G SL 2026 | D2: Enero | E2: Febrero | F2: Marzo | G2: Abril | H2: Mayo | I2: Junio | J2: Julio | K2: Agosto | L2: Septiembre | M2: Octubre | N2: Noviembre | O2: Diciembre | P2: Total
A3: Actualizado: 23/03/2026 09:26 h
A4: Turnover | D4: =D5+D25 | E4: =E5+E25 | F4: =F5+F25 | G4: =G5+G25 | H4: =H5+H25 | I4: =I5+I25 | J4: =J5+J25 | K4: =K5+K25 | ... O4: =O5+O25 | P4: =SUM(D4:O4)
A5: Product sales | B5: Product sales | D5: =D6+D16+D20+D22 | E5: =E6+E16+E20+E22 | F5: =F6+F16+F20+F22 | G5: =G6+G16+G20+G22 | H5: =H6+H16+H20+H22 | I5: =I6+I16+I20+I22 | J5: =J6+J16+J20+J22 | K5: =K6+K16+K20+K22 | ... O5: =O6+O16+O20+O22 | P5: =SUM(D5:O5)
A6: Shopify | C6: Shopify | D6: =SUM(D7:D15) | E6: =SUM(E7:E15) | F6: =SUM(F7:F15) | G6: =SUM(G7:G15) | H6: =SUM(H7:H15) | I6: =SUM(I7:I15) | J6: =SUM(J7:J15) | K6: =SUM(K7:K15) | ... O6: =SUM(O7:O15) | P6: =SUM(D6:O6) | Q6: ->
A7: ES | C7: ES | D7: =SUMIFS('i-shopify-sl'!$E:$E,'i-shopify-sl'!$A:$A,D$1,'i-shopify-sl'!$C:$C,$C7) | E7: =SUMIFS('i-shopify-sl'!$E:$E,'i-shopify-sl'!$A:$A,E$1,'i-shopify-sl'!$C:$C,$C7) | F7: =SUMIFS('i-shopify-sl'!$E:$E,'i-shopify-sl'!$A:$A,F$1,'i-shopify-sl'!$C:$C,$C7) | G7: =SUMIFS('i-shopify-sl'!$E:$E,'i-shopify-sl'!$A:$A,G$1,'i-shopify-sl'!$C:$C,$C7) | H7: =SUMIFS('i-shopify-sl'!$E:$E,'i-shopify-sl'!$A:$A,H$1,'i-shopify-sl'!$C:$C,$C7) | I7: =SUMIFS('i-shopify-sl'!$E:$E,'i-shopify-sl'!$A:$A,I$1,'i-shopify-sl'!$C:$C,$C7) | J7: =SUMIFS('i-shopify-sl'!$E:$E,'i-shopify-sl'!$A:$A,J$1,'i-shopify-sl'!$C:$C,$C7) | K7: =SUMIFS('i-shopify-sl'!$E:$E,'i-shopify-sl'!$A:$A,K$1,'i-shopify-sl'!$C:$C,$C7) | ... O7: =SUMIFS('i-shopify-sl'!$E:$E,'i-shopify-sl'!$A:$A,O$1,'i-shopify-sl'!$C:$C,$C7) | P7: =SUM(D7:O7) | Q7: ->
A8: FR | C8: FR | D8: =SUMIFS('i-shopify-sl'!$E:$E,'i-shopify-sl'!$A:$A,D$1,'i-shopify-sl'!$C:$C,$C8) | E8: =SUMIFS('i-shopify-sl'!$E:$E,'i-shopify-sl'!$A:$A,E$1,'i-shopify-sl'!$C:$C,$C8) | F8: =SUMIFS('i-shopify-sl'!$E:$E,'i-shopify-sl'!$A:$A,F$1,'i-shopify-sl'!$C:$C,$C8) | G8: =SUMIFS('i-shopify-sl'!$E:$E,'i-shopify-sl'!$A:$A,G$1,'i-shopify-sl'!$C:$C,$C8) | H8: =SUMIFS('i-shopify-sl'!$E:$E,'i-shopify-sl'!$A:$A,H$1,'i-shopify-sl'!$C:$C,$C8) | I8: =SUMIFS('i-shopify-sl'!$E:$E,'i-shopify-sl'!$A:$A,I$1,'i-shopify-sl'!$C:$C,$C8) | J8: =SUMIFS('i-shopify-sl'!$E:$E,'i-shopify-sl'!$A:$A,J$1,'i-shopify-sl'!$C:$C,$C8) | K8: =SUMIFS('i-shopify-sl'!$E:$E,'i-shopify-sl'!$A:$A,K$1,'i-shopify-sl'!$C:$C,$C8) | ... O8: =SUMIFS('i-shopify-sl'!$E:$E,'i-shopify-sl'!$A:$A,O$1,'i-shopify-sl'!$C:$C,$C8) | P8: =SUM(D8:O8) | Q8: ->
A9: DE | C9: DE | D9: =SUMIFS('i-shopify-sl'!$E:$E,'i-shopify-sl'!$A:$A,D$1,'i-shopify-sl'!$C:$C,$C9) | E9: =SUMIFS('i-shopify-sl'!$E:$E,'i-shopify-sl'!$A:$A,E$1,'i-shopify-sl'!$C:$C,$C9) | F9: =SUMIFS('i-shopify-sl'!$E:$E,'i-shopify-sl'!$A:$A,F$1,'i-shopify-sl'!$C:$C,$C9) | G9: =SUMIFS('i-shopify-sl'!$E:$E,'i-shopify-sl'!$A:$A,G$1,'i-shopify-sl'!$C:$C,$C9) | H9: =SUMIFS('i-shopify-sl'!$E:$E,'i-shopify-sl'!$A:$A,H$1,'i-shopify-sl'!$C:$C,$C9) | I9: =SUMIFS('i-shopify-sl'!$E:$E,'i-shopify-sl'!$A:$A,I$1,'i-shopify-sl'!$C:$C,$C9) | J9: =SUMIFS('i-shopify-sl'!$E:$E,'i-shopify-sl'!$A:$A,J$1,'i-shopify-sl'!$C:$C,$C9) | K9: =SUMIFS('i-shopify-sl'!$E:$E,'i-shopify-sl'!$A:$A,K$1,'i-shopify-sl'!$C:$C,$C9) | ... O9: =SUMIFS('i-shopify-sl'!$E:$E,'i-shopify-sl'!$A:$A,O$1,'i-shopify-sl'!$C:$C,$C9) | P9: =SUM(D9:O9) | Q9: ->
A10: IT | C10: IT | D10: =SUMIFS('i-shopify-sl'!$E:$E,'i-shopify-sl'!$A:$A,D$1,'i-shopify-sl'!$C:$C,$C10) | E10: =SUMIFS('i-shopify-sl'!$E:$E,'i-shopify-sl'!$A:$A,E$1,'i-shopify-sl'!$C:$C,$C10) | F10: =SUMIFS('i-shopify-sl'!$E:$E,'i-shopify-sl'!$A:$A,F$1,'i-shopify-sl'!$C:$C,$C10) | G10: =SUMIFS('i-shopify-sl'!$E:$E,'i-shopify-sl'!$A:$A,G$1,'i-shopify-sl'!$C:$C,$C10) | H10: =SUMIFS('i-shopify-sl'!$E:$E,'i-shopify-sl'!$A:$A,H$1,'i-shopify-sl'!$C:$C,$C10) | I10: =SUMIFS('i-shopify-sl'!$E:$E,'i-shopify-sl'!$A:$A,I$1,'i-shopify-sl'!$C:$C,$C10) | J10: =SUMIFS('i-shopify-sl'!$E:$E,'i-shopify-sl'!$A:$A,J$1,'i-shopify-sl'!$C:$C,$C10) | K10: =SUMIFS('i-shopify-sl'!$E:$E,'i-shopify-sl'!$A:$A,K$1,'i-shopify-sl'!$C:$C,$C10) | ... O10: =SUMIFS('i-shopify-sl'!$E:$E,'i-shopify-sl'!$A:$A,O$1,'i-shopify-sl'!$C:$C,$C10) | P10: =SUM(D10:O10) | Q10: ->
A11: AT | C11: AT | D11: =SUMIFS('i-shopify-sl'!$E:$E,'i-shopify-sl'!$A:$A,D$1,'i-shopify-sl'!$C:$C,$C11) | E11: =SUMIFS('i-shopify-sl'!$E:$E,'i-shopify-sl'!$A:$A,E$1,'i-shopify-sl'!$C:$C,$C11) | F11: =SUMIFS('i-shopify-sl'!$E:$E,'i-shopify-sl'!$A:$A,F$1,'i-shopify-sl'!$C:$C,$C11) | G11: =SUMIFS('i-shopify-sl'!$E:$E,'i-shopify-sl'!$A:$A,G$1,'i-shopify-sl'!$C:$C,$C11) | H11: =SUMIFS('i-shopify-sl'!$E:$E,'i-shopify-sl'!$A:$A,H$1,'i-shopify-sl'!$C:$C,$C11) | I11: =SUMIFS('i-shopify-sl'!$E:$E,'i-shopify-sl'!$A:$A,I$1,'i-shopify-sl'!$C:$C,$C11) | J11: =SUMIFS('i-shopify-sl'!$E:$E,'i-shopify-sl'!$A:$A,J$1,'i-shopify-sl'!$C:$C,$C11) | K11: =SUMIFS('i-shopify-sl'!$E:$E,'i-shopify-sl'!$A:$A,K$1,'i-shopify-sl'!$C:$C,$C11) | ... O11: =SUMIFS('i-shopify-sl'!$E:$E,'i-shopify-sl'!$A:$A,O$1,'i-shopify-sl'!$C:$C,$C11) | P11: =SUM(D11:O11) | Q11: ->
A12: BE | C12: BE | D12: =SUMIFS('i-shopify-sl'!$E:$E,'i-shopify-sl'!$A:$A,D$1,'i-shopify-sl'!$C:$C,$C12) | E12: =SUMIFS('i-shopify-sl'!$E:$E,'i-shopify-sl'!$A:$A,E$1,'i-shopify-sl'!$C:$C,$C12) | F12: =SUMIFS('i-shopify-sl'!$E:$E,'i-shopify-sl'!$A:$A,F$1,'i-shopify-sl'!$C:$C,$C12) | G12: =SUMIFS('i-shopify-sl'!$E:$E,'i-shopify-sl'!$A:$A,G$1,'i-shopify-sl'!$C:$C,$C12) | H12: =SUMIFS('i-shopify-sl'!$E:$E,'i-shopify-sl'!$A:$A,H$1,'i-shopify-sl'!$C:$C,$C12) | I12: =SUMIFS('i-shopify-sl'!$E:$E,'i-shopify-sl'!$A:$A,I$1,'i-shopify-sl'!$C:$C,$C12) | J12: =SUMIFS('i-shopify-sl'!$E:$E,'i-shopify-sl'!$A:$A,J$1,'i-shopify-sl'!$C:$C,$C12) | K12: =SUMIFS('i-shopify-sl'!$E:$E,'i-shopify-sl'!$A:$A,K$1,'i-shopify-sl'!$C:$C,$C12) | ... O12: =SUMIFS('i-shopify-sl'!$E:$E,'i-shopify-sl'!$A:$A,O$1,'i-shopify-sl'!$C:$C,$C12) | P12: =SUM(D12:O12) | Q12: ->
A13: NL | C13: NL | D13: =SUMIFS('i-shopify-sl'!$E:$E,'i-shopify-sl'!$A:$A,D$1,'i-shopify-sl'!$C:$C,$C13) | E13: =SUMIFS('i-shopify-sl'!$E:$E,'i-shopify-sl'!$A:$A,E$1,'i-shopify-sl'!$C:$C,$C13) | F13: =SUMIFS('i-shopify-sl'!$E:$E,'i-shopify-sl'!$A:$A,F$1,'i-shopify-sl'!$C:$C,$C13) | G13: =SUMIFS('i-shopify-sl'!$E:$E,'i-shopify-sl'!$A:$A,G$1,'i-shopify-sl'!$C:$C,$C13) | H13: =SUMIFS('i-shopify-sl'!$E:$E,'i-shopify-sl'!$A:$A,H$1,'i-shopify-sl'!$C:$C,$C13) | I13: =SUMIFS('i-shopify-sl'!$E:$E,'i-shopify-sl'!$A:$A,I$1,'i-shopify-sl'!$C:$C,$C13) | J13: =SUMIFS('i-shopify-sl'!$E:$E,'i-shopify-sl'!$A:$A,J$1,'i-shopify-sl'!$C:$C,$C13) | K13: =SUMIFS('i-shopify-sl'!$E:$E,'i-shopify-sl'!$A:$A,K$1,'i-shopify-sl'!$C:$C,$C13) | ... O13: =SUMIFS('i-shopify-sl'!$E:$E,'i-shopify-sl'!$A:$A,O$1,'i-shopify-sl'!$C:$C,$C13) | P13: =SUM(D13:O13) | Q13: ->
A14: PT | C14: PT | D14: =SUMIFS('i-shopify-sl'!$E:$E,'i-shopify-sl'!$A:$A,D$1,'i-shopify-sl'!$C:$C,$C14) | E14: =SUMIFS('i-shopify-sl'!$E:$E,'i-shopify-sl'!$A:$A,E$1,'i-shopify-sl'!$C:$C,$C14) | F14: =SUMIFS('i-shopify-sl'!$E:$E,'i-shopify-sl'!$A:$A,F$1,'i-shopify-sl'!$C:$C,$C14) | G14: =SUMIFS('i-shopify-sl'!$E:$E,'i-shopify-sl'!$A:$A,G$1,'i-shopify-sl'!$C:$C,$C14) | H14: =SUMIFS('i-shopify-sl'!$E:$E,'i-shopify-sl'!$A:$A,H$1,'i-shopify-sl'!$C:$C,$C14) | I14: =SUMIFS('i-shopify-sl'!$E:$E,'i-shopify-sl'!$A:$A,I$1,'i-shopify-sl'!$C:$C,$C14) | J14: =SUMIFS('i-shopify-sl'!$E:$E,'i-shopify-sl'!$A:$A,J$1,'i-shopify-sl'!$C:$C,$C14) | K14: =SUMIFS('i-shopify-sl'!$E:$E,'i-shopify-sl'!$A:$A,K$1,'i-shopify-sl'!$C:$C,$C14) | ... O14: =SUMIFS('i-shopify-sl'!$E:$E,'i-shopify-sl'!$A:$A,O$1,'i-shopify-sl'!$C:$C,$C14) | P14: =SUM(D14:O14) | Q14: ->
A15: XX | C15: XX | D15: =SUMIFS('i-shopify-sl'!$E:$E,'i-shopify-sl'!$A:$A,D$1,'i-shopify-sl'!$C:$C,$C15) | E15: =SUMIFS('i-shopify-sl'!$E:$E,'i-shopify-sl'!$A:$A,E$1,'i-shopify-sl'!$C:$C,$C15) | F15: =SUMIFS('i-shopify-sl'!$E:$E,'i-shopify-sl'!$A:$A,F$1,'i-shopify-sl'!$C:$C,$C15) | G15: =SUMIFS('i-shopify-sl'!$E:$E,'i-shopify-sl'!$A:$A,G$1,'i-shopify-sl'!$C:$C,$C15) | H15: =SUMIFS('i-shopify-sl'!$E:$E,'i-shopify-sl'!$A:$A,H$1,'i-shopify-sl'!$C:$C,$C15) | I15: =SUMIFS('i-shopify-sl'!$E:$E,'i-shopify-sl'!$A:$A,I$1,'i-shopify-sl'!$C:$C,$C15) | J15: =SUMIFS('i-shopify-sl'!$E:$E,'i-shopify-sl'!$A:$A,J$1,'i-shopify-sl'!$C:$C,$C15) | K15: =SUMIFS('i-shopify-sl'!$E:$E,'i-shopify-sl'!$A:$A,K$1,'i-shopify-sl'!$C:$C,$C15) | ... O15: =SUMIFS('i-shopify-sl'!$E:$E,'i-shopify-sl'!$A:$A,O$1,'i-shopify-sl'!$C:$C,$C15) | P15: =SUM(D15:O15) | Q15: ->
A16: Marketplaces | C16: Marketplaces | D16: =SUM(D17:D19) | E16: =SUM(E17:E19) | F16: =SUM(F17:F19) | G16: =SUM(G17:G19) | H16: =SUM(H17:H19) | I16: =SUM(I17:I19) | J16: =SUM(J17:J19) | K16: =SUM(K17:K19) | ... O16: =SUM(O17:O19) | P16: =SUM(D16:O16) | Q16: ->
A17: HANNUN | C17: HANNUN | D17: =SUMIFS('i-marketplaces-sl'!$E:$E,'i-marketplaces-sl'!$A:$A,D$1,'i-marketplaces-sl'!$C:$C,$C17) | E17: =SUMIFS('i-marketplaces-sl'!$E:$E,'i-marketplaces-sl'!$A:$A,E$1,'i-marketplaces-sl'!$C:$C,$C17) | F17: =SUMIFS('i-marketplaces-sl'!$E:$E,'i-marketplaces-sl'!$A:$A,F$1,'i-marketplaces-sl'!$C:$C,$C17) | G17: =SUMIFS('i-marketplaces-sl'!$E:$E,'i-marketplaces-sl'!$A:$A,G$1,'i-marketplaces-sl'!$C:$C,$C17) | H17: =SUMIFS('i-marketplaces-sl'!$E:$E,'i-marketplaces-sl'!$A:$A,H$1,'i-marketplaces-sl'!$C:$C,$C17) | I17: =SUMIFS('i-marketplaces-sl'!$E:$E,'i-marketplaces-sl'!$A:$A,I$1,'i-marketplaces-sl'!$C:$C,$C17) | J17: =SUMIFS('i-marketplaces-sl'!$E:$E,'i-marketplaces-sl'!$A:$A,J$1,'i-marketplaces-sl'!$C:$C,$C17) | K17: =SUMIFS('i-marketplaces-sl'!$E:$E,'i-marketplaces-sl'!$A:$A,K$1,'i-marketplaces-sl'!$C:$C,$C17) | ... O17: =SUMIFS('i-marketplaces-sl'!$E:$E,'i-marketplaces-sl'!$A:$A,O$1,'i-marketplaces-sl'!$C:$C,$C17) | P17: =SUM(D17:O17) | Q17: ->
A18: TOASTY | C18: TOASTY | D18: =SUMIFS('i-marketplaces-sl'!$E:$E,'i-marketplaces-sl'!$A:$A,D$1,'i-marketplaces-sl'!$C:$C,$C18) | E18: =SUMIFS('i-marketplaces-sl'!$E:$E,'i-marketplaces-sl'!$A:$A,E$1,'i-marketplaces-sl'!$C:$C,$C18) | F18: =SUMIFS('i-marketplaces-sl'!$E:$E,'i-marketplaces-sl'!$A:$A,F$1,'i-marketplaces-sl'!$C:$C,$C18) | G18: =SUMIFS('i-marketplaces-sl'!$E:$E,'i-marketplaces-sl'!$A:$A,G$1,'i-marketplaces-sl'!$C:$C,$C18) | H18: =SUMIFS('i-marketplaces-sl'!$E:$E,'i-marketplaces-sl'!$A:$A,H$1,'i-marketplaces-sl'!$C:$C,$C18) | I18: =SUMIFS('i-marketplaces-sl'!$E:$E,'i-marketplaces-sl'!$A:$A,I$1,'i-marketplaces-sl'!$C:$C,$C18) | J18: =SUMIFS('i-marketplaces-sl'!$E:$E,'i-marketplaces-sl'!$A:$A,J$1,'i-marketplaces-sl'!$C:$C,$C18) | K18: =SUMIFS('i-marketplaces-sl'!$E:$E,'i-marketplaces-sl'!$A:$A,K$1,'i-marketplaces-sl'!$C:$C,$C18) | ... O18: =SUMIFS('i-marketplaces-sl'!$E:$E,'i-marketplaces-sl'!$A:$A,O$1,'i-marketplaces-sl'!$C:$C,$C18) | P18: =SUM(D18:O18) | Q18: ->
A19: CHOOSE | C19: CHOOSE | D19: =SUMIFS('i-marketplaces-sl'!$E:$E,'i-marketplaces-sl'!$A:$A,D$1,'i-marketplaces-sl'!$C:$C,$C19) | E19: =SUMIFS('i-marketplaces-sl'!$E:$E,'i-marketplaces-sl'!$A:$A,E$1,'i-marketplaces-sl'!$C:$C,$C19) | F19: =SUMIFS('i-marketplaces-sl'!$E:$E,'i-marketplaces-sl'!$A:$A,F$1,'i-marketplaces-sl'!$C:$C,$C19) | G19: =SUMIFS('i-marketplaces-sl'!$E:$E,'i-marketplaces-sl'!$A:$A,G$1,'i-marketplaces-sl'!$C:$C,$C19) | H19: =SUMIFS('i-marketplaces-sl'!$E:$E,'i-marketplaces-sl'!$A:$A,H$1,'i-marketplaces-sl'!$C:$C,$C19) | I19: =SUMIFS('i-marketplaces-sl'!$E:$E,'i-marketplaces-sl'!$A:$A,I$1,'i-marketplaces-sl'!$C:$C,$C19) | J19: =SUMIFS('i-marketplaces-sl'!$E:$E,'i-marketplaces-sl'!$A:$A,J$1,'i-marketplaces-sl'!$C:$C,$C19) | K19: =SUMIFS('i-marketplaces-sl'!$E:$E,'i-marketplaces-sl'!$A:$A,K$1,'i-marketplaces-sl'!$C:$C,$C19) | ... O19: =SUMIFS('i-marketplaces-sl'!$E:$E,'i-marketplaces-sl'!$A:$A,O$1,'i-marketplaces-sl'!$C:$C,$C19) | P19: =SUM(D19:O19) | Q19: ->
A20: Rappels | C20: Rappels | D20: =D21 | E20: =E21 | F20: =F21 | G20: =G21 | H20: =H21 | I20: =I21 | J20: =J21 | K20: =K21 | ... O20: =O21 | P20: =SUM(D20:O20) | Q20: ->
A21: LIVITUM | C21: LIVITUM | D21: =SUMIFS('i-rappels-sl'!$E:$E,'i-rappels-sl'!$A:$A,D$1,'i-rappels-sl'!$C:$C,$C21) | E21: =SUMIFS('i-rappels-sl'!$E:$E,'i-rappels-sl'!$A:$A,E$1,'i-rappels-sl'!$C:$C,$C21) | F21: =SUMIFS('i-rappels-sl'!$E:$E,'i-rappels-sl'!$A:$A,F$1,'i-rappels-sl'!$C:$C,$C21) | G21: =SUMIFS('i-rappels-sl'!$E:$E,'i-rappels-sl'!$A:$A,G$1,'i-rappels-sl'!$C:$C,$C21) | H21: =SUMIFS('i-rappels-sl'!$E:$E,'i-rappels-sl'!$A:$A,H$1,'i-rappels-sl'!$C:$C,$C21) | I21: =SUMIFS('i-rappels-sl'!$E:$E,'i-rappels-sl'!$A:$A,I$1,'i-rappels-sl'!$C:$C,$C21) | J21: =SUMIFS('i-rappels-sl'!$E:$E,'i-rappels-sl'!$A:$A,J$1,'i-rappels-sl'!$C:$C,$C21) | K21: =SUMIFS('i-rappels-sl'!$E:$E,'i-rappels-sl'!$A:$A,K$1,'i-rappels-sl'!$C:$C,$C21) | ... O21: =SUMIFS('i-rappels-sl'!$E:$E,'i-rappels-sl'!$A:$A,O$1,'i-rappels-sl'!$C:$C,$C21) | P21: =SUM(D21:O21) | Q21: ->
A22: Supplies | C22: Supplies | D22: =D23 | E22: =E23 | F22: =F23 | G22: =G23 | H22: =H23 | I22: =I23 | J22: =J23 | K22: =K23 | ... O22: =O23 | P22: =SUM(D22:O22) | Q22: ->
A23: REVER | C23: REVER | D23: =SUMIFS('i-supplies-sl'!$E:$E,'i-supplies-sl'!$A:$A,D$1,'i-supplies-sl'!$C:$C,$C23) | E23: =SUMIFS('i-supplies-sl'!$E:$E,'i-supplies-sl'!$A:$A,E$1,'i-supplies-sl'!$C:$C,$C23) | F23: =SUMIFS('i-supplies-sl'!$E:$E,'i-supplies-sl'!$A:$A,F$1,'i-supplies-sl'!$C:$C,$C23) | G23: =SUMIFS('i-supplies-sl'!$E:$E,'i-supplies-sl'!$A:$A,G$1,'i-supplies-sl'!$C:$C,$C23) | H23: =SUMIFS('i-supplies-sl'!$E:$E,'i-supplies-sl'!$A:$A,H$1,'i-supplies-sl'!$C:$C,$C23) | I23: =SUMIFS('i-supplies-sl'!$E:$E,'i-supplies-sl'!$A:$A,I$1,'i-supplies-sl'!$C:$C,$C23) | J23: =SUMIFS('i-supplies-sl'!$E:$E,'i-supplies-sl'!$A:$A,J$1,'i-supplies-sl'!$C:$C,$C23) | K23: =SUMIFS('i-supplies-sl'!$E:$E,'i-supplies-sl'!$A:$A,K$1,'i-supplies-sl'!$C:$C,$C23) | ... O23: =SUMIFS('i-supplies-sl'!$E:$E,'i-supplies-sl'!$A:$A,O$1,'i-supplies-sl'!$C:$C,$C23) | P23: =SUM(D23:O23) | Q23: ->
P24: =SUM(D24:O24)
A25: Services | B25: Services | D25: =SUM(D26:D29) | E25: =SUM(E26:E29) | F25: =SUM(F26:F29) | G25: =SUM(G26:G29) | H25: =SUM(H26:H29) | I25: =SUM(I26:I29) | J25: =SUM(J26:J29) | K25: =SUM(K26:K29) | ... O25: =SUM(O26:O29) | P25: =SUM(D25:O25) | Q25: ->
A26: HANNUN | C26: HANNUN | D26: =SUMIFS('i-services-sl'!$E:$E,'i-services-sl'!$A:$A,D$1,'i-services-sl'!$C:$C,$C26) | E26: =SUMIFS('i-services-sl'!$E:$E,'i-services-sl'!$A:$A,E$1,'i-services-sl'!$C:$C,$C26) | F26: =SUMIFS('i-services-sl'!$E:$E,'i-services-sl'!$A:$A,F$1,'i-services-sl'!$C:$C,$C26) | G26: =SUMIFS('i-services-sl'!$E:$E,'i-services-sl'!$A:$A,G$1,'i-services-sl'!$C:$C,$C26) | H26: =SUMIFS('i-services-sl'!$E:$E,'i-services-sl'!$A:$A,H$1,'i-services-sl'!$C:$C,$C26) | I26: =SUMIFS('i-services-sl'!$E:$E,'i-services-sl'!$A:$A,I$1,'i-services-sl'!$C:$C,$C26) | J26: =SUMIFS('i-services-sl'!$E:$E,'i-services-sl'!$A:$A,J$1,'i-services-sl'!$C:$C,$C26) | K26: =SUMIFS('i-services-sl'!$E:$E,'i-services-sl'!$A:$A,K$1,'i-services-sl'!$C:$C,$C26) | ... O26: =SUMIFS('i-services-sl'!$E:$E,'i-services-sl'!$A:$A,O$1,'i-services-sl'!$C:$C,$C26) | P26: =SUM(D26:O26) | Q26: ->
A27: QHANDS | C27: QHANDS | D27: =SUMIFS('i-services-sl'!$E:$E,'i-services-sl'!$A:$A,D$1,'i-services-sl'!$C:$C,$C27) | E27: =SUMIFS('i-services-sl'!$E:$E,'i-services-sl'!$A:$A,E$1,'i-services-sl'!$C:$C,$C27) | F27: =SUMIFS('i-services-sl'!$E:$E,'i-services-sl'!$A:$A,F$1,'i-services-sl'!$C:$C,$C27) | G27: =SUMIFS('i-services-sl'!$E:$E,'i-services-sl'!$A:$A,G$1,'i-services-sl'!$C:$C,$C27) | H27: =SUMIFS('i-services-sl'!$E:$E,'i-services-sl'!$A:$A,H$1,'i-services-sl'!$C:$C,$C27) | I27: =SUMIFS('i-services-sl'!$E:$E,'i-services-sl'!$A:$A,I$1,'i-services-sl'!$C:$C,$C27) | J27: =SUMIFS('i-services-sl'!$E:$E,'i-services-sl'!$A:$A,J$1,'i-services-sl'!$C:$C,$C27) | K27: =SUMIFS('i-services-sl'!$E:$E,'i-services-sl'!$A:$A,K$1,'i-services-sl'!$C:$C,$C27) | ... O27: =SUMIFS('i-services-sl'!$E:$E,'i-services-sl'!$A:$A,O$1,'i-services-sl'!$C:$C,$C27) | P27: =SUM(D27:O27) | Q27: ->
A28: Ltd | C28: Ltd | D28: =SUMIFS('i-services-sl'!$E:$E,'i-services-sl'!$A:$A,D$1,'i-services-sl'!$C:$C,$C28) | E28: =SUMIFS('i-services-sl'!$E:$E,'i-services-sl'!$A:$A,E$1,'i-services-sl'!$C:$C,$C28) | F28: =SUMIFS('i-services-sl'!$E:$E,'i-services-sl'!$A:$A,F$1,'i-services-sl'!$C:$C,$C28) | G28: =SUMIFS('i-services-sl'!$E:$E,'i-services-sl'!$A:$A,G$1,'i-services-sl'!$C:$C,$C28) | H28: =SUMIFS('i-services-sl'!$E:$E,'i-services-sl'!$A:$A,H$1,'i-services-sl'!$C:$C,$C28) | I28: =SUMIFS('i-services-sl'!$E:$E,'i-services-sl'!$A:$A,I$1,'i-services-sl'!$C:$C,$C28) | J28: =SUMIFS('i-services-sl'!$E:$E,'i-services-sl'!$A:$A,J$1,'i-services-sl'!$C:$C,$C28) | K28: =SUMIFS('i-services-sl'!$E:$E,'i-services-sl'!$A:$A,K$1,'i-services-sl'!$C:$C,$C28) | ... O28: =SUMIFS('i-services-sl'!$E:$E,'i-services-sl'!$A:$A,O$1,'i-services-sl'!$C:$C,$C28) | P28: =SUM(D28:O28) | Q28: ->
A29: Inc | C29: Inc | D29: =SUMIFS('i-services-sl'!$E:$E,'i-services-sl'!$A:$A,D$1,'i-services-sl'!$C:$C,$C29) | E29: =SUMIFS('i-services-sl'!$E:$E,'i-services-sl'!$A:$A,E$1,'i-services-sl'!$C:$C,$C29) | F29: =SUMIFS('i-services-sl'!$E:$E,'i-services-sl'!$A:$A,F$1,'i-services-sl'!$C:$C,$C29) | G29: =SUMIFS('i-services-sl'!$E:$E,'i-services-sl'!$A:$A,G$1,'i-services-sl'!$C:$C,$C29) | H29: =SUMIFS('i-services-sl'!$E:$E,'i-services-sl'!$A:$A,H$1,'i-services-sl'!$C:$C,$C29) | I29: =SUMIFS('i-services-sl'!$E:$E,'i-services-sl'!$A:$A,I$1,'i-services-sl'!$C:$C,$C29) | J29: =SUMIFS('i-services-sl'!$E:$E,'i-services-sl'!$A:$A,J$1,'i-services-sl'!$C:$C,$C29) | K29: =SUMIFS('i-services-sl'!$E:$E,'i-services-sl'!$A:$A,K$1,'i-services-sl'!$C:$C,$C29) | ... O29: =SUMIFS('i-services-sl'!$E:$E,'i-services-sl'!$A:$A,O$1,'i-services-sl'!$C:$C,$C29) | P29: =SUM(D29:O29) | Q29: ->
P30: =SUM(D30:O30)
A31: Expenses | D31: =D32+D60 | E31: =E32+E60 | F31: =F32+F60 | G31: =G32+G60 | H31: =H32+H60 | I31: =I32+I60 | J31: =J32+J60 | K31: =K32+K60 | ... O31: =O32+O60 | P31: =SUM(D31:O31)
A32: COGS | B32: COGS | D32: =D33+D40+D47+D50 | E32: =E33+E40+E47+E50 | F32: =F33+F40+F47+F50 | G32: =G33+G40+G47+G50 | H32: =H33+H40+H47+H50 | I32: =I33+I40+I47+I50 | J32: =J33+J40+J47+J50 | K32: =K33+K40+K47+K50 | ... O32: =O33+O40+O47+O50 | P32: =SUM(D32:O32)
A33: Manufacturing (% sales) | C33: Manufacturing (% sales) | D33: =SUM(D34:D38) | E33: =SUM(E34:E38) | F33: =SUM(F34:F38) | G33: =SUM(G34:G38) | H33: =SUM(H34:H38) | I33: =SUM(I34:I38) | J33: =SUM(J34:J38) | K33: =SUM(K34:K38) | ... O33: =SUM(O34:O38) | P33: =SUM(D33:O33) | Q33: ->
A34: APPHOTOCAN | C34: APPHOTOCAN | D34: =SUMIFS('g-expenses-sl'!$G:$G,'g-expenses-sl'!$A:$A,D$1,'g-expenses-sl'!$D:$D,"manufacturing",'g-expenses-sl'!$E:$E,$C34) | E34: =SUMIFS('g-expenses-sl'!$G:$G,'g-expenses-sl'!$A:$A,E$1,'g-expenses-sl'!$D:$D,"manufacturing",'g-expenses-sl'!$E:$E,$C34) | F34: =SUMIFS('g-expenses-sl'!$G:$G,'g-expenses-sl'!$A:$A,F$1,'g-expenses-sl'!$D:$D,"manufacturing",'g-expenses-sl'!$E:$E,$C34) | G34: =SUMIFS('g-expenses-sl'!$G:$G,'g-expenses-sl'!$A:$A,G$1,'g-expenses-sl'!$D:$D,"manufacturing",'g-expenses-sl'!$E:$E,$C34) | H34: =SUMIFS('g-expenses-sl'!$G:$G,'g-expenses-sl'!$A:$A,H$1,'g-expenses-sl'!$D:$D,"manufacturing",'g-expenses-sl'!$E:$E,$C34) | I34: =SUMIFS('g-expenses-sl'!$G:$G,'g-expenses-sl'!$A:$A,I$1,'g-expenses-sl'!$D:$D,"manufacturing",'g-expenses-sl'!$E:$E,$C34) | J34: =SUMIFS('g-expenses-sl'!$G:$G,'g-expenses-sl'!$A:$A,J$1,'g-expenses-sl'!$D:$D,"manufacturing",'g-expenses-sl'!$E:$E,$C34) | K34: =SUMIFS('g-expenses-sl'!$G:$G,'g-expenses-sl'!$A:$A,K$1,'g-expenses-sl'!$D:$D,"manufacturing",'g-expenses-sl'!$E:$E,$C34) | ... O34: =SUMIFS('g-expenses-sl'!$G:$G,'g-expenses-sl'!$A:$A,O$1,'g-expenses-sl'!$D:$D,"manufacturing",'g-expenses-sl'!$E:$E,$C34) | P34: =SUM(D34:O34) | Q34: ->
A35: APPHOTOES | C35: APPHOTOES | D35: =SUMIFS('g-expenses-sl'!$G:$G,'g-expenses-sl'!$A:$A,D$1,'g-expenses-sl'!$D:$D,"manufacturing",'g-expenses-sl'!$E:$E,$C35) | E35: =SUMIFS('g-expenses-sl'!$G:$G,'g-expenses-sl'!$A:$A,E$1,'g-expenses-sl'!$D:$D,"manufacturing",'g-expenses-sl'!$E:$E,$C35) | F35: =SUMIFS('g-expenses-sl'!$G:$G,'g-expenses-sl'!$A:$A,F$1,'g-expenses-sl'!$D:$D,"manufacturing",'g-expenses-sl'!$E:$E,$C35) | G35: =SUMIFS('g-expenses-sl'!$G:$G,'g-expenses-sl'!$A:$A,G$1,'g-expenses-sl'!$D:$D,"manufacturing",'g-expenses-sl'!$E:$E,$C35) | H35: =SUMIFS('g-expenses-sl'!$G:$G,'g-expenses-sl'!$A:$A,H$1,'g-expenses-sl'!$D:$D,"manufacturing",'g-expenses-sl'!$E:$E,$C35) | I35: =SUMIFS('g-expenses-sl'!$G:$G,'g-expenses-sl'!$A:$A,I$1,'g-expenses-sl'!$D:$D,"manufacturing",'g-expenses-sl'!$E:$E,$C35) | J35: =SUMIFS('g-expenses-sl'!$G:$G,'g-expenses-sl'!$A:$A,J$1,'g-expenses-sl'!$D:$D,"manufacturing",'g-expenses-sl'!$E:$E,$C35) | K35: =SUMIFS('g-expenses-sl'!$G:$G,'g-expenses-sl'!$A:$A,K$1,'g-expenses-sl'!$D:$D,"manufacturing",'g-expenses-sl'!$E:$E,$C35) | ... O35: =SUMIFS('g-expenses-sl'!$G:$G,'g-expenses-sl'!$A:$A,O$1,'g-expenses-sl'!$D:$D,"manufacturing",'g-expenses-sl'!$E:$E,$C35) | P35: =SUM(D35:O35) | Q35: ->
A36: ARTLINK | C36: ARTLINK | D36: =SUMIFS('g-expenses-sl'!$G:$G,'g-expenses-sl'!$A:$A,D$1,'g-expenses-sl'!$D:$D,"manufacturing",'g-expenses-sl'!$E:$E,$C36) | E36: =SUMIFS('g-expenses-sl'!$G:$G,'g-expenses-sl'!$A:$A,E$1,'g-expenses-sl'!$D:$D,"manufacturing",'g-expenses-sl'!$E:$E,$C36) | F36: =SUMIFS('g-expenses-sl'!$G:$G,'g-expenses-sl'!$A:$A,F$1,'g-expenses-sl'!$D:$D,"manufacturing",'g-expenses-sl'!$E:$E,$C36) | G36: =SUMIFS('g-expenses-sl'!$G:$G,'g-expenses-sl'!$A:$A,G$1,'g-expenses-sl'!$D:$D,"manufacturing",'g-expenses-sl'!$E:$E,$C36) | H36: =SUMIFS('g-expenses-sl'!$G:$G,'g-expenses-sl'!$A:$A,H$1,'g-expenses-sl'!$D:$D,"manufacturing",'g-expenses-sl'!$E:$E,$C36) | I36: =SUMIFS('g-expenses-sl'!$G:$G,'g-expenses-sl'!$A:$A,I$1,'g-expenses-sl'!$D:$D,"manufacturing",'g-expenses-sl'!$E:$E,$C36) | J36: =SUMIFS('g-expenses-sl'!$G:$G,'g-expenses-sl'!$A:$A,J$1,'g-expenses-sl'!$D:$D,"manufacturing",'g-expenses-sl'!$E:$E,$C36) | K36: =SUMIFS('g-expenses-sl'!$G:$G,'g-expenses-sl'!$A:$A,K$1,'g-expenses-sl'!$D:$D,"manufacturing",'g-expenses-sl'!$E:$E,$C36) | ... O36: =SUMIFS('g-expenses-sl'!$G:$G,'g-expenses-sl'!$A:$A,O$1,'g-expenses-sl'!$D:$D,"manufacturing",'g-expenses-sl'!$E:$E,$C36) | P36: =SUM(D36:O36) | Q36: ->
A37: DCT | C37: DCT | D37: =SUMIFS('g-expenses-sl'!$G:$G,'g-expenses-sl'!$A:$A,D$1,'g-expenses-sl'!$D:$D,"manufacturing",'g-expenses-sl'!$E:$E,$C37) | E37: =SUMIFS('g-expenses-sl'!$G:$G,'g-expenses-sl'!$A:$A,E$1,'g-expenses-sl'!$D:$D,"manufacturing",'g-expenses-sl'!$E:$E,$C37) | F37: =SUMIFS('g-expenses-sl'!$G:$G,'g-expenses-sl'!$A:$A,F$1,'g-expenses-sl'!$D:$D,"manufacturing",'g-expenses-sl'!$E:$E,$C37) | G37: =SUMIFS('g-expenses-sl'!$G:$G,'g-expenses-sl'!$A:$A,G$1,'g-expenses-sl'!$D:$D,"manufacturing",'g-expenses-sl'!$E:$E,$C37) | H37: =SUMIFS('g-expenses-sl'!$G:$G,'g-expenses-sl'!$A:$A,H$1,'g-expenses-sl'!$D:$D,"manufacturing",'g-expenses-sl'!$E:$E,$C37) | I37: =SUMIFS('g-expenses-sl'!$G:$G,'g-expenses-sl'!$A:$A,I$1,'g-expenses-sl'!$D:$D,"manufacturing",'g-expenses-sl'!$E:$E,$C37) | J37: =SUMIFS('g-expenses-sl'!$G:$G,'g-expenses-sl'!$A:$A,J$1,'g-expenses-sl'!$D:$D,"manufacturing",'g-expenses-sl'!$E:$E,$C37) | K37: =SUMIFS('g-expenses-sl'!$G:$G,'g-expenses-sl'!$A:$A,K$1,'g-expenses-sl'!$D:$D,"manufacturing",'g-expenses-sl'!$E:$E,$C37) | ... O37: =SUMIFS('g-expenses-sl'!$G:$G,'g-expenses-sl'!$A:$A,O$1,'g-expenses-sl'!$D:$D,"manufacturing",'g-expenses-sl'!$E:$E,$C37) | P37: =SUM(D37:O37) | Q37: ->
A38: PRESSING | C38: PRESSING | D38: =SUMIFS('g-expenses-sl'!$G:$G,'g-expenses-sl'!$A:$A,D$1,'g-expenses-sl'!$D:$D,"manufacturing",'g-expenses-sl'!$E:$E,$C38) | E38: =SUMIFS('g-expenses-sl'!$G:$G,'g-expenses-sl'!$A:$A,E$1,'g-expenses-sl'!$D:$D,"manufacturing",'g-expenses-sl'!$E:$E,$C38) | F38: =SUMIFS('g-expenses-sl'!$G:$G,'g-expenses-sl'!$A:$A,F$1,'g-expenses-sl'!$D:$D,"manufacturing",'g-expenses-sl'!$E:$E,$C38) | G38: =SUMIFS('g-expenses-sl'!$G:$G,'g-expenses-sl'!$A:$A,G$1,'g-expenses-sl'!$D:$D,"manufacturing",'g-expenses-sl'!$E:$E,$C38) | H38: =SUMIFS('g-expenses-sl'!$G:$G,'g-expenses-sl'!$A:$A,H$1,'g-expenses-sl'!$D:$D,"manufacturing",'g-expenses-sl'!$E:$E,$C38) | I38: =SUMIFS('g-expenses-sl'!$G:$G,'g-expenses-sl'!$A:$A,I$1,'g-expenses-sl'!$D:$D,"manufacturing",'g-expenses-sl'!$E:$E,$C38) | J38: =SUMIFS('g-expenses-sl'!$G:$G,'g-expenses-sl'!$A:$A,J$1,'g-expenses-sl'!$D:$D,"manufacturing",'g-expenses-sl'!$E:$E,$C38) | K38: =SUMIFS('g-expenses-sl'!$G:$G,'g-expenses-sl'!$A:$A,K$1,'g-expenses-sl'!$D:$D,"manufacturing",'g-expenses-sl'!$E:$E,$C38) | ... O38: =SUMIFS('g-expenses-sl'!$G:$G,'g-expenses-sl'!$A:$A,O$1,'g-expenses-sl'!$D:$D,"manufacturing",'g-expenses-sl'!$E:$E,$C38) | P38: =SUM(D38:O38) | Q38: ->
A39: % Manufacturing / sales | C39: % Manufacturing / sales | D39: =IFERROR(D33/D5,0) | E39: =IFERROR(E33/E5,0) | F39: =IFERROR(F33/F5,0) | G39: =IFERROR(G33/G5,0) | H39: =IFERROR(H33/H5,0) | I39: =IFERROR(I33/I5,0) | J39: =IFERROR(J33/J5,0) | K39: =IFERROR(K33/K5,0) | ... O39: =IFERROR(O33/O5,0) | P39: =SUM(D39:O39)
A40: Logistics (% sales) | C40: Logistics (% sales) | D40: =SUM(D41:D45) | E40: =SUM(E41:E45) | F40: =SUM(F41:F45) | G40: =SUM(G41:G45) | H40: =SUM(H41:H45) | I40: =SUM(I41:I45) | J40: =SUM(J41:J45) | K40: =SUM(K41:K45) | ... O40: =SUM(O41:O45) | P40: =SUM(D40:O40) | Q40: ->
...

Sheet params
A1: <- Volver a P&G-SL
A2: key | B2: value
A3: entity | B3: SL
A4: year | B4: 2026
A5: generated_at_utc | B5: 2026-03-23T08:26:33Z

Sheet i-shopify-sl
A1: <- Volver a P&G-SL
A2: yyyymm | B2: entity | C2: line_item | D2: detail | E2: amount_net | F2: currency | G2: source | H2: invoice_number | I2: drive_url
A3: 202601 | B3: SL | C3: AT | D3: AT | E3: 5482.24 | F3: EUR | G3: finance.ventas_pyg
A4: 202601 | B4: SL | C4: BE | D4: BE | E4: 422.71 | F4: EUR | G4: finance.ventas_pyg
A5: 202601 | B5: SL | C5: DE | D5: DE | E5: 20924.16 | F5: EUR | G5: finance.ventas_pyg
A6: 202601 | B6: SL | C6: ES | D6: ES | E6: 61194.44 | F6: EUR | G6: finance.ventas_pyg
A7: 202601 | B7: SL | C7: FR | D7: FR | E7: 25590.35 | F7: EUR | G7: finance.ventas_pyg
A8: 202601 | B8: SL | C8: IT | D8: IT | E8: 18483.79 | F8: EUR | G8: finance.ventas_pyg
A9: 202601 | B9: SL | C9: NL | D9: NL | E9: 115.58 | F9: EUR | G9: finance.ventas_pyg
A10: 202601 | B10: SL | C10: PT | D10: PT | E10: 729.31 | F10: EUR | G10: finance.ventas_pyg
A11: 202601 | B11: SL | C11: XX | D11: XX | E11: 691.19 | F11: EUR | G11: finance.ventas_pyg
A12: 202602 | B12: SL | C12: AT | D12: AT | E12: 6077.94 | F12: EUR | G12: finance.ventas_pyg
A13: 202602 | B13: SL | C13: BE | D13: BE | E13: 998.68 | F13: EUR | G13: finance.ventas_pyg
A14: 202602 | B14: SL | C14: DE | D14: DE | E14: 19361.46 | F14: EUR | G14: finance.ventas_pyg
... A28: 202603 | B28: SL | C28: XX | D28: XX | E28: 227.22 | F28: EUR | G28: finance.ventas_pyg

Sheet i-marketplaces-sl
A1: <- Volver a P&G-SL
A2: yyyymm | B2: entity | C2: line_item | D2: detail | E2: amount_net | F2: currency | G2: source | H2: invoice_number | I2: drive_url
A3: 202601 | B3: SL | C3: HANNUN | D3: orders | E3: 1419.7 | F3: EUR | G3: documents | H3: 2026-0008 | I3: https://drive.google.com/file/d/1SRHb07OiC_DmTMCjAnZJpaif5amIl7Fl/view?usp=drivesdk
A4: 202602 | B4: SL | C4: HANNUN | D4: orders | E4: 1128.42 | F4: EUR | G4: documents | H4: 2026-0013 | I4: https://drive.google.com/file/d/1CmAISLBvUVe78NnGfNvevigmLiHzSEsg/view?usp=drivesdk
A5: 202602 | B5: SL | C5: TOASTY | D5: b2b_partner | E5: 1746.6 | F5: EUR | G5: documents | H5: AS-99158 | I5: https://drive.google.com/file/d/1Caf6SbLhjNsliYTmwyaOj9tn_dQke6Ff/view?usp=drivesdk
A6: 202603 | B6: SL | C6: CHOOSE | D6: campaign | E6: 15609.96 | F6: EUR | G6: documents | H6: AS-101940 | I6: https://drive.google.com/file/d/18nd9g2717srK8fdaeAjNuV-HtW9zUU3A/view?usp=drivesdk

Sheet i-rappels-sl
A1: <- Volver a P&G-SL
A2: yyyymm | B2: entity | C2: line_item | D2: detail | E2: amount_net | F2: currency | G2: source | H2: invoice_number | I2: drive_url
A3: 202601 | B3: SL | C3: LIVITUM | D3: rappels | E3: -1118.95 | F3: EUR | G3: documents | H3: A_2026-0006 | I3: https://drive.google.com/file/d/1TatcT909r9lQss48nnCsBt5kjo76SoJK/view?usp=drivesdk

Sheet i-supplies-sl
A1: <- Volver a P&G-SL
A2: yyyymm | B2: entity | C2: line_item | D2: detail | E2: amount_net | F2: currency | G2: source | H2: invoice_number | I2: drive_url
A3: 202601 | B3: SL | C3: REVER | D3: supplied_note | E3: -1753.49 | F3: EUR | G3: documents | H3: SUPPLIED-202512 | I3: https://drive.google.com/file/d/1fcDMocaa4cpTPjITHzeqYj2_zqO3NWYG/view?usp=drivesdk
A4: 202601 | B4: SL | C4: REVER | D4: supplied_note | E4: -422.97 | F4: EUR | G4: documents | H4: SUPPLIED-202601 | I4: https://drive.google.com/file/d/1JrhdQBAxThJrJre0y6m_O_546LXVrueL/view?usp=drivesdk
A5: 202602 | B5: SL | C5: REVER | D5: supplied_note | E5: -522.54 | F5: EUR | G5: documents | H5: SUPPLIED-202602 | I5: https://drive.google.com/file/d/1P7U8R2vW7HJBpC4dFcTfQ6Fl5v7lZf-T/view?usp=drivesdk

Sheet i-services-sl
A1: <- Volver a P&G-SL
A2: yyyymm | B2: entity | C2: line_item | D2: detail | E2: amount_net | F2: currency | G2: source | H2: invoice_number | I2: drive_url
A3: 202601 | B3: SL | C3: HANNUN | D3: renting_cnc | E3: 1661.16 | F3: EUR | G3: documents | H3: 2026-0006 | I3: https://drive.google.com/file/d/1ZNEswgq6fNRQmQBRT6GcjgdY_sepQuvN/view?usp=drivesdk
A4: 202601 | B4: SL | C4: HANNUN | D4: staff | E4: 1191.18 | F4: EUR | G4: documents | H4: 2026-0007 | I4: https://drive.google.com/file/d/1NSgOhocDqu_GBFUbkAHX1ly92CIuLykN/view?usp=drivesdk
A5: 202601 | B5: SL | C5: Inc | D5: shared_services | E5: 7334.44 | F5: EUR | G5: documents:shared_services | H5: 2026-0009 | I5: https://drive.google.com/file/d/1f0y-ak8qjEua6xrzfcweFpWZqOtA8h9C/view?usp=drivesdk
A6: 202601 | B6: SL | C6: Ltd | D6: shared_services | E6: 10732.87 | F6: EUR | G6: documents:shared_services | H6: 2026-0010 | I6: https://drive.google.com/file/d/1DVbcrKI34TY_XRmPCWYxFfktOzy1Bqmr/view?usp=drivesdk
A7: 202602 | B7: SL | C7: HANNUN | D7: staff | E7: 1191.18 | F7: EUR | G7: documents | H7: 2026-0011 | I7: https://drive.google.com/file/d/1il-dTsdyMbUZFKcN_lnqoNWLpAFjKN7A/view?usp=drivesdk
A8: 202602 | B8: SL | C8: Inc | D8: shared_services | E8: 8462.36 | F8: EUR | G8: documents:shared_services | H8: 2026-0014 | I8: https://drive.google.com/file/d/1rlqcAuJUaWxt0Udjbpq3E6fP_lfRq58_/view?usp=drivesdk
A9: 202602 | B9: SL | C9: Ltd | D9: shared_services | E9: 13068.98 | F9: EUR | G9: documents:shared_services | H9: 2026-0015 | I9: https://drive.google.com/file/d/1pNRISEZAlDdg2kXsh98mNhDndQFk42mV/view?usp=drivesdk
A10: 202602 | B10: SL | C10: QHANDS | D10: renting_cnc | E10: 1661.16 | F10: EUR | G10: documents | H10: 2026-0012 | I10: https://drive.google.com/file/d/1m_ONfUFq-mhxCI2SVs0iWw4Ss3ohvEPU/view?usp=drivesdk

Sheet g-expenses-sl
A1: <- Volver a P&G-SL
A2: yyyymm | B2: entity | C2: category | D2: subcategory | E2: supplier_code | F2: detail | G2: amount_net | H2: currency | I2: source | J2: invoice_number | K2: drive_url
A3: 202601 | B3: SL | C3: opex | D3: technology | E3: RAILWAY | G3: 20 | H3: USD | I3: documents | J3: 1602C2F5-0015 | K3: https://drive.google.com/file/d/1ih8AMHNM7ZQvhfJOhpZ3dpM0Bv3oyAA-/view?usp=drivesdk
A4: 202602 | B4: SL | C4: opex | D4: technology | E4: RAILWAY | G4: 20 | H4: USD | I4: documents | J4: 1602C2F5-0016 | K4: https://drive.google.com/file/d/1nql7QpcMxbeNk-s_Ku_8yFOrf0x8QVss/view?usp=drivesdk
A5: 202601 | B5: SL | C5: opex | D5: technology | E5: ADOBE | G5: 33.49 | H5: EUR | I5: documents | J5: IEE2026001813920 | K5: https://drive.google.com/file/d/1bfLhUT5wi1Zga5-YKV-y_tFqtaYvhqG_/view?usp=drivesdk
A6: 202601 | B6: SL | C6: cogs | D6: manufacturing | E6: APPHOTOCAN | G6: 29.22 | H6: EUR | I6: documents | J6: 26-1-147 | K6: https://drive.google.com/file/d/1R3F1S4DkkMdWjQCije5h6JcXrv2oanjz/view?usp=drivesdk
A7: 202601 | B7: SL | C7: cogs | D7: manufacturing | E7: APPHOTOES | G7: 4472.74 | H7: EUR | I7: documents | J7: 1-1115 | K7: https://drive.google.com/file/d/1WUqPHPgca1EQI6FEQ45b4g1OBJLlBFy7/view?usp=drivesdk
A8: 202601 | B8: SL | C8: cogs | D8: manufacturing | E8: APPHOTOES | G8: 2583.61 | H8: EUR | I8: documents | J8: 1-412 | K8: https://drive.google.com/file/d/1HSHnKuD3wT5VaYKRyqQtc1Kn3jvbtI5z/view?usp=drivesdk
A9: 202601 | B9: SL | C9: cogs | D9: manufacturing | E9: APPHOTOES | G9: 1083.14 | H9: EUR | I9: documents | J9: 1-527 | K9: https://drive.google.com/file/d/1QiOFa-Pu55ImYk1EgtLQ-1AJeKteGKKN/view?usp=drivesdk
A10: 202601 | B10: SL | C10: cogs | D10: manufacturing | E10: APPHOTOES | G10: 9758.59 | H10: EUR | I10: documents | J10: 1-841 | K10: https://drive.google.com/file/d/1Nv_kf16K0jbiVtLvDOdsF2s81ubDK86-/view?usp=drivesdk
A11: 202601 | B11: SL | C11: opex | D11: technology | E11: CANVA | G11: 9.91 | H11: EUR | I11: documents | J11: 04765-19148572 | K11: https://drive.google.com/file/d/1F1T1ZbmwTiAvZymdmK5UN5ILkYzAcyjE/view?usp=drivesdk
A12: 202601 | B12: SL | C12: opex | D12: administration | E12: CLARIS | G12: 808.08 | H12: EUR | I12: documents | J12: F00036/26 | K12: https://drive.google.com/file/d/1sZGtXApoakTTNvLB9pud8pMEBdr3FgDZ/view?usp=drivesdk
A13: 202601 | B13: SL | C13: cogs | D13: logistics | E13: CORREOS | G13: 155.8 | H13: EUR | I13: documents | J13: 4004550727 | K13: https://drive.google.com/file/d/13rt7yQ8sQuRvlpYE9WCitcMHEZMp3m_O/view?usp=drivesdk
A14: 202601 | B14: SL | C14: cogs | D14: logistics | E14: CORREOS | G14: 397.96 | H14: EUR | I14: documents | J14: 4004566874 | K14: https://drive.google.com/file/d/19fXXs3bT9JRPi6FOU7JWx3Antd-__jQl/view?usp=drivesdk
... A20: 202601 | B20: SL | C20: opex | D20: technology | E20: GODADDY | G20: 17.24 | H20: EUR | I20: documents | J20: 3994794936 | K20: https://drive.google.com/file/d/1wr9Nejy--4BUDpyg8riD4WzBFOQ_RYAA/view?usp=drivesdk
A21: 202601 | B21: SL | C21: opex | D21: marketing | E21: GOOGLEADS | F21: eu | G21: 24746.34 | H21: EUR | I21: documents | J21: 5489506571 | K21: https://drive.google.com/file/d/18pxQbj0cm3VVE381utczsaBPUOMg2_rE/view?usp=drivesdk
A22: 202601 | B22: SL | C22: opex | D22: marketing | E22: GOOGLEADS | F22: uk | G22: 2298.67 | H22: EUR | I22: documents | J22: 5489506571 | K22: https://drive.google.com/file/d/18pxQbj0cm3VVE381utczsaBPUOMg2_rE/view?usp=drivesdk
A23: 202601 | B23: SL | C23: opex | D23: marketing | E23: GOOGLEADS | F23: us | G23: 2119.05 | H23: EUR | I23: documents | J23: 5489506571 | K23: https://drive.google.com/file/d/18pxQbj0cm3VVE381utczsaBPUOMg2_rE/view?usp=drivesdk
A24: 202601 | B24: SL | C24: opex | D24: technology | E24: GOOGLEWORKSPACE | G24: 194.4 | H24: EUR | I24: documents | J24: 5472439457 | K24: https://drive.google.com/file/d/1iux2hxJTx8pApkdRTQ8TxrWAycKskSLW/view?usp=drivesdk
A25: 202601 | B25: SL | C25: opex | D25: technology | E25: GORGIAS | G25: 201.2 | H25: USD | I25: documents | J25: INC-01-2026-35934 | K25: https://drive.google.com/file/d/1cCVWMZjXH5GZ4KJ7Owu69neJD3Mu8nhQ/view?usp=drivesdk
A26: 202601 | B26: SL | C26: opex | D26: technology | E26: HETZNER | G26: 10.9 | H26: EUR | I26: documents | J26: 084000695806 | K26: https://drive.google.com/file/d/1mtjFeFve-rSAPTA0bq7zwh6FvresB1tx/view?usp=drivesdk
A27: 202601 | B27: SL | C27: opex | D27: technology | E27: KONVOAI | G27: 114.89 | H27: EUR | I27: documents | J27: B5F7DF3C-6721 | K27: https://drive.google.com/file/d/1FvjQkV9yZwLwYyh31yDEv4r6Ws9x-Gee/view?usp=drivesdk
A28: 202601 | B28: SL | C28: opex | D28: technology | E28: KONVOAI | G28: 339 | H28: EUR | I28: documents | J28: B5F7DF3C-6940 | K28: https://drive.google.com/file/d/1saa91nUMC9fiC166aUrnROE5ZHw8d_r6/view?usp=drivesdk
A29: 202601 | B29: SL | C29: opex | D29: technology | E29: MASMOVIL | G29: 5 | H29: EUR | I29: documents | J29: MC260001070524 | K29: https://drive.google.com/file/d/1Dqpxqnn8K6M513jJX6b-_iaNJoHc9CRf/view?usp=drivesdk
A30: 202601 | B30: SL | C30: opex | D30: marketing | E30: METAADS | F30: eu | G30: 20319.32 | H30: EUR | I30: documents | J30: 250807809 | K30: https://drive.google.com/file/d/18umjaalA1qWOFkhllNu22AbrnmcOGohV/view?usp=drivesdk
A31: 202601 | B31: SL | C31: opex | D31: marketing | E31: METAADS | F31: uk | G31: 3385.46 | H31: EUR | I31: documents | J31: 250807809 | K31: https://drive.google.com/file/d/18umjaalA1qWOFkhllNu22AbrnmcOGohV/view?usp=drivesdk
A32: 202601 | B32: SL | C32: opex | D32: marketing | E32: METAADS | F32: us | G32: 1779.68 | H32: EUR | I32: documents | J32: 250807809 | K32: https://drive.google.com/file/d/18umjaalA1qWOFkhllNu22AbrnmcOGohV/view?usp=drivesdk
A33: 202601 | B33: SL | C33: opex | D33: technology | E33: MICROSOFT | G33: 30.87 | H33: EUR | I33: documents | J33: G135222851 | K33: https://drive.google.com/file/d/1YkkVd0CygsXrJ-x-3pub1Sw9g6ZsG1la/view?usp=drivesdk
A34: 202601 | B34: SL | C34: opex | D34: technology | E34: OPENAI | F34: api_usage | G34: 10 | H34: USD | I34: documents | J34: BZHJNTUB0001 | K34: https://drive.google.com/file/d/1c_a7u0uC_WNkVQzPENEHHzZf2GoRgYzp/view?usp=drivesdk
A35: 202601 | B35: SL | C35: opex | D35: technology | E35: OPENAI | F35: chatgpt_plus | G35: 19.01 | H35: EUR | I35: documents | J35: 7BSDV5AM0001 | K35: https://drive.google.com/file/d/1Z8crn0ZC5tm2cibuFjiaNGAUQ32eDz4H/view?usp=drivesdk
A36: 202601 | B36: SL | C36: cogs | D36: manufacturing | E36: PRESSING | G36: 28979.31 | H36: EUR | I36: documents | J36: FAC/2026/26100000691 | K36: https://drive.google.com/file/d/1OUc0Fa83_INuKCsZQC_juJA8WSWOmU7e/view?usp=drivesdk
A37: 202601 | B37: SL | C37: opex | D37: technology | E37: PRODUCTHERO | G37: 134 | H37: EUR | I37: documents | J37: 205588 | K37: https://drive.google.com/file/d/14DyM0O39wOTD_wOQwkZ2nqk44A4Xr0Pd/view?usp=drivesdk
A38: 202601 | B38: SL | C38: opex | D38: technology | E38: REVER | G38: 434.8 | H38: EUR | I38: documents | J38: RVR-16471 | K38: https://drive.google.com/file/d/1MOlMl6uaY6n-XUO8ZDVih0oyxqYCdtvw/view?usp=drivesdk
A39: 202601 | B39: SL | C39: opex | D39: technology | E39: REVER | G39: 79 | H39: EUR | I39: documents | J39: RVR-16823 | K39: https://drive.google.com/file/d/15PYo6Nf9Rs0V66jula2uxmSQ1q_sREm9/view?usp=drivesdk
A40: 202601 | B40: SL | C40: opex | D40: technology | E40: SHOPIFY | G40: 2674.4 | H40: USD | I40: documents | J40: 479105361 | K40: https://drive.google.com/file/d/1xcXRJuhK0s-9Giwr-lbqS68FlhkSzTWB/view?usp=drivesdk
A41: 202601 | B41: SL | C41: cogs | D41: logistics | E41: SPRINGGDS | G41: 3.3 | H41: EUR | I41: documents | J41: E2600764 | K41: https://drive.google.com/file/d/1VbeIR7bk7enIlMQGnI8ZlR-KDaMoHDKn/view?usp=drivesdk
A42: 202601 | B42: SL | C42: opex | D42: administration | E42: TORRAS | G42: 15 | H42: EUR | I42: documents | J42: 7/186 | K42: https://drive.google.com/file/d/1PKaZMRQ1ZsO4JALcKcucZLVdRyUxpOON/view?usp=drivesdk
A43: 202601 | B43: SL | C43: cogs | D43: logistics | E43: UPS | G43: 204.42 | H43: EUR | I43: documents | J43: 326821409 | K43: https://drive.google.com/file/d/1j2ya4FHybtMpbOwe_dwCTFuK0BuXysGa/view?usp=drivesdk
A44: 202601 | B44: SL | C44: cogs | D44: logistics | E44: UPS | G44: 440.99 | H44: EUR | I44: documents | J44: 326838548 | K44: https://drive.google.com/file/d/1zXVkELtv1Sfm3Hs-3PVSAH4pEWbvWaOX/view?usp=drivesdk
A45: 202601 | B45: SL | C45: cogs | D45: logistics | E45: UPS | G45: 2253.28 | H45: EUR | I45: documents | J45: 326867966 | K45: https://drive.google.com/file/d/1icRXW3dXluuRK-dzvuDcN-maR8sKfRW3/view?usp=drivesdk
...

Sheet g-payment-fees-sl
A1: <- Volver a P&G-SL
A2: yyyymm | B2: entity | C2: supplier_code | D2: amount_net | E2: currency | F2: source
A3: 202601 | B3: SL | C3: PAYPAL | D3: 1405.82 | E3: EUR | F3: payment_fee_monthly_summary
A4: 202601 | B4: SL | C4: SHOPIFY | D4: 2616.7 | E4: EUR | F4: payment_fee_monthly_summary
A5: 202602 | B5: SL | C5: PAYPAL | D5: 1126.69 | E5: EUR | F5: payment_fee_monthly_summary
A6: 202602 | B6: SL | C6: SHOPIFY | D6: 2778.19 | E6: EUR | F6: payment_fee_monthly_summary
A7: 202603 | B7: SL | C7: PAYPAL | D7: 850.46 | E7: EUR | F7: payment_fee_monthly_summary
A8: 202603 | B8: SL | C8: SHOPIFY | D8: 2014.7 | E8: EUR | F8: payment_fee_monthly_summary

Sheet catalog-sl
A1: <- Volver a P&G-SL
A2: supplier_code | B2: supplier_name | C2: current_folder | D2: destination_path | E2: notes
A3: CORREOS | B3: CORREOS | C3: Correos | D3: expenses/cogs/logistics | E3: Peninsula/Baleares 21% IVA
A4: CORREOSCAN | B4: CORREOSCAN | C4: Correos | D4: expenses/cogs/logistics | E4: Canarias 7% IGIC
A5: GLS | B5: GLS | C5: GLS | D5: expenses/cogs/logistics | E5: OCR-based GLS parser via scanned PDF
A6: SPRINGGDS | B6: SPRINGGDS | C6: SPRING | D6: expenses/cogs/logistics | E6: Spring operating brand
A7: UPS | B7: UPS | C7: UPS | D7: expenses/cogs/logistics
A8: APPHOTOCAN | B8: APPHOTOCAN | C8: AP Photo | D8: expenses/cogs/manufacturing | E8: IGIC 7%
A9: APPHOTOES | B9: APPHOTOES | C9: AP Photo | D9: expenses/cogs/manufacturing
A10: ARTLINK | B10: ARTLINK | C10: Artlink | D10: expenses/cogs/manufacturing | E10: Frame purchases and related freight are treated as manufacturing
A11: DCT | B11: DCT | C11: DCT | D11: expenses/cogs/manufacturing
A12: PRESSING | B12: PRESSING | C12: Pressing | D12: expenses/cogs/manufacturing
A13: ROYALTIES | B13: ROYALTIES | C13: Artistas | D13: expenses/cogs/royalties | E13: Artist royalties received and issued by Artesta
A14: CLARIS | B14: CLARIS | C14: CLARIS | D14: expenses/opex/administration
A15: HANNUN | B15: HANNUN | C15: HANNUN | D15: expenses/opex/administration | E15: Bidirectional HANNUN relationship; incoming expense invoices and outgoing customer invoices
A16: NODA | B16: NODA | C16: NODA Asesores | D16: expenses/opex/administration
A17: TORRAS | B17: TORRAS | C17: TORRAS | D17: expenses/opex/administration
A18: VITALY | B18: VITALY | C18: Vitaly | D18: expenses/opex/administration | E18: Annual prevention and occupational health service
A19: GOOGLEADS | B19: GOOGLEADS | C19: Google | D19: expenses/opex/marketing
A20: METAADS | B20: METAADS | C20: Meta | D20: expenses/opex/marketing
A21: DOSCONSULTING | B21: DOSCONSULTING | C21: Nóminas | D21: expenses/opex/staff | E21: Monthly payroll management for SL
A22: ADOBE | B22: ADOBE | C22: ADOBE | D22: expenses/opex/technology
A23: CANVA | B23: CANVA | C23: canva | D23: expenses/opex/technology
A24: GODADDY | B24: GODADDY | C24: godaddy | D24: expenses/opex/technology
A25: GOOGLEWORKSPACE | B25: GOOGLEWORKSPACE | C25: Google | D25: expenses/opex/technology
A26: GORGIAS | B26: GORGIAS | C26: Gorgias | D26: expenses/opex/technology
A27: HETZNER | B27: HETZNER | C27: HETZNER | D27: expenses/opex/technology
A28: KONVOAI | B28: KONVOAI | C28: konvo | D28: expenses/opex/technology
A29: MASMOVIL | B29: MASMOVIL | C29: mas movil | D29: expenses/opex/technology
A30: MICROSOFT | B30: MICROSOFT | C30: MICROSOFT | D30: expenses/opex/technology
A31: OPENAI | B31: OPENAI | C31: chatgpt | D31: expenses/opex/technology | E31: Groups ChatGPT and API
A32: PRODUCTHERO | B32: PRODUCTHERO | C32: ProductHERO | D32: expenses/opex/technology
A33: RAILWAY | B33: RAILWAY | C33: RAILWAY | D33: expenses/opex/technology
A34: REVER | B34: REVER | C34: REVER | D34: expenses/opex/technology
A35: SHOPIFY | B35: SHOPIFY | C35: Shopify | D35: expenses/opex/technology
A36: YUMAAI | B36: YUMAAI | C36: YUMA | D36: expenses/opex/technology
A37: LIVITUM | B37: LIVITUM | C37: 709. Rappels | D37: income/other_income/rappels | E37: Rappel issued to Livitum
A38: CHOOSE | B38: CHOOSE | C38: CHOOSE | D38: income/sales/marketplaces | E38: Outgoing partner invoice
A39: TOASTY | B39: TOASTY | C39: TOASTY | D39: income/sales/marketplaces | E39: Outgoing partner invoice
A40: QHANDS | B40: QHANDS | C40: QHANDS | D40: income/shared-services | E40: Outgoing CNC rental invoice
