Workbook

Sheet Shopify_Payouts
A1: Transaction Date | B1: Type | C1: Order | D1: Card Brand | E1: Card Source | F1: Payout Status | G1: Payout Date | H1: Payout ID | I1: Available On | J1: Amount | K1: Fee | L1: Net | M1: Checkout | N1: Payment Method Name | O1: Presentment Amount | P1: Presentment Currency | Q1: Currency | R1: VAT | S1: Business Entity Name | T1: Business Entity ID
A2: 2026-01-31 22:33:19 +0100 | B2: charge | C2: AS-97246 | D2: master | E2: online | F2: paid | G2: 46057 | H2: 143913648466 | I2: 46057 | J2: 99.75 | K2: 1.6 | L2: 98.15 | M2: #47512490475858 | N2: card | O2: 99.75 | P2: EUR | Q2: EUR | R2: 0.00 | S2: Artesta Store SL | T2: MTc1MTkyNzM0Nw
A3: 2026-01-31 21:56:43 +0100 | B3: charge | C3: AS-97244 | D3: master | E3: online | F3: paid | G3: 46057 | H3: 143913648466 | I3: 46057 | J3: 67.95 | K3: 1.18 | L3: 66.77 | M3: #47512368644434 | N3: card | O3: 67.95 | P3: EUR | Q3: EUR | R3: 0.00 | S3: Artesta Store SL | T3: MTc1MTkyNzM0Nw
A4: 2026-01-31 21:49:01 +0100 | B4: charge | C4: AS-97243 | D4: visa | E4: online | F4: paid | G4: 46057 | H4: 143913648466 | I4: 46057 | J4: 85.9 | K4: 1.42 | L4: 84.48 | M4: #47512345215314 | N4: card | O4: 85.9 | P4: EUR | Q4: EUR | R4: 0.00 | S4: Artesta Store SL | T4: MTc1MTkyNzM0Nw
A5: 2026-01-31 21:16:23 +0100 | B5: charge | C5: AS-97240 | D5: master | E5: online | F5: paid | G5: 46057 | H5: 143913648466 | I5: 46057 | J5: 134.91 | K5: 2.05 | L5: 132.86 | M5: #47512226595154 | N5: card | O5: 134.91 | P5: EUR | Q5: EUR | R5: 0.00 | S5: Artesta Store SL | T5: MTc1MTkyNzM0Nw
A6: 2026-01-31 21:07:51 +0100 | B6: charge | C6: AS-97239 | D6: master | E6: online | F6: paid | G6: 46057 | H6: 143913648466 | I6: 46057 | J6: 38.87 | K6: 0.81 | L6: 38.06 | M6: #47512161616210 | N6: card | O6: 38.87 | P6: EUR | Q6: EUR | R6: 0.00 | S6: Artesta Store SL | T6: MTc1MTkyNzM0Nw
A7: 2026-01-31 21:05:59 +0100 | B7: charge | C7: AS-97238 | D7: master | E7: online | F7: paid | G7: 46057 | H7: 143913648466 | I7: 46057 | J7: 71.82 | K7: 1.23 | L7: 70.59 | M7: #47512196120914 | N7: card | O7: 71.82 | P7: EUR | Q7: EUR | R7: 0.00 | S7: Artesta Store SL | T7: MTc1MTkyNzM0Nw
A8: 2026-01-31 20:58:40 +0100 | B8: charge | C8: AS-97237 | D8: master | E8: online | F8: paid | G8: 46057 | H8: 143913648466 | I8: 46057 | J8: 67.95 | K8: 1.18 | L8: 66.77 | M8: #47512157749586 | N8: card | O8: 67.95 | P8: EUR | Q8: EUR | R8: 0.00 | S8: Artesta Store SL | T8: MTc1MTkyNzM0Nw
A9: 2026-01-31 20:00:07 +0100 | B9: charge | C9: AS-97234 | D9: master | E9: online | F9: paid | G9: 46057 | H9: 143913648466 | I9: 46057 | J9: 53.46 | K9: 0.99 | L9: 52.47 | M9: #47511953637714 | N9: card | O9: 53.46 | P9: EUR | Q9: EUR | R9: 0.00 | S9: Artesta Store SL | T9: MTc1MTkyNzM0Nw
A10: 2026-01-31 19:49:08 +0100 | B10: refund | C10: AS-97232 | D10: unknown | E10: online | F10: paid | G10: 46057 | H10: 143913648466 | I10: 46057 | J10: -49.9 | K10: 0 | L10: -49.9 | M10: #47511787929938 | N10: klarna | O10: 49.9 | P10: EUR | Q10: EUR | R10: 0.00 | S10: Artesta Store SL | T10: MTc1MTkyNzM0Nw
A11: 2026-01-31 19:45:50 +0100 | B11: charge | C11: AS-97233 | D11: unknown | E11: online | F11: paid | G11: 46057 | H11: 143913648466 | I11: 46057 | J11: 71.9 | K11: 3.94 | L11: 67.96 | M11: #47511906058578 | N11: klarna | O11: 71.9 | P11: EUR | Q11: EUR | R11: 0.00 | S11: Artesta Store SL | T11: MTc1MTkyNzM0Nw
A12: 2026-01-31 19:44:03 +0100 | B12: charge | C12: AS-97232 | D12: unknown | E12: online | F12: paid | G12: 46057 | H12: 143913648466 | I12: 46057 | J12: 49.9 | K12: 2.84 | L12: 47.06 | M12: #47511787929938 | N12: klarna | O12: 49.9 | P12: EUR | Q12: EUR | R12: 0.00 | S12: Artesta Store SL | T12: MTc1MTkyNzM0Nw
A13: 2026-01-31 19:14:51 +0100 | B13: charge | C13: AS-97229 | D13: visa | E13: online | F13: paid | G13: 46057 | H13: 143913648466 | I13: 46057 | J13: 80.85 | K13: 1.35 | L13: 79.5 | M13: #47511744381266 | N13: card | O13: 80.85 | P13: EUR | Q13: EUR | R13: 0.00 | S13: Artesta Store SL | T13: MTc1MTkyNzM0Nw
... A1531: 2026-01-01 01:13:05 +0100 | B1531: charge | C1531: AS-94794 | D1531: unknown | E1531: online | F1531: paid | G1531: 46028 | H1531: 142240285010 | I1531: 46028 | J1531: 114.95 | K1531: 6.09 | L1531: 108.86 | M1531: #47371590631762 | N1531: klarna | O1531: 114.95 | P1531: EUR | Q1531: EUR | R1531: 0.00 | S1531: Artesta Store SL | T1531: MTc1MTkyNzM0Nw

Sheet Sales_Shopify
A1: order_month_yyyymm | B1: order_name | C1: shipping_country_code | D1: shipping_state_code | E1: payment_gateway_names | F1: is_rever_tag | G1: is_hannun_tag | H1: is_mirakl_tag | I1: standard_rate | J1: payment_currency | K1: tax_rate | L1: shown_tax_presentment | M1: shown_gross_presentment | N1: shown_net_presentment | O1: tags | P1: descuadre | Q1: tax_rate_calculado
A2: 202601 | B2: AS-94795 | C2: DE | E2: ['paypal'] | F2: 0 | G2: 0 | H2: 0 | I2: 0.19 | J2: EUR | K2: 0.19 | L2: 6.05 | M2: 37.9 | N2: 31.85 | P2: 0 | Q2: 0.19
A3: 202601 | B3: AS-94797 | C3: ES | E3: ['shopify_payments'] | F3: 0 | G3: 0 | H3: 0 | I3: 0.21 | J3: EUR | K3: 0.21 | L3: 17.35 | M3: 99.95 | N3: 82.6 | P3: 0 | Q3: 0.21
A4: 202601 | B4: AS-94798 | C4: ES | E4: ['shopify_payments'] | F4: 0 | G4: 0 | H4: 0 | I4: 0.21 | J4: EUR | K4: 0.21 | L4: 9.28 | M4: 53.46 | N4: 44.18 | P4: 0 | Q4: 0.21
A5: 202601 | B5: AS-94799 | C5: DE | E5: ['paypal'] | F5: 0 | G5: 0 | H5: 0 | I5: 0.19 | J5: EUR | K5: 0.19 | L5: 2.86 | M5: 17.9 | N5: 15.04 | P5: 0 | Q5: 0.19
A6: 202601 | B6: AS-94800 | C6: ES | E6: ['shopify_payments'] | F6: 0 | G6: 0 | H6: 0 | I6: 0.21 | J6: EUR | K6: 0.21 | L6: 67.91 | M6: 391.32 | N6: 323.41 | P6: 0 | Q6: 0.21
A7: 202601 | B7: AS-94801 | C7: ES | E7: ['shopify_payments'] | F7: 0 | G7: 0 | H7: 0 | I7: 0.21 | J7: EUR | K7: 0.21 | L7: 9.36 | M7: 53.91 | N7: 44.55 | P7: 0 | Q7: 0.21
A8: 202601 | B8: AS-94802 | C8: FR | E8: ['shopify_payments'] | F8: 0 | G8: 0 | H8: 0 | I8: 0.2 | J8: EUR | K8: 0.2 | L8: 9.89 | M8: 59.31 | N8: 49.42 | P8: 0 | Q8: 0.2
A9: 202601 | B9: AS-94806 | C9: DE | E9: ['paypal'] | F9: 0 | G9: 0 | H9: 0 | I9: 0.19 | J9: EUR | K9: 0.19 | L9: 13.68 | M9: 85.7 | N9: 72.02 | P9: 0 | Q9: 0.19
A10: 202601 | B10: AS-94807 | C10: ES | E10: ['shopify_payments'] | F10: 0 | G10: 0 | H10: 0 | I10: 0.21 | J10: EUR | K10: 0.21 | L10: 7.78 | M10: 44.85 | N10: 37.07 | P10: 0 | Q10: 0.21
A11: 202601 | B11: AS-94808 | C11: IT | E11: ['paypal'] | F11: 0 | G11: 0 | H11: 0 | I11: 0.22 | J11: EUR | K11: 0.22 | L11: 7.19 | M11: 39.9 | N11: 32.71 | P11: 0 | Q11: 0.22
A12: 202601 | B12: AS-94809 | C12: DE | E12: ['paypal'] | F12: 0 | G12: 0 | H12: 0 | I12: 0.19 | J12: EUR | K12: 0.19 | L12: 6.05 | M12: 37.9 | N12: 31.85 | P12: 0 | Q12: 0.19
A13: 202601 | B13: AS-94810 | C13: AT | E13: ['shopify_payments'] | F13: 0 | G13: 0 | H13: 0 | I13: 0.2 | J13: EUR | K13: 0.2 | L13: 13.49 | M13: 80.91 | N13: 67.42 | P13: 0 | Q13: 0.2
... A43: 202601 | B43: AS-94847 | C43: DE | E43: ['paypal'] | F43: 0 | G43: 0 | H43: 0 | I43: 0.19 | J43: EUR | K43: 0.19 | L43: 6.05 | M43: 37.9 | N43: 31.85 | P43: 0 | Q43: 0.19
A44: 202601 | B44: AS-94803 | C44: ES | E44: ['shopify_payments'] | F44: 0 | G44: 0 | H44: 0 | I44: 0.21 | J44: EUR | K44: 0 | L44: 0 | M44: 0 | N44: 0 | O44: cancel-, customer-edit | P44: 0 | Q44: 0
A45: 202601 | B45: AS-94804 | C45: ES | E45: ['shopify_payments'] | F45: 0 | G45: 0 | H45: 0 | I45: 0.21 | J45: EUR | K45: 0.21 | L45: 3.63 | M45: 20.93 | N45: 17.3 | P45: 0 | Q45: 0.21
A46: 202601 | B46: AS-94796 | C46: DE | E46: ['paypal'] | F46: 0 | G46: 0 | H46: 0 | I46: 0.19 | J46: EUR | K46: 0.19 | L46: 0.8 | M46: 4.95 | N46: 4.15 | O46: Claim, Return | P46: 0 | Q46: 0.19
A47: 202601 | B47: AS-94794 | C47: DE | E47: ['shopify_payments'] | F47: 0 | G47: 0 | H47: 0 | I47: 0.19 | J47: EUR | K47: 0 | L47: 0 | M47: 0 | N47: 0 | O47: Claim, Return | P47: 0 | Q47: 0
A48: 202601 | B48: AS-88270 | C48: IT | E48: ['shopify_payments'] | F48: 0 | G48: 0 | H48: 0 | I48: 0.22 | J48: EUR | K48: 0.22 | L48: -13.33 | M48: -73.92 | N48: -60.59 | P48: 0 | Q48: 0.22
A49: 202601 | B49: AS-91995 | C49: ES | E49: ['shopify_payments'] | F49: 1 | G49: 0 | H49: 0 | I49: 0.21 | J49: EUR | K49: 0.21 | L49: -31.18 | M49: -179.64 | N49: -148.46 | O49: REVER returns | P49: 0 | Q49: 0.21
A50: 202601 | B50: AS-94849 | C50: IT | E50: ['shopify_payments'] | F50: 0 | G50: 0 | H50: 0 | I50: 0.22 | J50: EUR | K50: 0.22 | L50: 24.79 | M50: 137.48 | N50: 112.69 | P50: 0 | Q50: 0.22
A51: 202601 | B51: AS-94850 | C51: ES | E51: [] | F51: 0 | G51: 1 | H51: 0 | I51: 0.21 | J51: EUR | K51: 0 | L51: 6.51 | M51: 37.52 | N51: 31.01 | O51: Hannun | P51: 0 | Q51: 0.21
A52: 202601 | B52: AS-94851 | C52: ES | E52: ['shopify_payments'] | F52: 0 | G52: 0 | H52: 0 | I52: 0.21 | J52: EUR | K52: 0.21 | L52: 11.79 | M52: 67.95 | N52: 56.16 | P52: 0 | Q52: 0.21
A53: 202601 | B53: AS-94852 | C53: DE | E53: ['paypal'] | F53: 0 | G53: 0 | H53: 0 | I53: 0.19 | J53: EUR | K53: 0.19 | L53: 3.98 | M53: 24.9 | N53: 20.92 | P53: 0 | Q53: 0.19
A54: 202601 | B54: AS-94854 | C54: IT | E54: [] | F54: 0 | G54: 0 | H54: 0 | I54: 0.22 | J54: EUR | K54: 0 | L54: 0 | M54: 0 | N54: 0 | O54: Claim, GLS, Logistics | P54: 0 | Q54: 0
A55: 202601 | B55: AS-94855 | C55: ES | E55: ['shopify_payments'] | F55: 0 | G55: 0 | H55: 0 | I55: 0.21 | J55: EUR | K55: 0.21 | L55: 6.58 | M55: 37.9 | N55: 31.32 | P55: 0 | Q55: 0.21
A56: 202601 | B56: AS-94856 | C56: DE | E56: ['paypal'] | F56: 0 | G56: 0 | H56: 0 | I56: 0.19 | J56: EUR | K56: 0.19 | L56: 10.2 | M56: 63.9 | N56: 53.7 | P56: 0 | Q56: 0.19
A57: 202601 | B57: AS-94858 | C57: ES | E57: ['shopify_payments'] | F57: 0 | G57: 0 | H57: 0 | I57: 0.21 | J57: EUR | K57: 0.21 | L57: 17.35 | M57: 99.95 | N57: 82.6 | P57: 0 | Q57: 0.21
A58: 202601 | B58: AS-94859 | C58: IT | E58: ['shopify_payments'] | F58: 0 | G58: 0 | H58: 0 | I58: 0.22 | J58: EUR | K58: 0.22 | L58: 11.02 | M58: 61.11 | N58: 50.09 | P58: 0 | Q58: 0.22
A59: 202601 | B59: AS-94860 | C59: DE | E59: ['paypal'] | F59: 0 | G59: 0 | H59: 0 | I59: 0.19 | J59: EUR | K59: 0.19 | L59: 16.27 | M59: 101.9 | N59: 85.63 | P59: 0 | Q59: 0.19
A60: 202601 | B60: AS-94861 | C60: FR | E60: ['shopify_payments'] | F60: 0 | G60: 0 | H60: 0 | I60: 0.2 | J60: EUR | K60: 0.2 | L60: 19.16 | M60: 114.95 | N60: 95.79 | P60: 0 | Q60: 0.2
A61: 202601 | B61: AS-94862 | C61: ES | E61: [] | F61: 0 | G61: 0 | H61: 0 | I61: 0.21 | J61: EUR | K61: 0 | L61: 0 | M61: 0 | N61: 0 | O61: Claim, GLS, Logistics | P61: 0 | Q61: 0
A62: 202601 | B62: AS-94863 | C62: DE | E62: ['shopify_payments'] | F62: 0 | G62: 0 | H62: 0 | I62: 0.19 | J62: EUR | K62: 0.19 | L62: 12.76 | M62: 79.9 | N62: 67.14 | P62: 0 | Q62: 0.19
A63: 202601 | B63: AS-94864 | C63: FR | E63: ['shopify_payments'] | F63: 0 | G63: 0 | H63: 0 | I63: 0.2 | J63: EUR | K63: 0.2 | L63: 10.65 | M63: 63.9 | N63: 53.25 | P63: 0 | Q63: 0.2
A64: 202601 | B64: AS-94865 | C64: FR | E64: ['shopify_payments'] | F64: 0 | G64: 0 | H64: 0 | I64: 0.2 | J64: EUR | K64: 0.2 | L64: 14.83 | M64: 88.97 | N64: 74.14 | P64: 0 | Q64: 0.2
A65: 202601 | B65: AS-94866 | C65: FR | E65: ['shopify_payments'] | F65: 0 | G65: 0 | H65: 0 | I65: 0.2 | J65: EUR | K65: 0.2 | L65: 9.81 | M65: 58.85 | N65: 49.04 | P65: 0 | Q65: 0.2
A66: 202601 | B66: AS-94868 | C66: ES | E66: ['shopify_payments'] | F66: 0 | G66: 0 | H66: 0 | I66: 0.21 | J66: EUR | K66: 0.21 | L66: 49.97 | M66: 287.91 | N66: 237.94 | P66: 0 | Q66: 0.21
A67: 202601 | B67: AS-94869 | C67: FR | E67: ['shopify_payments'] | F67: 0 | G67: 0 | H67: 0 | I67: 0.2 | J67: EUR | K67: 0.2 | L67: 19.16 | M67: 114.95 | N67: 95.79 | P67: 0 | Q67: 0.2
A68: 202601 | B68: AS-94870 | C68: DE | E68: ['paypal'] | F68: 0 | G68: 0 | H68: 0 | I68: 0.19 | J68: EUR | K68: 0.19 | L68: 7.65 | M68: 47.9 | N68: 40.25 | P68: 0 | Q68: 0.19
A69: 202601 | B69: AS-94872 | C69: ES | E69: ['shopify_payments'] | F69: 0 | G69: 0 | H69: 0 | I69: 0.21 | J69: EUR | K69: 0.21 | L69: 6.58 | M69: 37.9 | N69: 31.32 | P69: 0 | Q69: 0.21
...

Sheet Paypal_Payouts
B1: Hora | C1: Zona horaria | D1: Nombre | E1: Tipo | F1: Estado | G1: Divisa | H1: Bruto | I1: Tarifa | J1: Neto | K1: Correo electrónico del remitente | L1: Correo electrónico del destinatario | M1: Id. de transacción | N1: Dirección de envío | O1: Estado de la dirección | P1: Nombre de artículo | Q1: Id. de artículo | R1: Importe de envío y manipulación | S1: Importe del seguro | T1: Impuesto de ventas | U1: Nombre de la opción 1 | V1: Valor de la opción 1 | W1: Nombre de la opción 2 | X1: Valor de la opción 2 | Y1: Id. de referencia de trans. | Z1: Número de factura | AA1: Número personalizado | AB1: Cantidad | AC1: Id. del recibo | AD1: Saldo | AE1: Línea de dirección 1 | AF1: Línea de dirección 2/Distrito/Barrio | AG1: Población | AH1: Estado/Provincia/Región/Condado/Territorio/Prefectura/República | AI1: Código postal | AJ1: País | AK1: Número de teléfono de contacto | AL1: Asunto | AM1: Nota | AN1: Código de país | AO1: Repercusiones en el saldo | AP1: Número de pedido | AQ1: pedido_id2 | AR1: pedido_id3 | AS1: pedido_id4
A2: 01/01/2026 | B2: 03:34:17 | C2: CET | D2: Siemone Schönitz | E2: Pago con Pago exprés | F2: Completado | G2: EUR | H2: 37.9 | I2: -1.45 | J2: 36.45 | K2: siemone.schoenitz@gmx.de | L2: info@artestaposters.com | M2: 65N51228E9959580X | N2: Siemone, Schönitz, Königsberger Straße 18, Uslar, 37170, Alemania | O2: Confirmada | P2: Scandi Japandi Houseplant 3 - Póster / Sin marco / 50x70 | R2: 4.95 | T2: 0 | Z2: rlpPq43qcJ2G529gz0Y3hQ17R | AA2: {"shop_id":751927347,"session_id":"rlpPq43qcJ2G529gz0Y3hQ17R"} | AB2: 1 | AD2: 5366.52 | AE2: Königsberger Straße 18 | AG2: Uslar | AI2: 37170 | AJ2: Alemania | AK2: +49 17631633932 | AL2: Scandi Japandi Houseplant 3 - Póster / Sin marco / 50x70 | AN2: DE | AO2: Crédito | AP2: =IFERROR(VLOOKUP(M2,Shopify_Transactions!V:BB,5,0),"Not_Found") -> AS-94795 | AQ2: =IFERROR(VLOOKUP(M2,Shopify_Transactions!X:BB,3,0),"Not_Found") -> Not_Found | AR2: =IFERROR(VLOOKUP(Z2,Shopify_Transactions!W:Z,4,0),"Not_Found") -> AS-94795 | AS2: =IF(AP2<>"Not_Found",AP2,IF(AQ2<>"Not_Found",AQ2,AR2)) -> AS-94795
A3: 01/01/2026 | B3: 07:42:46 | C3: CET | D3: Domenika Kusch | E3: Pago con Pago exprés | F3: Completado | G3: EUR | H3: 25.9 | I3: -1.1 | J3: 24.8 | K3: Domenika.Kusch@gmail.com | L3: info@artestaposters.com | M3: 1VY57255J0900715E | N3: Domenika, Kusch, Wolfshagen 8, Hamburg, 20535, Alemania | O3: Confirmada | P3: Colgador para póster de 60cm de madera y color negro | R3: 4.95 | T3: 0 | Z3: rKvBqDngbj2fMmeChnhphX247 | AA3: {"shop_id":751927347,"session_id":"rKvBqDngbj2fMmeChnhphX247"} | AB3: 1 | AD3: 5391.32 | AE3: Wolfshagen 8 | AG3: Hamburg | AI3: 20535 | AJ3: Alemania | AK3: +49 017693197672 | AL3: Colgador para póster de 60cm de madera y color negro | AN3: DE | AO3: Crédito | AP3: =IFERROR(VLOOKUP(M3,Shopify_Transactions!V:BB,5,0),"Not_Found") -> AS-94796 | AQ3: =IFERROR(VLOOKUP(M3,Shopify_Transactions!X:BB,3,0),"Not_Found") -> Not_Found | AR3: =IFERROR(VLOOKUP(Z3,Shopify_Transactions!W:Z,4,0),"Not_Found") -> AS-94796 | AS3: =IF(AP3<>"Not_Found",AP3,IF(AQ3<>"Not_Found",AQ3,AR3)) -> AS-94796
A4: 01/01/2026 | B4: 10:25:19 | C4: CET | D4: Eva Pischke | E4: Pago con Pago exprés | F4: Completado | G4: EUR | H4: 17.9 | I4: -0.87 | J4: 17.03 | K4: ep@stephanpischke.de | L4: info@artestaposters.com | M4: 26P35561C8773781H | N4: Eva Maria Pischke, Ackerstraße 5, Meerbusch, 40670, Alemania | O4: Confirmada | P4: Le petit dejeuner , Made in France - Póster / Sin marco / 20x30 | R4: 4.95 | T4: 0 | Z4: rEL1tkaxNS15hEpziAVQ7TSg1 | AA4: {"shop_id":751927347,"session_id":"rEL1tkaxNS15hEpziAVQ7TSg1"} | AB4: 1 | AD4: 5408.35 | AE4: Ackerstraße 5 | AG4: Meerbusch | AI4: 40670 | AJ4: Alemania | AK4: +49 1732875027 | AL4: Le petit dejeuner , Made in France - Póster / Sin marco / 20x30 | AN4: DE | AO4: Crédito | AP4: =IFERROR(VLOOKUP(M4,Shopify_Transactions!V:BB,5,0),"Not_Found") -> AS-94799 | AQ4: =IFERROR(VLOOKUP(M4,Shopify_Transactions!X:BB,3,0),"Not_Found") -> Not_Found | AR4: =IFERROR(VLOOKUP(Z4,Shopify_Transactions!W:Z,4,0),"Not_Found") -> AS-94799 | AS4: =IF(AP4<>"Not_Found",AP4,IF(AQ4<>"Not_Found",AQ4,AR4)) -> AS-94799
A5: 01/01/2026 | B5: 13:22:53 | C5: CET | D5: Sabrina Mißlinger | E5: Pago con Pago exprés | F5: Completado | G5: EUR | H5: 85.7 | I5: -2.84 | J5: 82.86 | K5: sabrina.he@gmx.de | L5: info@artestaposters.com | M5: 7BG53258A10745635 | N5: Sabrina Mißlinger, Birnbaumstr. 4, Furth, 84095, Alemania | O5: Confirmada | P5: Toy Captain America - Póster / Sin marco / 20x30, Marco roble 20x30cm - No, Toy Superman - Póster / Sin marco / 20x30 | R5: 0 | T5: 0 | Z5: rR0zuzQi9MH5yyb1PWtioXgmN | AA5: {"shop_id":751927347,"session_id":"rR0zuzQi9MH5yyb1PWtioXgmN"} | AB5: 6 | AD5: 5491.21 | AE5: Birnbaumstr. 4 | AG5: Furth | AI5: 84095 | AJ5: Alemania | AK5: +49 74037387 | AL5: Marco roble 20x30cm - No | AN5: DE | AO5: Crédito | AP5: =IFERROR(VLOOKUP(M5,Shopify_Transactions!V:BB,5,0),"Not_Found") -> AS-94806 | AQ5: =IFERROR(VLOOKUP(M5,Shopify_Transactions!X:BB,3,0),"Not_Found") -> Not_Found | AR5: =IFERROR(VLOOKUP(Z5,Shopify_Transactions!W:Z,4,0),"Not_Found") -> AS-94806 | AS5: =IF(AP5<>"Not_Found",AP5,IF(AQ5<>"Not_Found",AQ5,AR5)) -> AS-94806
A6: 01/01/2026 | B6: 14:46:22 | C6: CET | D6: andrea cabiola | E6: Pago con Pago exprés | F6: Completado | G6: EUR | H6: 39.9 | I6: -1.51 | J6: 38.39 | K6: andrea.cabiola@gmail.com | L6: info@artestaposters.com | M6: 1EU604669L4931209 | N6: Andrea Cabiola, Q.re Dott. Emanuele Piazza, 30, 30, Marostica, Vicenza, 36063, Italia | O6: Confirmada | P6: The cat - Lienzo / Sin marco / 30x40 | R6: 4.95 | T6: 0 | Z6: rynSFLdhtLslg1aIBHooTqXjO | AA6: {"shop_id":751927347,"session_id":"rynSFLdhtLslg1aIBHooTqXjO"} | AB6: 1 | AD6: 5529.6 | AE6: Q.re Dott. Emanuele Piazza, 30, 30 | AG6: Marostica | AH6: Vicenza | AI6: 36063 | AJ6: Italia | AK6: +39 3337464714 | AL6: The cat - Lienzo / Sin marco / 30x40 | AN6: IT | AO6: Crédito | AP6: =IFERROR(VLOOKUP(M6,Shopify_Transactions!V:BB,5,0),"Not_Found") -> AS-94808 | AQ6: =IFERROR(VLOOKUP(M6,Shopify_Transactions!X:BB,3,0),"Not_Found") -> Not_Found | AR6: =IFERROR(VLOOKUP(Z6,Shopify_Transactions!W:Z,4,0),"Not_Found") -> AS-94808 | AS6: =IF(AP6<>"Not_Found",AP6,IF(AQ6<>"Not_Found",AQ6,AR6)) -> AS-94808
A7: 01/01/2026 | B7: 15:25:06 | C7: CET | D7: sarah kregehr | E7: Pago con Pago exprés | F7: Completado | G7: EUR | H7: 37.9 | I7: -1.45 | J7: 36.45 | K7: sarah.kregehr@gmx.net | L7: info@artestaposters.com | M7: 7KG57170CV926344H | N7: Sarah Kregehr, Zastrowstr. 42, Kiel, 24114, Alemania | O7: Confirmada | P7: Sun Setting on the Seine (Special Edition) - Claude Monet - Póster / Sin marco / 50x70 | R7: 4.95 | T7: 0 | Z7: rRwVmycpJ7H781oQa99ieQMsr | AA7: {"shop_id":751927347,"session_id":"rRwVmycpJ7H781oQa99ieQMsr"} | AB7: 1 | AD7: 5566.05 | AE7: Zastrowstr. 42 | AG7: Kiel | AI7: 24114 | AJ7: Alemania | AK7: +49 4512802668576 | AL7: Sun Setting on the Seine (Special Edition) - Claude Monet - Póster / Sin marco / 50x70 | AN7: DE | AO7: Crédito | AP7: =IFERROR(VLOOKUP(M7,Shopify_Transactions!V:BB,5,0),"Not_Found") -> AS-94809 | AQ7: =IFERROR(VLOOKUP(M7,Shopify_Transactions!X:BB,3,0),"Not_Found") -> Not_Found | AR7: =IFERROR(VLOOKUP(Z7,Shopify_Transactions!W:Z,4,0),"Not_Found") -> AS-94809 | AS7: =IF(AP7<>"Not_Found",AP7,IF(AQ7<>"Not_Found",AQ7,AR7)) -> AS-94809
A8: 01/01/2026 | B8: 15:51:19 | C8: CET | D8: Simone Pirozzi | E8: Pago con Pago exprés | F8: Completado | G8: EUR | H8: 44.85 | I8: -1.65 | J8: 43.2 | K8: simo.pirozzi@gmail.com | L8: info@artestaposters.com | M8: 8P573960AN1045724 | N8: Simone, Pirozzi, via IX Maggio traversa Alessandro Volta 17, Castello di Cisterna, Napoli, 80030, Italia | O8: Confirmada | P8: Ginspiration No2 - Póster / Sin marco / 30x40, Floral Campbells - Póster / Sin marco / 30x40 | R8: 4.95 | T8: 0 | Z8: rMjyZN6D6I9sEL7Hto5VLZ5p9 | AA8: {"shop_id":751927347,"session_id":"rMjyZN6D6I9sEL7Hto5VLZ5p9"} | AB8: 2 | AD8: 5609.25 | AE8: via IX Maggio traversa Alessandro Volta 17 | AG8: Castello di Cisterna | AH8: Napoli | AI8: 80030 | AJ8: Italia | AK8: +39 3337957318 | AL8: Floral Campbells - Póster / Sin marco / 30x40 | AN8: IT | AO8: Crédito | AP8: =IFERROR(VLOOKUP(M8,Shopify_Transactions!V:BB,5,0),"Not_Found") -> AS-94811 | AQ8: =IFERROR(VLOOKUP(M8,Shopify_Transactions!X:BB,3,0),"Not_Found") -> Not_Found | AR8: =IFERROR(VLOOKUP(Z8,Shopify_Transactions!W:Z,4,0),"Not_Found") -> AS-94811 | AS8: =IF(AP8<>"Not_Found",AP8,IF(AQ8<>"Not_Found",AQ8,AR8)) -> AS-94811
A9: 01/01/2026 | B9: 17:10:30 | C9: CET | D9: Theresa Litzba | E9: Pago con Pago exprés | F9: Completado | G9: EUR | H9: 63.9 | I9: -2.2 | J9: 61.7 | K9: theresa.litzba@googlemail.com | L9: info@artestaposters.com | M9: 2LR05026NW557840J | N9: Theresa Litzba, Marienstraße 2e, Köln, 50825, Alemania | O9: Confirmada | P9: Surf Down - Póster / Madera negro / 40x50 | R9: 4.95 | T9: 0 | Z9: r8Xc0vge7019LIXhiXhNAzetf | AA9: {"shop_id":751927347,"session_id":"r8Xc0vge7019LIXhiXhNAzetf"} | AB9: 1 | AD9: 5670.95 | AE9: Marienstraße 2e | AG9: Köln | AI9: 50825 | AJ9: Alemania | AK9: +49 15227402303 | AL9: Surf Down - Póster / Madera negro / 40x50 | AN9: DE | AO9: Crédito | AP9: =IFERROR(VLOOKUP(M9,Shopify_Transactions!V:BB,5,0),"Not_Found") -> AS-94816 | AQ9: =IFERROR(VLOOKUP(M9,Shopify_Transactions!X:BB,3,0),"Not_Found") -> Not_Found | AR9: =IFERROR(VLOOKUP(Z9,Shopify_Transactions!W:Z,4,0),"Not_Found") -> AS-94816 | AS9: =IF(AP9<>"Not_Found",AP9,IF(AQ9<>"Not_Found",AQ9,AR9)) -> AS-94816
A10: 01/01/2026 | B10: 17:56:27 | C10: CET | D10: Tommy Heberle | E10: Pago con Pago exprés | F10: Completado | G10: EUR | H10: 110.57 | I10: -3.56 | J10: 107.01 | K10: tommy.heberle@gmail.com | L10: info@artestaposters.com | M10: 8C034025P1221142N | N10: Tommy, Heberle, Josef-Schofer-Straße 2, Karlsruhe, 76187, Alemania | O10: Confirmada | P10: Valencia, Spain - Póster / Sin marco / 70x100, Southern Spain V - Póster / Sin marco / 50x70, Tapas - Spain - Póster / Sin marco / 70x100 | R10: 0 | T10: 0 | Z10: rFJvk30JREFXcl6eEbUWsLkXp | AA10: {"shop_id":751927347,"session_id":"rFJvk30JREFXcl6eEbUWsLkXp"} | AB10: 3 | AD10: 5777.96 | AE10: Josef-Schofer-Straße 2 | AG10: Karlsruhe | AI10: 76187 | AJ10: Alemania | AK10: +49 15170890719 | AL10: Valencia, Spain - Póster / Sin marco / 70x100 | AN10: DE | AO10: Crédito | AP10: =IFERROR(VLOOKUP(M10,Shopify_Transactions!V:BB,5,0),"Not_Found") -> AS-94820 | AQ10: =IFERROR(VLOOKUP(M10,Shopify_Transactions!X:BB,3,0),"Not_Found") -> Not_Found | AR10: =IFERROR(VLOOKUP(Z10,Shopify_Transactions!W:Z,4,0),"Not_Found") -> AS-94820 | AS10: =IF(AP10<>"Not_Found",AP10,IF(AQ10<>"Not_Found",AQ10,AR10)) -> AS-94820
A11: 01/01/2026 | B11: 18:09:37 | C11: CET | D11: Raquel Jofre | E11: Pago con Pago exprés | F11: Completado | G11: EUR | H11: 58.95 | I11: -2.06 | J11: 56.89 | K11: rjofreh25@gmail.com | L11: info@artestaposters.com | M11: 2HE95554T0540935T | N11: Raquel Jofre Hombrado, Carrer de Teresa de Calcuta 21, SÚRIA, BARCELONA, 08260, España | O11: Confirmada | P11: Movement of Vaulted Chambers Exhibition - Paul Klee - Póster / Madera negro / 40x50 | R11: 0 | T11: 0 | Z11: ruDxI3uIiZwfoIlaEeyx7b0H7 | AA11: {"shop_id":751927347,"session_id":"ruDxI3uIiZwfoIlaEeyx7b0H7"} | AB11: 1 | AD11: 5834.85 | AE11: Carrer de Teresa de Calcuta 21 | AG11: SÚRIA | AH11: BARCELONA | AI11: 8260 | AJ11: España | AK11: +34 680762886 | AL11: Movement of Vaulted Chambers Exhibition - Paul Klee - Póster / Madera negro / 40x50 | AN11: ES | AO11: Crédito | AP11: =IFERROR(VLOOKUP(M11,Shopify_Transactions!V:BB,5,0),"Not_Found") -> AS-94821 | AQ11: =IFERROR(VLOOKUP(M11,Shopify_Transactions!X:BB,3,0),"Not_Found") -> Not_Found | AR11: =IFERROR(VLOOKUP(Z11,Shopify_Transactions!W:Z,4,0),"Not_Found") -> AS-94821 | AS11: =IF(AP11<>"Not_Found",AP11,IF(AQ11<>"Not_Found",AQ11,AR11)) -> AS-94821
A12: 01/01/2026 | B12: 18:12:36 | C12: CET | D12: Arne Lummerzheim | E12: Pago con Pago exprés | F12: Completado | G12: EUR | H12: 67.95 | I12: -2.32 | J12: 65.63 | K12: alu100@web.de | L12: info@artestaposters.com | M12: 8KA47748T9168140F | N12: Arne Lummerzheim, Parkstr. 26, Berlin, 13585, Alemania | O12: Confirmada | P12: Black Montmartre - Paris Step by Step - Póster / Madera negro / 50x70 | R12: 0 | T12: 0 | Z12: rG4TUudLGNFxxBFzCn9g0yuPn | AA12: {"shop_id":751927347,"session_id":"rG4TUudLGNFxxBFzCn9g0yuPn"} | AB12: 1 | AD12: 5900.48 | AE12: Parkstr. 26 | AG12: Berlin | AI12: 13585 | AJ12: Alemania | AK12: +49 015222571986 | AL12: Black Montmartre - Paris Step by Step - Póster / Madera negro / 50x70 | AN12: DE | AO12: Crédito | AP12: =IFERROR(VLOOKUP(M12,Shopify_Transactions!V:BB,5,0),"Not_Found") -> AS-94822 | AQ12: =IFERROR(VLOOKUP(M12,Shopify_Transactions!X:BB,3,0),"Not_Found") -> Not_Found | AR12: =IFERROR(VLOOKUP(Z12,Shopify_Transactions!W:Z,4,0),"Not_Found") -> AS-94822 | AS12: =IF(AP12<>"Not_Found",AP12,IF(AQ12<>"Not_Found",AQ12,AR12)) -> AS-94822
A13: 01/01/2026 | B13: 19:36:42 | C13: CET | D13: Niko Simak | E13: Pago con Pago exprés | F13: Completado | G13: EUR | H13: 182.85 | I13: -5.65 | J13: 177.2 | K13: niko.simak@t-online.de | L13: info@artestaposters.com | M13: 9SP93479742422154 | N13: Niko Simak, Am Gries 7, Erding, 85435, Alemania | O13: Confirmada | P13: Botanical, Fleurs et plantes -Ginkgo biloba leaf - Póster / Madera roble natural / 60x90, Exposition de linogravure, Ginkgo leaves - Póster / Madera roble natural / 60x90, Pablo Picasso Animals Drawings the elephant - Póster / Sin marco / 20x30 | R13: 0 | T13: 0 | Z13: rzPm2b27wgLuQh7pFm4XtuJcq | AA13: {"shop_id":751927347,"session_id":"rzPm2b27wgLuQh7pFm4XtuJcq"} | AB13: 3 | AD13: 6077.68 | AE13: Am Gries 7 | AG13: Erding | AI13: 85435 | AJ13: Alemania | AK13: +49 17663656458 | AL13: Exposition de linogravure, Ginkgo leaves - Póster / Madera roble natural / 60x90 | AN13: DE | AO13: Crédito | AP13: =IFERROR(VLOOKUP(M13,Shopify_Transactions!V:BB,5,0),"Not_Found") -> AS-94831 | AQ13: =IFERROR(VLOOKUP(M13,Shopify_Transactions!X:BB,3,0),"Not_Found") -> Not_Found | AR13: =IFERROR(VLOOKUP(Z13,Shopify_Transactions!W:Z,4,0),"Not_Found") -> AS-94831 | AS13: =IF(AP13<>"Not_Found",AP13,IF(AQ13<>"Not_Found",AQ13,AR13)) -> AS-94831
A14: 01/01/2026 | B14: 20:54:56 | C14: CET | D14: Carlo Lancini | E14: Pago con Pago exprés | F14: Completado | G14: EUR | H14: 79.9 | I14: -2.67 | J14: 77.23 | K14: carlolancini@tiscali.it | L14: info@artestaposters.com | M14: 4F210044PU032664W | N14: Carlo Lancini, Via Francesco Petrarca 8, Stezzano, Bergamo, 24040, Italia | O14: Confirmada | P14: Winter morning - Póster / Sin marco / 60x90, Chirping And Chilling (At Night) - Póster / Sin marco / 60x90 | R14: 0 | T14: 0 | Z14: rxZgU1TOGAExn1C9mOmxBbVeR | AA14: {"shop_id":751927347,"session_id":"rxZgU1TOGAExn1C9mOmxBbVeR"} | AB14: 2 | AD14: 6154.91 | AE14: Via Francesco Petrarca 8 | AG14: Stezzano | AH14: Bergamo | AI14: 24040 | AJ14: Italia | AK14: +39 0354379421 | AL14: Winter morning - Póster / Sin marco / 60x90 | AN14: IT | AO14: Crédito | AP14: =IFERROR(VLOOKUP(M14,Shopify_Transactions!V:BB,5,0),"Not_Found") -> AS-94835 | AQ14: =IFERROR(VLOOKUP(M14,Shopify_Transactions!X:BB,3,0),"Not_Found") -> Not_Found | AR14: =IFERROR(VLOOKUP(Z14,Shopify_Transactions!W:Z,4,0),"Not_Found") -> AS-94835 | AS14: =IF(AP14<>"Not_Found",AP14,IF(AQ14<>"Not_Found",AQ14,AR14)) -> AS-94835
A15: 01/01/2026 | B15: 21:42:06 | C15: CET | D15: EURIDICE LAZALDE GUTIERREZ | E15: Pago con Pago exprés | F15: Completado | G15: EUR | H15: 67.95 | I15: -2.32 | J15: 65.63 | K15: euridice.lazalde.gtz@gmail.com | L15: info@artestaposters.com | M15: 6C912892W3965535M | N15: Euridice LAZALDE Gutierrez, Viale Umbria 1, Bastia Umbra, Perugia, 06083, Italia | O15: Confirmada | P15: Mexico - Póster / Madera roble oscuro / 50x70 | R15: 0 | T15: 0 | Z15: r6B3qrX1uRteuXK2YCKzrIfBI | AA15: {"shop_id":751927347,"session_id":"r6B3qrX1uRteuXK2YCKzrIfBI"} | AB15: 1 | AD15: 6220.54 | AE15: Viale Umbria 1 | AG15: Bastia Umbra | AH15: Perugia | AI15: 6083 | AJ15: Italia | AK15: +39 3885820350 | AL15: Mexico - Póster / Madera roble oscuro / 50x70 | AN15: IT | AO15: Crédito | AP15: =IFERROR(VLOOKUP(M15,Shopify_Transactions!V:BB,5,0),"Not_Found") -> AS-94839 | AQ15: =IFERROR(VLOOKUP(M15,Shopify_Transactions!X:BB,3,0),"Not_Found") -> Not_Found | AR15: =IFERROR(VLOOKUP(Z15,Shopify_Transactions!W:Z,4,0),"Not_Found") -> AS-94839 | AS15: =IF(AP15<>"Not_Found",AP15,IF(AQ15<>"Not_Found",AQ15,AR15)) -> AS-94839
A16: 01/01/2026 | B16: 21:44:39 | C16: CET | D16: rolf clostermann | E16: Pago con Pago exprés | F16: Completado | G16: EUR | H16: 114.95 | I16: -3.68 | J16: 111.27 | K16: leslie.clostermann@gmail.com | L16: info@artestaposters.com | M16: 8HR26733VV295503E | N16: Leslie Clostermann, Gabainstr. 6, Wesel, 46483, Alemania | O16: Confirmada | P16: Mid Century Blue II - Lienzo / Madera negro / 50x70 | R16: 0 | T16: 0 | Z16: rH6WAmFf83ZbXZf2icWvwM9oM | AA16: {"shop_id":751927347,"session_id":"rH6WAmFf83ZbXZf2icWvwM9oM"} | AB16: 1 | AD16: 6331.81 | AE16: Gabainstr. 6 | AG16: Wesel | AI16: 46483 | AJ16: Alemania | AK16: +49 028599010125 | AL16: Mid Century Blue II - Lienzo / Madera negro / 50x70 | AN16: DE | AO16: Crédito | AP16: =IFERROR(VLOOKUP(M16,Shopify_Transactions!V:BB,5,0),"Not_Found") -> AS-94840 | AQ16: =IFERROR(VLOOKUP(M16,Shopify_Transactions!X:BB,3,0),"Not_Found") -> Not_Found | AR16: =IFERROR(VLOOKUP(Z16,Shopify_Transactions!W:Z,4,0),"Not_Found") -> AS-94840 | AS16: =IF(AP16<>"Not_Found",AP16,IF(AQ16<>"Not_Found",AQ16,AR16)) -> AS-94840
A17: 01/01/2026 | B17: 22:09:51 | C17: CET | D17: Reni Ahlborn | E17: Pago con Pago exprés | F17: Completado | G17: EUR | H17: 71.91 | I17: -2.44 | J17: 69.47 | K17: irene.ahlborn@web.de | L17: info@artestaposters.com | M17: 0BC33688L92679619 | N17: Irene Schwab-Ahlborn, Moorweg 45a, Schenefeld, 22869, Alemania | O17: Confirmada | P17: Pablo Picasso The Three Dancers Sktech poster - Póster / Sin marco / 60x90, Picasso Ladies of Avignon sketch Poster - Póster / Sin marco / 60x90 | R17: 0 | T17: 0 | Z17: r29RRtLUvXL6Tz39L5TWtgNnA | AA17: {"shop_id":751927347,"session_id":"r29RRtLUvXL6Tz39L5TWtgNnA"} | AB17: 2 | AD17: 6401.28 | AE17: Moorweg 45a | AG17: Schenefeld | AI17: 22869 | AJ17: Alemania | AK17: +49 15752834664 | AL17: Picasso Ladies of Avignon sketch Poster - Póster / Sin marco / 60x90 | AN17: DE | AO17: Crédito | AP17: =IFERROR(VLOOKUP(M17,Shopify_Transactions!V:BB,5,0),"Not_Found") -> AS-94842 | AQ17: =IFERROR(VLOOKUP(M17,Shopify_Transactions!X:BB,3,0),"Not_Found") -> Not_Found | AR17: =IFERROR(VLOOKUP(Z17,Shopify_Transactions!W:Z,4,0),"Not_Found") -> AS-94842 | AS17: =IF(AP17<>"Not_Found",AP17,IF(AQ17<>"Not_Found",AQ17,AR17)) -> AS-94842
A18: 01/01/2026 | B18: 22:23:43 | C18: CET | D18: Doreen Epstein | E18: Pago con Pago exprés | F18: Completado | G18: EUR | H18: 84.95 | I18: -2.81 | J18: 82.14 | K18: doreen.epstein@yahoo.de | L18: info@artestaposters.com | M18: 2FT21109V73915801 | N18: Doreen Epstein, Bürschgartenstraße 13, Wiesbaden, 65193, Alemania | O18: Confirmada | P18: La vie en France, St Tropez - Póster / Madera roble natural / 60x90 | R18: 0 | T18: 0 | Z18: rnDbfCSBaL9MVyHPi73lToJBJ | AA18: {"shop_id":751927347,"session_id":"rnDbfCSBaL9MVyHPi73lToJBJ"} | AB18: 1 | AD18: 6483.42 | AE18: Bürschgartenstraße 13 | AG18: Wiesbaden | AI18: 65193 | AJ18: Alemania | AK18: +49 17670067582 | AL18: La vie en France, St Tropez - Póster / Madera roble natural / 60x90 | AN18: DE | AO18: Crédito | AP18: =IFERROR(VLOOKUP(M18,Shopify_Transactions!V:BB,5,0),"Not_Found") -> AS-94843 | AQ18: =IFERROR(VLOOKUP(M18,Shopify_Transactions!X:BB,3,0),"Not_Found") -> Not_Found | AR18: =IFERROR(VLOOKUP(Z18,Shopify_Transactions!W:Z,4,0),"Not_Found") -> AS-94843 | AS18: =IF(AP18<>"Not_Found",AP18,IF(AQ18<>"Not_Found",AQ18,AR18)) -> AS-94843
A19: 01/01/2026 | B19: 23:40:36 | C19: CET | D19: Carolin Weihrauch | E19: Pago con Pago exprés | F19: Completado | G19: EUR | H19: 37.9 | I19: -1.45 | J19: 36.45 | K19: carolin-weihrauch@gmx.de | L19: info@artestaposters.com | M19: 2K825256CU025401D | N19: Carolin Weihrauch, Giselherstraße 13, Weinheim, 69469, Alemania | O19: Confirmada | P19: Maddies Mood - jotadejai - Póster / Sin marco / 50x70 | R19: 4.95 | T19: 0 | Z19: rbTKDXCCwJiLkypzQK0aXfiSm | AA19: {"shop_id":751927347,"session_id":"rbTKDXCCwJiLkypzQK0aXfiSm"} | AB19: 1 | AD19: 6519.87 | AE19: Giselherstraße 13 | AG19: Weinheim | AI19: 69469 | AJ19: Alemania | AK19: +49 17630426806 | AL19: Maddies Mood - jotadejai - Póster / Sin marco / 50x70 | AN19: DE | AO19: Crédito | AP19: =IFERROR(VLOOKUP(M19,Shopify_Transactions!V:BB,5,0),"Not_Found") -> AS-94847 | AQ19: =IFERROR(VLOOKUP(M19,Shopify_Transactions!X:BB,3,0),"Not_Found") -> Not_Found | AR19: =IFERROR(VLOOKUP(Z19,Shopify_Transactions!W:Z,4,0),"Not_Found") -> AS-94847 | AS19: =IF(AP19<>"Not_Found",AP19,IF(AQ19<>"Not_Found",AQ19,AR19)) -> AS-94847
A20: 02/01/2026 | B20: 03:06:04 | C20: CET | D20: Judith Heuer | E20: Pago con Pago exprés | F20: Completado | G20: EUR | H20: 24.9 | I20: -1.07 | J20: 23.83 | K20: juditheuer@web.de | L20: info@artestaposters.com | M20: 0H471785HL184274D | N20: Judith, Heuer, Bollerstaudenstrasse 6, Freiburg, 79111, Alemania | O20: Confirmada | P20: Linocut Tree - Alisa Galitsyna - Póster / Sin marco / 30x40 | R20: 4.95 | T20: 0 | Z20: r4vSAwDFqAFODjgyeQwb7YqUE | AA20: {"shop_id":751927347,"session_id":"r4vSAwDFqAFODjgyeQwb7YqUE"} | AB20: 1 | AD20: 6543.7 | AE20: Bollerstaudenstrasse 6 | AG20: Freiburg | AI20: 79111 | AJ20: Alemania | AK20: +49 7617070086 | AL20: Linocut Tree - Alisa Galitsyna - Póster / Sin marco / 30x40 | AN20: DE | AO20: Crédito | AP20: =IFERROR(VLOOKUP(M20,Shopify_Transactions!V:BB,5,0),"Not_Found") -> AS-94852 | AQ20: =IFERROR(VLOOKUP(M20,Shopify_Transactions!X:BB,3,0),"Not_Found") -> Not_Found | AR20: =IFERROR(VLOOKUP(Z20,Shopify_Transactions!W:Z,4,0),"Not_Found") -> AS-94852 | AS20: =IF(AP20<>"Not_Found",AP20,IF(AQ20<>"Not_Found",AQ20,AR20)) -> AS-94852
A21: 02/01/2026 | B21: 09:20:38 | C21: CET | D21: Antonella D'Agostino | E21: Reembolso de pago | F21: Completado | G21: EUR | H21: -42.5 | I21: 0 | J21: -42.5 | K21: info@artestaposters.com | L21: adagostino79@gmail.com | M21: 70D38532X6560444C | O21: No confirmada | P21: Dream Big - Póster / Madera negro / 60x90 | T21: 0 | Y21: 2FT67700GT9707127 | Z21: rPCOnHayv4pz9ocWKOiTL2ERc | AA21: {"shop_id":751927347,"session_id":"zG2XibzylGeidS5KCCVD0pczx"} | AB21: 1 | AD21: 6501.2 | AK21: +39 05321914250 | AL21: Dream Big - Póster / Madera negro / 60x90 | AO21: Cargo | AP21: =IFERROR(VLOOKUP(M21,Shopify_Transactions!V:BB,5,0),"Not_Found") -> AS-93059 | AQ21: =IFERROR(VLOOKUP(M21,Shopify_Transactions!X:BB,3,0),"Not_Found") -> AS-93059 | AR21: =IFERROR(VLOOKUP(Z21,Shopify_Transactions!W:Z,4,0),"Not_Found") -> AS-93059 | AS21: =IF(AP21<>"Not_Found",AP21,IF(AQ21<>"Not_Found",AQ21,AR21)) -> AS-93059
A22: 02/01/2026 | B22: 09:34:33 | C22: CET | D22: Rolf Bernau | E22: Pago con Pago exprés | F22: Completado | G22: EUR | H22: 63.9 | I22: -2.2 | J22: 61.7 | K22: Rolf.Bernau@alice.de | L22: info@artestaposters.com | M22: 9V1082071N1257400 | N22: Herr Rolf Bernau, Freimuthstr. 8b, Falkensee, 14612, Alemania | O22: Confirmada | P22: Gustav Klimt Garden Cat Print - Póster / Madera azul / 40x50 | R22: 4.95 | T22: 0 | Z22: rLI3K6gh3jmkEQgW96GQK41mA | AA22: {"shop_id":751927347,"session_id":"rLI3K6gh3jmkEQgW96GQK41mA"} | AB22: 1 | AD22: 6562.9 | AE22: Freimuthstr. 8b | AG22: Falkensee | AI22: 14612 | AJ22: Alemania | AK22: +49 01703436160 | AL22: Gustav Klimt Garden Cat Print - Póster / Madera azul / 40x50 | AN22: DE | AO22: Crédito | AP22: =IFERROR(VLOOKUP(M22,Shopify_Transactions!V:BB,5,0),"Not_Found") -> AS-94856 | AQ22: =IFERROR(VLOOKUP(M22,Shopify_Transactions!X:BB,3,0),"Not_Found") -> Not_Found | AR22: =IFERROR(VLOOKUP(Z22,Shopify_Transactions!W:Z,4,0),"Not_Found") -> AS-94856 | AS22: =IF(AP22<>"Not_Found",AP22,IF(AQ22<>"Not_Found",AQ22,AR22)) -> AS-94856
A23: 02/01/2026 | B23: 10:27:29 | C23: CET | D23: Rainer Plehwe | E23: Pago con Pago exprés | F23: Completado | G23: EUR | H23: 101.9 | I23: -3.31 | J23: 98.59 | K23: rainer.plehwe@freenet.de | L23: info@artestaposters.com | M23: 2WY88087XH197154R | N23: Plehwe Rainer, Deelacker 5, Schuby, 24850, Alemania | O23: Confirmada | P23: Pablo Picasso Animals Drawings the cat Esquisse D’un Félin - Póster / Madera blanco / 30x40, Pablo Picasso Animals Drawings the elephant - Póster / Madera blanco / 40x50 | R23: 0 | T23: 0 | Z23: r9OZ8HZ6ZOhzXVio74XH3RfqF | AA23: {"shop_id":751927347,"session_id":"r9OZ8HZ6ZOhzXVio74XH3RfqF"} | AB23: 2 | AD23: 6661.49 | AE23: Deelacker 5 | AG23: Schuby | AI23: 24850 | AJ23: Alemania | AK23: +49 15140190935 | AL23: Pablo Picasso Animals Drawings the elephant - Póster / Madera blanco / 40x50 | AN23: DE | AO23: Crédito | AP23: =IFERROR(VLOOKUP(M23,Shopify_Transactions!V:BB,5,0),"Not_Found") -> AS-94860 | AQ23: =IFERROR(VLOOKUP(M23,Shopify_Transactions!X:BB,3,0),"Not_Found") -> Not_Found | AR23: =IFERROR(VLOOKUP(Z23,Shopify_Transactions!W:Z,4,0),"Not_Found") -> AS-94860 | AS23: =IF(AP23<>"Not_Found",AP23,IF(AQ23<>"Not_Found",AQ23,AR23)) -> AS-94860
A24: 02/01/2026 | B24: 11:44:44 | C24: CET | E24: Retención del saldo disponible | F24: Completado | G24: EUR | H24: -2037.96 | I24: 0 | J24: -2037.96 | K24: info@artestaposters.com | M24: 479232030Y9989809 | AD24: 4623.53 | AO24: Cargo | AP24: =IFERROR(VLOOKUP(M24,Shopify_Transactions!V:BB,5,0),"Not_Found") -> Not_Found | AQ24: =IFERROR(VLOOKUP(M24,Shopify_Transactions!X:BB,3,0),"Not_Found") -> Not_Found | AR24: =IFERROR(VLOOKUP(Z24,Shopify_Transactions!W:Z,4,0),"Not_Found") -> Not_Found | AS24: =IF(AP24<>"Not_Found",AP24,IF(AQ24<>"Not_Found",AQ24,AR24)) -> Not_Found
A25: 02/01/2026 | B25: 11:44:53 | C25: CET | D25: Anna Carolline Da Cruz Farath | E25: Pago con Pago en serie | F25: Completado | G25: EUR | H25: -5.4 | I25: -0.11 | J25: -5.51 | K25: info@artestaposters.com | L25: galaxyeyes.shop@gmail.com | M25: 5HA55916NW8671213 | O25: No confirmada | Y25: 479232030Y9989809 | AA25: item_1767350658_1 | AD25: 4618.02 | AL25: Has recibido un pago | AM25: Te hemos enviado un pago por PayPal. | AO25: Cargo | AP25: =IFERROR(VLOOKUP(M25,Shopify_Transactions!V:BB,5,0),"Not_Found") -> Not_Found | AQ25: =IFERROR(VLOOKUP(M25,Shopify_Transactions!X:BB,3,0),"Not_Found") -> Not_Found | AR25: =IFERROR(VLOOKUP(Z25,Shopify_Transactions!W:Z,4,0),"Not_Found") -> Not_Found | AS25: =IF(AP25<>"Not_Found",AP25,IF(AQ25<>"Not_Found",AQ25,AR25)) -> Not_Found
A26: 02/01/2026 | B26: 11:44:53 | C26: CET | D26: PayPal | E26: Cancelación de retención de cuenta general | F26: Completado | G26: EUR | H26: 5.51 | I26: 0 | J26: 5.51 | L26: info@artestaposters.com | M26: 1CE1268435728604Y | Y26: 479232030Y9989809 | AD26: 4623.53 | AL26: Has recibido un pago | AO26: Crédito | AP26: =IFERROR(VLOOKUP(M26,Shopify_Transactions!V:BB,5,0),"Not_Found") -> Not_Found | AQ26: =IFERROR(VLOOKUP(M26,Shopify_Transactions!X:BB,3,0),"Not_Found") -> Not_Found | AR26: =IFERROR(VLOOKUP(Z26,Shopify_Transactions!W:Z,4,0),"Not_Found") -> Not_Found | AS26: =IF(AP26<>"Not_Found",AP26,IF(AQ26<>"Not_Found",AQ26,AR26)) -> Not_Found
A27: 02/01/2026 | B27: 11:44:53 | C27: CET | D27: Cordula Schaefer | E27: Pago con Pago en serie | F27: Completado | G27: EUR | H27: -6 | I27: -0.12 | J27: -6.12 | K27: info@artestaposters.com | L27: cordula.schaefer@gmx.net | M27: 7R100435TV757994D | O27: No confirmada | Y27: 479232030Y9989809 | AA27: item_1767350658_4 | AD27: 4617.41 | AL27: Has recibido un pago | AM27: Te hemos enviado un pago por PayPal. | AO27: Cargo | AP27: =IFERROR(VLOOKUP(M27,Shopify_Transactions!V:BB,5,0),"Not_Found") -> Not_Found | AQ27: =IFERROR(VLOOKUP(M27,Shopify_Transactions!X:BB,3,0),"Not_Found") -> Not_Found | AR27: =IFERROR(VLOOKUP(Z27,Shopify_Transactions!W:Z,4,0),"Not_Found") -> Not_Found | AS27: =IF(AP27<>"Not_Found",AP27,IF(AQ27<>"Not_Found",AQ27,AR27)) -> Not_Found
A28: 02/01/2026 | B28: 11:44:53 | C28: CET | D28: PayPal | E28: Cancelación de retención de cuenta general | F28: Completado | G28: EUR | H28: 6.12 | I28: 0 | J28: 6.12 | L28: info@artestaposters.com | M28: 04J78733D2957040J | Y28: 479232030Y9989809 | AD28: 4623.53 | AL28: Has recibido un pago | AO28: Crédito | AP28: =IFERROR(VLOOKUP(M28,Shopify_Transactions!V:BB,5,0),"Not_Found") -> Not_Found | AQ28: =IFERROR(VLOOKUP(M28,Shopify_Transactions!X:BB,3,0),"Not_Found") -> Not_Found | AR28: =IFERROR(VLOOKUP(Z28,Shopify_Transactions!W:Z,4,0),"Not_Found") -> Not_Found | AS28: =IF(AP28<>"Not_Found",AP28,IF(AQ28<>"Not_Found",AQ28,AR28)) -> Not_Found
A29: 02/01/2026 | B29: 11:44:53 | C29: CET | D29: Dana Shek | E29: Pago con Pago en serie | F29: Completado | G29: EUR | H29: -128.25 | I29: -2.57 | J29: -130.82 | K29: info@artestaposters.com | L29: dana.shek@gmail.com | M29: 5AH16117AS090991Y | O29: No confirmada | Y29: 479232030Y9989809 | AA29: item_1767350658_5 | AD29: 4492.71 | AL29: Has recibido un pago | AM29: Te hemos enviado un pago por PayPal. | AO29: Cargo | AP29: =IFERROR(VLOOKUP(M29,Shopify_Transactions!V:BB,5,0),"Not_Found") -> Not_Found | AQ29: =IFERROR(VLOOKUP(M29,Shopify_Transactions!X:BB,3,0),"Not_Found") -> Not_Found | AR29: =IFERROR(VLOOKUP(Z29,Shopify_Transactions!W:Z,4,0),"Not_Found") -> Not_Found | AS29: =IF(AP29<>"Not_Found",AP29,IF(AQ29<>"Not_Found",AQ29,AR29)) -> Not_Found
A30: 02/01/2026 | B30: 11:44:53 | C30: CET | D30: PayPal | E30: Cancelación de retención de cuenta general | F30: Completado | G30: EUR | H30: 130.82 | I30: 0 | J30: 130.82 | L30: info@artestaposters.com | M30: 1YL56527LA047635X | Y30: 479232030Y9989809 | AD30: 4623.53 | AL30: Has recibido un pago | AO30: Crédito | AP30: =IFERROR(VLOOKUP(M30,Shopify_Transactions!V:BB,5,0),"Not_Found") -> Not_Found | AQ30: =IFERROR(VLOOKUP(M30,Shopify_Transactions!X:BB,3,0),"Not_Found") -> Not_Found | AR30: =IFERROR(VLOOKUP(Z30,Shopify_Transactions!W:Z,4,0),"Not_Found") -> Not_Found | AS30: =IF(AP30<>"Not_Found",AP30,IF(AQ30<>"Not_Found",AQ30,AR30)) -> Not_Found
A31: 02/01/2026 | B31: 11:44:53 | C31: CET | D31: Wan Alvin Mak | E31: Pago con Pago en serie | F31: Completado | G31: EUR | H31: -34.2 | I31: -0.68 | J31: -34.88 | K31: info@artestaposters.com | L31: alvinmak74@gmail.com | M31: 7T226696B7863140L | O31: No confirmada | Y31: 479232030Y9989809 | AA31: item_1767350658_0 | AD31: 4588.65 | AL31: Has recibido un pago | AM31: Te hemos enviado un pago por PayPal. | AO31: Cargo | AP31: =IFERROR(VLOOKUP(M31,Shopify_Transactions!V:BB,5,0),"Not_Found") -> Not_Found | AQ31: =IFERROR(VLOOKUP(M31,Shopify_Transactions!X:BB,3,0),"Not_Found") -> Not_Found | AR31: =IFERROR(VLOOKUP(Z31,Shopify_Transactions!W:Z,4,0),"Not_Found") -> Not_Found | AS31: =IF(AP31<>"Not_Found",AP31,IF(AQ31<>"Not_Found",AQ31,AR31)) -> Not_Found
A32: 02/01/2026 | B32: 11:44:53 | C32: CET | D32: PayPal | E32: Cancelación de retención de cuenta general | F32: Completado | G32: EUR | H32: 34.88 | I32: 0 | J32: 34.88 | L32: info@artestaposters.com | M32: 80E036948J721470W | Y32: 479232030Y9989809 | AD32: 4623.53 | AL32: Has recibido un pago | AO32: Crédito | AP32: =IFERROR(VLOOKUP(M32,Shopify_Transactions!V:BB,5,0),"Not_Found") -> Not_Found | AQ32: =IFERROR(VLOOKUP(M32,Shopify_Transactions!X:BB,3,0),"Not_Found") -> Not_Found | AR32: =IFERROR(VLOOKUP(Z32,Shopify_Transactions!W:Z,4,0),"Not_Found") -> Not_Found | AS32: =IF(AP32<>"Not_Found",AP32,IF(AQ32<>"Not_Found",AQ32,AR32)) -> Not_Found
A33: 02/01/2026 | B33: 11:44:53 | C33: CET | D33: Bruno Morphet | E33: Pago con Pago en serie | F33: Completado | G33: EUR | H33: -28.5 | I33: -0.57 | J33: -29.07 | K33: info@artestaposters.com | L33: Bruno.Morphet@gmail.com | M33: 2G741075DW400002W | O33: No confirmada | Y33: 479232030Y9989809 | AA33: item_1767350658_3 | AD33: 4594.46 | AL33: Has recibido un pago | AM33: Te hemos enviado un pago por PayPal. | AO33: Cargo | AP33: =IFERROR(VLOOKUP(M33,Shopify_Transactions!V:BB,5,0),"Not_Found") -> Not_Found | AQ33: =IFERROR(VLOOKUP(M33,Shopify_Transactions!X:BB,3,0),"Not_Found") -> Not_Found | AR33: =IFERROR(VLOOKUP(Z33,Shopify_Transactions!W:Z,4,0),"Not_Found") -> Not_Found | AS33: =IF(AP33<>"Not_Found",AP33,IF(AQ33<>"Not_Found",AQ33,AR33)) -> Not_Found
A34: 02/01/2026 | B34: 11:44:53 | C34: CET | D34: PayPal | E34: Cancelación de retención de cuenta general | F34: Completado | G34: EUR | H34: 29.07 | I34: 0 | J34: 29.07 | L34: info@artestaposters.com | M34: 56V55145H52000300 | Y34: 479232030Y9989809 | AD34: 4623.53 | AL34: Has recibido un pago | AO34: Crédito | AP34: =IFERROR(VLOOKUP(M34,Shopify_Transactions!V:BB,5,0),"Not_Found") -> Not_Found | AQ34: =IFERROR(VLOOKUP(M34,Shopify_Transactions!X:BB,3,0),"Not_Found") -> Not_Found | AR34: =IFERROR(VLOOKUP(Z34,Shopify_Transactions!W:Z,4,0),"Not_Found") -> Not_Found | AS34: =IF(AP34<>"Not_Found",AP34,IF(AQ34<>"Not_Found",AQ34,AR34)) -> Not_Found
A35: 02/01/2026 | B35: 11:44:54 | C35: CET | D35: Artem Pozdniakov | E35: Pago con Pago en serie | F35: Completado | G35: EUR | H35: -18.9 | I35: -0.38 | J35: -19.28 | K35: info@artestaposters.com | L35: brain360@yandex.kz | M35: 9RR734633M188032T | O35: No confirmada | Y35: 479232030Y9989809 | AA35: item_1767350658_2 | AD35: 4604.25 | AL35: Has recibido un pago | AM35: Te hemos enviado un pago por PayPal. | AO35: Cargo | AP35: =IFERROR(VLOOKUP(M35,Shopify_Transactions!V:BB,5,0),"Not_Found") -> Not_Found | AQ35: =IFERROR(VLOOKUP(M35,Shopify_Transactions!X:BB,3,0),"Not_Found") -> Not_Found | AR35: =IFERROR(VLOOKUP(Z35,Shopify_Transactions!W:Z,4,0),"Not_Found") -> Not_Found | AS35: =IF(AP35<>"Not_Found",AP35,IF(AQ35<>"Not_Found",AQ35,AR35)) -> Not_Found
A36: 02/01/2026 | B36: 11:44:54 | C36: CET | D36: PayPal | E36: Cancelación de retención de cuenta general | F36: Completado | G36: EUR | H36: 19.28 | I36: 0 | J36: 19.28 | L36: info@artestaposters.com | M36: 9E319528RK662944F | Y36: 479232030Y9989809 | AD36: 4623.53 | AL36: Has recibido un pago | AO36: Crédito | AP36: =IFERROR(VLOOKUP(M36,Shopify_Transactions!V:BB,5,0),"Not_Found") -> Not_Found | AQ36: =IFERROR(VLOOKUP(M36,Shopify_Transactions!X:BB,3,0),"Not_Found") -> Not_Found | AR36: =IFERROR(VLOOKUP(Z36,Shopify_Transactions!W:Z,4,0),"Not_Found") -> Not_Found | AS36: =IF(AP36<>"Not_Found",AP36,IF(AQ36<>"Not_Found",AQ36,AR36)) -> Not_Found
A37: 02/01/2026 | B37: 11:44:55 | C37: CET | D37: Gal Design | E37: Pago con Pago en serie | F37: Completado | G37: EUR | H37: -145.35 | I37: -2.91 | J37: -148.26 | K37: info@artestaposters.com | L37: Gal.pittel@gmail.com | M37: 9M926396KT904862V | O37: No confirmada | Y37: 479232030Y9989809 | AA37: item_1767350658_9 | AD37: 4475.27 | AL37: Has recibido un pago | AM37: Te hemos enviado un pago por PayPal. | AO37: Cargo | AP37: =IFERROR(VLOOKUP(M37,Shopify_Transactions!V:BB,5,0),"Not_Found") -> Not_Found | AQ37: =IFERROR(VLOOKUP(M37,Shopify_Transactions!X:BB,3,0),"Not_Found") -> Not_Found | AR37: =IFERROR(VLOOKUP(Z37,Shopify_Transactions!W:Z,4,0),"Not_Found") -> Not_Found | AS37: =IF(AP37<>"Not_Found",AP37,IF(AQ37<>"Not_Found",AQ37,AR37)) -> Not_Found
A38: 02/01/2026 | B38: 11:44:55 | C38: CET | D38: PayPal | E38: Cancelación de retención de cuenta general | F38: Completado | G38: EUR | H38: 148.26 | I38: 0 | J38: 148.26 | L38: info@artestaposters.com | M38: 8C888240FV214483B | Y38: 479232030Y9989809 | AD38: 4623.53 | AL38: Has recibido un pago | AO38: Crédito | AP38: =IFERROR(VLOOKUP(M38,Shopify_Transactions!V:BB,5,0),"Not_Found") -> Not_Found | AQ38: =IFERROR(VLOOKUP(M38,Shopify_Transactions!X:BB,3,0),"Not_Found") -> Not_Found | AR38: =IFERROR(VLOOKUP(Z38,Shopify_Transactions!W:Z,4,0),"Not_Found") -> Not_Found | AS38: =IF(AP38<>"Not_Found",AP38,IF(AQ38<>"Not_Found",AQ38,AR38)) -> Not_Found
A39: 02/01/2026 | B39: 11:44:55 | C39: CET | D39: Katherine Stinchcomb-Smit | E39: Pago con Pago en serie | F39: Completado | G39: EUR | H39: -171 | I39: -3.42 | J39: -174.42 | K39: info@artestaposters.com | L39: katherine@creativenomadsdesign.com | M39: 041116387L360802H | O39: No confirmada | Y39: 479232030Y9989809 | AA39: item_1767350658_24 | AD39: 4449.11 | AL39: Has recibido un pago | AM39: Te hemos enviado un pago por PayPal. | AO39: Cargo | AP39: =IFERROR(VLOOKUP(M39,Shopify_Transactions!V:BB,5,0),"Not_Found") -> Not_Found | AQ39: =IFERROR(VLOOKUP(M39,Shopify_Transactions!X:BB,3,0),"Not_Found") -> Not_Found | AR39: =IFERROR(VLOOKUP(Z39,Shopify_Transactions!W:Z,4,0),"Not_Found") -> Not_Found | AS39: =IF(AP39<>"Not_Found",AP39,IF(AQ39<>"Not_Found",AQ39,AR39)) -> Not_Found
A40: 02/01/2026 | B40: 11:44:55 | C40: CET | D40: PayPal | E40: Cancelación de retención de cuenta general | F40: Completado | G40: EUR | H40: 174.42 | I40: 0 | J40: 174.42 | L40: info@artestaposters.com | M40: 8V210166GD155800M | Y40: 479232030Y9989809 | AD40: 4623.53 | AL40: Has recibido un pago | AO40: Crédito | AP40: =IFERROR(VLOOKUP(M40,Shopify_Transactions!V:BB,5,0),"Not_Found") -> Not_Found | AQ40: =IFERROR(VLOOKUP(M40,Shopify_Transactions!X:BB,3,0),"Not_Found") -> Not_Found | AR40: =IFERROR(VLOOKUP(Z40,Shopify_Transactions!W:Z,4,0),"Not_Found") -> Not_Found | AS40: =IF(AP40<>"Not_Found",AP40,IF(AQ40<>"Not_Found",AQ40,AR40)) -> Not_Found
...

Sheet Shopify_Transactions
A1: order_name | B1: order_month_yyyymm | C1: payment_gateway_names | D1: tags | E1: shipping_country_code | F1: shipping_state_code | G1: standard_rate | H1: tax_rate | I1: payment_currency | J1: imp_tax | K1: imp_gross | L1: imp_net | M1: gateway_filter | N1: order_id | O1: transaction_id | P1: gateway | Q1: kind | R1: status | S1: processed_at | T1: amount | U1: currency | V1: authorization_code | W1: payment_id | X1: gateway_transaction_id | Y1: receipt_json | Z1: Pedido
A2: AS-95859 | B2: 202601 | C2: ["shopify_payments"] | E2: AT | G2: 0.2 | H2: 0.2 | I2: EUR | J2: 6.32 | K2: 37.9 | L2: 31.58 | M2: shopify_payments | N2: gid://shopify/Order/7426608431442 | O2: gid://shopify/OrderTransaction/8599963369810 | P2: shopify_payments | Q2: SALE | R2: SUCCESS | S2: 2026-01-13T18:10:18Z | T2: 37.9 | U2: EUR | V2: py_3SpC2oIkWweOM9jA0M9Sd6qA | W2: ryRAmJLD1ZVCPmmkRasoWYlsz | X2: pi_3SpC2oIkWweOM9jA02NWFee1 | Y2: "{\"id\":\"pi_3SpC2oIkWweOM9jA02NWFee1\",\"object\":\"payment_intent\",\"amount\":3790,\"amount_capturable\":0,\"amount_received\":3790,\"canceled_at\":null,\"cancellation_reason\":null,\"capture_method\":\"automatic\",\"charges\":{\"object\":\"list\",\"data\":[{\"id\":\"py_3SpC2oIkWweOM9jA0M9Sd6qA\",\"object\":\"charge\",\"amount\":3790,\"application_fee\":\"fee_1SpC5KIkWweOM9jASFaEo78M\",\"balance_transaction\":\"txn_3SpC2oIkWweOM9jA09HrGYAx\",\"captured\":true,\"created\":1768327974,\"currency\":\"eur\",\"failure_code\":null,\"failure_message\":null,\"fraud_details\":{},\"livemode\":true,\"metadata\":{\"payments_extension_type\":\"klarna\",\"payments_extension\":\"true\",\"shop_id\":\"751927347\",\"reconciliation_flow\":\"payments_api\",\"payment_id\":\"ryRAmJLD1ZVCPmmkRasoWYlsz\"},\"outcome\":{\"advice_code\":null,\"network_advice_code\":null,\"network_decline_code\":null,\"network_status\":\"approved_by_network\",\"reason\":null,\"risk_level\":\"not_assessed\",\"seller_message\":\"Payment complete.\",\"type\":\"authorized\"},\"paid\":true,\"payment_intent\":\"pi_3SpC2oIkWweOM9jA02NWFee1\",\"payment_method\":\"pm_1SpC2oIkWweOM9jA2EYptUeA\",\"payment_method_details\":{\"klarna\":{\"payer_details\":{\"address\":{\"country\":\"AT\"}},\"payment_method_category\":\"pay_now\",\"preferred_locale\":\"de-AT\"},\"type\":\"klarna\"},\"refunded\":false,\"source\":null,\"status\":\"succeeded\"}],\"has_more\":false,\"total_count\":1,\"url\":\"\\/v1\\/charges?payment_intent=pi_3SpC2oIkWweOM9jA02NWFee1\"},\"latest_charge\":\"py_3SpC2oIkWweOM9jA0M9Sd6qA\",\"confirmation_method\":\"automatic\",\"created\":1768327818,\"currency\":\"eur\",\"customer\":null,\"last_payment_error\":null,\"livemode\":true,\"metadata\":{\"payments_extension_type\":\"klarna\",\"payments_extension\":\"true\",\"shop_id\":\"751927347\",\"reconciliation_flow\":\"payments_api\",\"payment_id\":\"ryRAmJLD1ZVCPmmkRasoWYlsz\"},\"next_action\":null,\"payment_method\":\"pm_1SpC2oIkWweOM9jA2EYptUeA\",\"payment_method_types\":[\"klarna\"],\"source\":null,\"status\":\"succeeded\"}" | Z2: =+A2 -> AS-95859
A3: AS-95104 | B3: 202601 | C3: ["shopify_payments"] | E3: DE | G3: 0.19 | H3: 0.19 | I3: EUR | J3: 8.77 | K3: 54.9 | L3: 46.13 | M3: shopify_payments | N3: gid://shopify/Order/7400359297362 | O3: gid://shopify/OrderTransaction/8464260399442 | P3: shopify_payments | Q3: SALE | R3: FAILURE | S3: 2025-12-08T10:56:03Z | T3: 299.95 | U3: EUR | W3: rlbbRIqxd8gUU8YFKiAIBOirS | X3: pi_3Sc26pIkWweOM9jA2jq2XrrO | Y3: "{\"id\":\"pi_3Sc26pIkWweOM9jA2jq2XrrO\",\"object\":\"payment_intent\",\"amount\":29995,\"amount_capturable\":0,\"amount_received\":0,\"canceled_at\":null,\"cancellation_reason\":null,\"capture_method\":\"automatic\",\"latest_charge\":null,\"confirmation_method\":\"manual\",\"created\":1765191363,\"currency\":\"eur\",\"customer\":null,\"last_payment_error\":null,\"livemode\":true,\"metadata\":{\"payment_id\":\"rlbbRIqxd8gUU8YFKiAIBOirS\",\"payments_extension\":\"true\",\"payments_extension_type\":\"card\",\"reconciliation_flow\":\"payments_api\",\"shop_id\":\"751927347\"},\"next_action\":{\"redirect_to_url\":{\"return_url\":\"https:\\/\\/artestastore.com\\/payment_providers\\/stripe\\/card\\/redirect\\/complete?session_id=rlbbRIqxd8gUU8YFKiAIBOirS\",\"url\":\"https:\\/\\/hooks.stripe.com\\/3d_secure_2\\/hosted?merchant=acct_1DdFjfIkWweOM9jA\\u0026payment_intent=pi_3Sc26pIkWweOM9jA2jq2XrrO\\u0026payment_intent_client_secret=pi_3Sc26pIkWweOM9jA2jq2XrrO_secret_ef4S0PGR9zevFMntKoouiqU0H\\u0026publishable_key=pk_live_xwMOVE2fmfvPMkkSA3diVqSq\\u0026source=payatt_3Sc26pIkWweOM9jA2A6pOFn0\\u0026stripe_account=acct_1DdFjfIkWweOM9jA\"},\"type\":\"redirect_to_url\"},\"payment_method\":\"pm_1Sc26pIkWweOM9jA9F5CtScT\",\"payment_method_types\":[\"card\"],\"source\":null,\"status\":\"requires_action\"}" | Z3: =+A3 -> AS-95104
A4: AS-95104 | B4: 202601 | C4: ["shopify_payments"] | E4: DE | G4: 0.19 | H4: 0.19 | I4: EUR | J4: 8.77 | K4: 54.9 | L4: 46.13 | M4: shopify_payments | N4: gid://shopify/Order/7400359297362 | O4: gid://shopify/OrderTransaction/8577337262418 | P4: shopify_payments | Q4: SALE | R4: SUCCESS | S4: 2026-01-05T06:24:45Z | T4: 54.9 | U4: EUR | V4: py_3Sm7DdIkWweOM9jA2V1yK6Z5 | W4: rP0NRLxBDWnejnIkCERZUXsx6 | X4: py_3Sm7DdIkWweOM9jA2V1yK6Z5 | Y4: "{\"id\":\"py_3Sm7DdIkWweOM9jA2V1yK6Z5\",\"object\":\"charge\",\"amount\":5490,\"application_fee\":\"fee_1Sm7EwIkWweOM9jANfClgved\",\"balance_transaction\":\"txn_3Sm7DdIkWweOM9jA2UlNKmRt\",\"captured\":true,\"created\":1767594366,\"currency\":\"eur\",\"failure_code\":null,\"failure_message\":null,\"fraud_details\":{},\"livemode\":true,\"metadata\":{\"payments_extension_type\":\"klarna\",\"reconciliation_flow\":\"payments_api\",\"shop_id\":\"751927347\",\"payments_extension\":\"true\",\"payment_id\":\"rP0NRLxBDWnejnIkCERZUXsx6\"},\"outcome\":{\"advice_code\":null,\"network_advice_code\":null,\"network_decline_code\":null,\"network_status\":\"approved_by_network\",\"reason\":null,\"risk_level\":\"not_assessed\",\"seller_message\":\"Payment complete.\",\"type\":\"authorized\"},\"paid\":true,\"payment_intent\":\"pi_3Sm7DdIkWweOM9jA20Gsbkf6\",\"payment_method\":\"pm_1Sm7DdIkWweOM9jAaGOpLufk\",\"payment_method_details\":{\"klarna\":{\"payer_details\":{\"address\":{\"country\":\"DE\"}},\"payment_method_category\":\"pay_later\",\"preferred_locale\":\"de-DE\"},\"type\":\"klarna\"},\"refunded\":false,\"source\":null,\"status\":\"succeeded\"}" | Z4: =+A4 -> AS-95104
A5: AS-95870 | B5: 202601 | C5: ["shopify_payments"] | E5: DE | G5: 0.19 | H5: 0.19 | I5: EUR | J5: 10.52 | K5: 65.9 | L5: 55.38 | M5: shopify_payments | N5: gid://shopify/Order/7426812576082 | O5: gid://shopify/OrderTransaction/8600215552338 | P5: shopify_payments | Q5: SALE | R5: SUCCESS | S5: 2026-01-13T20:03:19Z | T5: 65.9 | U5: EUR | V5: py_3SpDoCIkWweOM9jA1lSznUf1 | W5: rz5DDrJfvXuxGAl6nxxD9lbx2 | X5: pi_3SpDoCIkWweOM9jA1ILkq7VU | Y5: "{\"id\":\"pi_3SpDoCIkWweOM9jA1ILkq7VU\",\"object\":\"payment_intent\",\"amount\":6590,\"amount_capturable\":0,\"amount_received\":6590,\"canceled_at\":null,\"cancellation_reason\":null,\"capture_method\":\"automatic\",\"charges\":{\"object\":\"list\",\"data\":[{\"id\":\"py_3SpDoCIkWweOM9jA1lSznUf1\",\"object\":\"charge\",\"amount\":6590,\"application_fee\":\"fee_1SpDpLIkWweOM9jANuw67Ln2\",\"balance_transaction\":\"txn_3SpDoCIkWweOM9jA18LvrbSn\",\"captured\":true,\"created\":1768334671,\"currency\":\"eur\",\"failure_code\":null,\"failure_message\":null,\"fraud_details\":{},\"livemode\":true,\"metadata\":{\"payments_extension_type\":\"klarna\",\"reconciliation_flow\":\"payments_api\",\"shop_id\":\"751927347\",\"payments_extension\":\"true\",\"payment_id\":\"rz5DDrJfvXuxGAl6nxxD9lbx2\"},\"outcome\":{\"advice_code\":null,\"network_advice_code\":null,\"network_decline_code\":null,\"network_status\":\"approved_by_network\",\"reason\":null,\"risk_level\":\"not_assessed\",\"seller_message\":\"Payment complete.\",\"type\":\"authorized\"},\"paid\":true,\"payment_intent\":\"pi_3SpDoCIkWweOM9jA1ILkq7VU\",\"payment_method\":\"pm_1SpDoCIkWweOM9jAc50ynxkb\",\"payment_method_details\":{\"klarna\":{\"payer_details\":{\"address\":{\"country\":\"DE\"}},\"payment_method_category\":\"pay_later\",\"preferred_locale\":\"de-DE\"},\"type\":\"klarna\"},\"refunded\":false,\"source\":null,\"status\":\"succeeded\"}],\"has_more\":false,\"total_count\":1,\"url\":\"\\/v1\\/charges?payment_intent=pi_3SpDoCIkWweOM9jA1ILkq7VU\"},\"latest_charge\":\"py_3SpDoCIkWweOM9jA1lSznUf1\",\"confirmation_method\":\"automatic\",\"created\":1768334600,\"currency\":\"eur\",\"customer\":null,\"last_payment_error\":null,\"livemode\":true,\"metadata\":{\"payments_extension_type\":\"klarna\",\"reconciliation_flow\":\"payments_api\",\"shop_id\":\"751927347\",\"payments_extension\":\"true\",\"payment_id\":\"rz5DDrJfvXuxGAl6nxxD9lbx2\"},\"next_action\":null,\"payment_method\":\"pm_1SpDoCIkWweOM9jAc50ynxkb\",\"payment_method_types\":[\"klarna\"],\"source\":null,\"status\":\"succeeded\"}" | Z5: =+A5 -> AS-95870
A6: AS-96440 | B6: 202601 | C6: [] | D6: Claim, GLS, Logistics | E6: ES | G6: 0.21 | H6: 0 | I6: EUR | J6: 0 | K6: 0 | L6: 0 | M6: other | Z6: =+A6 -> AS-96440
